Workbook
Name IQ_CH: 110000
Name IQ_CQ: 5000
Name IQ_CY: 10000
Name IQ_DAILY: 500000
Name IQ_FH: 100000
Name IQ_FQ: 500
Name IQ_FY: 1000
Name IQ_LTM: 2000
Name IQ_MONTH: 15000
Name IQ_NTM: 6000
Name IQ_WEEK: 50000
Name IQ_YTD: 3000

Sheet Table for SF_for publication
A3: Special Feature Online Annex 1.1 Fiscal Measures in Selected Economies in Response to the COVID-19 Pandemic
A4: The Special Feature Online Annex summarizes key fiscal measures governments have announced or taken in selected economies in response to COVID-19 pandemic from January 1 to April 8, 2020. The special feature categorizes different types of fiscal support (for example, above-the-line and below-the-line measures) that have different implications for the public finances in the near term and beyond. Please refer to Box 1.1 of the April 2020 Fiscal Monitor for details. The Special Feature is not meant for comparison across members as responses vary depending on country-specific circumstances, including the impact of the pandemic and other shocks. It focuses on government discretionary measures that supplement existing automatic stabilizers. These existing stabilizers differ across countries in their breadth and scope. Estimates included here are preliminary as governments are taking additional measures or finalizing the details of individual measures. The information does not represent views of the IMF on the measures listed. For a broad range of countries on their monetary and fiscal policies in response to the pandemic, please see IMF Policy Tracker (https://www.imf.org/en/Topics/imf-and-covid19/Policy-Responses-to-COVID-19).
A5: Online Annex Table 1.1. Selected Fiscal Measures in Response to COVID-19 Pandemic (as of April 8 2020)
C7: Above-the line measures | J7: Below the line measures | O7: Contingent liabilities | S7: Other measures | U7: Links
A8: Country / Country group | D8: Total size /1 /2 | E8: Total size /2 | F8: Spending and revenue measures in the health sector | G8: Total size | H8: Spending and revenue measures in areas other than health | K8: Total size | L8: Total size /2 | M8: Equity injections, asset purchases, loans, debt assumptions, quasi-fiscal operations, use of extra-budgetary funds | P8: Total size /2 | Q8: Guarantees on loans and other contingent liabilities | S8: Automatic stabilizers, contingency lines
A9: G20 advanced economies
A10: Australia | C10: LC bn | D10: 197.4 | E10: 3.6 | F10: Spending measures (AUS $3.6 bn): • Support for primary and aged care, hospitals, and research to ensure effective diagnosis and treatment of the infected and minimize the spread of the virus. • The Commonwealth government to pay for half of all additional costs incurred by states and territories in diagnosing and treating patients with COVID-19. | G10: =D10-E10 -> 193.8 | H10: Spending measures (AUS $188 bn): Tax-free cash payments to eligible small businesses to continue operations; wage subsidies for small businesses to keep their workers; payments to lower-income Australians, including pensioners, other social security and veteran income support recipients, and eligible concession card holders. Revenue measures (AUS 5.8 bn): Asset write-off; accelerated depreciation deductions to support investment; tax reliefs for Australian airlines and airports; waiver of fees and charges for tourism businesses in most affected regions and communities. | J10: LC bn | K10: 35 | L10: 15 | M10: • Government to provide the Australian Office of Financial Management with an investment capacity (AUS $15 bn) to invest in structured finance markets used by smaller lenders. | O10: LC bn | P10: 20 | Q10: • Under a Coronavirus SME Guarantee Scheme, government to guarantee 50 percent of loans (up to AUS $40 bn) offered by local lenders to SMEs. | S10: Parliament approved an advance authorization of A$40 billion for unforeseen events. | U10: https://treasury.gov.au/coronavirus
C11: USD bn | D11: =D10/#REF! -> #REF! | J11: USD bn | K11: =K10/VLOOKUP(A10,#REF!,7,0) -> #REF! | L11: =L10/VLOOKUP(A10,#REF!,7,0) -> #REF! | O11: USD bn | P11: =K11-L11 -> #REF!
C12: % GDP | D12: =(D10/VLOOKUP(A10,#REF!,4,0))*100 -> #REF! | J12: % GDP | K12: =(K10/VLOOKUP(A10,#REF!,4,0))*100 -> #REF! | L12: =(L10/VLOOKUP(A10,#REF!,4,0))*100 -> #REF! | O12: % GDP | P12: =(P10/VLOOKUP(A10,#REF!,4,0))*100 -> #REF!
A13: Canada | C13: LC bn | D13: =190-85+E13 -> 108.175 | E13: =1.125+2.05 -> 3.175 | F13: Spending measures (CAN $3.2 bn): Support to the health system including for increased testing, vaccine development, medical supplies, mitigation efforts; and greater support for Indigenous communities. | G13: 105 | H13: Spending measures (CAN $105 bn): Income support for firms and people , including payments to workers without access to sick leave and employment insurance, an increase in existing GST tax credits and child care benefits, support to the most vulnerable including through a new Indigenous Community Support Fund, and a firm subsidy equal to 75 percent of employee wages for up to 3 months. Deferral of payments (CAN $85 bn): Liquidity support through temporary interest-free tax deferrals for businesses and self employed, amounting to CAN $55 bn in deferred income taxes and CAN $30 bn in deferred GST/HST and customs duties for imports. | J13: LC bn | K13: 70 | L13: 5 | M13: • Farm Credit Canada will receive support from the government that will allow for an additional CAN $5 bn in lending capacity to producers, agribusinesses, and food processors. | O13: LC bn | P13: 65 | Q13: • Canada Emergency Business Account program will provide up to CAN $25 bn in funds and guarantees for eligible financial institutions to provide interest-free loans to small businesses. • SME Loan and Guarantee program will guarantee up to CAN $40 bn in lending, supported through Export Development Canada and Business Development Bank. | U13: https://www.canada.ca/en/public-health/services/diseases/coronavirus-disease-covid-19.html | V13: $100 million to support federal public health measures such as enhanced surveillance, increased testing at the National Microbiology Laboratory. The package includes $275 million for additional research such as vaccine development, $200 million for federal medical supplies, and support for Indigenous communities and education efforts. $500 million to provinces and territories for critical health care system needs and to support mitigation efforts, including access to testing, equipment and to enhance surveillance and monitoring. $50 million for Public Health Agency of Canada's COVID-19 communications and public education efforts. $2 bn to support diagnostic testing and to purchase ventilators and protective personal equipment, including for bulk purchases with provinces and territories. Personal protective equipment includes things like more masks and face shields, gowns, and hand sanitizer. $50 million has been made available in funding for members of the Next Generation Manufacturing Supercluster to develop and scale-up new, in-demand technologies, equipment, and medical products.
C14: USD bn | D14: =D13/VLOOKUP(A13,#REF!,7,0) -> #REF! | J14: USD bn | L14: =L13/VLOOKUP(A13,#REF!,7,0) -> #REF! | O14: USD bn | P14: =P13/VLOOKUP(A13,#REF!,7,0) -> #REF!
C15: % GDP | D15: =(D13/VLOOKUP(A13,#REF!,4,0))*100 -> #REF! | J15: % GDP | L15: =(L13/VLOOKUP(A13,#REF!,4,0))*100 -> #REF! | O15: % GDP | P15: =(P13/VLOOKUP(A13,#REF!,4,0))*100 -> #REF!
A16: Euro Area/ European Union | C16: LC bn | D16: 37 | E16: 0.05 | F16: Spending measures (€0.05 bn): The European Commission redirected funding of €47.5 million towards research on COVID-19 vaccine development, treatment, and diagnostics. | G16: 37 | H16: Spending measures (€37 bn): • The European Commission announced that the size of the Corona Response Investment Initiative will be raised to €37 bn, to support public investment for hospitals, labor markets, and stressed regions. • The Commission proposed to extend the scope of the EU Solidarity Fund by also including a public health crisis within its scope, in view of mobilizing it if needed for the hardest hit EU member states. Up to €0.8 bn is available in 2020. | J16: LC bn | K16: 1 | O16: LC bn | P16: 1 | Q16: • Redirecting €1 bn from the EU Budget as a guarantee to the European Investment Fund to incentivize banks to provide liquidity to hit SMEs and midcaps. | S16: The European Commission also activated the general escape clause in the EU fiscal rules, which suspends the fiscal adjustment requirements for countries not at their medium-term objective and allow countries to run deficits in excess of 3 percent of GDP. Credit holidays to existing debtors that are negatively affected will be provided.
C17: USD bn | D17: =D16/VLOOKUP(A16,#REF!,6,0) -> #REF! | J17: USD bn | O17: USD bn | P17: =P16/VLOOKUP(A16,#REF!,7,0) -> #REF!
C18: % GDP | D18: =(D16/VLOOKUP(A16,#REF!,4,0))*100 -> #REF! | J18: % GDP | O18: % GDP | P18: =(P16/VLOOKUP(A16,#REF!,4,0))*100 -> #REF!
A19: France | C19: LC bn | D19: =11+5.5 -> 16.5 | E19: 2 | F19: Spending measures (€5.5 bn): Support for streamlining and boosting health insurance for the sick or their caregivers, and higher spending on health supplies . | G19: 9.5 | H19: Spending measures (€11 bn): Subsidies for wages of workers under the reduced-hour scheme and direct financial support to affected SMEs and independent workers. Deferral of payments/advance pay of liabilities (€48.5 bn): • Liquidity support through postponement of social security contributions and tax payment for companies, and rent and utility payments for affected SMEs. • Accelerated refund of tax credits (e.g. CIT and VAT). | J19: LC bn | K19: =P19 -> 312 | O19: LC bn | P19: 312 | Q19: • State guarantees for bank loans to companies (€300 bn). | S19: Liquidity support through postponement of social security contributions and tax payment for companies (€33.5 bn). | U19: https://www.economie.gouv.fr/coronavirus-soutien-entreprises#
C20: USD bn | D20: =D19/VLOOKUP(A19,#REF!,7,0) -> #REF! | J20: USD bn | K20: =P20 -> #REF! | O20: USD bn | P20: =P19/VLOOKUP(A19,#REF!,7,0) -> #REF!
C21: % GDP | D21: =(D19/VLOOKUP(A19,#REF!,4,0))*100 -> #REF! | J21: % GDP | K21: =P21 -> #REF! | O21: % GDP | P21: =(P19/VLOOKUP(A19,#REF!,4,0))*100 -> #REF!
A22: Germany | C22: LC bn | D22: 143 | E22: 11.2 | F22: Spending measures (€11.2 bn): Additional spending on hospital capacity, medical equipment, research, and information campaigns . | G22: =D22-E22 -> 131.8 | H22: Spending measures (€131.8 bn): including grants to hard hit small businesses and self-employed, increased access to childcare and basic social security benefits, and temporary relief to affected tenants. There is also support to firms and households provided through the “Kurzabeit” program, part of which could be considered discretionary because the program parameters have been changed. Deferral of payments: including options for deferring tax payments and reducing prepayments until the year-end without penalties. | J22: LC bn | K22: 1025 | L22: 200 | M22: • An economic stabilization fund (WSF) of €600 bn is setup with three components: (i) €100 bn for government equity investments in significantly affected companies; (ii) €100 bn loan to state development bank KfW for financing affected firms that do not have access to KfW’s existing programs; | O22: LC bn | P22: =825-63 -> 762 | Q22: (iii) €400 bn to provide additional state guarantees to non-financial corporations to alleviate liquidity bottlenecks and support refinancing. • An expansion of the existing KfW-programs, by increasing the guarantee framework for KfW to €822 bn from the current €460 bn. • Total guarantees provided by state governments to be increased by €63 bn. | S22: The government provides options for deferring tax payments and reducing prepayments; while tax penalties will not be levied until the end of this year. | U22: https://www.bundesregierung.de/breg-de/themen/coronavirus
C23: USD bn | D23: =D22/VLOOKUP(A22,#REF!,7,0) -> #REF! | J23: USD bn | L23: =L22/VLOOKUP(A22,#REF!,7,0) -> #REF! | O23: USD bn | P23: =P22/VLOOKUP(A22,#REF!,7,0) -> #REF!
C24: % GDP | D24: =(D22/VLOOKUP(A22,#REF!,4,0))*100 -> #REF! | J24: % GDP | L24: =(L22/VLOOKUP(A22,#REF!,4,0))*100 -> #REF! | O24: % GDP | P24: =(P22/VLOOKUP(A22,#REF!,4,0))*100 -> #REF!
A25: Italy | C25: LC bn | D25: 20 | E25: 3.2 | F25: Spending measures (€3.2 bn): including on medical equipment and staff, as well as civil protection. | G25: 10.3 | H25: Spending measures (€16.7 bn): including Income support to laid-off workers and the self-employed by broadening the wage supplementation fund (€10.3). Deferral of payments: including postponement of certain tax and social security payments for SMEs, as well as taxes and utility bill payments in most affected municipalities. | J25: LC bn | K25: 65.1 | O25: LC bn | P25: 530 | Q25: • SME loans subject to moratorium (€70 bn). The guarantee covers up to 30% of the value. • Enhancement of the SME Guarantee Fund from €40 bn to over €100 bn. • State guarantee of €0.5 bn to the state development bank—Cassa Deposit e Prestiti—to support lending and liquidity to banks to enable them to finance medium to large enterprises. • All business, the guarantee (€200) will cover between 70% and 90% of the amount financed. • Co-insurance scheme for exporters (€200). | S25: Other measures to support businesses, including tax deferrals and postponement of utility bill payments in most affected municipalities (€6.4 bn), a moratorium on loan repayments for households and SMEs, including on mortgages and overdrafts (€220 bn), incentives for financial and non-financial companies in the form of Deferred Tax Activities | U25: http://www.mef.gov.it/en/inevidenza/Protect-health-support-the-economy-preserve-employment-levels-and-incomes-00001/
C26: USD bn | D26: =D25/VLOOKUP(A25,#REF!,7,0) -> #REF! | J26: USD bn | O26: USD bn | P26: =P25/VLOOKUP(A25,#REF!,7,0) -> #REF! | U26: http://www.governo.it/it/articolo/comunicato-stampa-del-consiglio-dei-ministri-n-39/14417
C27: % GDP | D27: =(D25/VLOOKUP(A25,#REF!,4,0))*100 -> #REF! | J27: % GDP | O27: % GDP | P27: =(P25/VLOOKUP(A25,#REF!,4,0))*100 -> #REF!
A28: Japan | C28: LC bn /3 | D28: 53000 | E28: 62 | F28: Spending measures: - Transfers to local governments which could be spent on COVID-19 related measures (JPY 1.1 trillion) - Production, procurement and distribution of critical equipment such as masks and ventilators (JPY 0.2 trillion) - Other health-related measures (Support for development of vaccines, etc.) | G28: =383-78 -> 305 | H28: Spending measures: - Cash handout to affected households (JPY 300,000 per eligible household) (JPY 4.0 trillion). - Lump-sum transfer to affected firms (JPY 2 million per firm for SMEs, JPY 1 million for the self-employed) (JPY 2.3 trillion). - Subsidies for public/private financial institutions' lending (JPY 3.8 trillion) - Measures to accelerate recovery and rebuild resilient economic structure such as incentive measures for consumption in affected service sectors and infrastructure investments (in the post-containment phase) (JPY 10.8 trillion). Revenue measures: - Reduction of property tax, expansion of the loss carry-back program, etc. Deferral of payment: - Deferral of payment of taxes and social security premiums by affected firms and households for one year. | J28: LC bn | L28: 53200 | M28: - The government boosted special financing and guarantees primarily for micro, small and medium-sized business operators affected by COVID-19 through the Japan Finance Corporation and other institutions. (JPY 45 trillion) - Other off-budget operations using the Development Bank of Japan and other agencies (primarily for infrastructure projects in the post-containment phase) (JPY 8 trillion) | O28: LC bn | P28: 2000 | Q28: - Guarantees on bonds/borrowing by the Development Bank of Japan and the Japan Finance Corporation (JPY 1 trillion) - Guarantees on external bonds issued by the Development Bank of Japan and Japan Bank for International Cooperation (JPY 1 trillion) | S28: Japan has made a contribution of SDR14 million (US$19 million) to the IMF’s Catastrophe Containment and Relief Trust. The deadline for tax return filing and payment of personal income tax, gift tax, and consumption tax (for the self-employed) was extended from mid-March to mid-April; tax payments for people and businesses negatively impacted by the COVID-19 outbreak are deferred. In addition, the ¥26 trillion (about 4.8 percent of GDP) December 2019 stimulus package is being used to offset the adverse impact of COVID-19 on the economy as well as counter the economic slowdown.
C29: USD bn | D29: =D28/VLOOKUP(A28,#REF!,7,0) -> #REF! | J29: USD bn | L29: =L28/VLOOKUP(A28,#REF!,7,0) -> #REF! | O29: USD bn | P29: =P28/VLOOKUP(A28,#REF!,7,0) -> #REF!
C30: % GDP | D30: =(D28/VLOOKUP(A28,#REF!,4,0))*100 -> #REF! | J30: % GDP | L30: =(L28/VLOOKUP(A28,#REF!,4,0))*100 -> #REF! | O30: % GDP | P30: =(P28/VLOOKUP(A28,#REF!,4,0))*100 -> #REF!
A31: Korea | C31: LC bn | D31: 26000 | E31: 2500 | F31: Spending measures (KRW 2.5 tn): Epidemic prevention and treatment, support for medical institutions and quarantined households. | G31: 23500 | H31: Spending measures (KRW 21 tn): • Support for households, including employment retention support, consumption coupons for the poor, emergency family care support, and cash transfers to bottom 70% of households. • Support for local communities, including local gift certificates and local government grants for infection prevention. Support for firms, including for wages and rent for small merchants. Revenue measures (KRW 2.5 tn): Consumption tax cut for auto purchases; temporary income tax cuts for landlords who reduce commercial rents; VAT reduction for the self-employed; social security contribution cut for households. Deferral of payments: Tax deferral covering a broad range of taxes for small businesses and the self-employed in medical, tourism, performance, hospitality, and other affected sectors; social security contribution payment deferral for households. | J31: LC bn | L31: 70000 | M31: • Expand lending of both state-owned and commercial banks to SMEs, small merchants, mid-sized firms, and large companies (the latter on a case-by-case basis) including emergency lending, partial and full guarantees, and collateralization of loan obligations. | O31: LC bn | S31: Tax payment deferral covering a broad range of taxes for small businesses and the self-employed in medical, tourism, performance, hospitality, and other affected sectors. Social security contribution payment deferral for households | U31: https://english.moef.go.kr/pc/selectTbPressCenterDtl.do?boardCd=N0001&seq=4860
C32: USD bn | D32: =D31/VLOOKUP(A31,#REF!,7,0) -> #REF! | J32: USD bn | L32: =L31/VLOOKUP(A31,#REF!,7,0) -> #REF! | O32: USD bn
C33: % GDP | D33: =(D31/VLOOKUP(A31,#REF!,4,0))*100 -> #REF! | J33: % GDP | L33: =(L31/VLOOKUP(A31,#REF!,4,0))*100 -> #REF! | O33: % GDP
A34: Spain | C34: LC bn | D34: 13.9 | E34: 3.9 | F34: Spending measures (€3.9 bn): • Budget support from the contingency fund to the Ministry of Health (€1 bn); advance transfer to the regions for the regional health services (€2.8 bn); additional funding for research related to the development of drugs and vaccines (€0.1 bn). • An emergency management process for the procurement of all goods and services needed by the public sector to implement any measure to address the pandemic. | G34: =8.9-3.9 -> 5 | H34: Spending measures (€10 bn depending on the usage and duration of the measures and could be higher): · Entitlement of unemployment benefit for workers temporarily laid off under the Temporary Employment Adjustment Schemes owing to the pandemic, with no requirement for prior minimum contribution or reduction of accumulated entitlement. · Increased sick pay for COVID-19 infected workers or those quarantined, from 60 to 75 percent of the regulatory base, paid by the Social Security budget; allowance for self-employed workers affected. · A temporary subsidy for affected household employees and for temporary workers whose contract expires during the state of emergency and are not entitled to collect unemployment benefits; and additional provision of assistance to dependents. · Transfer to autonomous communities funding meals for children affected by the school closure; new rental assistance programs for certain vulnerable renters; and extension of the social benefit for energy provision. Revenue measures: • Exemptions of social contributions for affected companies that maintain employment, and a 50 percent exemption from employer’s social security contributions for workers with permanent discontinuous contracts in the tourism sector and related activities (from February to June 2020). • A 6-month suspension of social security contributions for the self-employed (for April-June), subject to a condition of continued activity in May and June; and more flexibility for workers to access savings from their pension plans. Deferral of payments of taxes for small and medium enterprises and self-employed for six months (€14 bn). | J34: LC bn | L34: 10 | M34: • Additional funding for the Instituto de Crédito Official (ICO) credit lines (€10 bn) | O34: LC bn | P34: 102 | Q34: • The government has approved a line of public guarantees and guarantees worth up to €100 bn. An additional guarantees of €2 bn for exporters through the Spanish Export Insurance Credit Company; some guarantees for loan maturity extensions to farmers using the special 2017 drought credit lines. | U34: https://www.lamoncloa.gob.es/consejodeministros/resumenes/Paginas/2020/170320-pg-consejo.aspx | V34: =849+223 -> 1072
C35: USD bn | D35: =D34/VLOOKUP(A34,#REF!,7,0) -> #REF! | J35: USD bn | L35: =L34/#REF! -> #REF! | O35: USD bn | P35: =P34/VLOOKUP(A34,#REF!,7,0) -> #REF!
C36: % GDP | D36: =(D34/VLOOKUP(A34,#REF!,4,0))*100 -> #REF! | J36: % GDP | L36: =L34/#REF!*100 -> #REF! | O36: % GDP | P36: =(P34/VLOOKUP(A34,#REF!,4,0))*100 -> #REF!
A37: United Kingdom | C37: LC bn | D37: 65 | E37: 5 | F37: Spending measures (£5 bn): • Additional funding for the National Health Service, including to expand the number of hospital beds, medical staff and equipment. Revenue measures: • Waiver of VAT and duties on critical medical imports. | G37: 60 | H37: Spending measures (£60 bn): • Income support, including a Job Retention Scheme to subsidize furloughed employees' wages and firms' social security contributions; an income support scheme for the self-employed; direct grants for small firms in the most-affected sectors; compensation for paid sick leave; strengthening the social safety net to support vulnerable people (by nearly £7 bn) under the Universal Credit and other benefit schemes; support for renters by increasing the Local Housing Allowance. • International support, with £150 million made available to the IMF’s Catastrophe Containment and Relief Trust. Revenue measures: property tax (business rate) holiday for firms in affected sectors. Deferral of payments: Liquidity support, including deferral of income tax for the self employed and VAT payments; Time to Pay arrangements (tax debt restructuring) for businesses and individuals. | J37: LC bn | K37: 330 | L37: 330 | M37: • The Coronavirus Business Interruption Loan Scheme (CBILS) launched with the British Business Bank will support SMEs with access to loans of up to £5 million and for up to 6 years. The government will cover the first 12 months of interest payments and any lender-levied fees. • Under the new Covid-19 Corporate Financing Facility (CCFF), the Bank of England will buy short term debt from larger companies. The combined size of the CBILS and CCCF schemes is £330 bn (15% of GDP). | O37: LC bn | Q37: • Under CBILS, the government will provide lenders with a guarantee of 80% on each loan. • The Coronavirus Large Business Interruption Loan Scheme (CLBILS) will provide a government guarantee of 80 percent to enable banks to make loans of up to £25 million to firms with an annual turnover of between £45 million and £500 million. | S37: Deferral of income tax for the self employed and VAT payments; property tax (business rate) holiday for firms in most affected sectors, Time to Pay arrangements (tax debt restructuring) for businesses and individuals. To support the international response, the government has made available £150 million to the IMF’s Catastrophe Containment and Relief Trust. | U37: https://www.gov.uk/government/publications/guidance-to-employers-and-businesses-about-covid-19/covid-19-support-for-businesses
C38: USD bn | D38: =D37/VLOOKUP(A37,#REF!,7,0) -> #REF! | J38: USD bn | L38: =L37/VLOOKUP(A37,#REF!,7,0) -> #REF! | O38: USD bn
C39: % GDP | D39: =(D37/VLOOKUP(A37,#REF!,4,0))*100 -> #REF! | J39: % GDP | L39: =(L37/VLOOKUP(A37,#REF!,4,0))*100 -> #REF! | O39: % GDP
A40: United States | C40: LC bn | D40: 1395 | E40: 141 | F40: Spending measures: • Coronavirus Preparedness and Response Supplemental Appropriations Act (March 6, 2020) approved with $8.3bn for treatments, drugs, and public health measures, of which US$1.25 bn is included for international assistance. • Coronavirus Aid, Relief, and Economic Security Act (March 27, 2020) approved $100 bn for hospitals, $1.32 bn for community centers, $4.3 bn for the Center of Disease Control, and $27 bn for vaccine development. | G40: =D40-E40 -> 1254 | H40: Spending measures: • Families First Coronavirus Response Act (March 16, 2020) includes an estimated $83.3 bn for 2 weeks paid sick leave, up to 3 months emergency leave for those infected (at 2/3 pay), food assistance, free virus testing; and federal transfers to states for Medicaid (increased by 6.2% during emergency period); and $1 bn in expanded unemployment insurance. • Coronavirus Aid, Relief, and Economic Security Act (March 27, 2020) includes extended unemployment insurance payments ($250 bn); transfers to state and local governments ($150 bn), food assistance ($24 bn), education funding ($30 bn), transit funding ($25 bn). Revenue measures: • Tax rebates ($250 bn) of $1,200 for singles/$2,400 for married couples filing jointly and $500 per qualifying child, employee retention tax credit ($50 bn). Deferral of payments: • IRS extended income tax filing deadline by 90 days; employers' payroll taxes are delayed to 2021 and 2022. | J40: LC bn | K40: 859 | L40: 859 | M40: • Coronavirus Aid, Relief, and Economic Security Act (March 27, 2020) includes $510 bn in loans and loan guarantees for large businesses, $349 bn in loans for small businesses. | O40: LC bn | S40: IRS extended income tax filing deadline by 90 days; Delay of employers' payroll taxes to 2021 and 2022
C41: USD bn | D41: =D40/VLOOKUP(A40,#REF!,7,0) -> #REF! | J41: USD bn | L41: =L40/VLOOKUP(A40,#REF!,7,0) -> #REF! | O41: USD bn
C42: % GDP | D42: =(D40/VLOOKUP(A40,#REF!,4,0))*100 -> #REF! | J42: % GDP | L42: =(L40/VLOOKUP(A40,#REF!,4,0))*100 -> #REF! | O42: % GDP
A44: G20 emerging market economies
...

Sheet Abweichungen
B3: AP Link für GDP Werte | D3: https://api.worldbank.org/v2/country/AUS;CAN;FRA;DEU;ITA;JPN;KOR;ESP;GBR;USA;MEX;TUR;AUT;BEL;CZE;DNK;EST;FIN;GRC;ISL;IRL;ISR;LVA;LTU;LUX;NLD;NZL;NOR;PRT;SVK;SVN;SWE;CHE;CHL;COL;CRI;HUN;POL/indicator/NY.GDP.MKTP.KD?date=2019:2019&downloadformat=excel
A8: Country | B8: Werte IMF | C8: Werte Datenbank | D8: Differenz in PP | F8: Description of the differences
A9: =Summary.Global!B9 -> Australia | B9: 0.199 | C9: 0.1841 | D9: =C9-B9 -> -0.0149 | E9: =(C9-B9)/B9 -> -0.074874372 | F9: Others than health has also consist spending of 2022. As we do not record those elements we have to subtract it, the subtraction of those 30 bn leads to almost a perfect hit
A10: =Summary.Global!B10 -> Canada | B10: 0.227 | C10: 0.216 | D10: =C10-B10 -> -0.011 | E10: =(C10-B10)/B10 -> -0.04845815
A11: =Summary.Global!B11 -> France | B11: =Summary.Global!Q11 -> 0.25003382 | C11: =Summary.Global!R11 -> 0.2612 | D11: =C11-B11 -> 0.011166183 | E11: =(C11-B11)/B11 -> 0.044658691
A12: =Summary.Global!B12 -> Germany | B12: =Summary.Global!Q12 -> 0.44833033 | C12: =Summary.Global!R12 -> 0.4595 | D12: =C12-B12 -> 0.011169673 | E12: =(C12-B12)/B12 -> 0.024913936
A13: =Summary.Global!B13 -> Italy | B13: =Summary.Global!Q13 -> 0.45259746 | C13: 0.4466 | D13: =C13-B13 -> -0.0059974566 | E13: =(C13-B13)/B13 -> -0.013251194
A14: =Summary.Global!B14 -> Japan | B14: 0.4435 | C14: 0.4303 | D14: =C14-B14 -> -0.0132 | E14: =(C14-B14)/B14 -> -0.029763247
A15: =Summary.Global!B15 -> Korea | B15: 0.1653 | C15: 0.16 | D15: =C15-B15 -> -0.0053 | E15: =(C15-B15)/B15 -> -0.032062916
A16: =Summary.Global!B16 -> Spain | B16: =Summary.Global!Q16 -> 0.21857252 | C16: =Summary.Global!R16 -> 0.2257 | D16: =C16-B16 -> 0.0071274756 | E16: =(C16-B16)/B16 -> 0.032609202
A17: =Summary.Global!B17 -> United Kingdom | B17: =Summary.Global!Q17 -> 0.30887124 | C17: 0.3199 | D17: =C17-B17 -> 0.011028758 | E17: =(C17-B17)/B17 -> 0.035706653
A18: =Summary.Global!B18 -> United States | B18: =Summary.Global!Q18 -> 0.28960396 | C18: 0.283 | D18: =C18-B18 -> -0.0066039604 | E18: =(C18-B18)/B18 -> -0.022803419
A19: =Summary.Global!B19 -> Mexico | B19: 0.0219 | C19: 0.02192 | D19: =C19-B19 -> 2e-05 | E19: =(C19-B19)/B19 -> 0.00091324201
A20: =Summary.Global!B20 -> Turkey | B20: 0.1672 | C20: 0.142 | D20: =C20-B20 -> -0.0252 | E20: =(C20-B20)/B20 -> -0.1507177 | F20: All measures are reliable and matching IMF estimates, th eonly part is I do not count the Quasi-fiscal operations (noncommercial activity of public corporations on behalf of government) as it is not a government spending as well as not special backed by the government-> this would increase the share to the numbers of the IMF
A21: =Summary.Global!B21 -> Austria | B21: =Summary.Global!Q21 -> 0.18857318 | C21: 0.1762 | D21: =C21-B21 -> -0.012373176 | E21: =(C21-B21)/B21 -> -0.06561472 | F21: 0.1762 | G21: Difference is due to FX differences and the fact that IMF counted also the automatic stabilizaotr as extra spending despite this was in the regular budget. Especially they only record the % of GDP and gives no decription of the measures in the categorys. Checking the Tracker shows that I have included all https://www.imf.org/en/topics/imf-and-covid19/policy-responses-to-covid-19?path=Topics&path=imf-and-covid19&path=Policy-Responses-to-COVID-19
A22: =Summary.Global!B22 -> Belgium | B22: =Summary.Global!Q22 -> 0.20903867 | C22: =Summary.Global!R22 -> 0.214 | D22: =C22-B22 -> 0.0049613271 | E22: =(C22-B22)/B22 -> 0.023734016
A23: =Summary.Global!B23 -> Czech republic | B23: 0.247 | C23: =Summary.Global!R23 -> 0.2464 | D23: =C23-B23 -> -0.0006 | E23: =(C23-B23)/B23 -> -0.0024291498
A24: =Summary.Global!B24 -> Denmark | B24: =Summary.Global!Q24 -> 0.20422753 | C24: 0.2083 | D24: =C24-B24 -> 0.0040724655 | E24: =(C24-B24)/B24 -> 0.019940825 | F24: 0.2083 | G24: IMF Data is wrong, they completely miss out the health spending, I've got all the sources that perfectly add up to 500
A25: =Summary.Global!B25 -> Estonia | B25: =Summary.Global!Q25 -> 0.10854569 | C25: 0.1578 | D25: =C25-B25 -> 0.049254315 | E25: =(C25-B25)/B25 -> 0.45376575 | F25: 0.1578 | G25: Difference is the tax deferral https://news.err.ee/1073742/supplementary-budget-passes-its-first-riigikogu-reading who is completely missed out in the IMF document. When withdrawing thi smeasure I will be around 11%
A26: =Summary.Global!B26 -> Finland | B26: 0.142 | C26: 0.1489 | D26: =C26-B26 -> 0.0069 | E26: =(C26-B26)/B26 -> 0.048591549
A27: =Summary.Global!B27 -> Greece | B27: =Summary.Global!Q27 -> 0.19442999 | C27: 0.188 | D27: =C27-B27 -> -0.0064299858 | E27: =(C27-B27)/B27 -> -0.033070957
A28: =Summary.Global!B28 -> Iceland | B28: =Summary.Global!Q28 -> 0.11765787 | C28: 0.112 | D28: =C28-B28 -> -0.0056578686 | E28: =(C28-B28)/B28 -> -0.048087464
A29: =Summary.Global!B29 -> Ireland | B29: 0.143 | C29: 0.125 | D29: =C29-B29 -> -0.018 | E29: =(C29-B29)/B29 -> -0.12587413 | F29: Effectiv number were lot lower, official report and budget/statement of government proving that as well as ESRB https://www.esrb.europa.eu/home/search/coronavirus/countries/html/esrb.covidpmc_Ireland.en.html
A30: =Summary.Global!B30 -> Israel | B30: =Summary.Global!Q30 -> 0.16311979 | C30: 0.1636 | D30: =C30-B30 -> 0.00048020785 | E30: =(C30-B30)/B30 -> 0.0029438969
A31: =Summary.Global!B31 -> Latvia | B31: =Summary.Global!Q31 -> 0.1437927 | C31: 0.1441 | D31: =C31-B31 -> 0.00030730102 | E31: =(C31-B31)/B31 -> 0.0021371114
A32: =Summary.Global!B32 -> Lithuania | B32: =Summary.Global!Q32 -> 0.12193285 | C32: 0.117 | D32: =C32-B32 -> -0.0049328485 | E32: =(C32-B32)/B32 -> -0.040455452
A33: =Summary.Global!B33 -> Luxembourg | B33: 0.109 | C33: 0.104 | D33: =C33-B33 -> -0.005 | E33: =(C33-B33)/B33 -> -0.04587156
A34: =Summary.Global!B34 -> The Netherlands | B34: 0.159 | C34: 0.1597 | D34: =C34-B34 -> 0.0007 | E34: =(C34-B34)/B34 -> 0.0044025157
A35: =Summary.Global!B35 -> New Zealand | B35: 0.1535 | C35: 0.17 | D35: =C35-B35 -> 0.0165 | E35: =(C35-B35)/B35 -> 0.10749186 | F35: The sum of all listed measures are simply wrong in the IMF database (overestimate it by 6 pp. Wage subsidies was effective used by 18bn and IMF onli records the first bracket swith 13.9bn. This can be shown in the official report https://www.msd.govt.nz/documents/about-msd-and-our-work/publications-resources/statistics/covid-19/who-received-the-2021-covid-19-wage-subsidies.pdf. Another difference arised in the loans, the IMF do not ocunt the spoken loan amounts of 2.26bn but is clearly statet in the official report https://www.taxpolicy.ird.govt.nz/-/media/project/ir/tp/publications/2021/2021-ir-crsp-activation/2021-ir-crsp-activation.pdf?modified=20210728054252 As well as the wrong numbers in the guarantee section that is also documented in official sources: https://www.treasury.govt.nz/news-and-events/news/business-finance-guarantee-scheme-open-business | G35: This all adds up to a difference of like 9bn what woul leave us with the exact same amount from the imf->e.g., 42bn
A36: =Summary.Global!B36 -> Norway | B36: 0.102 | C36: =Summary.Global!R36 -> 0.0988 | D36: =C36-B36 -> -0.0032 | E36: =(C36-B36)/B36 -> -0.031372549
A37: =Summary.Global!B37 -> Portugal | B37: =Summary.Global!Q37 -> 0.12139874 | C37: 0.149 | D37: =C37-B37 -> 0.027601264 | E37: =(C37-B37)/B37 -> 0.22736039 | F37: 0.149 | G37: Difference is due to the wrong counted value of the guarantees in the IMF document-> when we adjust it to the IMF values we hit 12.5%-> see here: https://ec.europa.eu/competition/state_aid/cases1/202015/285326_2145493_24_2.pdf#:~:text=,its%20approval%20until%2031%20DecemberEC:%20https://ec.europa.eu/commission/presscorner/detail/en/ip_20_599EC%20detail:%20https://ec.europa.eu/competition/state_aid/cases1/202015/285326_2145493_24_2.pdfGovt:%20https://www.portugal.gov.pt/pt/gc22/comunicacao/noticia?i=linha-de-credito-covid-19-acessivel-a-todos-os-setores-economicos-e-a-empresarios-individuais
A38: =Summary.Global!B38 -> Slovak Republic | B38: 0.087 | C38: 0.117 | D38: =C38-B38 -> 0.03 | E38: =(C38-B38)/B38 -> 0.34482759 | F38: IMF has to low Guarantee sheme with about 2.4bn https://ec.europa.eu/commission/presscorner/detail/en/mex_20_1132
A39: =Summary.Global!B39 -> Slovenia | B39: =Summary.Global!Q39 -> 0.17399103 | C39: =Summary.Global!R39 -> 0.1769 | D39: =C39-B39 -> 0.0029089715 | E39: =(C39-B39)/B39 -> 0.016719089
A40: =Summary.Global!B40 -> Sweden | B40: 0.1603 | C40: 0.135 | D40: =C40-B40 -> -0.0253 | E40: =(C40-B40)/B40 -> -0.15782907 | F40: Differenz ist aufgrund von viel zu überhöhten Tax Deferrals des IMF-> rund 200bn SEK zu hoch wie effektiv. Dafür aber ca. 150 zu tiefe Guarantees envelope. Bereinigt um diese elemente sind die zahlen konsistent-> Source: https://www.riksrevisionen.se/en/news-archive/nyhetsarkiv-eng/2025-02-20-deferred-tax-payments-more-costly-than-expected.html
A41: =Summary.Global!B41 -> Switzerland | B41: 0.137 | C41: 0.126 | D41: =C41-B41 -> -0.011 | E41: =(C41-B41)/B41 -> -0.080291971 | F41: Differenz entsteht durch die falsche angabe vom IMF bezüglich der Kurzarbeit (Ankündigung) und Loan an das IMF-> Keine inlädnische Wirkung. Der Bund trug 2020–2022 laut Bundesratsbericht rund 82 % der Corona-bedingten öffentlichen Ausgaben, der Rest entfiel auf Kantone/Gemeinden.
A42: =Summary.Global!B42 -> Chile | B42: 0.1693 | C42: 0.288 | D42: =C42-B42 -> 0.1187 | E42: =(C42-B42)/B42 -> 0.70112227 | F42: 0.288 | G42: Informe de Gestión y Sostenibilidad 2021
A43: =Summary.Global!B43 -> Colombia | B43: 0.0961 | C43: 0.085 | D43: =C43-B43 -> -0.0111 | E43: =(C43-B43)/B43 -> -0.11550468 | F43: Differences are due to different estimation about "other than health" spending where the IMF used the announced values and: IMF list equity injection "Equity injection for capitalization of Findeter and Bancoldex (Colombian Development Banks) for the purpose of credit lines" whom is not belegbar mit quellen, weder from the government side nor from the bank sid. find in the following th ststements of both banks from 2021 where we do not see a change in equity. | G43: bancoldex_estados_financieros_separados_2021-2020_0.pdf
A44: =Summary.Global!B44 -> Costa Rica | B44: =Summary.Global!Q44 -> 0.015532172 | C44: 0.0176 | D44: =C44-B44 -> 0.0020678276 | E44: =(C44-B44)/B44 -> 0.1331319 | F44: Differences are due to the differences between FX rate and also IMF uses onli announced values
A45: =Summary.Global!B45 -> Hungary | B45: =Summary.Global!Q45 -> 0.16392116 | C45: =Summary.Global!R45 -> 0.1559 | D45: =C45-B45 -> -0.0080211559 | E45: =(C45-B45)/B45 -> -0.048933012
A46: =Summary.Global!B46 -> Poland | B46: 0.1153 | C46: 0.1143 | D46: =C46-B46 -> -0.001 | E46: =(C46-B46)/B46 -> -0.0086730269

Sheet Database
C2: Fiscal Monitor: Database of Country Fiscal Measures in Response to the COVID-19 Pandemic
H4: A. Above-the line measures | Q4: B. Below the line measures | T4: C. Contingent liabilities | Y4: Other measures | AA4: Links
A5: G20 + Spain | B5: Country Group | C5: s | D5: Government Level | F5: Unit | G5: Total on-budget (A-D) | H5: Total size | I5: Additional spending and forgone revenue in the health sector | J5: Total size | K5: Additional spending and forgone revenue in areas other than health | L5: Total size | M5: D. Accelerated spending and deferred revenue in areas other than health | O5: Unit | P5: Total off-budget (B+C) | Q5: Total size | R5: Equity injections, asset purchases, loans, debt assumptions, including through extra-budgetary funds | T5: Unit | U5: Total size | V5: Guarantees (on loans, deposits etc.) | W5: Total size | X5: Quasi-fiscal operations (noncommercial activity of public corporations on behalf of government) | Y5: Automatic stabilizers, contingency lines | AD5: lookupID
A6: 1 | B6: AE | C6: Australia | D6: General Government | F6: LC bn | G6: 361.7 | H6: 20 | I6: Additional spending (AUD 20.0 bn): •Australia is co-funding the WHO’s Pacific regional coronavirus response plan (together with New Zealand). •The Commonwealth government increased the budget to secure access to COVID-19 vaccines and roll out a national Vaccination Program. •The health spending package provides support across primary care, aged care, hospitals and research, to diagnose and treat people with the Coronavirus. •In relation to aged care, temporary measures will be introduced to support the aged care sector, which helps ensure the continuity of residential and home care. •The Commonwealth government will pay for half of all additional costs incurred by states and territories in diagnosing and treating patients with, or suspected of having, COVID-19, and efforts to minimize the spread of the virus. • The 2020-21 Mid-Year Economic and FIscal Outlook (MYEFO), released on December 17, includes cost of vaccine procurement and rollout. | J6: 341.7 | K6: Additional spending (AUD 239.2 bn): At the Commonwealth government level • Measures include tax-free cash flow assistance, wage subsidies, payments to lower-income Australians (pensioners, other social security and veteran income support recipients, and eligible concession cardholders), and the Home Builder program. • FY2021 budget, released on October 6, includes additional spending measures under the JobMaker program, comprising job hiring credit, infrastructure projects, and others for job creation. • The 2020-21 MYEFO extends coronavirus supplement and other income support measures through end-March 2021. • The FY2022 budget adds spending on infrastructure investment, extension of aviation and tourism support, women’s economic support package, and various programs for job creation At state and local government levels • Measures include discount utility bills, cash payments to vulnerable households, and construction and infrastructure projects. • The Commonwealth government will help finance fast-track infrastructure projects across States and Territories and the arts industry for job creation, as well as the new home care package for the senior citizens. • Pandemic Leave Disaster Payment has been arranged with the State and Territory governments, which provides a lump sum payment to help workers during their 14-day self-isolation period. Forgone revenue (AUD 102.5 bn): At the Commonwealth government level • Measures include raising the asset write-off threshold, accelerated depreciation deductions, and COVID-19 Relief and Recovery Fund which provides waiver of fees and charges to affected industries (e.g., aviation industry), regions, and communities. • FY2021 budget includes additional revenue measures under the JobMaker program, comprising extension of immediate expensing, loss carry-backs, income tax cut for lower- and middle-income earners, and tax incentives for R&D. • The FY2022 budget extends temporary full expensing and loss carry-backs for businesses, and retains the low- and middle-income tax offset for FY2021-22. At state and local government levels • Measures include payroll tax relief for businesses. | O6: LC bn | P6: 35 | Q6: 15 | R6: • The Government’s Structured Finance Support Fund provides up to AUD15 bn to the Australian Office of Financial Management to support continued access to structured finance markets used by smaller lenders, providing both consumer and business credit. | T6: LC bn | U6: 20 | V6: • The Coronavirus SME Guarantee Scheme provides a loan guarantee arrangement between the government and participating banks to cover the immediate cash flow needs of SMEs. In mid-July 2020, this scheme was extended through June 2021, with the maximum loan size raised from A$250,000 to A$1 million and the maximum maturity extended to five years. • In March 2021, the government renamed it the SME Recovery Loan Scheme, under which the government guarantees 80 percent (previously: 50 percent) of new SME loan amounts (starting April 2021), with the maximum loan size raised to A$5 million and the maximum maturity extended to ten years. The scheme also offers up to 24 months of repayment holidays. | Y6: Parliament approved an advance authorization of A$40 billion for unforeseen events. | AA6: https://treasury.gov.au/coronavirus | AD6: =C6&F6 -> AustraliaLC bn
F7: USD bn | G7: 249.7258 | H7: 13.808449 | J7: 235.91735 | O7: USD bn | P7: 24.164785 | Q7: 10.356337 | T7: USD bn | U7: 13.808449 | AD7: =C6&F7 -> AustraliaUSD bn
F8: % GDP | G8: 18.370673 | H8: 1.0157961 | J8: 17.354877 | O8: % GDP | P8: 1.7776432 | Q8: 0.7618471 | T8: % GDP | U8: 1.0157961 | AD8: =C6&F8 -> Australia% GDP
A9: 1 | B9: AE | C9: Canada | D9: Central Government | F9: LC bn | G9: 351.1 | H9: 61.2 | I9: Additional spending (CAD 61.2 bn): Support to the health system including Safe Restart Agreement, Safe Return to Class, Vaccines and Therapeutics, PPE and Medical Equipment, Long-Term Care, Helping Health Care Systems Recover, Canada’s COVID-19 Immunization Plan, Supporting the Mental Health of Those Most Affected by COVID-19, Supporting Indigenous Communities in the Fight Against COVID-19, Safe Return to School on Reserve, International COVID-19 Response and Recovery, Enhanced Border and Quarantine Measures, and Other Public Health Support | J9: 289.9 | K9: Additional spending (CAD 289.9 bn): Households (CAN 253.6 bn) of which: • Emergency response benefit, Recovery benefits, and enhanced employment insurance (CAN 120.2 bn) • Wage subsidies and protecting jobs (CAN 110.5.2 bn) • Others, including support to students, seniors, and vulnerable groups (CAN 22.9 bn) Businesses (CAN 36.2 bn) of which: • Emergency business account with 25% loan forgiveness (CAN 13.8 bn) • Emergency rent subsidy (CAN 8.4 bn) • Others, including sector-specific support and sub-nationals support (CAN 14 bn) | L9: 85.1 | M9: Deferred revenue (CAD 85.1 bn): Income Tax Payment Deferral until September 30, 2020 ($55 billion); Sales Tax Remittance and Customs Duty Payments Deferral ($30 billion); and Supporting Jobs and Safe Operations of Junior Mining Companies ($50 million) | O9: LC bn | P9: 87.1 | Q9: 5.2 | R9: • Supporting Farm Credit Canada by allowing an additional $5.2 billion in lending capacity to producers, agribusinesses, and food processors. This is a capital injection. | T9: LC bn | U9: 81.9 | V9: • Established a Business Credit Availability Program (BCAP) to provide support through the Business Development Bank of Canada (BDC) and Export Development Canada (EDC), which work with private sector lenders to coordinate on credit solutions for individual businesses, including in sectors such as oil and gas, air transportation, exportation, and tourism. This includes combination of loan guarantees and shared financing arrangements. The BCAP consists of: the Canada Emergency Business Account (for small firms), the Mid-Market Guarantee and Financing Program, the Large Employer Emergency Financing Facility, and Support for the Agriculture and Agri-Food Sector. | AA9: https://www.canada.ca/en/public-health/services/diseases/coronavirus-disease-covid-19.html | AB9: $100 million to support federal public health measures such as enhanced surveillance, increased testing at the National Microbiology Laboratory. The package includes $275 million for additional research such as vaccine development, $200 million for federal medical supplies, and support for Indigenous communities and education efforts. $500 million to provinces and territories for critical health care system needs and to support mitigation efforts, including access to testing, equipment and to enhance surveillance and monitoring. $50 million for Public Health Agency of Canada's COVID-19 communications and public education efforts. $2 bn to support diagnostic testing and to purchase ventilators and protective personal equipment, including for bulk purchases with provinces and territories. Personal protective equipment includes things like more masks and face shields, gowns, and hand sanitizer. $50 million has been made available in funding for members of the Next Generation Manufacturing Supercluster to develop and scale-up new, in-demand technologies, equipment, and medical products. | AD9: =C9&F9 -> CanadaLC bn
F10: USD bn | G10: 261.78973 | H10: 45.632389 | J10: 216.15734 | L10: 68.027304 | O10: USD bn | P10: 64.944135 | Q10: 3.8772618 | T10: USD bn | U10: 61.066873 | AD10: =C9&F10 -> CanadaUSD bn
F11: % GDP | G11: 15.923589 | H11: 2.7756298 | J11: 13.147959 | L11: 3.8595767 | O11: % GDP | P11: 3.9502836 | Q11: 0.23583783 | T11: % GDP | U11: 3.7144457 | AD11: =C9&F11 -> Canada% GDP
A12: n.a. | B12: n.a. | C12: European Union | F12: LC bn | G12: 427.85 | H12: 0.05 | I12: Additional spending (€0.05 bn): The European Commission redirected funding of €47.5 mn towards research on COVID-19 vaccine development, treatment, and diagnostics. | J12: 427.8 | K12: Additional spending (€427.8 bn): • In April 2020, the European Commission announced that the size of the Corona Response Investment Initiative will be raised to €37 bn, which includes an upfront cash injection of €8 bn from the EU cohesion funds, to support public investment for hospitals, labor markets, and stressed regions. The Commission extended the scope of the EU Solidarity Fund by also including a public health crisis within its scope, in view of mobilizing it if needed for the hardest hit EU member states. The Coronavirus Response Investment Initiative Plus (CRII+) introduced greater flexibility to allow that all non-utilized support from the European cohesion funds can be mobilized to the fullest. This flexibility is provided for through: transfer possibilities across the three cohesion policy funds (the European Regional Development Fund, European Social Fund and Cohesion Fund); transfers between the different categories of regions; flexibility when it comes to thematic concentration; and a 100% EU co-financing rate for cohesion policy programs for the accounting year 2020-2021, allowing Member States to benefit for full EU financing for crisis-related measures. •On December 11, EU leaders agreed on the Next Generation EU (NGEU) recovery package, which includes €390 bn in grants to EU members. The main instrument is the Recovery and Resilience Facility (RRF), which will fund member countries’ investments and reforms. The NGEU’s grant element comprises: €312.5 bn is from the RRF and will be committed in 2021–2023 (70 percent for 2021 and 2022 and 30 percent for 2023); €47.5 bn to top up cohesion funds (ReactEU) that can be used for investments and expenditures related to the crisis (e.g., investing in active labor market policies, short-time work schemes); €10 bn to top up to the Just Transition Fund to help regions/workers dependent on carbon intensive industries transition away from those industries; R&D (€5 bn); support for private sector investment (€5.6 bn), rural development (€7.5 bn), and rescEU (€1.9 bn). • As of early June, 2021, 24 EU countries had submitted national Recovery and Resilience Plans (RRPs). These are being assessed by the European Commission. The EC has raised 45 billion euros in bond issuance by end-July which will help finance pre-financing portion in 2021 (13% of total loans and grants, which amounts to 491 billion euros as of August). | O12: LC bn | P12: 765 | Q12: 700 | R12: On April 9 2020, the euro area finance ministers (Eurogroup) agreed on establishing safety nets for workers, businesses and sovereigns, amounting to a package of which €340 bn were below-the-line measures: •A new and temporary EU unemployment reinsurance fund (SURE) will provide up to €100 bn in loans on favorable terms to governments, in support of national unemployment, short-time work schemes, and health-related measures. Loans will be guaranteed by the EU budget and EU member states. The instrument will then be operational until 31 December 2022. •The ESM will provide Pandemic Crisis Support to its members to finance crisis-related health spending of up to 2 percent of a requesting member’s 2019 GDP. Should all 19 countries draw from the credit line, this would amount to around €240 bn.The loans from the ESM are meant to finance direct and indirect health-related spending in response to the Covid-19 crisis. On July 21, the European Council approved the Next Generation EU recovery fund. Part of this is EUR 360 billion in loans available from the Recovery and Resilience Facility (RRF) that EU members can apply for to finance parts of their national recovery and resilience plans. | T12: LC bn | U12: 65 | V12: •The EU Council agreed on a new pan-European guarantee fund of €25 bn, which could support €200 bn of total financing for hard-hit SMEs throughout the European Investment Bank or national development banks. The guarantee fund comes on top of an earlier support package of up to €40 bn for the European Investment Bank in March, and both packages are likely to be funded by voluntary contributions from member states. | Y12: The European Commission also activated the general escape clause in the EU fiscal rules, which suspends the fiscal adjustment requirements for countries not at their medium-term objective and allow countries to run deficits in excess of 3 percent of GDP. Credit holidays to existing debtors that are negatively affected will be provided. | AD12: =C12&F12 -> European UnionLC bn
F13: USD bn | G13: 488.29744 | H13: 0.057064093 | J13: 488.24038 | O13: USD bn | P13: 873.08062 | Q13: 798.8973 | T13: USD bn | U13: 74.183321 | AD13: =C12&F13 -> European UnionUSD bn
F14: % GDP | G14: 3.7559633 | H14: 0.00043893459 | J14: 3.7555243 | O14: % GDP | P14: 6.7156992 | Q14: 6.1450842 | T14: % GDP | U14: 0.57061496 | AD14: =C12&F14 -> European Union% GDP
A15: 1 | B15: AE | C15: France | D15: General Government | F15: LC bn | G15: 221.9 | H15: 33.9 | I15: Additional spending (€33.9 bn): • Support for streamlining and boosting health insurance (paid sick leave) for the sick or their caregivers, higher spending on health supplies; bonuses for health workers. • Additional investment and equipment in the health sector announced in the recovery plan for 2021 and beyond. | J15: 188 | K15: Additional spending (€155.4 bn): Support for wages of workers under the subsidized short-time work scheme; direct financial support for affected small and very small enterprises (and regardless of size for heavily affected firms in December 2020), liberal professions, and independent workers; direct transfers for low-income families; extension of expiring unemployment and other benefits; additional transfers for self-employed; additional spending in social programs; incentives to purchase greener vehicles; subsidies for green investment for the auto and aerospace sectors. Foregone revenue (€32.6 bn): Exoneration of social security contributions for affected firms in selected sectors; carry back for corporate income taxes; permanent cuts in production taxes (recovery plan) for 2021 onward. (The amount reported for forgone revenue includes the equivalent cuts in production taxes for 2 years) | L15: 69.5 | M15: Accelerated spending (€17.5 bn): Accelerated refund of tax credits (e.g. CIT and VAT). Deferred revenue (€52 bn): Postponement of social security contributions and tax payment for companies. | O15: LC bn | P15: 350.3 | Q15: 15.8 | R15: • Envelope for direct equity support (mostly for strategic companies, e.g., Air France-KLM, SNCF). | T15: LC bn | U15: 334.5 | V15: • State guarantees for bank loans to companies and credit reinsurance schemes (€315 bn); other guarantees (€12.5 bn). • The recovery plan also includes the creation of a up to €20 bn fund leveraged by public guarantees (€7 bn), to provide quasi-equity support or equity loans to firms. | Y15: Liquidity support through postponement of social security contributions and tax payment for companies (€33.5 bn). | AA15: https://www.economie.gouv.fr/coronavirus-soutien-entreprises# | AD15: =C15&F15 -> FranceLC bn
F16: USD bn | G16: 252.88464 | H16: 38.63357 | J16: 214.25107 | L16: 79.204517 | O16: USD bn | P16: 399.21356 | Q16: 18.006207 | T16: USD bn | U16: 381.20735 | AD16: =C15&F16 -> FranceUSD bn
F17: % GDP | G17: 9.6358441 | H17: 1.4720825 | J17: 8.1637616 | L17: 3.0179863 | O17: % GDP | P17: 15.21152 | Q17: 0.68610337 | T17: % GDP | U17: 14.525416 | AD17: =C15&F17 -> France% GDP
A18: 1 | B18: AE | C18: Germany | D18: General Government | F18: LC bn | G18: 516 | H18: 61 | I18: Additional spending (€61 bn): on vaccines, equipment, research, information campaigns, as well as broader measures to modernize and improve the capacity of hospitals. | J18: 455 | K18: Additional spending (€346 bn): including grants to hard hit small businesses and self-employed, increased access to childcare and basic social security benefits, temporary relief to affected tenants, income support for families, and incentivizing green and digital investment. There is also support to firms and households provided through the “Kurzabeit” program, part of which is considered discretionary because the program parameters have been changed. Forgone revenue (€109 bn): a temporary VAT reduction (the general VAT cut was expired at end-2020, but special VAT cuts for restaurants and food services remain in place), corporate tax reliefs, personal income tax reliefs, and social security contribution reduction. | M18: Deferred revenue: including options for deferring tax payments and reducing prepayments until the year-end without penalties. | O18: LC bn | P18: 927 | Q18: 100 | R18: • An economic stabilization fund (WSF) of €600 bn is established with three components: (i) €100 bn for government equity investments in significantly affected companies; (ii) €100 bn loan to state development bank KfW for financing affected firms that do not have access to KfW’s existing programs; | T18: LC bn | U18: 827 | V18: (iii) €400 bn to provide additional state guarantees to non-financial corporations to alleviate liquidity bottlenecks and support refinancing. • For the new and expansion of the existing KfW-programs, the guarantee framework of the federal government was increased by €357 bn. • Total guarantees provided by state governments to be increased by €70 bn. | Y18: The government provides options for deferring tax payments and reducing prepayments; while tax penalties will not be levied until the end of this year. | AA18: https://www.bundesregierung.de/breg-de/themen/coronavirus | AD18: =C18&F18 -> GermanyLC bn
F19: USD bn | G19: 588.90144 | H19: 69.618193 | J19: 519.28325 | O19: USD bn | P19: 1057.9683 | Q19: 114.12819 | T19: USD bn | U19: 943.8401 | AD19: =C18&F19 -> GermanyUSD bn
F20: % GDP | G20: 15.322667 | H20: 1.8114005 | J20: 13.638353 | O20: % GDP | P20: 27.786271 | Q20: 2.9974402 | T20: % GDP | U20: 24.78883 | AD20: =C18&F20 -> Germany% GDP
A21: 1 | B21: AE | C21: Italy | D21: General Government | F21: LC bn | G21: 180 | H21: 20 | I21: Additional spending (€19.5 bn): including on medical equipment, staff, and vaccine. Forgone revenue (€0.5 bn): zero VAT rate on targeted medical equipment. | J21: 160 | K21: Additional spending (€150 bn): including broadening the wage supplementation fund to provide income support to laid-off workers and the self-employed, vouchers for the payment of babysitters (€80 bn), grants for SME (€60 bn), education (€4 bn), and other (€10 bn). Forgone revenue (€10 bn): corporate income tax credits (€4 bn) and social security contribution reduction (€6 bn). | L21: 7 | M21: Deferred revenue: mostly due to postponement of VAT, CIT, and social security contributions as well as property taxes. | O21: LC bn | P21: 582.25 | Q21: 3.25 | R21: • Equity injection to Alitalia (€3.3 bn) | T21: LC bn | U21: 579 | V21: The total guarantee is estimated at about 579 bn euros, aimed to unlock more than 750 billion euros of liquidity for businesses and households. (Note that the amount reported here is the originally announced ceiling, and the current level of contracted guarantees is about one-fourth of the announced). | Y21: Other measures to support businesses, including tax deferrals and postponement of utility bill payments in most affected municipalities (€6.4 bn), a moratorium on loan repayments for households and SMEs, including on mortgages and overdrafts (€220 bn), incentives for financial and non-financial companies in the form of Deferred Tax Activities | AA21: http://www.mef.gov.it/en/inevidenza/Protect-health-support-the-economy-preserve-employment-levels-and-incomes-00001/ | AD21: =C21&F21 -> ItalyLC bn
F22: USD bn | G22: 205.43073 | H22: 22.825637 | J22: 182.6051 | L22: 7.988973 | O22: USD bn | P22: 664.51136 | Q22: 3.709166 | T22: USD bn | U22: 660.8022 | AA22: http://www.governo.it/it/articolo/comunicato-stampa-del-consiglio-dei-ministri-n-39/14417 | AD22: =C21&F22 -> ItalyUSD bn
F23: % GDP | G23: 10.898556 | H23: 1.2109506 | J23: 9.687605 | L23: 0.42383272 | O23: % GDP | P23: 35.2538 | Q23: 0.19677948 | T23: % GDP | U23: 35.057021 | AD23: =C21&F23 -> Italy% GDP
