Workbook
Name IQ_CH: 110000
Name IQ_CQ: 5000
Name IQ_CY: 10000
Name IQ_DAILY: 500000
Name IQ_FH: 100000
Name IQ_FQ: 500
Name IQ_FY: 1000
Name IQ_LTM: 2000
Name IQ_MONTH: 15000
Name IQ_NTM: 6000
Name IQ_WEEK: 50000
Name IQ_YTD: 3000

Sheet 2020
B1: Table 1. Summary of Country Fiscal Measures in Response to the COVID-19 Pandemic
B2: (USD billion and percent of GDP)
B3: USD Billion
C4: Above the line measures | G4: Liquidity support | K4: Above the line measures | P4: Liquidity support
C5: Additional spending or foregone revenues | F5: Accelerated spending / deferred revenue | H5: Below the line measures: equity injections, loans, asset purchase or debt assumptions. | I5: Contingent liabilities | K5: Additional spending or foregone revenues | N5: Accelerated spending / deferred revenue | Q5: Below the line measures: equity injections, loans, asset purchase or debt assumptions. | R5: Contingent liabilities
C6: Subtotal | D6: Health sector | E6: Non-health sector | G6: Subtotal | I6: Guarantees | J6: Quasi-fiscal operations | K6: Subtotal | L6: Health sector | M6: Non-health sector | P6: Subtotal | R6: Guarantees | S6: Quasi-fiscal operations
B7: G20: Advanced economies
B8: Australia | C8: 218.44778 | D8: 11.460914 | E8: 206.98687 | F8: 0 | G8: 24.164577 | H8: 10.356247 | I8: 13.80833 | J8: 0 | K8: 16.177852 | L8: 0.8487748 | M8: 15.329077 | N8: 0 | P8: 1.7895854 | Q8: 0.76696518 | R8: 1.0226202 | S8: 0
B9: Canada | C9: 240.10444 | D9: 39.211354 | E9: 200.89308 | F9: 63.244119 | G9: 65.922694 | H9: 3.869052 | I9: 62.053642 | J9: 0 | K9: 14.646142 | L9: 2.3918552 | M9: 12.254287 | N9: 3.8578309 | P9: 4.0212214 | Q9: 0.23600848 | R9: 3.7852129 | S9: 0
B10: France | C10: 198.05783 | D10: 20.261089 | E10: 177.79675 | F10: 62.604488 | G10: 404.65264 | H10: 23.903532 | I10: 380.74911 | J10: 0 | K10: 7.7103009 | L10: 0.78875492 | M10: 6.921546 | N10: 2.4371641 | P10: 15.752942 | Q10: 0.93055356 | R10: 14.822389 | S10: 0
B11: Germany | C11: 417.74267 | D11: 45.530537 | E11: 372.21214 | F11: 0 | G11: 1054.3734 | H11: 113.82634 | I11: 940.54706 | J11: 0 | K11: 11.033705 | L11: 1.2025837 | M11: 9.8311217 | N11: 0 | P11: 27.848832 | Q11: 3.0064592 | R11: 24.842373 | S11: 0
B12: Italy | C12: 127.4855 | D12: 10.813502 | E12: 116.672 | F12: 7.9678439 | G12: 662.75387 | H12: 3.6993561 | I12: 659.05452 | J12: 0 | K12: 6.8248555 | L12: 0.57889399 | M12: 6.2459615 | N12: 0.42655347 | P12: 35.480108 | Q12: 0.19804268 | R12: 35.282066 | S12: 0
B13: Japan | C13: 782.33295 | D13: 89.837276 | E13: 692.49567 | F13: 243.30929 | G13: 1428.0384 | H13: 0 | I13: 146.92138 | J13: 1281.117 | K13: 15.580393 | L13: 1.789136 | M13: 13.791257 | N13: 4.8455768 | P13: 28.439808 | Q13: 0 | R13: 2.9259829 | S13: 25.513825
B14: Korea | C14: 56.080292 | D14: 4.3138686 | E14: 51.766423 | F14: 27.913268 | G14: 165.70331 | H14: 0 | I14: 59.971232 | J14: 105.73207 | K14: 3.4422077 | L14: 0.26478521 | M14: 3.1774225 | N14: 1.713316 | P14: 10.170867 | Q14: 0 | R14: 3.6810335 | S14: 6.4898335
B15: Spain | C15: 52.473943 | D15: 5.008359 | E15: 47.465584 | F15: 0.61466224 | G15: 183.53245 | H15: 0.72735032 | I15: 171.42247 | J15: 11.382634 | K15: 4.1298486 | L15: 0.3941721 | M15: 3.7356765 | N15: 0.048375667 | P15: 14.444526 | Q15: 0.057244539 | R15: 13.491436 | S15: 0.89584568
B16: United Kingdom | C16: 440.54616 | D16: 144.71429 | E16: 295.83187 | F16: 8.964602 | G16: 436.70419 | H16: 1.2806574 | I16: 435.42353 | J16: 0 | K16: 16.258004 | L16: 5.3405653 | M16: 10.917439 | N16: 0.33083148 | P16: 16.116219 | Q16: 0.04726164 | R16: 16.068957 | S16: 0
B17: United States | C17: 3503.3 | D17: 483.8 | E17: 3019.5 | F17: 18 | G17: 510 | H17: 56 | I17: 454 | J17: 0 | K17: 16.719306 | L17: 2.3089088 | M17: 14.410397 | N17: 0.085904007 | P17: 2.4339469 | Q17: 0.26725691 | R17: 2.16669 | S17: 0
B18: Mexico | C18: 7.2279883 | D18: 2.3467495 | E18: 4.8812389 | F18: 4.318019 | G18: 13.588243 | H18: 1.8445451 | I18: 1.1504705 | J18: 10.593227 | K18: 0.68126555 | L18: 0.22119012 | M18: 0.46007544 | N18: 0.40698981 | P18: 1.2807439 | Q18: 0.17385543 | R18: 0.10843624 | S18: 0.99845218
B19: Turkey | C19: 7.6102085 | D19: 2.0161373 | E19: 5.5940711 | F19: 9.8677143 | G19: 63.976864 | H19: 2.9816115 | I19: 43.446339 | J19: 17.548914 | K19: 1.0708244 | L19: 0.28368856 | M19: 0.78713585 | N19: 1.3884757 | P19: 9.0021171 | Q19: 0.41953941 | R19: 6.1132886 | S19: 2.4692891
... B42: Colombia | C42: 11.060054 | D42: 2.9135225 | E42: 8.1465315 | F42: 0.10756165 | G42: 15.411434 | H42: 8.5363618 | I42: 6.875072 | J42: 0 | K42: 4.1001316 | L42: 1.0800875 | M42: 3.0200441 | N42: 0.039874754 | P42: 5.7132548 | Q42: 3.1645602 | R42: 2.5486946 | S42: 0
B43: Costa Rica | C43: 0.84666153 | D43: 0.19538343 | E43: 0.6512781 | F43: 0.40447798 | H43: 0 | I43: 0 | J43: 0 | K43: 1.4290119 | L43: 0.32977198 | M43: 1.0992399 | N43: 0.68268585 | P43: 0 | Q43: 0 | R43: 0 | S43: 0
B44: Hungary | C44: 5.997549 | D44: 1.769415 | E44: 4.228134 | F44: 0 | G44: 6.6270226 | H44: 0 | I44: 6.6270226 | J44: 0 | K44: 4 | L44: 1.1800921 | M44: 2.8199079 | N44: 0 | P44: 4.4198205 | Q44: 0 | R44: 4.4198205 | S44: 0
B45: Poland | C45: 44.709731 | D45: 2.1654286 | E45: 42.544303 | F45: 0 | G45: 31.589782 | H45: 12.737815 | I45: 18.851967 | J45: 0 | K45: 7.6769895 | L45: 0.37182 | M45: 7.3051695 | N45: 0 | P45: 5.4241977 | Q45: 2.1871765 | R45: 3.2370212 | S45: 0

Sheet 2021
B1: Table 1. Summary of Country Fiscal Measures in Response to the COVID-19 Pandemic since January 2020
B2: (USD billion and percent of 2020 GDP)
B3: USD Billion
C4: Above the line measures | G4: Liquidity support | K4: Above the line measures | O4: Liquidity support
C5: Additional spending or foregone revenues | F5: Accelerated spending / deferred revenue | H5: Below the line measures: equity injections, loans, asset purchase or debt assumptions. | I5: Contingent liabilities | K5: Additional spending or foregone revenues | N5: Accelerated spending / deferred revenue | P5: Below the line measures: equity injections, loans, asset purchase or debt assumptions. | Q5: Contingent liabilities
C6: Subtotal | D6: Health sector | E6: Non-health sector | G6: Subtotal | I6: Guarantees | J6: Quasi-fiscal operations | K6: Subtotal | L6: Health sector | M6: Non-health sector | O6: Subtotal | Q6: Guarantees | R6: Quasi-fiscal operations
B7: G20: Advanced economies | S7: GDP 2020 Usbn
B8: Australia | C8: 249.7258 | D8: 13.808449 | E8: 235.91735 | F8: 0 | G8: 24.164785 | H8: 10.356337 | I8: 13.808449 | J8: 0 | K8: 18.370673 | L8: 1.0157961 | M8: 17.354877 | N8: 0 | O8: =P8+Q8 -> 1.7776432 | P8: 0.7618471 | Q8: 1.0157961 | R8: 0 | S8: =('2020'!C8/'2020'!K8)*100 -> 1350.2891
B9: Canada | C9: 261.78973 | D9: 45.632389 | E9: 216.15734 | F9: 68.027304 | G9: 64.944135 | H9: 3.8772618 | I9: 61.066873 | J9: 0 | K9: 15.923589 | L9: 2.7756298 | M9: 13.147959 | N9: 3.8595767 | O9: =P9+Q9 -> 3.9502836 | P9: 0.23583783 | Q9: 3.7144457 | R9: 0 | S9: =('2020'!C9/'2020'!K9)*100 -> 1639.3699
B10: France | C10: 252.88464 | D10: 38.63357 | E10: 214.25107 | F10: 79.204517 | G10: 399.21356 | H10: 18.006207 | I10: 381.20735 | J10: 0 | K10: 9.6358441 | L10: 1.4720825 | M10: 8.1637616 | N10: 3.0179863 | O10: =P10+Q10 -> 15.21152 | P10: 0.68610337 | Q10: 14.525416 | R10: 0 | S10: =('2020'!C10/'2020'!K10)*100 -> 2568.7432
B11: Germany | C11: 588.90144 | D11: 69.618193 | E11: 519.28325 | F11: 0 | G11: 1057.9683 | H11: 114.12819 | I11: 943.8401 | J11: 0 | K11: 15.322667 | L11: 1.8114005 | M11: 13.638353 | N11: 0 | O11: =P11+Q11 -> 27.786271 | P11: 2.9974402 | Q11: 24.78883 | R11: 0 | S11: =('2020'!C11/'2020'!K11)*100 -> 3786.0597
B12: Italy | C12: 205.43073 | D12: 22.825637 | E12: 182.6051 | F12: 7.988973 | G12: 664.51136 | H12: 3.709166 | I12: 660.8022 | J12: 0 | K12: 10.898556 | L12: 1.2109506 | M12: 9.687605 | N12: 0.42383272 | O12: =P12+Q12 -> 35.2538 | P12: 0.19677948 | Q12: 35.057021 | R12: 0 | S12: =('2020'!C12/'2020'!K12)*100 -> 1867.959
B13: Japan | C13: 843.83379 | D13: 104.89388 | E13: 738.93991 | F13: 27.160022 | G13: 1429.1791 | H13: 0 | I13: 147.03874 | J13: 1282.1403 | K13: 16.725807 | L13: 2.0791236 | M13: 14.646684 | N13: 0.53834452 | O13: =P13+Q13 -> 2.9144858 | P13: 0 | Q13: 2.9144858 | R13: 25.413574 | S13: =('2020'!C13/'2020'!K13)*100 -> 5021.2658
B14: Korea | C14: 104.83005 | D14: 11.9491 | E14: 92.880946 | F14: 27.965978 | G14: 166.01622 | H14: 0 | I14: 60.084481 | J14: 105.93174 | K14: 6.3988747 | L14: 0.7293786 | M14: 5.6694961 | N14: 1.7070563 | O14: =P14+Q14 -> 3.6675846 | P14: 0 | Q14: 3.6675846 | R14: 6.4661224 | S14: =('2020'!C14/'2020'!K14)*100 -> 1629.1955
B15: Spain | C15: 107.45169 | D15: 21.924025 | E15: 85.527663 | F15: 0.051357684 | G15: 184.01915 | H15: 0.72927911 | I15: 171.87705 | J15: 11.412819 | K15: 8.3916545 | L15: 1.7122006 | M15: 6.6794539 | N15: 0.0040108811 | O15: =P15+Q15 -> 13.480037 | P15: 0.056954511 | Q15: 13.423082 | R15: 0.89130691 | S15: =('2020'!C15/'2020'!K15)*100 -> 1270.6021
B16: United Kingdom | C16: 522.16797 | D16: 130.86273 | E16: 391.30523 | F16: 16.0371 | G16: 452.92619 | H16: 1.321457 | I16: 451.60473 | J16: 0 | K16: 19.270477 | L16: 4.8294563 | M16: 14.441021 | N16: 0.59184513 | O16: =P16+Q16 -> 16.715127 | P16: 0.048768039 | Q16: 16.666359 | R16: 0 | S16: =('2020'!C16/'2020'!K16)*100 -> 2709.7186
B17: United States | C17: 5328.3 | D17: 687.3 | E17: 4641 | F17: 17.98 | G17: 510 | H17: 56 | I17: 454 | J17: 0 | K17: 25.501885 | L17: 3.2895004 | M17: 22.212384 | N17: 0.086054442 | O17: =P17+Q17 -> 2.4409213 | P17: 0.26802273 | Q17: 2.1728986 | R17: 0 | S17: =('2020'!C17/'2020'!K17)*100 -> 20953.621
B18: Mexico | C18: 7.0279602 | D18: 4.8032152 | E18: 2.224745 | F18: 4.281936 | G18: 13.41363 | H18: 0.89362143 | I18: 0.2792567 | J18: 12.240752 | K18: 0.65442397 | L18: 0.44726194 | M18: 0.20716202 | N18: 0.39872189 | O18: =P18+Q18 -> 0.10921513 | P18: 0.083211524 | Q18: 0.026003601 | R18: 1.1398245 | S18: =('2020'!C18/'2020'!K18)*100 -> 1060.9649
B19: Turkey | C19: 25.234121 | D19: 2.7673372 | E19: 22.466784 | F19: 10.013767 | G19: 69.354606 | H19: 2.9955712 | I19: 45.932092 | J19: 20.426943 | K19: 3.5051336 | L19: 0.38439565 | M19: 3.1207379 | N19: 1.3909575 | O19: =P19+Q19 -> 6.7962737 | P19: 0.41609839 | Q19: 6.3801753 | R19: 2.8373947 | S19: =('2020'!C19/'2020'!K19)*100 -> 710.68687
... B45: Poland | C45: 38.516359 | D45: 3.7695771 | E45: 34.746782 | F45: 0 | G45: 28.720588 | H45: 9.7444851 | I45: 18.976103 | J45: 0 | K45: 6.463387 | L45: 0.6325685 | M45: 5.8308185 | N45: 0 | O45: =P45+Q45 -> 4.8195695 | P45: 1.6352111 | Q45: 3.1843584 | R45: 0 | S45: =('2020'!C45/'2020'!K45)*100 -> 582.38625

Sheet data
A1: Country | B1: Quarter | C1: ab_us | D1: health_us | E1: nhealth_us | F1: acc_us | G1: of_us | H1: be_us | I1: gu_us | J1: qf_us | K1: ab_per | L1: ab_ppp | M1: health_per | N1: health_ppp | O1: nhealth_per | P1: nhealth_ppp | Q1: acc_per | R1: acc_ppp | S1: of_per | T1: of_ppp | U1: be_per | V1: be_ppp | W1: gu_per | X1: gu_ppp | Y1: qf_us | Z1: qf_ppp | AA1: GDP 2019 in US Dollar constant PPP 2019 | AB1: in bn | AC1: GDP 2019 in US Dollar constant Prices 2015 | AD1: in bn
A2: AUS | B2: Q1.2020 | C2: =D2+E2 -> 110.0051 | D2: 2.1168 | E2: 107.8883 | F2: 0 | G2: =H2+I2 -> 24.0029 | H2: 10.3255 | I2: 13.6774 | J2: 0 | K2: =M2+O2 -> 7.3593163 | L2: =N2+P2 -> 8.9689107 | M2: =($D2/$AD2)*100 -> 0.14161344 | N2: =($D2/$AB2)*100 -> 0.17258646 | O2: =($E2/$AD2)*100 -> 7.2177029 | P2: =($E2/$AB2)*100 -> 8.7963243 | Q2: =($F2/$AD2)*100 -> 0 | R2: =($F2/$AB2)*100 -> 0 | S2: =U2+W2 -> 1.6057886 | T2: =V2+X2 -> 1.956999 | U2: =($H2/$AD2)*100 -> 0.69077361 | V2: =($H2/AB2)*100 -> 0.84185631 | W2: =($I2/$AD2)*100 -> 0.91501497 | X2: =($I2/$AB2)*100 -> 1.1151427 | Y2: =($J2/$AD2)*100 -> 0 | Z2: =($J2/$AB2)*100 -> 0 | AA2: 1.2265157e+12 | AB2: 1226.5157 | AC2: 1.4947734e+12 | AD2: 1494.7734
A3: CAN | B3: Q1.2020 | C3: =D3+E3 -> 81 | D3: 2.4 | E3: 78.6 | F3: 63.75 | G3: =H3+I3 -> 51.7 | H3: 3.7 | I3: 48 | J3: 0 | K3: =M3+O3 -> 4.7742401 | L3: =N3+P3 -> 4.6997712 | M3: =($D3/$AD3)*100 -> 0.14145896 | N3: =($D3/$AB3)*100 -> 0.13925248 | O3: =($E3/$AD3)*100 -> 4.6327811 | P3: =($E3/$AB3)*100 -> 4.5605187 | Q3: =($F3/$AD3)*100 -> 3.7575038 | R3: =($F3/$AB3)*100 -> 3.698894 | S3: =U3+W3 -> 3.0472619 | T3: =V3+X3 -> 2.9997305 | U3: =($H3/$AD3)*100 -> 0.21808257 | V3: =($H3/AB3)*100 -> 0.21468091 | W3: =($I3/$AD3)*100 -> 2.8291793 | X3: =($I3/$AB3)*100 -> 2.7850496 | Y3: =($J3/$AD3)*100 -> 0 | Z3: =($J3/$AB3)*100 -> 0 | AA3: 1.7234882e+12 | AB3: 1723.4882 | AC3: 1.6966051e+12 | AD3: 1696.6051
A4: FRA | B4: Q1.2020 | C4: =D4+E4 -> 16.5 | D4: 5.5 | E4: 11 | F4: 48.5 | G4: =H4+I4 -> 348 | H4: 0 | I4: 348 | J4: 0 | K4: =M4+O4 -> 0.63053811 | L4: =N4+P4 -> 0.56757784 | M4: =($D4/$AD4)*100 -> 0.21017937 | N4: =($D4/$AB4)*100 -> 0.18919261 | O4: =($E4/$AD4)*100 -> 0.42035874 | P4: =($E4/$AB4)*100 -> 0.37838523 | Q4: =($F4/$AD4)*100 -> 1.8533999 | R4: =($F4/$AB4)*100 -> 1.6683349 | S4: =U4+W4 -> 13.298622 | T4: =V4+X4 -> 11.970733 | U4: =($H4/$AD4)*100 -> 0 | V4: =($H4/AB4)*100 -> 0 | W4: =($I4/$AD4)*100 -> 13.298622 | X4: =($I4/$AB4)*100 -> 11.970733 | Y4: =($J4/$AD4)*100 -> 0 | Z4: =($J4/$AB4)*100 -> 0 | AA4: 2.9070902e+12 | AB4: 2907.0902 | AC4: 2.6168125e+12 | AD4: 2616.8125
A5: DEU | B5: Q1.2020 | C5: =D5+E5 -> 143 | D5: 11.2 | E5: 131.8 | F5: 0 | G5: =H5+I5 -> 1072 | H5: 223 | I5: 849 | J5: 0 | K5: =M5+O5 -> 3.9751845 | L5: =N5+P5 -> 3.4360259 | M5: =($D5/$AD5)*100 -> 0.31134312 | N5: =($D5/$AB5)*100 -> 0.26911531 | O5: =($E5/$AD5)*100 -> 3.6638413 | P5: =($E5/$AB5)*100 -> 3.1669106 | Q5: =($F5/$AD5)*100 -> 0 | R5: =($F5/$AB5)*100 -> 0 | S5: =U5+W5 -> 29.799984 | T5: =V5+X5 -> 25.75818 | U5: =($H5/$AD5)*100 -> 6.1990639 | V5: =($H5/AB5)*100 -> 5.3582781 | W5: =($I5/$AD5)*100 -> 23.60092 | X5: =($I5/$AB5)*100 -> 20.399902 | Y5: =($J5/$AD5)*100 -> 0 | Z5: =($J5/$AB5)*100 -> 0 | AA5: 4.1617847e+12 | AB5: 4161.7847 | AC5: 3.5973173e+12 | AD5: 3597.3173
A6: ITA | B6: Q1.2020 | C6: =D6+E6 -> 22 | D6: 3.63 | E6: 18.37 | F6: 0 | G6: =H6+I6 -> 591 | H6: 0 | I6: 591 | J6: 0 | K6: =M6+O6 -> 1.1469339 | L6: =N6+P6 -> 0.94111213 | M6: =($D6/$AD6)*100 -> 0.18924409 | N6: =($D6/$AB6)*100 -> 0.1552835 | O6: =($E6/$AD6)*100 -> 0.95768981 | P6: =($E6/$AB6)*100 -> 0.78582863 | Q6: =($F6/$AD6)*100 -> 0 | R6: =($F6/$AB6)*100 -> 0 | S6: =U6+W6 -> 30.810815 | T6: =V6+X6 -> 25.281694 | U6: =($H6/$AD6)*100 -> 0 | V6: =($H6/AB6)*100 -> 0 | W6: =($I6/$AD6)*100 -> 30.810815 | X6: =($I6/$AB6)*100 -> 25.281694 | Y6: =($J6/$AD6)*100 -> 0 | Z6: =($J6/$AB6)*100 -> 0 | AA6: 2.3376598e+12 | AB6: 2337.6598 | AC6: 1.9181576e+12 | AD6: 1918.1576
A7: JPN | B7: Q1.2020 | C7: =D7+E7 -> 497 | D7: 12.1906 | E7: 484.8094 | F7: 0 | G7: =H7+I7 -> 19 | H7: 0 | I7: 19 | J7: 0 | K7: =M7+O7 -> 10.888777 | L7: =N7+P7 -> 9.3335923 | M7: =($D7/$AD7)*100 -> 0.26708396 | N7: =($D7/$AB7)*100 -> 0.22893781 | O7: =($E7/$AD7)*100 -> 10.621693 | P7: =($E7/$AB7)*100 -> 9.1046545 | Q7: =($F7/$AD7)*100 -> 0 | R7: =($F7/$AB7)*100 -> 0 | S7: =U7+W7 -> 0.41627116 | T7: =V7+X7 -> 0.35681741 | U7: =($H7/$AD7)*100 -> 0 | V7: =($H7/AB7)*100 -> 0 | W7: =($I7/$AD7)*100 -> 0.41627116 | X7: =($I7/$AB7)*100 -> 0.35681741 | Y7: =($J7/$AD7)*100 -> 0 | Z7: =($J7/$AB7)*100 -> 0 | AA7: 5.3248522e+12 | AB7: 5324.8522 | AC7: 4.5643326e+12 | AD7: 4564.3326
A8: KOR | B8: Q1.2020 | C8: =D8+E8 -> 24 | D8: 2.5 | E8: 21.5 | F8: 14 | G8: =H8+I8 -> 215 | H8: 101 | I8: 114 | J8: 0 | K8: =M8+O8 -> 1.46507 | L8: =N8+P8 -> 1.112894 | M8: =($D8/$AD8)*100 -> 0.15261146 | N8: =($D8/$AB8)*100 -> 0.11592646 | O8: =($E8/$AD8)*100 -> 1.3124586 | P8: =($E8/$AB8)*100 -> 0.99696756 | Q8: =($F8/$AD8)*100 -> 0.85462418 | R8: =($F8/$AB8)*100 -> 0.64918818 | S8: =U8+W8 -> 13.124586 | T8: =V8+X8 -> 9.9696756 | U8: =($H8/$AD8)*100 -> 6.165503 | V8: =($H8/AB8)*100 -> 4.683429 | W8: =($I8/$AD8)*100 -> 6.9590826 | X8: =($I8/$AB8)*100 -> 5.2862466 | Y8: =($J8/$AD8)*100 -> 0 | Z8: =($J8/$AB8)*100 -> 0 | AA8: 2.1565396e+12 | AB8: 2156.5396 | AC8: 1.638147e+12 | AD8: 1638.147
A9: ESP | B9: Q1.2020 | C9: =D9+E9 -> 14.8929 | D9: 4.1786 | E9: 10.7143 | F9: 0 | G9: =H9+I9 -> 175.6152 | H9: 11 | I9: 164.6152 | J9: 11.4316 | K9: =M9+O9 -> 1.1249106 | L9: =N9+P9 -> 0.82898249 | M9: =($D9/$AD9)*100 -> 0.31562366 | N9: =($D9/$AB9)*100 -> 0.23259313 | O9: =($E9/$AD9)*100 -> 0.80928698 | P9: =($E9/$AB9)*100 -> 0.59638936 | Q9: =($F9/$AD9)*100 -> 0 | R9: =($F9/$AB9)*100 -> 0 | S9: =U9+W9 -> 13.264805 | T9: =V9+X9 -> 9.775257 | U9: =($H9/$AD9)*100 -> 0.83086686 | V9: =($H9/AB9)*100 -> 0.61229226 | W9: =($I9/$AD9)*100 -> 12.433938 | X9: =($I9/$AB9)*100 -> 9.1629648 | Y9: =($J9/$AD9)*100 -> 0.86346706 | Z9: =($J9/$AB9)*100 -> 0.63631638 | AA9: 1.7965277e+12 | AB9: 1796.5277 | AC9: 1.3239185e+12 | AD9: 1323.9185
A10: GBR | B10: Q1.2020 | C10: =D10+E10 -> 83 | D10: 6.3846154 | E10: 76.615385 | F10: 0 | G10: =H10+I10 -> 423 | H10: 423 | I10: 0 | J10: 0 | K10: =M10+O10 -> 2.628755 | L10: =N10+P10 -> 2.8212212 | M10: =($D10/$AD10)*100 -> 0.20221192 | N10: =($D10/$AB10)*100 -> 0.21701702 | O10: =($E10/$AD10)*100 -> 2.4265431 | P10: =($E10/$AB10)*100 -> 2.6042042 | Q10: =($F10/$AD10)*100 -> 0 | R10: =($F10/$AB10)*100 -> 0 | S10: =U10+W10 -> 13.397149 | T10: =V10+X10 -> 14.378031 | U10: =($H10/$AD10)*100 -> 13.397149 | V10: =($H10/AB10)*100 -> 14.378031 | W10: =($I10/$AD10)*100 -> 0 | X10: =($I10/$AB10)*100 -> 0 | Y10: =($J10/$AD10)*100 -> 0 | Z10: =($J10/$AB10)*100 -> 0 | AA10: 2.9419883e+12 | AB10: 2941.9883 | AC10: 3.1573882e+12 | AD10: 3157.3882
A11: USA | B11: Q1.2020 | C11: =D11+E11 -> 1395 | D11: 9.45 | E11: 1385.55 | F11: 0 | G11: =H11+I11 -> 510 | H11: 56 | I11: 454 | J11: 0 | K11: =M11+O11 -> 6.9998582 | L11: =N11+P11 -> 6.9840045 | M11: =($D11/$AD11)*100 -> 0.047418394 | N11: =($D11/$AB11)*100 -> 0.047310998 | O11: =($E11/$AD11)*100 -> 6.9524398 | P11: =($E11/$AB11)*100 -> 6.9366935 | Q11: =($F11/$AD11)*100 -> 0 | R11: =($F11/$AB11)*100 -> 0 | S11: =U11+W11 -> 2.5590879 | T11: =V11+X11 -> 2.553292 | U11: =($H11/$AD11)*100 -> 0.28099789 | V11: =($H11/AB11)*100 -> 0.28036147 | W11: =($I11/$AD11)*100 -> 2.27809 | X11: =($I11/$AB11)*100 -> 2.2729305 | Y11: =($J11/$AD11)*100 -> 0 | Z11: =($J11/$AB11)*100 -> 0 | AA11: 1.9974214e+13 | AB11: 19974.214 | AC11: 19928975197000 | AD11: 19928.975
A12: MEX | B12: Q1.2020 | C12: =D12+E12 -> 1.862 | D12: 1.862 | E12: 0 | F12: 0 | G12: =H12+I12 -> 3.3 | H12: 3.3 | I12: 0 | J12: 0 | K12: =M12+O12 -> 0.14556526 | L12: =N12+P12 -> 0.078180517 | M12: =($D12/$AD12)*100 -> 0.14556526 | N12: =($D12/$AB12)*100 -> 0.078180517 | O12: =($E12/$AD12)*100 -> 0 | P12: =($E12/$AB12)*100 -> 0 | Q12: =($F12/$AD12)*100 -> 0 | R12: =($F12/$AB12)*100 -> 0 | S12: =U12+W12 -> 0.25798355 | T12: =V12+X12 -> 0.13855838 | U12: =($H12/$AD12)*100 -> 0.25798355 | V12: =($H12/AB12)*100 -> 0.13855838 | W12: =($I12/$AD12)*100 -> 0 | X12: =($I12/$AB12)*100 -> 0 | Y12: =($J12/$AD12)*100 -> 0 | Z12: =($J12/$AB12)*100 -> 0 | AA12: 2.3816676e+12 | AB12: 2381.6676 | AC12: 1.2791513e+12 | AD12: 1279.1513
A13: TUR | B13: Q1.2020 | C13: =D13+E13 -> 0 | D13: 0 | E13: 0 | F13: 0 | G13: =H13+I13 -> 3.8 | H13: 0 | I13: 3.8 | J13: 0 | K13: =M13+O13 -> 0 | L13: =N13+P13 -> 0 | M13: =($D13/$AD13)*100 -> 0 | N13: =($D13/$AB13)*100 -> 0 | O13: =($E13/$AD13)*100 -> 0 | P13: =($E13/$AB13)*100 -> 0 | Q13: =($F13/$AD13)*100 -> 0 | R13: =($F13/$AB13)*100 -> 0 | S13: =U13+W13 -> 0.38112296 | T13: =V13+X13 -> 0.16282574 | U13: =($H13/$AD13)*100 -> 0 | V13: =($H13/AB13)*100 -> 0 | W13: =($I13/$AD13)*100 -> 0.38112296 | X13: =($I13/$AB13)*100 -> 0.16282574 | Y13: =($J13/$AD13)*100 -> 0 | Z13: =($J13/$AB13)*100 -> 0 | AA13: 2.3337834e+12 | AB13: 2333.7834 | AC13: 9.9705355e+11 | AD13: 997.05355
... A27: NLD | B27: Q1.2020 | C27: =D27+E27 -> 22 | D27: 0 | E27: 22 | F27: 45 | G27: =H27+I27 -> 0 | H27: 0 | I27: 0 | J27: 0 | K27: =M27+O27 -> 2.618267 | L27: =N27+P27 -> 2.3594 | M27: =($D27/$AD27)*100 -> 0 | N27: =($D27/$AB27)*100 -> 0 | O27: =($E27/$AD27)*100 -> 2.618267 | P27: =($E27/$AB27)*100 -> 2.3594 | Q27: =($F27/$AD27)*100 -> 5.3555462 | R27: =($F27/$AB27)*100 -> 4.8260455 | S27: =U27+W27 -> 0 | T27: =V27+X27 -> 0 | U27: =($H27/$AD27)*100 -> 0 | V27: =($H27/AB27)*100 -> 0 | W27: =($I27/$AD27)*100 -> 0 | X27: =($I27/$AB27)*100 -> 0 | Y27: =($J27/$AD27)*100 -> 0 | Z27: =($J27/$AB27)*100 -> 0 | AA27: 9.3244043e+11 | AB27: 932.44043 | AC27: 8.4025043e+11 | AD27: 840.25043
A28: NZL | B28: Q1.2020 | C28: =D28+E28 -> 11.088516 | D28: 0.31570903 | E28: 10.772806 | F28: 0 | G28: =H28+I28 -> 6.6522016 | H28: 2.7058387 | I28: 3.9463629 | K28: =M28+O28 -> 5.4639624 | L28: =N28+P28 -> 5.7165015 | M28: =($D28/$AD28)*100 -> 0.15556837 | N28: =($D28/$AB28)*100 -> 0.16275859 | O28: =($E28/$AD28)*100 -> 5.3083941 | P28: =($E28/$AB28)*100 -> 5.5537429 | Q28: =($F28/$AD28)*100 -> 0 | R28: =($F28/$AB28)*100 -> 0 | S28: =U28+W28 -> 3.2779302 | T28: =V28+X28 -> 3.429433 | U28: =($H28/$AD28)*100 -> 1.3333256 | V28: =($H28/AB28)*100 -> 1.3949506 | W28: =($I28/$AD28)*100 -> 1.9446046 | X28: =($I28/$AB28)*100 -> 2.0344824 | Y28: =($J28/$AD28)*100 -> 0 | Z28: =($J28/$AB28)*100 -> 0 | AA28: 1.9397381e+11 | AB28: 193.97381 | AC28: 2.0293909e+11 | AD28: 202.93909
A29: NOR | B29: Q1.2020 | C29: =D29+E29 -> 8.1 | D29: 0 | E29: 8.1 | F29: 0 | G29: =H29+I29 -> 10.6 | H29: 5.3 | I29: 5.3 | J29: 0 | K29: =M29+O29 -> 1.9744091 | L29: =N29+P29 -> 2.4511712 | M29: =($D29/$AD29)*100 -> 0 | N29: =($D29/$AB29)*100 -> 0 | O29: =($E29/$AD29)*100 -> 1.9744091 | P29: =($E29/$AB29)*100 -> 2.4511712 | Q29: =($F29/$AD29)*100 -> 0 | R29: =($F29/$AB29)*100 -> 0 | S29: =U29+W29 -> 2.5837946 | T29: =V29+X29 -> 3.2077056 | U29: =($H29/$AD29)*100 -> 1.2918973 | V29: =($H29/AB29)*100 -> 1.6038528 | W29: =($I29/$AD29)*100 -> 1.2918973 | X29: =($I29/$AB29)*100 -> 1.6038528 | Y29: =($J29/$AD29)*100 -> 0 | Z29: =($J29/$AB29)*100 -> 0 | AA29: 3.3045427e+11 | AB29: 330.45427 | AC29: 4.1024933e+11 | AD29: 410.24933
A30: PRT | B30: Q1.2020 | C30: =D30+E30 -> 7.2019168 | D30: 1.8290582 | E30: 5.3728586 | F30: 9.030975 | G30: =H30+I30 -> 14.861098 | H30: 0 | I30: 14.861098 | J30: 0 | K30: =M30+O30 -> 3.2388198 | L30: =N30+P30 -> 2.1106626 | M30: =($D30/$AD30)*100 -> 0.82255741 | N30: =($D30/$AB30)*100 -> 0.53604129 | O30: =($E30/$AD30)*100 -> 2.4162624 | P30: =($E30/$AB30)*100 -> 1.5746213 | Q30: =($F30/$AD30)*100 -> 4.0613772 | R30: =($F30/$AB30)*100 -> 2.6467038 | S30: =U30+W30 -> 6.6832789 | T30: =V30+X30 -> 4.3553354 | U30: =($H30/$AD30)*100 -> 0 | V30: =($H30/AB30)*100 -> 0 | W30: =($I30/$AD30)*100 -> 6.6832789 | X30: =($I30/$AB30)*100 -> 4.3553354 | Y30: =($J30/$AD30)*100 -> 0 | Z30: =($J30/$AB30)*100 -> 0 | AA30: 3.4121593e+11 | AB30: 341.21593 | AC30: 2.2236238e+11 | AD30: 222.36238
A31: SVK | B31: Q1.2020 | C31: =D31+E31 -> 2.5149551 | D31: 0.18290582 | E31: 2.3320493 | F31: 1.4060885 | G31: =H31+I31 -> 4.5840772 | H31: 0 | I31: 4.5840772 | J31: 0 | K31: =M31+O31 -> 2.5278709 | L31: =N31+P31 -> 1.3840355 | M31: =($D31/$AD31)*100 -> 0.18384516 | N31: =($D31/$AB31)*100 -> 0.10065713 | O31: =($E31/$AD31)*100 -> 2.3440258 | P31: =($E31/$AB31)*100 -> 1.2833784 | Q31: =($F31/$AD31)*100 -> 1.4133097 | R31: =($F31/$AB31)*100 -> 0.77380168 | S31: =U31+W31 -> 4.6076193 | T31: =V31+X31 -> 2.5227193 | U31: =($H31/$AD31)*100 -> 0 | V31: =($H31/AB31)*100 -> 0 | W31: =($I31/$AD31)*100 -> 4.6076193 | X31: =($I31/$AB31)*100 -> 2.5227193 | Y31: =($J31/$AD31)*100 -> 0 | Z31: =($J31/$AB31)*100 -> 0 | AA31: 1.8171174e+11 | AB31: 181.71174 | AC31: 9.9489061e+10 | AD31: 99.489061
A32: SVN | B32: Q1.2020 | C32: =D32+E32 -> 4.115381 | D32: 0.11431614 | E32: 4.0010649 | F32: 0 | G32: =H32+I32 -> 3.3151681 | H32: 0.68589684 | I32: 2.6292712 | J32: 0.11431614 | K32: =M32+O32 -> 8.162527 | L32: =N32+P32 -> 5.412314 | M32: =($D32/$AD32)*100 -> 0.22673686 | N32: =($D32/$AB32)*100 -> 0.15034206 | O32: =($E32/$AD32)*100 -> 7.9357901 | P32: =($E32/$AB32)*100 -> 5.261972 | Q32: =($F32/$AD32)*100 -> 0 | R32: =($F32/$AB32)*100 -> 0 | S32: =U32+W32 -> 6.575369 | T32: =V32+X32 -> 4.3599196 | U32: =($H32/$AD32)*100 -> 1.3604212 | V32: =($H32/AB32)*100 -> 0.90205234 | W32: =($I32/$AD32)*100 -> 5.2149478 | X32: =($I32/$AB32)*100 -> 3.4578673 | Y32: =($J32/$AD32)*100 -> 0.22673686 | Z32: =($J32/$AB32)*100 -> 0.15034206 | AA32: 7.6037366e+10 | AB32: 76.037366 | AC32: 5.0417978e+10 | AD32: 50.417978
A33: SWE | B33: Q1.2020 | C33: =D33+E33 -> 11 | D33: 0 | E33: 11 | F33: 0 | G33: =H33+I33 -> 25 | H33: 0 | I33: 25 | J33: 0 | K33: =M33+O33 -> 2.0006501 | L33: =N33+P33 -> 2.1113062 | M33: =($D33/$AD33)*100 -> 0 | N33: =($D33/$AB33)*100 -> 0 | O33: =($E33/$AD33)*100 -> 2.0006501 | P33: =($E33/$AB33)*100 -> 2.1113062 | Q33: =($F33/$AD33)*100 -> 0 | R33: =($F33/$AB33)*100 -> 0 | S33: =U33+W33 -> 4.546932 | T33: =V33+X33 -> 4.7984231 | U33: =($H33/$AD33)*100 -> 0 | V33: =($H33/AB33)*100 -> 0 | W33: =($I33/$AD33)*100 -> 4.546932 | X33: =($I33/$AB33)*100 -> 4.7984231 | Y33: =($J33/$AD33)*100 -> 0 | Z33: =($J33/$AB33)*100 -> 0 | AA33: 5.2100449e+11 | AB33: 521.00449 | AC33: 5.4982128e+11 | AD33: 549.82128
A34: CHE | B34: Q1.2020 | C34: =D34+E34 -> 1.6825977 | D34: 0 | E34: 1.6825977 | F34: 0 | G34: =H34+I34 -> 0.21161296 | H34: =0.0516129+0.05677419 -> 0.10838709 | I34: =0.10322587 -> 0.10322587 | J34: 0 | K34: =M34+O34 -> 0.22521425 | L34: =N34+P34 -> 0.28479303 | M34: =($D34/$AD34)*100 -> 0 | N34: =($D34/$AB34)*100 -> 0 | O34: =($E34/$AD34)*100 -> 0.22521425 | P34: =($E34/$AB34)*100 -> 0.28479303 | Q34: =($F34/$AD34)*100 -> 0 | R34: =($F34/$AB34)*100 -> 0 | S34: =U34+W34 -> 0.028324212 | T34: =V34+X34 -> 0.035817175 | U34: =($H34/$AD34)*100 -> 0.014507519 | V34: =($H34/AB34)*100 -> 0.018345376 | W34: =($I34/$AD34)*100 -> 0.013816694 | X34: =($I34/$AB34)*100 -> 0.017471799 | Y34: =($J34/$AD34)*100 -> 0 | Z34: =($J34/$AB34)*100 -> 0 | AA34: 5.9081422e+11 | AB34: 590.81422 | AC34: 7.4710978e+11 | AD34: 747.10978
A35: CHL | B35: Q1.2020 | C35: =D35+E35 -> 4.6 | D35: 1 | E35: 3.6 | F35: 4.7152702 | G35: =H35+I35 -> 2.4 | H35: 2.4 | I35: 0 | J35: 0 | K35: =M35+O35 -> 1.7559969 | L35: =N35+P35 -> 1.0424015 | M35: =($D35/$AD35)*100 -> 0.38173846 | N35: =($D35/$AB35)*100 -> 0.22660903 | O35: =($E35/$AD35)*100 -> 1.3742585 | P35: =($E35/$AB35)*100 -> 0.81579252 | Q35: =($F35/$AD35)*100 -> 1.8 | R35: =($F35/$AB35)*100 -> 1.0685228 | S35: =U35+W35 -> 0.91617231 | T35: =V35+X35 -> 0.54386168 | U35: =($H35/$AD35)*100 -> 0.91617231 | V35: =($H35/AB35)*100 -> 0.54386168 | W35: =($I35/$AD35)*100 -> 0 | X35: =($I35/$AB35)*100 -> 0 | Y35: =($J35/$AD35)*100 -> 0 | Z35: =($J35/$AB35)*100 -> 0 | AA35: 4.4128868e+11 | AB35: 441.28868 | AC35: 2.6195946e+11 | AD35: 261.95946
A36: COL | B36: Q1.2020 | C36: =D36+E36 -> 0 | D36: 0 | E36: 0 | F36: 0 | G36: =H36+I36 -> 0.1 | H36: 0.1 | I36: 0 | J36: 0 | K36: =M36+O36 -> 0 | L36: =N36+P36 -> 0 | M36: =($D36/$AD36)*100 -> 0 | N36: =($D36/$AB36)*100 -> 0 | O36: =($E36/$AD36)*100 -> 0 | P36: =($E36/$AB36)*100 -> 0 | Q36: =($F36/$AD36)*100 -> 0 | R36: =($F36/$AB36)*100 -> 0 | S36: =U36+W36 -> 0.031113334 | T36: =V36+X36 -> 0.014482907 | U36: =($H36/$AD36)*100 -> 0.031113334 | V36: =($H36/AB36)*100 -> 0.014482907 | W36: =($I36/$AD36)*100 -> 0 | X36: =($I36/$AB36)*100 -> 0 | Y36: =($J36/$AD36)*100 -> 0 | Z36: =($J36/$AB36)*100 -> 0 | AA36: 6.9046913e+11 | AB36: 690.46913 | AC36: 3.2140561e+11 | AD36: 321.40561
A37: CRI | B37: Q1.2020 | C37: =D37+E37 -> 0.717434 | D37: 0.17 | E37: 0.547434 | F37: 0 | G37: =H37+I37 -> 0 | H37: 0 | I37: 0 | J37: 0 | K37: =M37+O37 -> 1.1143309 | L37: =N37+P37 -> 0.78637134 | M37: =($D37/$AD37)*100 -> 0.26404693 | N37: =($D37/$AB37)*100 -> 0.18633509 | O37: =($E37/$AD37)*100 -> 0.85028393 | P37: =($E37/$AB37)*100 -> 0.60003625 | Q37: =($F37/$AD37)*100 -> 0 | R37: =($F37/$AB37)*100 -> 0 | S37: =U37+W37 -> 0 | T37: =V37+X37 -> 0 | U37: =($H37/$AD37)*100 -> 0 | V37: =($H37/AB37)*100 -> 0 | W37: =($I37/$AD37)*100 -> 0 | X37: =($I37/$AB37)*100 -> 0 | Y37: =($J37/$AD37)*100 -> 0 | Z37: =($J37/$AB37)*100 -> 0 | AA37: 9.1233488e+10 | AB37: 91.233488 | AC37: 6.4382494e+10 | AD37: 64.382494
A38: HUN | B38: Q1.2020 | C38: =D38+E38 -> 4.419749 | D38: 0 | E38: 4.419749 | F38: 0 | G38: =H38+I38 -> 0 | H38: 0 | I38: 0 | J38: 0 | K38: =M38+O38 -> 2.9987989 | L38: =N38+P38 -> 1.42624 | M38: =($D38/$AD38)*100 -> 0 | N38: =($D38/$AB38)*100 -> 0 | O38: =($E38/$AD38)*100 -> 2.9987989 | P38: =($E38/$AB38)*100 -> 1.42624 | Q38: =($F38/$AD38)*100 -> 0 | R38: =($F38/$AB38)*100 -> 0 | S38: =U38+W38 -> 0 | T38: =V38+X38 -> 0 | U38: =($H38/$AD38)*100 -> 0 | V38: =($H38/AB38)*100 -> 0 | W38: =($I38/$AD38)*100 -> 0 | X38: =($I38/$AB38)*100 -> 0 | Y38: =($J38/$AD38)*100 -> 0 | Z38: =($J38/$AB38)*100 -> 0 | AA38: 3.0988816e+11 | AB38: 309.88816 | AC38: 1.4738397e+11 | AD38: 147.38397
A39: POL | B39: Q1.2020 | C39: =D39+E39 -> 17 | D39: 8 | E39: 9 | F39: 0 | G39: =H39+I39 -> 17 | H39: 0 | I39: 17 | J39: 0 | K39: =M39+O39 -> 2.9746119 | L39: =N39+P39 -> 1.3986902 | M39: =($D39/$AD39)*100 -> 1.3998174 | N39: =($D39/$AB39)*100 -> 0.65820713 | O39: =($E39/$AD39)*100 -> 1.5747946 | P39: =($E39/$AB39)*100 -> 0.74048302 | Q39: =($F39/$AD39)*100 -> 0 | R39: =($F39/$AB39)*100 -> 0 | S39: =U39+W39 -> 2.9746119 | T39: =V39+X39 -> 1.3986902 | U39: =($H39/$AD39)*100 -> 0 | V39: =($H39/AB39)*100 -> 0 | W39: =($I39/$AD39)*100 -> 2.9746119 | X39: =($I39/$AB39)*100 -> 1.3986902 | Y39: =($J39/$AD39)*100 -> 0 | Z39: =($J39/$AB39)*100 -> 0 | AA39: 1.2154229e+12 | AB39: 1215.4229 | AC39: 5.7150312e+11 | AD39: 571.50312
A41: AUS | B41: Q2.2020 | C41: =D41+E41 -> 110.37182 | D41: 3.2712453 | E41: 107.10057 | F41: 0 | G41: =H41+I41 -> 22.898717 | H41: 9.8137358 | I41: 13.084981 | J41: 0 | K41: =M41+O41 -> 7.3838495 | L41: =N41+P41 -> 8.9988097 | M41: =($D41/$AD41)*100 -> 0.21884557 | N41: =($D41/$AB41)*100 -> 0.26671042 | O41: =($E41/$AD41)*100 -> 7.1650039 | P41: =($E41/$AB41)*100 -> 8.7320993 | Q41: =($F41/$AD41)*100 -> 0 | R41: =($F41/$AB41)*100 -> 0 | S41: =U41+W41 -> 1.531919 | T41: =V41+X41 -> 1.866973 | U41: =($H41/$AD41)*100 -> 0.6565367 | V41: =($H41/AB41)*100 -> 0.80013127 | W41: =($I41/$AD41)*100 -> 0.87538227 | X41: =($I41/$AB41)*100 -> 1.0668417 | Y41: =($J41/$AD41)*100 -> 0 | Z41: =($J41/$AB41)*100 -> 0 | AA41: 1.2265157e+12 | AB41: 1226.5157 | AC41: 1.4947734e+12 | AD41: 1494.7734
A42: CAN | B42: Q2.2020 | C42: =D42+E42 -> 86.382127 | D42: 2.8794042 | E42: 83.502722 | F42: 61.18734 | G42: =H42+I42 -> 50.389574 | H42: 3.5992553 | I42: 46.790319 | J42: 0 | K42: =M42+O42 -> 5.0914693 | L42: =N42+P42 -> 5.0120522 | M42: =($D42/$AD42)*100 -> 0.16971564 | N42: =($D42/$AB42)*100 -> 0.16706841 | O42: =($E42/$AD42)*100 -> 4.9217536 | P42: =($E42/$AB42)*100 -> 4.8449838 | Q42: =($F42/$AD42)*100 -> 3.6064574 | R42: =($F42/$AB42)*100 -> 3.5502037 | S42: =U42+W42 -> 2.9700237 | T42: =V42+X42 -> 2.9236971 | U42: =($H42/$AD42)*100 -> 0.21214455 | V42: =($H42/AB42)*100 -> 0.20883551 | W42: =($I42/$AD42)*100 -> 2.7578792 | X42: =($I42/$AB42)*100 -> 2.7148616 | Y42: =($J42/$AD42)*100 -> 0 | Z42: =($J42/$AB42)*100 -> 0 | AA42: 1.7234882e+12 | AB42: 1723.4882 | AC42: 1.6966051e+12 | AD42: 1696.6051
A43: FRA | B43: Q2.2020 | C43: =D43+E43 -> 62.619278 | D43: 8.7426566 | E43: 53.876621 | F43: 60.65218 | G43: =H43+I43 -> 380.30556 | H43: 22.949473 | I43: 357.35609 | J43: 0 | K43: =M43+O43 -> 2.3929601 | L43: =N43+P43 -> 2.154019 | M43: =($D43/$AD43)*100 -> 0.33409565 | N43: =($D43/$AB43)*100 -> 0.30073564 | O43: =($E43/$AD43)*100 -> 2.0588644 | P43: =($E43/$AB43)*100 -> 1.8532834 | Q43: =($F43/$AD43)*100 -> 2.3177885 | R43: =($F43/$AB43)*100 -> 2.0863535 | S43: =U43+W43 -> 14.533161 | T43: =V43+X43 -> 13.082 | U43: =($H43/$AD43)*100 -> 0.87700107 | V43: =($H43/AB43)*100 -> 0.78943106 | W43: =($I43/$AD43)*100 -> 13.65616 | X43: =($I43/$AB43)*100 -> 12.292569 | Y43: =($J43/$AD43)*100 -> 0 | Z43: =($J43/$AB43)*100 -> 0 | AA43: 2.9070902e+12 | AB43: 2907.0902 | AC43: 2.6168125e+12 | AD43: 2616.8125
A44: DEU | B44: Q2.2020 | C44: =D44+E44 -> 332.22095 | D44: 25.135138 | E44: 307.08581 | F44: 0 | G44: =H44+I44 -> 1114.6887 | H44: 218.56641 | I44: 896.1223 | J44: 0 | K44: =M44+O44 -> 9.2352417 | L44: =N44+P44 -> 7.9826558 | M44: =($D44/$AD44)*100 -> 0.69871894 | N44: =($D44/$AB44)*100 -> 0.60395093 | O44: =($E44/$AD44)*100 -> 8.5365227 | P44: =($E44/$AB44)*100 -> 7.3787049 | Q44: =($F44/$AD44)*100 -> 0 | R44: =($F44/$AB44)*100 -> 0 | S44: =U44+W44 -> 30.986666 | T44: =V44+X44 -> 26.783911 | U44: =($H44/$AD44)*100 -> 6.0758169 | V44: =($H44/AB44)*100 -> 5.2517472 | W44: =($I44/$AD44)*100 -> 24.910849 | X44: =($I44/$AB44)*100 -> 21.532164 | Y44: =($J44/$AD44)*100 -> 0 | Z44: =($J44/$AB44)*100 -> 0 | AA44: 4.1617847e+12 | AB44: 4161.7847 | AC44: 3.5973173e+12 | AD44: 3597.3173
A45: ITA | B45: Q2.2020 | C45: =D45+E45 -> 60.105764 | D45: 7.1034085 | E45: 53.002355 | F45: 7.6498245 | G45: =H45+I45 -> 582.80734 | H45: 3.6063458 | I45: 579.201 | J45: 0 | K45: =M45+O45 -> 3.1335154 | L45: =N45+P45 -> 2.5711938 | M45: =($D45/$AD45)*100 -> 0.37032454 | N45: =($D45/$AB45)*100 -> 0.30386836 | O45: =($E45/$AD45)*100 -> 2.7631908 | P45: =($E45/$AB45)*100 -> 2.2673254 | Q45: =($F45/$AD45)*100 -> 0.39881105 | R45: =($F45/$AB45)*100 -> 0.32724285 | S45: =U45+W45 -> 30.383705 | T45: =V45+X45 -> 24.93123 | U45: =($H45/$AD45)*100 -> 0.18801092 | V45: =($H45/AB45)*100 -> 0.15427163 | W45: =($I45/$AD45)*100 -> 30.195694 | X45: =($I45/$AB45)*100 -> 24.776958 | Y45: =($J45/$AD45)*100 -> 0 | Z45: =($J45/$AB45)*100 -> 0 | AA45: 2.3376598e+12 | AB45: 2337.6598 | AC45: 1.9181576e+12 | AD45: 1918.1576
A46: JPN | B46: Q2.2020 | C46: =D46+E46 -> 551.10682 | D46: 38.427517 | E46: 512.67931 | F46: 243.68669 | G46: =H46+I46 -> 147.14927 | H46: 0 | I46: 147.14927 | J46: 1021.6096 | K46: =M46+O46 -> 12.074204 | L46: =N46+P46 -> 10.349711 | M46: =($D46/$AD46)*100 -> 0.84190878 | N46: =($D46/$AB46)*100 -> 0.72166353 | O46: =($E46/$AD46)*100 -> 11.232295 | P46: =($E46/$AB46)*100 -> 9.6280476 | Q46: =($F46/$AD46)*100 -> 5.3389337 | R46: =($F46/$AB46)*100 -> 4.5764029 | S46: =U46+W46 -> 3.2238946 | T46: =V46+X46 -> 2.7634433 | U46: =($H46/$AD46)*100 -> 0 | V46: =($H46/AB46)*100 -> 0 | W46: =($I46/$AD46)*100 -> 3.2238946 | X46: =($I46/$AB46)*100 -> 2.7634433 | Y46: =($J46/$AD46)*100 -> 22.382453 | Z46: =($J46/$AB46)*100 -> 19.185689 | AA46: 5.3248522e+12 | AB46: 5324.8522 | AC46: 4.5643326e+12 | AD46: 4564.3326
A47: KOR | B47: Q2.2020 | C47: =D47+E47 -> 47.759349 | D47: 3.7812909 | E47: 43.978058 | F47: 27.126652 | G47: =H47+I47 -> 28.030874 | H47: 0 | I47: 28.030874 | J47: 120.83691 | K47: =M47+O47 -> 2.9154496 | L47: =N47+P47 -> 2.2146289 | M47: =($D47/$AD47)*100 -> 0.23082733 | N47: =($D47/$AB47)*100 -> 0.17534067 | O47: =($E47/$AD47)*100 -> 2.6846222 | P47: =($E47/$AB47)*100 -> 2.0392882 | Q47: =($F47/$AD47)*100 -> 1.6559352 | R47: =($F47/$AB47)*100 -> 1.2578787 | S47: =U47+W47 -> 1.7111331 | T47: =V47+X47 -> 1.299808 | U47: =($H47/$AD47)*100 -> 0 | V47: =($H47/AB47)*100 -> 0 | W47: =($I47/$AD47)*100 -> 1.7111331 | X47: =($I47/$AB47)*100 -> 1.299808 | Y47: =($J47/$AD47)*100 -> 7.3764387 | Z47: =($J47/$AB47)*100 -> 5.6032779 | AA47: 2.1565396e+12 | AB47: 2156.5396 | AC47: 1.638147e+12 | AD47: 1638.147
... A58: FIN | B58: Q2.2020 | C58: =D58+E58 -> 7.6050184 | D58: 1.5966277 | E58: 6.0083907 | F58: 5.7373684 | G58: =H58+I58 -> 16.851471 | H58: 2.6446536 | I58: 14.206817 | J58: 1.0928321 | K58: =M58+O58 -> 2.9853553 | L58: =N58+P58 -> 2.9950177 | M58: =($D58/$AD58)*100 -> 0.62675731 | N58: =($D58/$AB58)*100 -> 0.62878587 | O58: =($E58/$AD58)*100 -> 2.358598 | P58: =($E58/$AB58)*100 -> 2.3662318 | Q58: =($F58/$AD58)*100 -> 2.252208 | R58: =($F58/$AB58)*100 -> 2.2594975 | S58: =U58+W58 -> 6.6150567 | T58: =V58+X58 -> 6.6364669 | U58: =($H58/$AD58)*100 -> 1.0381606 | V58: =($H58/AB58)*100 -> 1.0415207 | W58: =($I58/$AD58)*100 -> 5.576896 | X58: =($I58/$AB58)*100 -> 5.5949461 | Y58: =($J58/$AD58)*100 -> 0.428992 | Z58: =($J58/$AB58)*100 -> 0.43038047 | AA58: 2.5392232e+11 | AB58: 253.92232 | AC58: 2.5474416e+11 | AD58: 254.74416
A59: GRC | B59: Q2.2020 | C59: =D59+E59 -> 10.391907 | D59: 0.70761691 | E59: 9.68429 | F59: 0 | G59: =H59+I59 -> 8.9610144 | H59: 6.4199944 | I59: =1.1082+1.43282 -> 2.54102 | J59: 0 | K59: =M59+O59 -> 5.0964951 | L59: =N59+P59 -> 3.4462238 | M59: =($D59/$AD59)*100 -> 0.34703603 | N59: =($D59/$AB59)*100 -> 0.23466398 | O59: =($E59/$AD59)*100 -> 4.7494591 | P59: =($E59/$AB59)*100 -> 3.2115598 | Q59: =($F59/$AD59)*100 -> 0 | R59: =($F59/$AB59)*100 -> 0 | S59: =U59+W59 -> 4.3947436 | T59: =V59+X59 -> 2.971703 | U59: =($H59/$AD59)*100 -> 3.1485531 | V59: =($H59/AB59)*100 -> 2.1290354 | W59: =($I59/$AD59)*100 -> 1.2461905 | X59: =($I59/$AB59)*100 -> 0.84266764 | Y59: =($J59/$AD59)*100 -> 0 | Z59: =($J59/$AB59)*100 -> 0 | AA59: 3.0154475e+11 | AB59: 301.54475 | AC59: 2.0390301e+11 | AD59: 203.90301
A60: ISL | B60: Q2.2020 | C60: =D60+E60 -> 0.8825382 | D60: 0.021328007 | E60: 0.8612102 | F60: 0 | G60: =H60+I60 -> 0.91931063 | H60: 0 | I60: 0.91931063 | J60: 0 | K60: =M60+O60 -> 4.2572996 | L60: =N60+P60 -> 4.6280958 | M60: =($D60/$AD60)*100 -> 0.10288474 | N60: =($D60/$AB60)*100 -> 0.11184565 | O60: =($E60/$AD60)*100 -> 4.1544149 | P60: =($E60/$AB60)*100 -> 4.5162502 | Q60: =($F60/$AD60)*100 -> 0 | R60: =($F60/$AB60)*100 -> 0 | S60: =U60+W60 -> 4.4346871 | T60: =V60+X60 -> 4.8209332 | U60: =($H60/$AD60)*100 -> 0 | V60: =($H60/AB60)*100 -> 0 | W60: =($I60/$AD60)*100 -> 4.4346871 | X60: =($I60/$AB60)*100 -> 4.8209332 | Y60: =($J60/$AD60)*100 -> 0 | Z60: =($J60/$AB60)*100 -> 0 | AA60: 1.9069143e+10 | AB60: 19.069143 | AC60: 2.073e+10 | AD60: 20.73
A61: IRL | B61: Q2.2020 | C61: =D61+E61 -> 23.434809 | D61: 2.2863228 | E61: 21.148486 | F61: 2.8579035 | G61: =H61+I61 -> 6.8589684 | H61: 4.5726456 | I61: 2.2863228 | J61: 0 | K61: =M61+O61 -> 6.3087257 | L61: =N61+P61 -> 5.6078791 | M61: =($D61/$AD61)*100 -> 0.61548543 | N61: =($D61/$AB61)*100 -> 0.54711016 | O61: =($E61/$AD61)*100 -> 5.6932403 | P61: =($E61/$AB61)*100 -> 5.060769 | Q61: =($F61/$AD61)*100 -> 0.76935679 | R61: =($F61/$AB61)*100 -> 0.6838877 | S61: =U61+W61 -> 1.8464563 | T61: =V61+X61 -> 1.6413305 | U61: =($H61/$AD61)*100 -> 1.2309709 | V61: =($H61/AB61)*100 -> 1.0942203 | W61: =($I61/$AD61)*100 -> 0.61548543 | X61: =($I61/$AB61)*100 -> 0.54711016 | Y61: =($J61/$AD61)*100 -> 0 | Z61: =($J61/$AB61)*100 -> 0 | AA61: 4.1789076e+11 | AB61: 417.89076 | AC61: 3.714666e+11 | AD61: 371.4666
A62: ISR | B62: Q2.2020 | C62: =D62+E62 -> 25.918306 | D62: 4.0163262 | E62: 21.90198 | F62: 2.0803992 | G62: =H62+I62 -> 11.153251 | H62: 0.95351629 | I62: 10.199735 | J62: 0 | K62: =M62+O62 -> 7.2304548 | L62: =N62+P62 -> 7.5696716 | M62: =($D62/$AD62)*100 -> 1.1204384 | N62: =($D62/$AB62)*100 -> 1.1730037 | O62: =($E62/$AD62)*100 -> 6.1100164 | P62: =($E62/$AB62)*100 -> 6.3966678 | Q62: =($F62/$AD62)*100 -> 0.58037095 | R62: =($F62/$AB62)*100 -> 0.60759906 | S62: =U62+W62 -> 3.1114331 | T62: =V62+X62 -> 3.2574061 | U62: =($H62/$AD62)*100 -> 0.26600335 | V62: =($H62/AB62)*100 -> 0.2784829 | W62: =($I62/$AD62)*100 -> 2.8454298 | X62: =($I62/$AB62)*100 -> 2.9789232 | Y62: =($J62/$AD62)*100 -> 0 | Z62: =($J62/$AB62)*100 -> 0 | AA62: 3.4239671e+11 | AB62: 342.39671 | AC62: 3.5846025e+11 | AD62: 358.46025
A63: LVA | B63: Q2.2020 | C63: =D63+E63 -> 2.6412118 | D63: 0.23110604 | E63: 2.4101058 | F63: 0 | G63: =H63+I63 -> 1.0485611 | H63: 0.23110604 | I63: 0.81745506 | J63: 0 | K63: =M63+O63 -> 8.7573112 | L63: =N63+P63 -> 4.7655872 | M63: =($D63/$AD63)*100 -> 0.76626473 | N63: =($D63/$AB63)*100 -> 0.41698888 | O63: =($E63/$AD63)*100 -> 7.9910464 | P63: =($E63/$AB63)*100 -> 4.3485983 | Q63: =($F63/$AD63)*100 -> 0 | R63: =($F63/$AB63)*100 -> 0 | S63: =U63+W63 -> 3.4766525 | T63: =V63+X63 -> 1.8919381 | U63: =($H63/$AD63)*100 -> 0.76626473 | V63: =($H63/AB63)*100 -> 0.41698888 | W63: =($I63/$AD63)*100 -> 2.7103878 | X63: =($I63/$AB63)*100 -> 1.4749492 | Y63: =($J63/$AD63)*100 -> 0 | Z63: =($J63/$AB63)*100 -> 0 | AA63: 55422589740 | AB63: 55.42259 | AC63: 3.0160078e+10 | AD63: 30.160078
A64: LTU | B64: Q2.2020 | C64: =D64+E64 -> 2.5949764 | D64: 0.5715807 | E64: 2.0233957 | F64: 2.5035235 | G64: =H64+I64 -> 1.9662376 | H64: 0.36581165 | I64: 1.600426 | J64: 0 | K64: =M64+O64 -> 5.3818961 | L64: =N64+P64 -> 2.6714858 | M64: =($D64/$AD64)*100 -> 1.1854397 | N64: =($D64/$AB64)*100 -> 0.58843299 | O64: =($E64/$AD64)*100 -> 4.1964564 | P64: =($E64/$AB64)*100 -> 2.0830528 | Q64: =($F64/$AD64)*100 -> 5.1922257 | R64: =($F64/$AB64)*100 -> 2.5773365 | S64: =U64+W64 -> 4.0779124 | T64: =V64+X64 -> 2.0242095 | U64: =($H64/$AD64)*100 -> 0.75868139 | V64: =($H64/AB64)*100 -> 0.37659711 | W64: =($I64/$AD64)*100 -> 3.3192311 | X64: =($I64/$AB64)*100 -> 1.6476124 | Y64: =($J64/$AD64)*100 -> 0 | Z64: =($J64/$AB64)*100 -> 0 | AA64: 9.7136073e+10 | AB64: 97.136073 | AC64: 4.8216769e+10 | AD64: 48.216769
...

Sheet diff
A1: Country | B1: Quarter | C1: ab_us | D1: health_us | E1: nhealth_us | F1: acc_us | G1: of_us | H1: be_us | I1: gu_us | J1: qf_us | K1: ab_per | L1: ab_ppp | M1: health_per | N1: health_ppp | O1: nhealth_per | P1: nhealth_ppp | Q1: acc_per | R1: acc_ppp | S1: of_per | T1: of_ppp | U1: be_per | V1: be_ppp | W1: gu_per | X1: gu_ppp | Y1: qf_us | Z1: qf_ppp | AA1: GDP 2019 in US Dollar constant PPP 2019 | AB1: in bn | AC1: GDP 2019 in US Dollar constant Prices 2015 | AD1: in bn
A2: AUS | B2: Q1.2020 | C2: =D2+E2 -> 130.0051 | D2: 2.1168 | E2: 127.8883 | F2: 0 | G2: =H2+I2 -> 24.0029 | H2: 10.3255 | I2: 13.6774 | J2: 0 | K2: =M2+O2 -> 8.6973118 | L2: =N2+P2 -> 10.599546 | M2: =($D2/$AD2)*100 -> 0.14161344 | N2: =($D2/$AB2)*100 -> 0.17258646 | O2: =($E2/$AD2)*100 -> 8.5556983 | P2: =($E2/$AB2)*100 -> 10.42696 | Q2: =($F2/$AD2)*100 -> 0 | R2: =($F2/$AB2)*100 -> 0 | S2: =U2+W2 -> 1.6057886 | T2: =V2+X2 -> 1.956999 | U2: =($H2/$AD2)*100 -> 0.69077361 | V2: =($H2/AB2)*100 -> 0.84185631 | W2: =($I2/$AD2)*100 -> 0.91501497 | X2: =($I2/$AB2)*100 -> 1.1151427 | Y2: =($J2/$AD2)*100 -> 0 | Z2: =($J2/$AB2)*100 -> 0 | AA2: 1.2265157e+12 | AB2: 1226.5157 | AC2: 1.4947734e+12 | AD2: 1494.7734
A3: CAN | B3: Q1.2020 | C3: =D3+E3 -> 81 | D3: 2.4 | E3: 78.6 | F3: 63.75 | G3: =H3+I3 -> 51.7 | H3: 3.7 | I3: 48 | J3: 0 | K3: =M3+O3 -> 4.7742401 | L3: =N3+P3 -> 4.6997712 | M3: =($D3/$AD3)*100 -> 0.14145896 | N3: =($D3/$AB3)*100 -> 0.13925248 | O3: =($E3/$AD3)*100 -> 4.6327811 | P3: =($E3/$AB3)*100 -> 4.5605187 | Q3: =($F3/$AD3)*100 -> 3.7575038 | R3: =($F3/$AB3)*100 -> 3.698894 | S3: =U3+W3 -> 3.0472619 | T3: =V3+X3 -> 2.9997305 | U3: =($H3/$AD3)*100 -> 0.21808257 | V3: =($H3/AB3)*100 -> 0.21468091 | W3: =($I3/$AD3)*100 -> 2.8291793 | X3: =($I3/$AB3)*100 -> 2.7850496 | Y3: =($J3/$AD3)*100 -> 0 | Z3: =($J3/$AB3)*100 -> 0 | AA3: 1.7234882e+12 | AB3: 1723.4882 | AC3: 1.6966051e+12 | AD3: 1696.6051
A4: FRA | B4: Q1.2020 | C4: =D4+E4 -> 16.5 | D4: 5.5 | E4: 11 | F4: 48.5 | G4: =H4+I4 -> 348 | H4: 0 | I4: 348 | J4: 0 | K4: =M4+O4 -> 0.63053811 | L4: =N4+P4 -> 0.56757784 | M4: =($D4/$AD4)*100 -> 0.21017937 | N4: =($D4/$AB4)*100 -> 0.18919261 | O4: =($E4/$AD4)*100 -> 0.42035874 | P4: =($E4/$AB4)*100 -> 0.37838523 | Q4: =($F4/$AD4)*100 -> 1.8533999 | R4: =($F4/$AB4)*100 -> 1.6683349 | S4: =U4+W4 -> 13.298622 | T4: =V4+X4 -> 11.970733 | U4: =($H4/$AD4)*100 -> 0 | V4: =($H4/AB4)*100 -> 0 | W4: =($I4/$AD4)*100 -> 13.298622 | X4: =($I4/$AB4)*100 -> 11.970733 | Y4: =($J4/$AD4)*100 -> 0 | Z4: =($J4/$AB4)*100 -> 0 | AA4: 2.9070902e+12 | AB4: 2907.0902 | AC4: 2.6168125e+12 | AD4: 2616.8125
A5: DEU | B5: Q1.2020 | C5: =D5+E5 -> 143 | D5: 11.2 | E5: 131.8 | F5: 0 | G5: =H5+I5 -> 1072 | H5: 223 | I5: 849 | J5: 0 | K5: =M5+O5 -> 3.9751845 | L5: =N5+P5 -> 3.4360259 | M5: =($D5/$AD5)*100 -> 0.31134312 | N5: =($D5/$AB5)*100 -> 0.26911531 | O5: =($E5/$AD5)*100 -> 3.6638413 | P5: =($E5/$AB5)*100 -> 3.1669106 | Q5: =($F5/$AD5)*100 -> 0 | R5: =($F5/$AB5)*100 -> 0 | S5: =U5+W5 -> 29.799984 | T5: =V5+X5 -> 25.75818 | U5: =($H5/$AD5)*100 -> 6.1990639 | V5: =($H5/AB5)*100 -> 5.3582781 | W5: =($I5/$AD5)*100 -> 23.60092 | X5: =($I5/$AB5)*100 -> 20.399902 | Y5: =($J5/$AD5)*100 -> 0 | Z5: =($J5/$AB5)*100 -> 0 | AA5: 4.1617847e+12 | AB5: 4161.7847 | AC5: 3.5973173e+12 | AD5: 3597.3173
A6: ITA | B6: Q1.2020 | C6: =D6+E6 -> 22 | D6: 3.63 | E6: 18.37 | F6: 0 | G6: =H6+I6 -> 591 | H6: 0 | I6: 591 | J6: 0 | K6: =M6+O6 -> 1.1469339 | L6: =N6+P6 -> 0.94111213 | M6: =($D6/$AD6)*100 -> 0.18924409 | N6: =($D6/$AB6)*100 -> 0.1552835 | O6: =($E6/$AD6)*100 -> 0.95768981 | P6: =($E6/$AB6)*100 -> 0.78582863 | Q6: =($F6/$AD6)*100 -> 0 | R6: =($F6/$AB6)*100 -> 0 | S6: =U6+W6 -> 30.810815 | T6: =V6+X6 -> 25.281694 | U6: =($H6/$AD6)*100 -> 0 | V6: =($H6/AB6)*100 -> 0 | W6: =($I6/$AD6)*100 -> 30.810815 | X6: =($I6/$AB6)*100 -> 25.281694 | Y6: =($J6/$AD6)*100 -> 0 | Z6: =($J6/$AB6)*100 -> 0 | AA6: 2.3376598e+12 | AB6: 2337.6598 | AC6: 1.9181576e+12 | AD6: 1918.1576
A7: JPN | B7: Q1.2020 | C7: =D7+E7 -> 497 | D7: 12.1906 | E7: 484.8094 | F7: 0 | G7: =H7+I7 -> 518 | H7: 499 | I7: 19 | J7: 0 | K7: =M7+O7 -> 10.888777 | L7: =N7+P7 -> 9.3335923 | M7: =($D7/$AD7)*100 -> 0.26708396 | N7: =($D7/$AB7)*100 -> 0.22893781 | O7: =($E7/$AD7)*100 -> 10.621693 | P7: =($E7/$AB7)*100 -> 9.1046545 | Q7: =($F7/$AD7)*100 -> 0 | R7: =($F7/$AB7)*100 -> 0 | S7: =U7+W7 -> 11.348866 | T7: =V7+X7 -> 9.7279695 | U7: =($H7/$AD7)*100 -> 10.932595 | V7: =($H7/AB7)*100 -> 9.3711521 | W7: =($I7/$AD7)*100 -> 0.41627116 | X7: =($I7/$AB7)*100 -> 0.35681741 | Y7: =($J7/$AD7)*100 -> 0 | Z7: =($J7/$AB7)*100 -> 0 | AA7: 5.3248522e+12 | AB7: 5324.8522 | AC7: 4.5643326e+12 | AD7: 4564.3326
A8: KOR | B8: Q1.2020 | C8: =D8+E8 -> 24 | D8: 2.5 | E8: 21.5 | F8: 14 | G8: =H8+I8 -> 215 | H8: 101 | I8: 114 | J8: 0 | K8: =M8+O8 -> 1.46507 | L8: =N8+P8 -> 1.112894 | M8: =($D8/$AD8)*100 -> 0.15261146 | N8: =($D8/$AB8)*100 -> 0.11592646 | O8: =($E8/$AD8)*100 -> 1.3124586 | P8: =($E8/$AB8)*100 -> 0.99696756 | Q8: =($F8/$AD8)*100 -> 0.85462418 | R8: =($F8/$AB8)*100 -> 0.64918818 | S8: =U8+W8 -> 13.124586 | T8: =V8+X8 -> 9.9696756 | U8: =($H8/$AD8)*100 -> 6.165503 | V8: =($H8/AB8)*100 -> 4.683429 | W8: =($I8/$AD8)*100 -> 6.9590826 | X8: =($I8/$AB8)*100 -> 5.2862466 | Y8: =($J8/$AD8)*100 -> 0 | Z8: =($J8/$AB8)*100 -> 0 | AA8: 2.1565396e+12 | AB8: 2156.5396 | AC8: 1.638147e+12 | AD8: 1638.147
A9: ESP | B9: Q1.2020 | C9: =D9+E9 -> 14.8929 | D9: 4.1786 | E9: 10.7143 | F9: 0 | G9: =H9+I9 -> 175.6152 | H9: 11 | I9: 164.6152 | J9: 11.4316 | K9: =M9+O9 -> 1.1249106 | L9: =N9+P9 -> 0.82898249 | M9: =($D9/$AD9)*100 -> 0.31562366 | N9: =($D9/$AB9)*100 -> 0.23259313 | O9: =($E9/$AD9)*100 -> 0.80928698 | P9: =($E9/$AB9)*100 -> 0.59638936 | Q9: =($F9/$AD9)*100 -> 0 | R9: =($F9/$AB9)*100 -> 0 | S9: =U9+W9 -> 13.264805 | T9: =V9+X9 -> 9.775257 | U9: =($H9/$AD9)*100 -> 0.83086686 | V9: =($H9/AB9)*100 -> 0.61229226 | W9: =($I9/$AD9)*100 -> 12.433938 | X9: =($I9/$AB9)*100 -> 9.1629648 | Y9: =($J9/$AD9)*100 -> 0.86346706 | Z9: =($J9/$AB9)*100 -> 0.63631638 | AA9: 1.7965277e+12 | AB9: 1796.5277 | AC9: 1.3239185e+12 | AD9: 1323.9185
A10: GBR | B10: Q1.2020 | C10: =D10+E10 -> 83 | D10: 6.3846154 | E10: 76.615385 | F10: 0 | G10: =H10+I10 -> 423 | H10: 423 | I10: 0 | J10: 0 | K10: =M10+O10 -> 2.628755 | L10: =N10+P10 -> 2.8212212 | M10: =($D10/$AD10)*100 -> 0.20221192 | N10: =($D10/$AB10)*100 -> 0.21701702 | O10: =($E10/$AD10)*100 -> 2.4265431 | P10: =($E10/$AB10)*100 -> 2.6042042 | Q10: =($F10/$AD10)*100 -> 0 | R10: =($F10/$AB10)*100 -> 0 | S10: =U10+W10 -> 13.397149 | T10: =V10+X10 -> 14.378031 | U10: =($H10/$AD10)*100 -> 13.397149 | V10: =($H10/AB10)*100 -> 14.378031 | W10: =($I10/$AD10)*100 -> 0 | X10: =($I10/$AB10)*100 -> 0 | Y10: =($J10/$AD10)*100 -> 0 | Z10: =($J10/$AB10)*100 -> 0 | AA10: 2.9419883e+12 | AB10: 2941.9883 | AC10: 3.1573882e+12 | AD10: 3157.3882
A11: USA | B11: Q1.2020 | C11: =D11+E11 -> 1395 | D11: 9.45 | E11: 1385.55 | F11: 0 | G11: =H11+I11 -> 859 | H11: 405 | I11: 454 | J11: 0 | K11: =M11+O11 -> 6.9998582 | L11: =N11+P11 -> 6.9840045 | M11: =($D11/$AD11)*100 -> 0.047418394 | N11: =($D11/$AB11)*100 -> 0.047310998 | O11: =($E11/$AD11)*100 -> 6.9524398 | P11: =($E11/$AB11)*100 -> 6.9366935 | Q11: =($F11/$AD11)*100 -> 0 | R11: =($F11/$AB11)*100 -> 0 | S11: =U11+W11 -> 4.3103069 | T11: =V11+X11 -> 4.3005447 | U11: =($H11/$AD11)*100 -> 2.0322169 | V11: =($H11/AB11)*100 -> 2.0276142 | W11: =($I11/$AD11)*100 -> 2.27809 | X11: =($I11/$AB11)*100 -> 2.2729305 | Y11: =($J11/$AD11)*100 -> 0 | Z11: =($J11/$AB11)*100 -> 0 | AA11: 1.9974214e+13 | AB11: 19974.214 | AC11: 19928975197000 | AD11: 19928.975
A12: MEX | B12: Q1.2020 | C12: =D12+E12 -> 7.9 | D12: 7.9 | E12: 0 | F12: 0 | G12: =H12+I12 -> 3.3 | H12: 3.3 | I12: 0 | J12: 0 | K12: =M12+O12 -> 0.61759698 | L12: =N12+P12 -> 0.33170037 | M12: =($D12/$AD12)*100 -> 0.61759698 | N12: =($D12/$AB12)*100 -> 0.33170037 | O12: =($E12/$AD12)*100 -> 0 | P12: =($E12/$AB12)*100 -> 0 | Q12: =($F12/$AD12)*100 -> 0 | R12: =($F12/$AB12)*100 -> 0 | S12: =U12+W12 -> 0.25798355 | T12: =V12+X12 -> 0.13855838 | U12: =($H12/$AD12)*100 -> 0.25798355 | V12: =($H12/AB12)*100 -> 0.13855838 | W12: =($I12/$AD12)*100 -> 0 | X12: =($I12/$AB12)*100 -> 0 | Y12: =($J12/$AD12)*100 -> 0 | Z12: =($J12/$AB12)*100 -> 0 | AA12: 2.3816676e+12 | AB12: 2381.6676 | AC12: 1.2791513e+12 | AD12: 1279.1513
A13: TUR | B13: Q1.2020 | C13: =D13+E13 -> 11 | D13: 11 | E13: 0 | F13: 0 | G13: =H13+I13 -> 3.8 | H13: 0 | I13: 3.8 | J13: 0 | K13: =M13+O13 -> 1.1032507 | L13: =N13+P13 -> 0.47133766 | M13: =($D13/$AD13)*100 -> 1.1032507 | N13: =($D13/$AB13)*100 -> 0.47133766 | O13: =($E13/$AD13)*100 -> 0 | P13: =($E13/$AB13)*100 -> 0 | Q13: =($F13/$AD13)*100 -> 0 | R13: =($F13/$AB13)*100 -> 0 | S13: =U13+W13 -> 0.38112296 | T13: =V13+X13 -> 0.16282574 | U13: =($H13/$AD13)*100 -> 0 | V13: =($H13/AB13)*100 -> 0 | W13: =($I13/$AD13)*100 -> 0.38112296 | X13: =($I13/$AB13)*100 -> 0.16282574 | Y13: =($J13/$AD13)*100 -> 0 | Z13: =($J13/$AB13)*100 -> 0 | AA13: 2.3337834e+12 | AB13: 2333.7834 | AC13: 9.9705355e+11 | AD13: 997.05355
... A27: NLD | B27: Q1.2020 | C27: =D27+E27 -> 22 | D27: 0 | E27: 22 | F27: 45 | G27: =H27+I27 -> 0 | H27: 0 | I27: 0 | J27: 0 | K27: =M27+O27 -> 2.618267 | L27: =N27+P27 -> 2.3594 | M27: =($D27/$AD27)*100 -> 0 | N27: =($D27/$AB27)*100 -> 0 | O27: =($E27/$AD27)*100 -> 2.618267 | P27: =($E27/$AB27)*100 -> 2.3594 | Q27: =($F27/$AD27)*100 -> 5.3555462 | R27: =($F27/$AB27)*100 -> 4.8260455 | S27: =U27+W27 -> 0 | T27: =V27+X27 -> 0 | U27: =($H27/$AD27)*100 -> 0 | V27: =($H27/AB27)*100 -> 0 | W27: =($I27/$AD27)*100 -> 0 | X27: =($I27/$AB27)*100 -> 0 | Y27: =($J27/$AD27)*100 -> 0 | Z27: =($J27/$AB27)*100 -> 0 | AA27: 9.3244043e+11 | AB27: 932.44043 | AC27: 8.4025043e+11 | AD27: 840.25043
A28: NZL | B28: Q1.2020 | C28: =D28+E28 -> 11.088516 | D28: 0.31570903 | E28: 10.772806 | F28: 0 | G28: =H28+I28 -> 6.6522016 | H28: 2.7058387 | I28: 3.9463629 | K28: =M28+O28 -> 5.4639624 | L28: =N28+P28 -> 5.7165015 | M28: =($D28/$AD28)*100 -> 0.15556837 | N28: =($D28/$AB28)*100 -> 0.16275859 | O28: =($E28/$AD28)*100 -> 5.3083941 | P28: =($E28/$AB28)*100 -> 5.5537429 | Q28: =($F28/$AD28)*100 -> 0 | R28: =($F28/$AB28)*100 -> 0 | S28: =U28+W28 -> 3.2779302 | T28: =V28+X28 -> 3.429433 | U28: =($H28/$AD28)*100 -> 1.3333256 | V28: =($H28/AB28)*100 -> 1.3949506 | W28: =($I28/$AD28)*100 -> 1.9446046 | X28: =($I28/$AB28)*100 -> 2.0344824 | Y28: =($J28/$AD28)*100 -> 0 | Z28: =($J28/$AB28)*100 -> 0 | AA28: 1.9397381e+11 | AB28: 193.97381 | AC28: 2.0293909e+11 | AD28: 202.93909
A29: NOR | B29: Q1.2020 | C29: =D29+E29 -> 8.1 | D29: 0 | E29: 8.1 | F29: 0 | G29: =H29+I29 -> 10.6 | H29: 5.3 | I29: 5.3 | J29: 0 | K29: =M29+O29 -> 1.9744091 | L29: =N29+P29 -> 2.4511712 | M29: =($D29/$AD29)*100 -> 0 | N29: =($D29/$AB29)*100 -> 0 | O29: =($E29/$AD29)*100 -> 1.9744091 | P29: =($E29/$AB29)*100 -> 2.4511712 | Q29: =($F29/$AD29)*100 -> 0 | R29: =($F29/$AB29)*100 -> 0 | S29: =U29+W29 -> 2.5837946 | T29: =V29+X29 -> 3.2077056 | U29: =($H29/$AD29)*100 -> 1.2918973 | V29: =($H29/AB29)*100 -> 1.6038528 | W29: =($I29/$AD29)*100 -> 1.2918973 | X29: =($I29/$AB29)*100 -> 1.6038528 | Y29: =($J29/$AD29)*100 -> 0 | Z29: =($J29/$AB29)*100 -> 0 | AA29: 3.3045427e+11 | AB29: 330.45427 | AC29: 4.1024933e+11 | AD29: 410.24933
A30: PRT | B30: Q1.2020 | C30: =D30+E30 -> 7.2019168 | D30: 1.8290582 | E30: 5.3728586 | F30: 9.030975 | G30: =H30+I30 -> 14.861098 | H30: 0 | I30: 14.861098 | J30: 0 | K30: =M30+O30 -> 3.2388198 | L30: =N30+P30 -> 2.1106626 | M30: =($D30/$AD30)*100 -> 0.82255741 | N30: =($D30/$AB30)*100 -> 0.53604129 | O30: =($E30/$AD30)*100 -> 2.4162624 | P30: =($E30/$AB30)*100 -> 1.5746213 | Q30: =($F30/$AD30)*100 -> 4.0613772 | R30: =($F30/$AB30)*100 -> 2.6467038 | S30: =U30+W30 -> 6.6832789 | T30: =V30+X30 -> 4.3553354 | U30: =($H30/$AD30)*100 -> 0 | V30: =($H30/AB30)*100 -> 0 | W30: =($I30/$AD30)*100 -> 6.6832789 | X30: =($I30/$AB30)*100 -> 4.3553354 | Y30: =($J30/$AD30)*100 -> 0 | Z30: =($J30/$AB30)*100 -> 0 | AA30: 3.4121593e+11 | AB30: 341.21593 | AC30: 2.2236238e+11 | AD30: 222.36238
A31: SVK | B31: Q1.2020 | C31: =D31+E31 -> 2.5149551 | D31: 0.18290582 | E31: 2.3320493 | F31: 1.4060885 | G31: =H31+I31 -> 4.5840772 | H31: 0 | I31: 4.5840772 | J31: 0 | K31: =M31+O31 -> 2.5278709 | L31: =N31+P31 -> 1.3840355 | M31: =($D31/$AD31)*100 -> 0.18384516 | N31: =($D31/$AB31)*100 -> 0.10065713 | O31: =($E31/$AD31)*100 -> 2.3440258 | P31: =($E31/$AB31)*100 -> 1.2833784 | Q31: =($F31/$AD31)*100 -> 1.4133097 | R31: =($F31/$AB31)*100 -> 0.77380168 | S31: =U31+W31 -> 4.6076193 | T31: =V31+X31 -> 2.5227193 | U31: =($H31/$AD31)*100 -> 0 | V31: =($H31/AB31)*100 -> 0 | W31: =($I31/$AD31)*100 -> 4.6076193 | X31: =($I31/$AB31)*100 -> 2.5227193 | Y31: =($J31/$AD31)*100 -> 0 | Z31: =($J31/$AB31)*100 -> 0 | AA31: 1.8171174e+11 | AB31: 181.71174 | AC31: 9.9489061e+10 | AD31: 99.489061
A32: SVN | B32: Q1.2020 | C32: =D32+E32 -> 4.115381 | D32: 0.11431614 | E32: 4.0010649 | F32: 0 | G32: =H32+I32 -> 3.3151681 | H32: 0.68589684 | I32: 2.6292712 | J32: 0.11431614 | K32: =M32+O32 -> 8.162527 | L32: =N32+P32 -> 5.412314 | M32: =($D32/$AD32)*100 -> 0.22673686 | N32: =($D32/$AB32)*100 -> 0.15034206 | O32: =($E32/$AD32)*100 -> 7.9357901 | P32: =($E32/$AB32)*100 -> 5.261972 | Q32: =($F32/$AD32)*100 -> 0 | R32: =($F32/$AB32)*100 -> 0 | S32: =U32+W32 -> 6.575369 | T32: =V32+X32 -> 4.3599196 | U32: =($H32/$AD32)*100 -> 1.3604212 | V32: =($H32/AB32)*100 -> 0.90205234 | W32: =($I32/$AD32)*100 -> 5.2149478 | X32: =($I32/$AB32)*100 -> 3.4578673 | Y32: =($J32/$AD32)*100 -> 0.22673686 | Z32: =($J32/$AB32)*100 -> 0.15034206 | AA32: 7.6037366e+10 | AB32: 76.037366 | AC32: 5.0417978e+10 | AD32: 50.417978
A33: SWE | B33: Q1.2020 | C33: =D33+E33 -> 11 | D33: 0 | E33: 11 | F33: 0 | G33: =H33+I33 -> 25 | H33: 0 | I33: 25 | J33: 0 | K33: =M33+O33 -> 2.0006501 | L33: =N33+P33 -> 2.1113062 | M33: =($D33/$AD33)*100 -> 0 | N33: =($D33/$AB33)*100 -> 0 | O33: =($E33/$AD33)*100 -> 2.0006501 | P33: =($E33/$AB33)*100 -> 2.1113062 | Q33: =($F33/$AD33)*100 -> 0 | R33: =($F33/$AB33)*100 -> 0 | S33: =U33+W33 -> 4.546932 | T33: =V33+X33 -> 4.7984231 | U33: =($H33/$AD33)*100 -> 0 | V33: =($H33/AB33)*100 -> 0 | W33: =($I33/$AD33)*100 -> 4.546932 | X33: =($I33/$AB33)*100 -> 4.7984231 | Y33: =($J33/$AD33)*100 -> 0 | Z33: =($J33/$AB33)*100 -> 0 | AA33: 5.2100449e+11 | AB33: 521.00449 | AC33: 5.4982128e+11 | AD33: 549.82128
A34: CHE | B34: Q1.2020 | C34: =D34+E34 -> 1.6825977 | D34: 0 | E34: 1.6825977 | F34: 0 | G34: =H34+I34 -> 0.21161296 | H34: =0.0516129+0.05677419 -> 0.10838709 | I34: =0.10322587 -> 0.10322587 | J34: 0 | K34: =M34+O34 -> 0.22521425 | L34: =N34+P34 -> 0.28479303 | M34: =($D34/$AD34)*100 -> 0 | N34: =($D34/$AB34)*100 -> 0 | O34: =($E34/$AD34)*100 -> 0.22521425 | P34: =($E34/$AB34)*100 -> 0.28479303 | Q34: =($F34/$AD34)*100 -> 0 | R34: =($F34/$AB34)*100 -> 0 | S34: =U34+W34 -> 0.028324212 | T34: =V34+X34 -> 0.035817175 | U34: =($H34/$AD34)*100 -> 0.014507519 | V34: =($H34/AB34)*100 -> 0.018345376 | W34: =($I34/$AD34)*100 -> 0.013816694 | X34: =($I34/$AB34)*100 -> 0.017471799 | Y34: =($J34/$AD34)*100 -> 0 | Z34: =($J34/$AB34)*100 -> 0 | AA34: 5.9081422e+11 | AB34: 590.81422 | AC34: 7.4710978e+11 | AD34: 747.10978
A35: CHL | B35: Q1.2020 | C35: =D35+E35 -> 4.6 | D35: 1 | E35: 3.6 | F35: 4.7152702 | G35: =H35+I35 -> 2.4 | H35: 2.4 | I35: 0 | J35: 0 | K35: =M35+O35 -> 1.7559969 | L35: =N35+P35 -> 1.0424015 | M35: =($D35/$AD35)*100 -> 0.38173846 | N35: =($D35/$AB35)*100 -> 0.22660903 | O35: =($E35/$AD35)*100 -> 1.3742585 | P35: =($E35/$AB35)*100 -> 0.81579252 | Q35: =($F35/$AD35)*100 -> 1.8 | R35: =($F35/$AB35)*100 -> 1.0685228 | S35: =U35+W35 -> 0.91617231 | T35: =V35+X35 -> 0.54386168 | U35: =($H35/$AD35)*100 -> 0.91617231 | V35: =($H35/AB35)*100 -> 0.54386168 | W35: =($I35/$AD35)*100 -> 0 | X35: =($I35/$AB35)*100 -> 0 | Y35: =($J35/$AD35)*100 -> 0 | Z35: =($J35/$AB35)*100 -> 0 | AA35: 4.4128868e+11 | AB35: 441.28868 | AC35: 2.6195946e+11 | AD35: 261.95946
A36: COL | B36: Q1.2020 | C36: =D36+E36 -> 0 | D36: 0 | E36: 0 | F36: 0 | G36: =H36+I36 -> 0.1 | H36: 0.1 | I36: 0 | J36: 0 | K36: =M36+O36 -> 0 | L36: =N36+P36 -> 0 | M36: =($D36/$AD36)*100 -> 0 | N36: =($D36/$AB36)*100 -> 0 | O36: =($E36/$AD36)*100 -> 0 | P36: =($E36/$AB36)*100 -> 0 | Q36: =($F36/$AD36)*100 -> 0 | R36: =($F36/$AB36)*100 -> 0 | S36: =U36+W36 -> 0.031113334 | T36: =V36+X36 -> 0.014482907 | U36: =($H36/$AD36)*100 -> 0.031113334 | V36: =($H36/AB36)*100 -> 0.014482907 | W36: =($I36/$AD36)*100 -> 0 | X36: =($I36/$AB36)*100 -> 0 | Y36: =($J36/$AD36)*100 -> 0 | Z36: =($J36/$AB36)*100 -> 0 | AA36: 6.9046913e+11 | AB36: 690.46913 | AC36: 3.2140561e+11 | AD36: 321.40561
A37: CRI | B37: Q1.2020 | C37: =D37+E37 -> 0.717434 | D37: 0.17 | E37: 0.547434 | F37: 0 | G37: =H37+I37 -> 0 | H37: 0 | I37: 0 | J37: 0 | K37: =M37+O37 -> 1.1143309 | L37: =N37+P37 -> 0.78637134 | M37: =($D37/$AD37)*100 -> 0.26404693 | N37: =($D37/$AB37)*100 -> 0.18633509 | O37: =($E37/$AD37)*100 -> 0.85028393 | P37: =($E37/$AB37)*100 -> 0.60003625 | Q37: =($F37/$AD37)*100 -> 0 | R37: =($F37/$AB37)*100 -> 0 | S37: =U37+W37 -> 0 | T37: =V37+X37 -> 0 | U37: =($H37/$AD37)*100 -> 0 | V37: =($H37/AB37)*100 -> 0 | W37: =($I37/$AD37)*100 -> 0 | X37: =($I37/$AB37)*100 -> 0 | Y37: =($J37/$AD37)*100 -> 0 | Z37: =($J37/$AB37)*100 -> 0 | AA37: 9.1233488e+10 | AB37: 91.233488 | AC37: 6.4382494e+10 | AD37: 64.382494
A38: HUN | B38: Q1.2020 | C38: =D38+E38 -> 4.419749 | D38: 0 | E38: 4.419749 | F38: 0 | G38: =H38+I38 -> 0 | H38: 0 | I38: 0 | J38: 0 | K38: =M38+O38 -> 2.9987989 | L38: =N38+P38 -> 1.42624 | M38: =($D38/$AD38)*100 -> 0 | N38: =($D38/$AB38)*100 -> 0 | O38: =($E38/$AD38)*100 -> 2.9987989 | P38: =($E38/$AB38)*100 -> 1.42624 | Q38: =($F38/$AD38)*100 -> 0 | R38: =($F38/$AB38)*100 -> 0 | S38: =U38+W38 -> 0 | T38: =V38+X38 -> 0 | U38: =($H38/$AD38)*100 -> 0 | V38: =($H38/AB38)*100 -> 0 | W38: =($I38/$AD38)*100 -> 0 | X38: =($I38/$AB38)*100 -> 0 | Y38: =($J38/$AD38)*100 -> 0 | Z38: =($J38/$AB38)*100 -> 0 | AA38: 3.0988816e+11 | AB38: 309.88816 | AC38: 1.4738397e+11 | AD38: 147.38397
A39: POL | B39: Q1.2020 | C39: =D39+E39 -> 17 | D39: 8 | E39: 9 | F39: 0 | G39: =H39+I39 -> 17 | H39: 0 | I39: 17 | J39: 0 | K39: =M39+O39 -> 2.9746119 | L39: =N39+P39 -> 1.3986902 | M39: =($D39/$AD39)*100 -> 1.3998174 | N39: =($D39/$AB39)*100 -> 0.65820713 | O39: =($E39/$AD39)*100 -> 1.5747946 | P39: =($E39/$AB39)*100 -> 0.74048302 | Q39: =($F39/$AD39)*100 -> 0 | R39: =($F39/$AB39)*100 -> 0 | S39: =U39+W39 -> 2.9746119 | T39: =V39+X39 -> 1.3986902 | U39: =($H39/$AD39)*100 -> 0 | V39: =($H39/AB39)*100 -> 0 | W39: =($I39/$AD39)*100 -> 2.9746119 | X39: =($I39/$AB39)*100 -> 1.3986902 | Y39: =($J39/$AD39)*100 -> 0 | Z39: =($J39/$AB39)*100 -> 0 | AA39: 1.2154229e+12 | AB39: 1215.4229 | AC39: 5.7150312e+11 | AD39: 571.50312
