Workbook
Name IQ_CH: 110000
Name IQ_CQ: 5000
Name IQ_CY: 10000
Name IQ_DAILY: 500000
Name IQ_FH: 100000
Name IQ_FQ: 500
Name IQ_FY: 1000
Name IQ_LTM: 2000
Name IQ_MONTH: 15000
Name IQ_NTM: 6000
Name IQ_WEEK: 50000
Name IQ_YTD: 3000

Sheet data
A1: Country | B1: Quarter | C1: ab_us | D1: health_us | E1: nhealth_us | F1: acc_us | G1: of_us | H1: be_us | I1: gu_us | J1: qf_us | K1: ab_per | L1: ab_ppp | M1: health_per | N1: health_ppp | O1: nhealth_per | P1: nhealth_ppp | Q1: acc_per | R1: acc_ppp | S1: of_per | T1: of_ppp | U1: be_per | V1: be_ppp | W1: gu_per | X1: gu_ppp | Y1: qf_per | Z1: qf_ppp | AA1: in bn | AB1: in bn
A2: AUS | B2: Q1.2020 | C2: =D2+E2 -> 110.0051 | D2: 2.1168 | E2: 107.8883 | F2: 0 | G2: =H2+I2 -> 24.0029 | H2: 10.3255 | I2: 13.6774 | J2: 0 | K2: =M2+O2 -> 7.3593163 | L2: =N2+P2 -> 8.9689107 | M2: =($D2/$AB2)*100 -> 0.14161344 | N2: =($D2/$AA2)*100 -> 0.17258646 | O2: =($E2/$AB2)*100 -> 7.2177029 | P2: =($E2/$AA2)*100 -> 8.7963243 | Q2: =($F2/$AB2)*100 -> 0 | R2: =($F2/$AA2)*100 -> 0 | S2: =U2+W2 -> 1.6057886 | T2: =V2+X2 -> 1.956999 | U2: =($H2/$AB2)*100 -> 0.69077361 | V2: =($H2/AA2)*100 -> 0.84185631 | W2: =($I2/$AB2)*100 -> 0.91501497 | X2: =($I2/$AA2)*100 -> 1.1151427 | Y2: =($J2/$AB2)*100 -> 0 | Z2: =($J2/$AA2)*100 -> 0 | AA2: 1226.5157 | AB2: 1494.7734
A3: CAN | B3: Q1.2020 | C3: =D3+E3 -> 81 | D3: 2.4 | E3: 78.6 | F3: 63.75 | G3: =H3+I3 -> 51.7 | H3: 3.7 | I3: 48 | J3: 0 | K3: =M3+O3 -> 4.7742401 | L3: =N3+P3 -> 4.6997712 | M3: =($D3/$AB3)*100 -> 0.14145896 | N3: =($D3/$AA3)*100 -> 0.13925248 | O3: =($E3/$AB3)*100 -> 4.6327811 | P3: =($E3/$AA3)*100 -> 4.5605187 | Q3: =($F3/$AB3)*100 -> 3.7575038 | R3: =($F3/$AA3)*100 -> 3.698894 | S3: =U3+W3 -> 3.0472619 | T3: =V3+X3 -> 2.9997305 | U3: =($H3/$AB3)*100 -> 0.21808257 | V3: =($H3/AA3)*100 -> 0.21468091 | W3: =($I3/$AB3)*100 -> 2.8291793 | X3: =($I3/$AA3)*100 -> 2.7850496 | Y3: =($J3/$AB3)*100 -> 0 | Z3: =($J3/$AA3)*100 -> 0 | AA3: 1723.4882 | AB3: 1696.6051
A4: FRA | B4: Q1.2020 | C4: =D4+E4 -> 16.5 | D4: 5.5 | E4: 11 | F4: 48.5 | G4: =H4+I4 -> 348 | H4: 0 | I4: 348 | J4: 0 | K4: =M4+O4 -> 0.63053811 | L4: =N4+P4 -> 0.56757784 | M4: =($D4/$AB4)*100 -> 0.21017937 | N4: =($D4/$AA4)*100 -> 0.18919261 | O4: =($E4/$AB4)*100 -> 0.42035874 | P4: =($E4/$AA4)*100 -> 0.37838523 | Q4: =($F4/$AB4)*100 -> 1.8533999 | R4: =($F4/$AA4)*100 -> 1.6683349 | S4: =U4+W4 -> 13.298622 | T4: =V4+X4 -> 11.970733 | U4: =($H4/$AB4)*100 -> 0 | V4: =($H4/AA4)*100 -> 0 | W4: =($I4/$AB4)*100 -> 13.298622 | X4: =($I4/$AA4)*100 -> 11.970733 | Y4: =($J4/$AB4)*100 -> 0 | Z4: =($J4/$AA4)*100 -> 0 | AA4: 2907.0902 | AB4: 2616.8125
A5: DEU | B5: Q1.2020 | C5: =D5+E5 -> 143 | D5: 11.2 | E5: 131.8 | F5: 0 | G5: =H5+I5 -> 1072 | H5: 223 | I5: 849 | J5: 0 | K5: =M5+O5 -> 3.9751845 | L5: =N5+P5 -> 3.4360259 | M5: =($D5/$AB5)*100 -> 0.31134312 | N5: =($D5/$AA5)*100 -> 0.26911531 | O5: =($E5/$AB5)*100 -> 3.6638413 | P5: =($E5/$AA5)*100 -> 3.1669106 | Q5: =($F5/$AB5)*100 -> 0 | R5: =($F5/$AA5)*100 -> 0 | S5: =U5+W5 -> 29.799984 | T5: =V5+X5 -> 25.75818 | U5: =($H5/$AB5)*100 -> 6.1990639 | V5: =($H5/AA5)*100 -> 5.3582781 | W5: =($I5/$AB5)*100 -> 23.60092 | X5: =($I5/$AA5)*100 -> 20.399902 | Y5: =($J5/$AB5)*100 -> 0 | Z5: =($J5/$AA5)*100 -> 0 | AA5: 4161.7847 | AB5: 3597.3173
A6: ITA | B6: Q1.2020 | C6: =D6+E6 -> 22 | D6: 3.63 | E6: 18.37 | F6: 0 | G6: =H6+I6 -> 591 | H6: 0 | I6: 591 | J6: 0 | K6: =M6+O6 -> 1.1469339 | L6: =N6+P6 -> 0.94111213 | M6: =($D6/$AB6)*100 -> 0.18924409 | N6: =($D6/$AA6)*100 -> 0.1552835 | O6: =($E6/$AB6)*100 -> 0.95768981 | P6: =($E6/$AA6)*100 -> 0.78582863 | Q6: =($F6/$AB6)*100 -> 0 | R6: =($F6/$AA6)*100 -> 0 | S6: =U6+W6 -> 30.810815 | T6: =V6+X6 -> 25.281694 | U6: =($H6/$AB6)*100 -> 0 | V6: =($H6/AA6)*100 -> 0 | W6: =($I6/$AB6)*100 -> 30.810815 | X6: =($I6/$AA6)*100 -> 25.281694 | Y6: =($J6/$AB6)*100 -> 0 | Z6: =($J6/$AA6)*100 -> 0 | AA6: 2337.6598 | AB6: 1918.1576
A7: JPN | B7: Q1.2020 | C7: =D7+E7 -> 497 | D7: 12.1906 | E7: 484.8094 | F7: 0 | G7: =H7+I7 -> 19 | H7: 0 | I7: 19 | J7: 0 | K7: =M7+O7 -> 10.888777 | L7: =N7+P7 -> 9.3335923 | M7: =($D7/$AB7)*100 -> 0.26708396 | N7: =($D7/$AA7)*100 -> 0.22893781 | O7: =($E7/$AB7)*100 -> 10.621693 | P7: =($E7/$AA7)*100 -> 9.1046545 | Q7: =($F7/$AB7)*100 -> 0 | R7: =($F7/$AA7)*100 -> 0 | S7: =U7+W7 -> 0.41627116 | T7: =V7+X7 -> 0.35681741 | U7: =($H7/$AB7)*100 -> 0 | V7: =($H7/AA7)*100 -> 0 | W7: =($I7/$AB7)*100 -> 0.41627116 | X7: =($I7/$AA7)*100 -> 0.35681741 | Y7: =($J7/$AB7)*100 -> 0 | Z7: =($J7/$AA7)*100 -> 0 | AA7: 5324.8522 | AB7: 4564.3326
A8: KOR | B8: Q1.2020 | C8: =D8+E8 -> 24 | D8: 2.5 | E8: 21.5 | F8: 14 | G8: =H8+I8 -> 215 | H8: 101 | I8: 114 | J8: 0 | K8: =M8+O8 -> 1.46507 | L8: =N8+P8 -> 1.112894 | M8: =($D8/$AB8)*100 -> 0.15261146 | N8: =($D8/$AA8)*100 -> 0.11592646 | O8: =($E8/$AB8)*100 -> 1.3124586 | P8: =($E8/$AA8)*100 -> 0.99696756 | Q8: =($F8/$AB8)*100 -> 0.85462418 | R8: =($F8/$AA8)*100 -> 0.64918818 | S8: =U8+W8 -> 13.124586 | T8: =V8+X8 -> 9.9696756 | U8: =($H8/$AB8)*100 -> 6.165503 | V8: =($H8/AA8)*100 -> 4.683429 | W8: =($I8/$AB8)*100 -> 6.9590826 | X8: =($I8/$AA8)*100 -> 5.2862466 | Y8: =($J8/$AB8)*100 -> 0 | Z8: =($J8/$AA8)*100 -> 0 | AA8: 2156.5396 | AB8: 1638.147
A9: ESP | B9: Q1.2020 | C9: =D9+E9 -> 14.8929 | D9: 4.1786 | E9: 10.7143 | F9: 0 | G9: =H9+I9 -> 175.6152 | H9: 11 | I9: 164.6152 | J9: 11.4316 | K9: =M9+O9 -> 1.1249106 | L9: =N9+P9 -> 0.82898249 | M9: =($D9/$AB9)*100 -> 0.31562366 | N9: =($D9/$AA9)*100 -> 0.23259313 | O9: =($E9/$AB9)*100 -> 0.80928698 | P9: =($E9/$AA9)*100 -> 0.59638936 | Q9: =($F9/$AB9)*100 -> 0 | R9: =($F9/$AA9)*100 -> 0 | S9: =U9+W9 -> 13.264805 | T9: =V9+X9 -> 9.775257 | U9: =($H9/$AB9)*100 -> 0.83086686 | V9: =($H9/AA9)*100 -> 0.61229226 | W9: =($I9/$AB9)*100 -> 12.433938 | X9: =($I9/$AA9)*100 -> 9.1629648 | Y9: =($J9/$AB9)*100 -> 0.86346706 | Z9: =($J9/$AA9)*100 -> 0.63631638 | AA9: 1796.5277 | AB9: 1323.9185
A10: GBR | B10: Q1.2020 | C10: =D10+E10 -> 83 | D10: 6.3846154 | E10: 76.615385 | F10: 0 | G10: =H10+I10 -> 423 | H10: 423 | I10: 0 | J10: 0 | K10: =M10+O10 -> 2.628755 | L10: =N10+P10 -> 2.8212212 | M10: =($D10/$AB10)*100 -> 0.20221192 | N10: =($D10/$AA10)*100 -> 0.21701702 | O10: =($E10/$AB10)*100 -> 2.4265431 | P10: =($E10/$AA10)*100 -> 2.6042042 | Q10: =($F10/$AB10)*100 -> 0 | R10: =($F10/$AA10)*100 -> 0 | S10: =U10+W10 -> 13.397149 | T10: =V10+X10 -> 14.378031 | U10: =($H10/$AB10)*100 -> 13.397149 | V10: =($H10/AA10)*100 -> 14.378031 | W10: =($I10/$AB10)*100 -> 0 | X10: =($I10/$AA10)*100 -> 0 | Y10: =($J10/$AB10)*100 -> 0 | Z10: =($J10/$AA10)*100 -> 0 | AA10: 2941.9883 | AB10: 3157.3882
A11: USA | B11: Q1.2020 | C11: =D11+E11 -> 1395 | D11: 9.45 | E11: 1385.55 | F11: 0 | G11: =H11+I11 -> 510 | H11: 56 | I11: 454 | J11: 0 | K11: =M11+O11 -> 6.9998582 | L11: =N11+P11 -> 6.9840045 | M11: =($D11/$AB11)*100 -> 0.047418394 | N11: =($D11/$AA11)*100 -> 0.047310998 | O11: =($E11/$AB11)*100 -> 6.9524398 | P11: =($E11/$AA11)*100 -> 6.9366935 | Q11: =($F11/$AB11)*100 -> 0 | R11: =($F11/$AA11)*100 -> 0 | S11: =U11+W11 -> 2.5590879 | T11: =V11+X11 -> 2.553292 | U11: =($H11/$AB11)*100 -> 0.28099789 | V11: =($H11/AA11)*100 -> 0.28036147 | W11: =($I11/$AB11)*100 -> 2.27809 | X11: =($I11/$AA11)*100 -> 2.2729305 | Y11: =($J11/$AB11)*100 -> 0 | Z11: =($J11/$AA11)*100 -> 0 | AA11: 19974.214 | AB11: 19928.975
A12: MEX | B12: Q1.2020 | C12: =D12+E12 -> 1.862 | D12: 1.862 | E12: 0 | F12: 0 | G12: =H12+I12 -> 3.3 | H12: 3.3 | I12: 0 | J12: 0 | K12: =M12+O12 -> 0.14556526 | L12: =N12+P12 -> 0.078180517 | M12: =($D12/$AB12)*100 -> 0.14556526 | N12: =($D12/$AA12)*100 -> 0.078180517 | O12: =($E12/$AB12)*100 -> 0 | P12: =($E12/$AA12)*100 -> 0 | Q12: =($F12/$AB12)*100 -> 0 | R12: =($F12/$AA12)*100 -> 0 | S12: =U12+W12 -> 0.25798355 | T12: =V12+X12 -> 0.13855838 | U12: =($H12/$AB12)*100 -> 0.25798355 | V12: =($H12/AA12)*100 -> 0.13855838 | W12: =($I12/$AB12)*100 -> 0 | X12: =($I12/$AA12)*100 -> 0 | Y12: =($J12/$AB12)*100 -> 0 | Z12: =($J12/$AA12)*100 -> 0 | AA12: 2381.6676 | AB12: 1279.1513
A13: TUR | B13: Q1.2020 | C13: =D13+E13 -> 0 | D13: 0 | E13: 0 | F13: 0 | G13: =H13+I13 -> 3.8 | H13: 0 | I13: 3.8 | J13: 0 | K13: =M13+O13 -> 0 | L13: =N13+P13 -> 0 | M13: =($D13/$AB13)*100 -> 0 | N13: =($D13/$AA13)*100 -> 0 | O13: =($E13/$AB13)*100 -> 0 | P13: =($E13/$AA13)*100 -> 0 | Q13: =($F13/$AB13)*100 -> 0 | R13: =($F13/$AA13)*100 -> 0 | S13: =U13+W13 -> 0.38112296 | T13: =V13+X13 -> 0.16282574 | U13: =($H13/$AB13)*100 -> 0 | V13: =($H13/AA13)*100 -> 0 | W13: =($I13/$AB13)*100 -> 0.38112296 | X13: =($I13/$AA13)*100 -> 0.16282574 | Y13: =($J13/$AB13)*100 -> 0 | Z13: =($J13/$AA13)*100 -> 0 | AA13: 2333.7834 | AB13: 997.05355
... A27: NLD | B27: Q1.2020 | C27: =D27+E27 -> 22 | D27: 0 | E27: 22 | F27: 45 | G27: =H27+I27 -> 0 | H27: 0 | I27: 0 | J27: 0 | K27: =M27+O27 -> 2.618267 | L27: =N27+P27 -> 2.3594 | M27: =($D27/$AB27)*100 -> 0 | N27: =($D27/$AA27)*100 -> 0 | O27: =($E27/$AB27)*100 -> 2.618267 | P27: =($E27/$AA27)*100 -> 2.3594 | Q27: =($F27/$AB27)*100 -> 5.3555462 | R27: =($F27/$AA27)*100 -> 4.8260455 | S27: =U27+W27 -> 0 | T27: =V27+X27 -> 0 | U27: =($H27/$AB27)*100 -> 0 | V27: =($H27/AA27)*100 -> 0 | W27: =($I27/$AB27)*100 -> 0 | X27: =($I27/$AA27)*100 -> 0 | Y27: =($J27/$AB27)*100 -> 0 | Z27: =($J27/$AA27)*100 -> 0 | AA27: 932.44043 | AB27: 840.25043
A28: NZL | B28: Q1.2020 | C28: =D28+E28 -> 11.088516 | D28: 0.31570903 | E28: 10.772806 | F28: 0 | G28: =H28+I28 -> 6.6522016 | H28: 2.7058387 | I28: 3.9463629 | K28: =M28+O28 -> 5.4639624 | L28: =N28+P28 -> 5.7165015 | M28: =($D28/$AB28)*100 -> 0.15556837 | N28: =($D28/$AA28)*100 -> 0.16275859 | O28: =($E28/$AB28)*100 -> 5.3083941 | P28: =($E28/$AA28)*100 -> 5.5537429 | Q28: =($F28/$AB28)*100 -> 0 | R28: =($F28/$AA28)*100 -> 0 | S28: =U28+W28 -> 3.2779302 | T28: =V28+X28 -> 3.429433 | U28: =($H28/$AB28)*100 -> 1.3333256 | V28: =($H28/AA28)*100 -> 1.3949506 | W28: =($I28/$AB28)*100 -> 1.9446046 | X28: =($I28/$AA28)*100 -> 2.0344824 | Y28: =($J28/$AB28)*100 -> 0 | Z28: =($J28/$AA28)*100 -> 0 | AA28: 193.97381 | AB28: 202.93909
A29: NOR | B29: Q1.2020 | C29: =D29+E29 -> 8.1 | D29: 0 | E29: 8.1 | F29: 0 | G29: =H29+I29 -> 10.6 | H29: 5.3 | I29: 5.3 | J29: 0 | K29: =M29+O29 -> 1.9744091 | L29: =N29+P29 -> 2.4511712 | M29: =($D29/$AB29)*100 -> 0 | N29: =($D29/$AA29)*100 -> 0 | O29: =($E29/$AB29)*100 -> 1.9744091 | P29: =($E29/$AA29)*100 -> 2.4511712 | Q29: =($F29/$AB29)*100 -> 0 | R29: =($F29/$AA29)*100 -> 0 | S29: =U29+W29 -> 2.5837946 | T29: =V29+X29 -> 3.2077056 | U29: =($H29/$AB29)*100 -> 1.2918973 | V29: =($H29/AA29)*100 -> 1.6038528 | W29: =($I29/$AB29)*100 -> 1.2918973 | X29: =($I29/$AA29)*100 -> 1.6038528 | Y29: =($J29/$AB29)*100 -> 0 | Z29: =($J29/$AA29)*100 -> 0 | AA29: 330.45427 | AB29: 410.24933
A30: PRT | B30: Q1.2020 | C30: =D30+E30 -> 7.2019168 | D30: 1.8290582 | E30: 5.3728586 | F30: 9.030975 | G30: =H30+I30 -> 14.861098 | H30: 0 | I30: 14.861098 | J30: 0 | K30: =M30+O30 -> 3.2388198 | L30: =N30+P30 -> 2.1106626 | M30: =($D30/$AB30)*100 -> 0.82255741 | N30: =($D30/$AA30)*100 -> 0.53604129 | O30: =($E30/$AB30)*100 -> 2.4162624 | P30: =($E30/$AA30)*100 -> 1.5746213 | Q30: =($F30/$AB30)*100 -> 4.0613772 | R30: =($F30/$AA30)*100 -> 2.6467038 | S30: =U30+W30 -> 6.6832789 | T30: =V30+X30 -> 4.3553354 | U30: =($H30/$AB30)*100 -> 0 | V30: =($H30/AA30)*100 -> 0 | W30: =($I30/$AB30)*100 -> 6.6832789 | X30: =($I30/$AA30)*100 -> 4.3553354 | Y30: =($J30/$AB30)*100 -> 0 | Z30: =($J30/$AA30)*100 -> 0 | AA30: 341.21593 | AB30: 222.36238
A31: SVK | B31: Q1.2020 | C31: =D31+E31 -> 2.5149551 | D31: 0.18290582 | E31: 2.3320493 | F31: 1.4060885 | G31: =H31+I31 -> 4.5840772 | H31: 0 | I31: 4.5840772 | J31: 0 | K31: =M31+O31 -> 2.5278709 | L31: =N31+P31 -> 1.3840355 | M31: =($D31/$AB31)*100 -> 0.18384516 | N31: =($D31/$AA31)*100 -> 0.10065713 | O31: =($E31/$AB31)*100 -> 2.3440258 | P31: =($E31/$AA31)*100 -> 1.2833784 | Q31: =($F31/$AB31)*100 -> 1.4133097 | R31: =($F31/$AA31)*100 -> 0.77380168 | S31: =U31+W31 -> 4.6076193 | T31: =V31+X31 -> 2.5227193 | U31: =($H31/$AB31)*100 -> 0 | V31: =($H31/AA31)*100 -> 0 | W31: =($I31/$AB31)*100 -> 4.6076193 | X31: =($I31/$AA31)*100 -> 2.5227193 | Y31: =($J31/$AB31)*100 -> 0 | Z31: =($J31/$AA31)*100 -> 0 | AA31: 181.71174 | AB31: 99.489061
A32: SVN | B32: Q1.2020 | C32: =D32+E32 -> 4.115381 | D32: 0.11431614 | E32: 4.0010649 | F32: 0 | G32: =H32+I32 -> 3.3151681 | H32: 0.68589684 | I32: 2.6292712 | J32: 0.11431614 | K32: =M32+O32 -> 8.162527 | L32: =N32+P32 -> 5.412314 | M32: =($D32/$AB32)*100 -> 0.22673686 | N32: =($D32/$AA32)*100 -> 0.15034206 | O32: =($E32/$AB32)*100 -> 7.9357901 | P32: =($E32/$AA32)*100 -> 5.261972 | Q32: =($F32/$AB32)*100 -> 0 | R32: =($F32/$AA32)*100 -> 0 | S32: =U32+W32 -> 6.575369 | T32: =V32+X32 -> 4.3599196 | U32: =($H32/$AB32)*100 -> 1.3604212 | V32: =($H32/AA32)*100 -> 0.90205234 | W32: =($I32/$AB32)*100 -> 5.2149478 | X32: =($I32/$AA32)*100 -> 3.4578673 | Y32: =($J32/$AB32)*100 -> 0.22673686 | Z32: =($J32/$AA32)*100 -> 0.15034206 | AA32: 76.037366 | AB32: 50.417978
A33: SWE | B33: Q1.2020 | C33: =D33+E33 -> 11 | D33: 0 | E33: 11 | F33: 0 | G33: =H33+I33 -> 25 | H33: 0 | I33: 25 | J33: 0 | K33: =M33+O33 -> 2.0006501 | L33: =N33+P33 -> 2.1113062 | M33: =($D33/$AB33)*100 -> 0 | N33: =($D33/$AA33)*100 -> 0 | O33: =($E33/$AB33)*100 -> 2.0006501 | P33: =($E33/$AA33)*100 -> 2.1113062 | Q33: =($F33/$AB33)*100 -> 0 | R33: =($F33/$AA33)*100 -> 0 | S33: =U33+W33 -> 4.546932 | T33: =V33+X33 -> 4.7984231 | U33: =($H33/$AB33)*100 -> 0 | V33: =($H33/AA33)*100 -> 0 | W33: =($I33/$AB33)*100 -> 4.546932 | X33: =($I33/$AA33)*100 -> 4.7984231 | Y33: =($J33/$AB33)*100 -> 0 | Z33: =($J33/$AA33)*100 -> 0 | AA33: 521.00449 | AB33: 549.82128
A34: CHE | B34: Q1.2020 | C34: =D34+E34 -> 1.6825977 | D34: 0 | E34: 1.6825977 | F34: 0 | G34: =H34+I34 -> 0.21161296 | H34: =0.0516129+0.05677419 -> 0.10838709 | I34: =0.10322587 -> 0.10322587 | J34: 0 | K34: =M34+O34 -> 0.22521425 | L34: =N34+P34 -> 0.28479303 | M34: =($D34/$AB34)*100 -> 0 | N34: =($D34/$AA34)*100 -> 0 | O34: =($E34/$AB34)*100 -> 0.22521425 | P34: =($E34/$AA34)*100 -> 0.28479303 | Q34: =($F34/$AB34)*100 -> 0 | R34: =($F34/$AA34)*100 -> 0 | S34: =U34+W34 -> 0.028324212 | T34: =V34+X34 -> 0.035817175 | U34: =($H34/$AB34)*100 -> 0.014507519 | V34: =($H34/AA34)*100 -> 0.018345376 | W34: =($I34/$AB34)*100 -> 0.013816694 | X34: =($I34/$AA34)*100 -> 0.017471799 | Y34: =($J34/$AB34)*100 -> 0 | Z34: =($J34/$AA34)*100 -> 0 | AA34: 590.81422 | AB34: 747.10978
A35: CHL | B35: Q1.2020 | C35: =D35+E35 -> 4.6 | D35: 1 | E35: 3.6 | F35: 4.7152702 | G35: =H35+I35 -> 2.4 | H35: 2.4 | I35: 0 | J35: 0 | K35: =M35+O35 -> 1.7559969 | L35: =N35+P35 -> 1.0424015 | M35: =($D35/$AB35)*100 -> 0.38173846 | N35: =($D35/$AA35)*100 -> 0.22660903 | O35: =($E35/$AB35)*100 -> 1.3742585 | P35: =($E35/$AA35)*100 -> 0.81579252 | Q35: =($F35/$AB35)*100 -> 1.8 | R35: =($F35/$AA35)*100 -> 1.0685228 | S35: =U35+W35 -> 0.91617231 | T35: =V35+X35 -> 0.54386168 | U35: =($H35/$AB35)*100 -> 0.91617231 | V35: =($H35/AA35)*100 -> 0.54386168 | W35: =($I35/$AB35)*100 -> 0 | X35: =($I35/$AA35)*100 -> 0 | Y35: =($J35/$AB35)*100 -> 0 | Z35: =($J35/$AA35)*100 -> 0 | AA35: 441.28868 | AB35: 261.95946
A36: COL | B36: Q1.2020 | C36: =D36+E36 -> 0 | D36: 0 | E36: 0 | F36: 0 | G36: =H36+I36 -> 0.1 | H36: 0.1 | I36: 0 | J36: 0 | K36: =M36+O36 -> 0 | L36: =N36+P36 -> 0 | M36: =($D36/$AB36)*100 -> 0 | N36: =($D36/$AA36)*100 -> 0 | O36: =($E36/$AB36)*100 -> 0 | P36: =($E36/$AA36)*100 -> 0 | Q36: =($F36/$AB36)*100 -> 0 | R36: =($F36/$AA36)*100 -> 0 | S36: =U36+W36 -> 0.031113334 | T36: =V36+X36 -> 0.014482907 | U36: =($H36/$AB36)*100 -> 0.031113334 | V36: =($H36/AA36)*100 -> 0.014482907 | W36: =($I36/$AB36)*100 -> 0 | X36: =($I36/$AA36)*100 -> 0 | Y36: =($J36/$AB36)*100 -> 0 | Z36: =($J36/$AA36)*100 -> 0 | AA36: 690.46913 | AB36: 321.40561
A37: CRI | B37: Q1.2020 | C37: =D37+E37 -> 0.717434 | D37: 0.17 | E37: 0.547434 | F37: 0 | G37: =H37+I37 -> 0 | H37: 0 | I37: 0 | J37: 0 | K37: =M37+O37 -> 1.1143309 | L37: =N37+P37 -> 0.78637134 | M37: =($D37/$AB37)*100 -> 0.26404693 | N37: =($D37/$AA37)*100 -> 0.18633509 | O37: =($E37/$AB37)*100 -> 0.85028393 | P37: =($E37/$AA37)*100 -> 0.60003625 | Q37: =($F37/$AB37)*100 -> 0 | R37: =($F37/$AA37)*100 -> 0 | S37: =U37+W37 -> 0 | T37: =V37+X37 -> 0 | U37: =($H37/$AB37)*100 -> 0 | V37: =($H37/AA37)*100 -> 0 | W37: =($I37/$AB37)*100 -> 0 | X37: =($I37/$AA37)*100 -> 0 | Y37: =($J37/$AB37)*100 -> 0 | Z37: =($J37/$AA37)*100 -> 0 | AA37: 91.233488 | AB37: 64.382494
A38: HUN | B38: Q1.2020 | C38: =D38+E38 -> 4.419749 | D38: 0 | E38: 4.419749 | F38: 0 | G38: =H38+I38 -> 0 | H38: 0 | I38: 0 | J38: 0 | K38: =M38+O38 -> 2.9987989 | L38: =N38+P38 -> 1.42624 | M38: =($D38/$AB38)*100 -> 0 | N38: =($D38/$AA38)*100 -> 0 | O38: =($E38/$AB38)*100 -> 2.9987989 | P38: =($E38/$AA38)*100 -> 1.42624 | Q38: =($F38/$AB38)*100 -> 0 | R38: =($F38/$AA38)*100 -> 0 | S38: =U38+W38 -> 0 | T38: =V38+X38 -> 0 | U38: =($H38/$AB38)*100 -> 0 | V38: =($H38/AA38)*100 -> 0 | W38: =($I38/$AB38)*100 -> 0 | X38: =($I38/$AA38)*100 -> 0 | Y38: =($J38/$AB38)*100 -> 0 | Z38: =($J38/$AA38)*100 -> 0 | AA38: 309.88816 | AB38: 147.38397
A39: POL | B39: Q1.2020 | C39: =D39+E39 -> 17 | D39: 8 | E39: 9 | F39: 0 | G39: =H39+I39 -> 17 | H39: 0 | I39: 17 | J39: 0 | K39: =M39+O39 -> 2.9746119 | L39: =N39+P39 -> 1.3986902 | M39: =($D39/$AB39)*100 -> 1.3998174 | N39: =($D39/$AA39)*100 -> 0.65820713 | O39: =($E39/$AB39)*100 -> 1.5747946 | P39: =($E39/$AA39)*100 -> 0.74048302 | Q39: =($F39/$AB39)*100 -> 0 | R39: =($F39/$AA39)*100 -> 0 | S39: =U39+W39 -> 2.9746119 | T39: =V39+X39 -> 1.3986902 | U39: =($H39/$AB39)*100 -> 0 | V39: =($H39/AA39)*100 -> 0 | W39: =($I39/$AB39)*100 -> 2.9746119 | X39: =($I39/$AA39)*100 -> 1.3986902 | Y39: =($J39/$AB39)*100 -> 0 | Z39: =($J39/$AA39)*100 -> 0 | AA39: 1215.4229 | AB39: 571.50312
A40: AUS | B40: Q2.2020 | C40: =D40+E40 -> 110.37182 | D40: 3.2712453 | E40: 107.10057 | F40: 0 | G40: =H40+I40 -> 22.898717 | H40: 9.8137358 | I40: 13.084981 | J40: 0 | K40: =M40+O40 -> 7.3838495 | L40: =N40+P40 -> 8.9988097 | M40: =($D40/$AB40)*100 -> 0.21884557 | N40: =($D40/$AA40)*100 -> 0.26671042 | O40: =($E40/$AB40)*100 -> 7.1650039 | P40: =($E40/$AA40)*100 -> 8.7320993 | Q40: =($F40/$AB40)*100 -> 0 | R40: =($F40/$AA40)*100 -> 0 | S40: =U40+W40 -> 1.531919 | T40: =V40+X40 -> 1.866973 | U40: =($H40/$AB40)*100 -> 0.6565367 | V40: =($H40/AA40)*100 -> 0.80013127 | W40: =($I40/$AB40)*100 -> 0.87538227 | X40: =($I40/$AA40)*100 -> 1.0668417 | Y40: =($J40/$AB40)*100 -> 0 | Z40: =($J40/$AA40)*100 -> 0 | AA40: 1226.5157 | AB40: 1494.7734
A41: CAN | B41: Q2.2020 | C41: =D41+E41 -> 86.382127 | D41: 2.8794042 | E41: 83.502722 | F41: 61.18734 | G41: =H41+I41 -> 50.389574 | H41: 3.5992553 | I41: 46.790319 | J41: 0 | K41: =M41+O41 -> 5.0914693 | L41: =N41+P41 -> 5.0120522 | M41: =($D41/$AB41)*100 -> 0.16971564 | N41: =($D41/$AA41)*100 -> 0.16706841 | O41: =($E41/$AB41)*100 -> 4.9217536 | P41: =($E41/$AA41)*100 -> 4.8449838 | Q41: =($F41/$AB41)*100 -> 3.6064574 | R41: =($F41/$AA41)*100 -> 3.5502037 | S41: =U41+W41 -> 2.9700237 | T41: =V41+X41 -> 2.9236971 | U41: =($H41/$AB41)*100 -> 0.21214455 | V41: =($H41/AA41)*100 -> 0.20883551 | W41: =($I41/$AB41)*100 -> 2.7578792 | X41: =($I41/$AA41)*100 -> 2.7148616 | Y41: =($J41/$AB41)*100 -> 0 | Z41: =($J41/$AA41)*100 -> 0 | AA41: 1723.4882 | AB41: 1696.6051
A42: FRA | B42: Q2.2020 | C42: =D42+E42 -> 62.619278 | D42: 8.7426566 | E42: 53.876621 | F42: 60.65218 | G42: =H42+I42 -> 380.30556 | H42: 22.949473 | I42: 357.35609 | J42: 0 | K42: =M42+O42 -> 2.3929601 | L42: =N42+P42 -> 2.154019 | M42: =($D42/$AB42)*100 -> 0.33409565 | N42: =($D42/$AA42)*100 -> 0.30073564 | O42: =($E42/$AB42)*100 -> 2.0588644 | P42: =($E42/$AA42)*100 -> 1.8532834 | Q42: =($F42/$AB42)*100 -> 2.3177885 | R42: =($F42/$AA42)*100 -> 2.0863535 | S42: =U42+W42 -> 14.533161 | T42: =V42+X42 -> 13.082 | U42: =($H42/$AB42)*100 -> 0.87700107 | V42: =($H42/AA42)*100 -> 0.78943106 | W42: =($I42/$AB42)*100 -> 13.65616 | X42: =($I42/$AA42)*100 -> 12.292569 | Y42: =($J42/$AB42)*100 -> 0 | Z42: =($J42/$AA42)*100 -> 0 | AA42: 2907.0902 | AB42: 2616.8125
A43: DEU | B43: Q2.2020 | C43: =D43+E43 -> 332.22095 | D43: 25.135138 | E43: 307.08581 | F43: 0 | G43: =H43+I43 -> 1114.6887 | H43: 218.56641 | I43: 896.1223 | J43: 0 | K43: =M43+O43 -> 9.2352417 | L43: =N43+P43 -> 7.9826558 | M43: =($D43/$AB43)*100 -> 0.69871894 | N43: =($D43/$AA43)*100 -> 0.60395093 | O43: =($E43/$AB43)*100 -> 8.5365227 | P43: =($E43/$AA43)*100 -> 7.3787049 | Q43: =($F43/$AB43)*100 -> 0 | R43: =($F43/$AA43)*100 -> 0 | S43: =U43+W43 -> 30.986666 | T43: =V43+X43 -> 26.783911 | U43: =($H43/$AB43)*100 -> 6.0758169 | V43: =($H43/AA43)*100 -> 5.2517472 | W43: =($I43/$AB43)*100 -> 24.910849 | X43: =($I43/$AA43)*100 -> 21.532164 | Y43: =($J43/$AB43)*100 -> 0 | Z43: =($J43/$AA43)*100 -> 0 | AA43: 4161.7847 | AB43: 3597.3173
A44: ITA | B44: Q2.2020 | C44: =D44+E44 -> 60.105764 | D44: 7.1034085 | E44: 53.002355 | F44: 7.6498245 | G44: =H44+I44 -> 582.80734 | H44: 3.6063458 | I44: 579.201 | J44: 0 | K44: =M44+O44 -> 3.1335154 | L44: =N44+P44 -> 2.5711938 | M44: =($D44/$AB44)*100 -> 0.37032454 | N44: =($D44/$AA44)*100 -> 0.30386836 | O44: =($E44/$AB44)*100 -> 2.7631908 | P44: =($E44/$AA44)*100 -> 2.2673254 | Q44: =($F44/$AB44)*100 -> 0.39881105 | R44: =($F44/$AA44)*100 -> 0.32724285 | S44: =U44+W44 -> 30.383705 | T44: =V44+X44 -> 24.93123 | U44: =($H44/$AB44)*100 -> 0.18801092 | V44: =($H44/AA44)*100 -> 0.15427163 | W44: =($I44/$AB44)*100 -> 30.195694 | X44: =($I44/$AA44)*100 -> 24.776958 | Y44: =($J44/$AB44)*100 -> 0 | Z44: =($J44/$AA44)*100 -> 0 | AA44: 2337.6598 | AB44: 1918.1576
A45: JPN | B45: Q2.2020 | C45: =D45+E45 -> 551.10682 | D45: 38.427517 | E45: 512.67931 | F45: 243.68669 | G45: =H45+I45 -> 147.14927 | H45: 0 | I45: 147.14927 | J45: 1021.6096 | K45: =M45+O45 -> 12.074204 | L45: =N45+P45 -> 10.349711 | M45: =($D45/$AB45)*100 -> 0.84190878 | N45: =($D45/$AA45)*100 -> 0.72166353 | O45: =($E45/$AB45)*100 -> 11.232295 | P45: =($E45/$AA45)*100 -> 9.6280476 | Q45: =($F45/$AB45)*100 -> 5.3389337 | R45: =($F45/$AA45)*100 -> 4.5764029 | S45: =U45+W45 -> 3.2238946 | T45: =V45+X45 -> 2.7634433 | U45: =($H45/$AB45)*100 -> 0 | V45: =($H45/AA45)*100 -> 0 | W45: =($I45/$AB45)*100 -> 3.2238946 | X45: =($I45/$AA45)*100 -> 2.7634433 | Y45: =($J45/$AB45)*100 -> 22.382453 | Z45: =($J45/$AA45)*100 -> 19.185689 | AA45: 5324.8522 | AB45: 4564.3326
A46: KOR | B46: Q2.2020 | C46: =D46+E46 -> 47.759349 | D46: 3.7812909 | E46: 43.978058 | F46: 27.126652 | G46: =H46+I46 -> 28.030874 | H46: 0 | I46: 28.030874 | J46: 120.83691 | K46: =M46+O46 -> 2.9154496 | L46: =N46+P46 -> 2.2146289 | M46: =($D46/$AB46)*100 -> 0.23082733 | N46: =($D46/$AA46)*100 -> 0.17534067 | O46: =($E46/$AB46)*100 -> 2.6846222 | P46: =($E46/$AA46)*100 -> 2.0392882 | Q46: =($F46/$AB46)*100 -> 1.6559352 | R46: =($F46/$AA46)*100 -> 1.2578787 | S46: =U46+W46 -> 1.7111331 | T46: =V46+X46 -> 1.299808 | U46: =($H46/$AB46)*100 -> 0 | V46: =($H46/AA46)*100 -> 0 | W46: =($I46/$AB46)*100 -> 1.7111331 | X46: =($I46/$AA46)*100 -> 1.299808 | Y46: =($J46/$AB46)*100 -> 7.3764387 | Z46: =($J46/$AA46)*100 -> 5.6032779 | AA46: 2156.5396 | AB46: 1638.147
... A57: FIN | B57: Q2.2020 | C57: =D57+E57 -> 7.6050184 | D57: 1.5966277 | E57: 6.0083907 | F57: 5.7373684 | G57: =H57+I57 -> 16.851471 | H57: 2.6446536 | I57: 14.206817 | J57: 1.0928321 | K57: =M57+O57 -> 2.9853553 | L57: =N57+P57 -> 2.9950177 | M57: =($D57/$AB57)*100 -> 0.62675731 | N57: =($D57/$AA57)*100 -> 0.62878587 | O57: =($E57/$AB57)*100 -> 2.358598 | P57: =($E57/$AA57)*100 -> 2.3662318 | Q57: =($F57/$AB57)*100 -> 2.252208 | R57: =($F57/$AA57)*100 -> 2.2594975 | S57: =U57+W57 -> 6.6150567 | T57: =V57+X57 -> 6.6364669 | U57: =($H57/$AB57)*100 -> 1.0381606 | V57: =($H57/AA57)*100 -> 1.0415207 | W57: =($I57/$AB57)*100 -> 5.576896 | X57: =($I57/$AA57)*100 -> 5.5949461 | Y57: =($J57/$AB57)*100 -> 0.428992 | Z57: =($J57/$AA57)*100 -> 0.43038047 | AA57: 253.92232 | AB57: 254.74416
A58: GRC | B58: Q2.2020 | C58: =D58+E58 -> 10.391907 | D58: 0.70761691 | E58: 9.68429 | F58: 0 | G58: =H58+I58 -> 8.9610144 | H58: 6.4199944 | I58: =1.1082+1.43282 -> 2.54102 | J58: 0 | K58: =M58+O58 -> 5.0964951 | L58: =N58+P58 -> 3.4462238 | M58: =($D58/$AB58)*100 -> 0.34703603 | N58: =($D58/$AA58)*100 -> 0.23466398 | O58: =($E58/$AB58)*100 -> 4.7494591 | P58: =($E58/$AA58)*100 -> 3.2115598 | Q58: =($F58/$AB58)*100 -> 0 | R58: =($F58/$AA58)*100 -> 0 | S58: =U58+W58 -> 4.3947436 | T58: =V58+X58 -> 2.971703 | U58: =($H58/$AB58)*100 -> 3.1485531 | V58: =($H58/AA58)*100 -> 2.1290354 | W58: =($I58/$AB58)*100 -> 1.2461905 | X58: =($I58/$AA58)*100 -> 0.84266764 | Y58: =($J58/$AB58)*100 -> 0 | Z58: =($J58/$AA58)*100 -> 0 | AA58: 301.54475 | AB58: 203.90301
A59: ISL | B59: Q2.2020 | C59: =D59+E59 -> 0.8825382 | D59: 0.021328007 | E59: 0.8612102 | F59: 0 | G59: =H59+I59 -> 0.91931063 | H59: 0 | I59: 0.91931063 | J59: 0 | K59: =M59+O59 -> 4.2572996 | L59: =N59+P59 -> 4.6280958 | M59: =($D59/$AB59)*100 -> 0.10288474 | N59: =($D59/$AA59)*100 -> 0.11184565 | O59: =($E59/$AB59)*100 -> 4.1544149 | P59: =($E59/$AA59)*100 -> 4.5162502 | Q59: =($F59/$AB59)*100 -> 0 | R59: =($F59/$AA59)*100 -> 0 | S59: =U59+W59 -> 4.4346871 | T59: =V59+X59 -> 4.8209332 | U59: =($H59/$AB59)*100 -> 0 | V59: =($H59/AA59)*100 -> 0 | W59: =($I59/$AB59)*100 -> 4.4346871 | X59: =($I59/$AA59)*100 -> 4.8209332 | Y59: =($J59/$AB59)*100 -> 0 | Z59: =($J59/$AA59)*100 -> 0 | AA59: 19.069143 | AB59: 20.73
A60: IRL | B60: Q2.2020 | C60: =D60+E60 -> 23.434809 | D60: 2.2863228 | E60: 21.148486 | F60: 2.8579035 | G60: =H60+I60 -> 6.8589684 | H60: 4.5726456 | I60: 2.2863228 | J60: 0 | K60: =M60+O60 -> 6.3087257 | L60: =N60+P60 -> 5.6078791 | M60: =($D60/$AB60)*100 -> 0.61548543 | N60: =($D60/$AA60)*100 -> 0.54711016 | O60: =($E60/$AB60)*100 -> 5.6932403 | P60: =($E60/$AA60)*100 -> 5.060769 | Q60: =($F60/$AB60)*100 -> 0.76935679 | R60: =($F60/$AA60)*100 -> 0.6838877 | S60: =U60+W60 -> 1.8464563 | T60: =V60+X60 -> 1.6413305 | U60: =($H60/$AB60)*100 -> 1.2309709 | V60: =($H60/AA60)*100 -> 1.0942203 | W60: =($I60/$AB60)*100 -> 0.61548543 | X60: =($I60/$AA60)*100 -> 0.54711016 | Y60: =($J60/$AB60)*100 -> 0 | Z60: =($J60/$AA60)*100 -> 0 | AA60: 417.89076 | AB60: 371.4666
A61: ISR | B61: Q2.2020 | C61: =D61+E61 -> 25.918306 | D61: 4.0163262 | E61: 21.90198 | F61: 2.0803992 | G61: =H61+I61 -> 11.153251 | H61: 0.95351629 | I61: 10.199735 | J61: 0 | K61: =M61+O61 -> 7.2304548 | L61: =N61+P61 -> 7.5696716 | M61: =($D61/$AB61)*100 -> 1.1204384 | N61: =($D61/$AA61)*100 -> 1.1730037 | O61: =($E61/$AB61)*100 -> 6.1100164 | P61: =($E61/$AA61)*100 -> 6.3966678 | Q61: =($F61/$AB61)*100 -> 0.58037095 | R61: =($F61/$AA61)*100 -> 0.60759906 | S61: =U61+W61 -> 3.1114331 | T61: =V61+X61 -> 3.2574061 | U61: =($H61/$AB61)*100 -> 0.26600335 | V61: =($H61/AA61)*100 -> 0.2784829 | W61: =($I61/$AB61)*100 -> 2.8454298 | X61: =($I61/$AA61)*100 -> 2.9789232 | Y61: =($J61/$AB61)*100 -> 0 | Z61: =($J61/$AA61)*100 -> 0 | AA61: 342.39671 | AB61: 358.46025
A62: LVA | B62: Q2.2020 | C62: =D62+E62 -> 2.6412118 | D62: 0.23110604 | E62: 2.4101058 | F62: 0 | G62: =H62+I62 -> 1.0485611 | H62: 0.23110604 | I62: 0.81745506 | J62: 0 | K62: =M62+O62 -> 8.7573112 | L62: =N62+P62 -> 4.7655872 | M62: =($D62/$AB62)*100 -> 0.76626473 | N62: =($D62/$AA62)*100 -> 0.41698888 | O62: =($E62/$AB62)*100 -> 7.9910464 | P62: =($E62/$AA62)*100 -> 4.3485983 | Q62: =($F62/$AB62)*100 -> 0 | R62: =($F62/$AA62)*100 -> 0 | S62: =U62+W62 -> 3.4766525 | T62: =V62+X62 -> 1.8919381 | U62: =($H62/$AB62)*100 -> 0.76626473 | V62: =($H62/AA62)*100 -> 0.41698888 | W62: =($I62/$AB62)*100 -> 2.7103878 | X62: =($I62/$AA62)*100 -> 1.4749492 | Y62: =($J62/$AB62)*100 -> 0 | Z62: =($J62/$AA62)*100 -> 0 | AA62: 55.42259 | AB62: 30.160078
A63: LTU | B63: Q2.2020 | C63: =D63+E63 -> 2.5949764 | D63: 0.5715807 | E63: 2.0233957 | F63: 2.5035235 | G63: =H63+I63 -> 1.9662376 | H63: 0.36581165 | I63: 1.600426 | J63: 0 | K63: =M63+O63 -> 5.3818961 | L63: =N63+P63 -> 2.6714858 | M63: =($D63/$AB63)*100 -> 1.1854397 | N63: =($D63/$AA63)*100 -> 0.58843299 | O63: =($E63/$AB63)*100 -> 4.1964564 | P63: =($E63/$AA63)*100 -> 2.0830528 | Q63: =($F63/$AB63)*100 -> 5.1922257 | R63: =($F63/$AA63)*100 -> 2.5773365 | S63: =U63+W63 -> 4.0779124 | T63: =V63+X63 -> 2.0242095 | U63: =($H63/$AB63)*100 -> 0.75868139 | V63: =($H63/AA63)*100 -> 0.37659711 | W63: =($I63/$AB63)*100 -> 3.3192311 | X63: =($I63/$AA63)*100 -> 1.6476124 | Y63: =($J63/$AB63)*100 -> 0 | Z63: =($J63/$AA63)*100 -> 0 | AA63: 97.136073 | AB63: 48.216769
...

Sheet diff
A1: Country | B1: Quarter | C1: ab_us | D1: health_us | E1: nhealth_us | F1: acc_us | G1: of_us | H1: be_us | I1: gu_us | J1: qf_us | K1: ab_per | L1: ab_ppp | M1: health_per | N1: health_ppp | O1: nhealth_per | P1: nhealth_ppp | Q1: acc_per | R1: acc_ppp | S1: of_per | T1: of_ppp | U1: be_per | V1: be_ppp | W1: gu_per | X1: gu_ppp | Y1: qf_per | Z1: qf_ppp | AA1: real_gdp_per | AB1: real_gdp_ppp
A2: AUS | B2: Q2.2020 | C2: =data!C40-data!C2 -> 0.36671522 | D2: =data!D40-data!D2 -> 1.1544453 | E2: =data!E40-data!E2 -> -0.78773004 | F2: =data!F40-data!F2 -> 0 | G2: =data!G40-data!G2 -> -1.1041831 | H2: =data!H40-data!H2 -> -0.51176421 | I2: =data!I40-data!I2 -> -0.59241894 | J2: =data!J40-data!J2 -> 0 | ... Z2: =data!Z40-data!Z2 -> 0 | AA2: 1226.5157 | AB2: 1494.7734
A3: CAN | B3: Q2.2020 | C3: =data!C41-data!C3 -> 5.3821267 | D3: =data!D41-data!D3 -> 0.47940422 | E3: =data!E41-data!E3 -> 4.9027225 | F3: =data!F41-data!F3 -> -2.5626603 | G3: =data!G41-data!G3 -> -1.3104261 | H3: =data!H41-data!H3 -> -0.10074472 | I3: =data!I41-data!I3 -> -1.2096814 | J3: =data!J41-data!J3 -> 0 | ... Z3: =data!Z41-data!Z3 -> 0 | AA3: 1723.4882 | AB3: 1696.6051
A4: FRA | B4: Q2.2020 | C4: =data!C42-data!C4 -> 46.119278 | D4: =data!D42-data!D4 -> 3.2426566 | E4: =data!E42-data!E4 -> 42.876621 | F4: =data!F42-data!F4 -> 12.15218 | G4: =data!G42-data!G4 -> 32.305561 | H4: =data!H42-data!H4 -> 22.949473 | I4: =data!I42-data!I4 -> 9.356087 | J4: =data!J42-data!J4 -> 0 | ... Z4: =data!Z42-data!Z4 -> 0 | AA4: 2907.0902 | AB4: 2616.8125
A5: DEU | B5: Q2.2020 | C5: =data!C43-data!C5 -> 189.22095 | D5: =data!D43-data!D5 -> 13.935138 | E5: =data!E43-data!E5 -> 175.28581 | F5: =data!F43-data!F5 -> 0 | G5: =data!G43-data!G5 -> 42.688712 | H5: =data!H43-data!H5 -> -4.4335859 | I5: =data!I43-data!I5 -> 47.122298 | J5: =data!J43-data!J5 -> 0 | ... Z5: =data!Z43-data!Z5 -> 0 | AA5: 4161.7847 | AB5: 3597.3173
A6: ITA | B6: Q2.2020 | C6: =data!C44-data!C6 -> 38.105764 | D6: =data!D44-data!D6 -> 3.4734085 | E6: =data!E44-data!E6 -> 34.632355 | F6: =data!F44-data!F6 -> 7.6498245 | G6: =data!G44-data!G6 -> -8.1926568 | H6: =data!H44-data!H6 -> 3.6063458 | I6: =data!I44-data!I6 -> -11.799003 | J6: =data!J44-data!J6 -> 0 | ... Z6: =data!Z44-data!Z6 -> 0 | AA6: 2337.6598 | AB6: 1918.1576
A7: JPN | B7: Q2.2020 | C7: =data!C45-data!C7 -> 54.106824 | D7: =data!D45-data!D7 -> 26.236917 | E7: =data!E45-data!E7 -> 27.869908 | F7: =data!F45-data!F7 -> 243.68669 | G7: =data!G45-data!G7 -> 128.14927 | H7: =data!H45-data!H7 -> 0 | I7: =data!I45-data!I7 -> 128.14927 | J7: =data!J45-data!J7 -> 1021.6096 | ... Z7: =data!Z45-data!Z7 -> 19.185689 | AA7: 5324.8522 | AB7: 4564.3326
A8: KOR | B8: Q2.2020 | C8: =data!C46-data!C8 -> 23.759349 | D8: =data!D46-data!D8 -> 1.2812909 | E8: =data!E46-data!E8 -> 22.478058 | F8: =data!F46-data!F8 -> 13.126652 | G8: =data!G46-data!G8 -> -186.96913 | H8: =data!H46-data!H8 -> -101 | I8: =data!I46-data!I8 -> -85.969126 | J8: =data!J46-data!J8 -> 120.83691 | ... Z8: =data!Z46-data!Z8 -> 5.6032779 | AA8: 2156.5396 | AB8: 1638.147
A9: ESP | B9: Q2.2020 | C9: =data!C47-data!C9 -> 24.886187 | D9: =data!D47-data!D9 -> 0.5205779 | E9: =data!E47-data!E9 -> 24.365609 | F9: =data!F47-data!F9 -> 0 | G9: =data!G47-data!G9 -> -60.841605 | H9: =data!H47-data!H9 -> -10.864489 | I9: =data!I47-data!I9 -> -49.977116 | J9: =data!J47-data!J9 -> -0.5032793 | ... Z9: =data!Z47-data!Z9 -> -0.028014002 | AA9: 1796.5277 | AB9: 1323.9185
A10: GBR | B10: Q2.2020 | C10: =data!C48-data!C10 -> 71.618784 | D10: =data!D48-data!D10 -> 1.8120431 | E10: =data!E48-data!E10 -> 69.806741 | F10: =data!F48-data!F10 -> 0 | G10: =data!G48-data!G10 -> 0.49401988 | H10: =data!H48-data!H10 -> -421.75808 | I10: =data!I48-data!I10 -> 422.2521 | J10: =data!J48-data!J10 -> 0 | ... Z10: =data!Z48-data!Z10 -> 0 | AA10: 2941.9883 | AB10: 3157.3882
A11: USA | B11: Q2.2020 | C11: =data!C49-data!C11 -> 1048 | D11: =data!D49-data!D11 -> 294.55 | E11: =data!E49-data!E11 -> 753.45 | F11: =data!F49-data!F11 -> 0 | G11: =data!G49-data!G11 -> 0 | H11: =data!H49-data!H11 -> 0 | I11: =data!I49-data!I11 -> 0 | J11: =data!J49-data!J11 -> 0 | ... Z11: =data!Z49-data!Z11 -> 0 | AA11: 19974.214 | AB11: 19928.975
A12: MEX | B12: Q2.2020 | C12: =data!C50-data!C12 -> 4.9963816 | D12: =data!D50-data!D12 -> 0.00042542129 | E12: =data!E50-data!E12 -> 4.9959562 | F12: =data!F50-data!F12 -> 2.1604135 | G12: =data!G50-data!G12 -> -1.5306958 | H12: =data!H50-data!H12 -> -1.5306958 | I12: =data!I50-data!I12 -> 0 | J12: =data!J50-data!J12 -> 3.0264413 | ... Z12: =data!Z50-data!Z12 -> 0.12707237 | AA12: 2381.6676 | AB12: 1279.1513
A13: TUR | B13: Q2.2020 | C13: =data!C51-data!C13 -> 1.6541353 | D13: =data!D51-data!D13 -> 0 | E13: =data!E51-data!E13 -> 1.6541353 | F13: =data!F51-data!F13 -> 9.9097744 | G13: =data!G51-data!G13 -> 44.019549 | H13: =data!H51-data!H13 -> 3.0075188 | I13: =data!I51-data!I13 -> 41.01203 | J13: =data!J51-data!J13 -> 15.473684 | ... Z13: =data!Z51-data!Z13 -> 0.66303 | AA13: 2333.7834 | AB13: 997.05355
... A229: POL | B229: Q3.2021 | C229: =data!C267-data!C229 -> 0 | D229: =data!D267-data!D229 -> 0 | E229: =data!E267-data!E229 -> 0 | F229: =data!F267-data!F229 -> 0 | G229: =data!G267-data!G229 -> 0 | H229: =data!H267-data!H229 -> 0 | I229: =data!I267-data!I229 -> 0 | J229: =data!J267-data!J229 -> 0 | ... Z229: =data!Z267-data!Z229 -> 0 | AA229: 1215.4229 | AB229: 571.50312

Sheet Tabelle1
