Workbook
Name IQ_CH: 110000
Name IQ_CQ: 5000
Name IQ_CY: 10000
Name IQ_DAILY: 500000
Name IQ_FH: 100000
Name IQ_FQ: 500
Name IQ_FY: 1000
Name IQ_LTM: 2000
Name IQ_MONTH: 15000
Name IQ_NTM: 6000
Name IQ_WEEK: 50000
Name IQ_YTD: 3000

Sheet 2020
B1: Table 1. Summary of Country Fiscal Measures in Response to the COVID-19 Pandemic
B2: (USD billion and percent of GDP)
B3: USD Billion
C4: Above the line measures | G4: Liquidity support | K4: Above the line measures | T4: Liquidity support
C5: Additional spending or foregone revenues | F5: Accelerated spending / deferred revenue | H5: Below the line measures: equity injections, loans, asset purchase or debt assumptions. | I5: Contingent liabilities | K5: Additional spending or foregone revenues | Q5: Accelerated spending / deferred revenue | V5: Below the line measures: equity injections, loans, asset purchase or debt assumptions. | X5: Contingent liabilities
C6: Subtotal | D6: Health sector | E6: Non-health sector | G6: Subtotal | I6: Guarantees | J6: Quasi-fiscal operations | K6: Subtotal | M6: Health sector | O6: Non-health sector | T6: Subtotal | X6: Guarantees | Z6: Quasi-fiscal operations
B7: G20: Advanced economies | K7: ab_per | L7: ab_ppp | M7: health_per | N7: health_ppp | O7: nhealth_per | P7: nhealth_ppp | Q7: acc_per | S7: acc_ppp | T7: of_per | U7: of_ppp | V7: be_per | W7: be_ppp | X7: gu_per | Y7: gu_ppp | Z7: qf_per | AA7: qf_ppp | AB7: GDP 2019 in US Dollar constant PPP 2019 | AC7: in bn | AD7: GDP 2019 in US Dollar constant Prices 2015 | AE7: in bn
B8: Australia | C8: 218.44778 | D8: 11.460914 | E8: 206.98687 | F8: 0 | G8: 24.164577 | H8: 10.356247 | I8: 13.80833 | J8: 0 | K8: =M8+O8 -> 14.614107 | L8: =N8+P8 -> 17.810435 | M8: =($D8/$AE8)*100 -> 0.76673254 | N8: =($D8/$AC8)*100 -> 0.93442861 | O8: =($E8/$AE8)*100 -> 13.847374 | P8: =($E8/$AC8)*100 -> 16.876006 | Q8: =($F8/$AE8)*100 -> 0 | S8: =($F8/$AC8)*100 -> 0 | T8: =W8+Y8 -> 1.9701808 | U8: =W8+Y8 -> 1.9701808 | V8: =($H8/$AE8)*100 -> 0.69283061 | W8: =($H8/$AC8)*100 -> 0.84436321 | X8: =($I8/$AE8)*100 -> 0.92377415 | Y8: =($I8/$AC8)*100 -> 1.1258176 | Z8: =($J8/AE8)*100 -> 0 | AA8: =($J8/$AC8)*100 -> 0 | AB8: 1.2265157e+12 | AC8: 1226.5157 | AD8: 1.4947734e+12 | AE8: 1494.7734
B9: Canada | C9: 240.10444 | D9: 39.211354 | E9: 200.89308 | F9: 63.244119 | G9: 65.922694 | H9: 3.869052 | I9: 62.053642 | J9: 0 | K9: =M9+O9 -> 14.152052 | L9: =N9+P9 -> 13.931308 | M9: =($D9/$AE9)*100 -> 2.3111656 | N9: =($D9/$AC9)*100 -> 2.275116 | O9: =($E9/$AE9)*100 -> 11.840887 | P9: =($E9/$AC9)*100 -> 11.656192 | Q9: =($F9/$AE9)*100 -> 3.7276865 | S9: =($F9/$AC9)*100 -> 3.6695419 | T9: =W9+Y9 -> 3.8249577 | U9: =W9+Y9 -> 3.8249577 | V9: =($H9/$AE9)*100 -> 0.2280467 | W9: =($H9/$AC9)*100 -> 0.22448962 | X9: =($I9/$AE9)*100 -> 3.6575183 | Y9: =($I9/$AC9)*100 -> 3.6004681 | Z9: =($J9/AE9)*100 -> 0 | AA9: =($J9/$AC9)*100 -> 0 | AB9: 1.7234882e+12 | AC9: 1723.4882 | AD9: 1.6966051e+12 | AE9: 1696.6051
B10: France | C10: 198.05783 | D10: 20.261089 | E10: 177.79675 | F10: 62.604488 | G10: 404.65264 | H10: 23.903532 | I10: 380.74911 | J10: 0 | K10: =M10+O10 -> 7.5686674 | L10: =N10+P10 -> 6.8129235 | M10: =($D10/$AE10)*100 -> 0.77426598 | N10: =($D10/$AC10)*100 -> 0.69695424 | O10: =($E10/$AE10)*100 -> 6.7944014 | P10: =($E10/$AC10)*100 -> 6.1159692 | Q10: =($F10/$AE10)*100 -> 2.3923949 | S10: =($F10/$AC10)*100 -> 2.1535103 | T10: =W10+Y10 -> 13.919507 | U10: =W10+Y10 -> 13.919507 | V10: =($H10/$AE10)*100 -> 0.91345986 | W10: =($H10/$AC10)*100 -> 0.82224938 | X10: =($I10/$AE10)*100 -> 14.550111 | Y10: =($I10/$AC10)*100 -> 13.097258 | Z10: =($J10/AE10)*100 -> 0 | AA10: =($J10/$AC10)*100 -> 0 | AB10: 2.9070902e+12 | AC10: 2907.0902 | AD10: 2.6168125e+12 | AE10: 2616.8125
B11: Germany | C11: 417.74267 | D11: 45.530537 | E11: 372.21214 | F11: 0 | G11: 1054.3734 | H11: 113.82634 | I11: 940.54706 | J11: 0 | K11: =M11+O11 -> 11.612617 | L11: =N11+P11 -> 10.037585 | M11: =($D11/$AE11)*100 -> 1.2656803 | N11: =($D11/$AC11)*100 -> 1.0940147 | O11: =($E11/$AE11)*100 -> 10.346936 | P11: =($E11/$AC11)*100 -> 8.9435702 | Q11: =($F11/$AE11)*100 -> 0 | S11: =($F11/$AC11)*100 -> 0 | T11: =W11+Y11 -> 25.334645 | U11: =W11+Y11 -> 25.334645 | V11: =($H11/$AE11)*100 -> 3.1642007 | W11: =($H11/$AC11)*100 -> 2.7350367 | X11: =($I11/$AE11)*100 -> 26.145791 | Y11: =($I11/$AC11)*100 -> 22.599609 | Z11: =($J11/AE11)*100 -> 0 | AA11: =($J11/$AC11)*100 -> 0 | AB11: 4.1617847e+12 | AC11: 4161.7847 | AD11: 3.5973173e+12 | AE11: 3597.3173
B12: Italy | C12: 127.4855 | D12: 10.813502 | E12: 116.672 | F12: 7.9678439 | G12: 662.75387 | H12: 3.6993561 | I12: 659.05452 | J12: 0 | K12: =M12+O12 -> 6.6462475 | L12: =N12+P12 -> 5.4535524 | M12: =($D12/$AE12)*100 -> 0.56374421 | N12: =($D12/$AC12)*100 -> 0.4625781 | O12: =($E12/$AE12)*100 -> 6.0825033 | P12: =($E12/$AC12)*100 -> 4.9909743 | Q12: =($F12/$AE12)*100 -> 0.41539047 | S12: =($F12/$AC12)*100 -> 0.34084702 | T12: =W12+Y12 -> 28.351168 | U12: =W12+Y12 -> 28.351168 | V12: =($H12/$AE12)*100 -> 0.19285986 | W12: =($H12/$AC12)*100 -> 0.1582504 | X12: =($I12/$AE12)*100 -> 34.358726 | Y12: =($I12/$AC12)*100 -> 28.192918 | Z12: =($J12/AE12)*100 -> 0 | AA12: =($J12/$AC12)*100 -> 0 | AB12: 2.3376598e+12 | AC12: 2337.6598 | AD12: 1.9181576e+12 | AE12: 1918.1576
B13: Japan | C13: 782.33295 | D13: 89.837276 | E13: 692.49567 | F13: 243.30929 | G13: 1428.0384 | H13: 0 | I13: 146.92138 | J13: 1281.117 | K13: =M13+O13 -> 17.140139 | L13: =N13+P13 -> 14.692106 | M13: =($D13/$AE13)*100 -> 1.9682456 | N13: =($D13/$AC13)*100 -> 1.6871318 | O13: =($E13/$AE13)*100 -> 15.171893 | P13: =($E13/$AC13)*100 -> 13.004974 | Q13: =($F13/$AE13)*100 -> 5.3306653 | S13: =($F13/$AC13)*100 -> 4.5693153 | T13: =W13+Y13 -> 2.7591635 | U13: =W13+Y13 -> 2.7591635 | V13: =($H13/$AE13)*100 -> 0 | W13: =($H13/$AC13)*100 -> 0 | X13: =($I13/$AE13)*100 -> 3.2189017 | Y13: =($I13/$AC13)*100 -> 2.7591635 | Z13: =($J13/AE13)*100 -> 28.068003 | AA13: =($J13/$AC13)*100 -> 24.059203 | AB13: 5.3248522e+12 | AC13: 5324.8522 | AD13: 4.5643326e+12 | AE13: 4564.3326
B14: Korea | C14: 56.080292 | D14: 4.3138686 | E14: 51.766423 | F14: 27.913268 | G14: 165.70331 | H14: 0 | I14: 59.971232 | J14: 105.73207 | K14: =M14+O14 -> 3.4233981 | L14: =N14+P14 -> 2.6004759 | M14: =($D14/$AE14)*100 -> 0.26333832 | N14: =($D14/$AC14)*100 -> 0.20003661 | O14: =($E14/$AE14)*100 -> 3.1600598 | P14: =($E14/$AC14)*100 -> 2.4004393 | Q14: =($F14/$AE14)*100 -> 1.7039538 | S14: =($F14/$AC14)*100 -> 1.2943545 | T14: =W14+Y14 -> 2.7809011 | U14: =W14+Y14 -> 2.7809011 | V14: =($H14/$AE14)*100 -> 0 | W14: =($H14/$AC14)*100 -> 0 | X14: =($I14/$AE14)*100 -> 3.6609189 | Y14: =($I14/$AC14)*100 -> 2.7809011 | Z14: =($J14/AE14)*100 -> 6.4543705 | AA14: =($J14/$AC14)*100 -> 4.902858 | AB14: 2.1565396e+12 | AC14: 2156.5396 | AD14: 1.638147e+12 | AE14: 1638.147
B15: Spain | C15: 52.473943 | D15: 5.008359 | E15: 47.465584 | F15: 0.61466224 | G15: 183.53245 | H15: 0.72735032 | I15: 171.42247 | J15: 11.382634 | K15: =M15+O15 -> 3.9635328 | L15: =N15+P15 -> 2.9208536 | M15: =($D15/$AE15)*100 -> 0.37829814 | N15: =($D15/$AC15)*100 -> 0.27877995 | O15: =($E15/$AE15)*100 -> 3.5852346 | P15: =($E15/$AC15)*100 -> 2.6420736 | Q15: =($F15/$AE15)*100 -> 0.046427499 | S15: =($F15/$AC15)*100 -> 0.034213903 | T15: =W15+Y15 -> 9.5823638 | U15: =W15+Y15 -> 9.5823638 | V15: =($H15/$AE15)*100 -> 0.054939207 | W15: =($H15/$AC15)*100 -> 0.040486452 | X15: =($I15/$AE15)*100 -> 12.948114 | Y15: =($I15/$AC15)*100 -> 9.5418774 | Z15: =($J15/AE15)*100 -> 0.8597685 | AA15: =($J15/$AC15)*100 -> 0.6335908 | AB15: 1.7965277e+12 | AC15: 1796.5277 | AD15: 1.3239185e+12 | AE15: 1323.9185
B16: United Kingdom | C16: 440.54616 | D16: 144.71429 | E16: 295.83187 | F16: 8.964602 | G16: 436.70419 | H16: 1.2806574 | I16: 435.42353 | J16: 0 | K16: =M16+O16 -> 13.952867 | L16: =N16+P16 -> 14.974436 | M16: =($D16/$AE16)*100 -> 4.5833544 | N16: =($D16/$AC16)*100 -> 4.9189281 | O16: =($E16/$AE16)*100 -> 9.3695121 | P16: =($E16/$AC16)*100 -> 10.055508 | Q16: =($F16/$AE16)*100 -> 0.28392461 | S16: =($F16/$AC16)*100 -> 0.30471236 | T16: =W16+Y16 -> 14.843845 | U16: =W16+Y16 -> 14.843845 | V16: =($H16/$AE16)*100 -> 0.040560659 | W16: =($H16/$AC16)*100 -> 0.043530337 | X16: =($I16/$AE16)*100 -> 13.790624 | Y16: =($I16/$AC16)*100 -> 14.800315 | Z16: =($J16/AE16)*100 -> 0 | AA16: =($J16/$AC16)*100 -> 0 | AB16: 2.9419883e+12 | AC16: 2941.9883 | AD16: 3.1573882e+12 | AE16: 3157.3882
B17: United States | C17: 3503.3 | D17: 483.8 | E17: 3019.5 | F17: 18 | G17: 510 | H17: 56 | I17: 454 | J17: 0 | K17: =M17+O17 -> 17.578927 | L17: =N17+P17 -> 17.539113 | M17: =($D17/$AE17)*100 -> 2.4276211 | N17: =($D17/$AC17)*100 -> 2.4221229 | O17: =($E17/$AE17)*100 -> 15.151306 | P17: =($E17/$AC17)*100 -> 15.11699 | Q17: =($F17/$AE17)*100 -> 0.090320751 | S17: =($F17/$AC17)*100 -> 0.090116187 | T17: =W17+Y17 -> 2.553292 | U17: =W17+Y17 -> 2.553292 | V17: =($H17/$AE17)*100 -> 0.28099789 | W17: =($H17/$AC17)*100 -> 0.28036147 | X17: =($I17/$AE17)*100 -> 2.27809 | Y17: =($I17/$AC17)*100 -> 2.2729305 | Z17: =($J17/AE17)*100 -> 0 | AA17: =($J17/$AC17)*100 -> 0 | AB17: 1.9974214e+13 | AC17: 19974.214 | AD17: 19928975197000 | AE17: 19928.975
B18: Mexico | C18: 7.2279883 | D18: 2.3467495 | E18: 4.8812389 | F18: 4.318019 | G18: 13.588243 | H18: 1.8445451 | I18: 1.1504705 | J18: 10.593227 | K18: =M18+O18 -> 0.56506124 | L18: =N18+P18 -> 0.30348435 | M18: =($D18/$AE18)*100 -> 0.18346144 | N18: =($D18/$AC18)*100 -> 0.09853388 | O18: =($E18/$AE18)*100 -> 0.3815998 | P18: =($E18/$AC18)*100 -> 0.20495047 | Q18: =($F18/$AE18)*100 -> 0.33756905 | S18: =($F18/$AC18)*100 -> 0.18130234 | T18: =W18+Y18 -> 0.12575288 | U18: =W18+Y18 -> 0.12575288 | V18: =($H18/$AE18)*100 -> 0.14420069 | W18: =($H18/$AC18)*100 -> 0.07744763 | X18: =($I18/$AE18)*100 -> 0.089940137 | Y18: =($I18/$AC18)*100 -> 0.048305249 | Z18: =($J18/AE18)*100 -> 0.82814494 | AA18: =($J18/$AC18)*100 -> 0.44478193 | AB18: 2.3816676e+12 | AC18: 2381.6676 | AD18: 1.2791513e+12 | AE18: 1279.1513
B19: Turkey | C19: 7.6102085 | D19: 2.0161373 | E19: 5.5940711 | F19: 9.8677143 | G19: 63.976864 | H19: 2.9816115 | I19: 43.446339 | J19: 17.548914 | K19: =M19+O19 -> 0.76326978 | L19: =N19+P19 -> 0.32608889 | M19: =($D19/$AE19)*100 -> 0.20220953 | N19: =($D19/$AC19)*100 -> 0.086389221 | O19: =($E19/$AE19)*100 -> 0.56106025 | P19: =($E19/$AC19)*100 -> 0.23969967 | Q19: =($F19/$AE19)*100 -> 0.9896875 | S19: =($F19/$AC19)*100 -> 0.42282049 | T19: =W19+Y19 -> 1.9893856 | U19: =W19+Y19 -> 1.9893856 | V19: =($H19/$AE19)*100 -> 0.29904226 | W19: =($H19/$AC19)*100 -> 0.12775871 | X19: =($I19/$AE19)*100 -> 4.357473 | Y19: =($I19/$AC19)*100 -> 1.8616269 | Z19: =($J19/AE19)*100 -> 1.7600773 | AA19: =($J19/$AC19)*100 -> 0.75195125 | AB19: 2.3337834e+12 | AC19: 2333.7834 | AD19: 9.9705355e+11 | AE19: 997.05355
... B42: Colombia | C42: 11.060054 | D42: 2.9135225 | E42: 8.1465315 | F42: 0.10756165 | G42: 15.411434 | H42: 8.5363618 | I42: 6.875072 | J42: 0 | K42: =M42+O42 -> 3.4411515 | L42: =N42+P42 -> 1.6018173 | M42: =($D42/$AE42)*100 -> 0.906494 | N42: =($D42/$AC42)*100 -> 0.42196275 | O42: =($E42/$AE42)*100 -> 2.5346575 | P42: =($E42/$AC42)*100 -> 1.1798546 | Q42: =($F42/$AE42)*100 -> 0.033466017 | S42: =($F42/$AC42)*100 -> 0.015578054 | T42: =W42+Y42 -> 2.2320236 | U42: =W42+Y42 -> 2.2320236 | V42: =($H42/$AE42)*100 -> 2.6559468 | W42: =($H42/$AC42)*100 -> 1.2363133 | X42: =($I42/$AE42)*100 -> 2.1390641 | Y42: =($I42/$AC42)*100 -> 0.99571027 | Z42: =($J42/AE42)*100 -> 0 | AA42: =($J42/$AC42)*100 -> 0 | AB42: 6.9046913e+11 | AC42: 690.46913 | AD42: 3.2140561e+11 | AE42: 321.40561
B43: Costa Rica | C43: 0.84666153 | D43: 0.19538343 | E43: 0.6512781 | F43: 0.40447798 | H43: 0 | I43: 0 | J43: 0 | K43: =M43+O43 -> 1.3150493 | L43: =N43+P43 -> 0.92801618 | M43: =($D43/$AE43)*100 -> 0.30347291 | N43: =($D43/$AC43)*100 -> 0.21415758 | O43: =($E43/$AE43)*100 -> 1.0115764 | P43: =($E43/$AC43)*100 -> 0.7138586 | Q43: =($F43/$AE43)*100 -> 0.62824217 | S43: =($F43/$AC43)*100 -> 0.44334376 | T43: =W43+Y43 -> 0 | U43: =W43+Y43 -> 0 | V43: =($H43/$AE43)*100 -> 0 | W43: =($H43/$AC43)*100 -> 0 | X43: =($I43/$AE43)*100 -> 0 | Y43: =($I43/$AC43)*100 -> 0 | Z43: =($J43/AE43)*100 -> 0 | AA43: =($J43/$AC43)*100 -> 0 | AB43: 9.1233488e+10 | AC43: 91.233488 | AD43: 6.4382494e+10 | AE43: 64.382494
B44: Hungary | C44: 5.997549 | D44: 1.769415 | E44: 4.228134 | F44: 0 | G44: 6.6270226 | H44: 0 | I44: 6.6270226 | J44: 0 | K44: =M44+O44 -> 4.0693359 | L44: =N44+P44 -> 1.9353915 | M44: =($D44/$AE44)*100 -> 1.2005478 | N44: =($D44/$AC44)*100 -> 0.57098503 | O44: =($E44/$AE44)*100 -> 2.8687882 | P44: =($E44/$AC44)*100 -> 1.3644064 | Q44: =($F44/$AE44)*100 -> 0 | S44: =($F44/$AC44)*100 -> 0 | T44: =W44+Y44 -> 2.1385207 | U44: =W44+Y44 -> 2.1385207 | V44: =($H44/$AE44)*100 -> 0 | W44: =($H44/$AC44)*100 -> 0 | X44: =($I44/$AE44)*100 -> 4.4964336 | Y44: =($I44/$AC44)*100 -> 2.1385207 | Z44: =($J44/AE44)*100 -> 0 | AA44: =($J44/$AC44)*100 -> 0 | AB44: 3.0988816e+11 | AC44: 309.88816 | AD44: 1.4738397e+11 | AE44: 147.38397
B45: Poland | C45: 44.709731 | D45: 2.1654286 | E45: 42.544303 | F45: 0 | G45: 31.589782 | H45: 12.737815 | I45: 18.851967 | J45: 0 | K45: =M45+O45 -> 7.8231824 | L45: =N45+P45 -> 3.678533 | M45: =($D45/$AE45)*100 -> 0.37890057 | N45: =($D45/$AC45)*100 -> 0.17816257 | O45: =($E45/$AE45)*100 -> 7.4442819 | P45: =($E45/$AC45)*100 -> 3.5003704 | Q45: =($F45/$AE45)*100 -> 0 | S45: =($F45/$AC45)*100 -> 0 | T45: =W45+Y45 -> 2.5990775 | U45: =W45+Y45 -> 2.5990775 | V45: =($H45/$AE45)*100 -> 2.2288269 | W45: =($H45/$AC45)*100 -> 1.0480151 | X45: =($I45/$AE45)*100 -> 3.2986638 | Y45: =($I45/$AC45)*100 -> 1.5510624 | Z45: =($J45/AE45)*100 -> 0 | AA45: =($J45/$AC45)*100 -> 0 | AB45: 1.2154229e+12 | AC45: 1215.4229 | AD45: 5.7150312e+11 | AE45: 571.50312

Sheet 2021
B1: Table 1. Summary of Country Fiscal Measures in Response to the COVID-19 Pandemic since January 2020
B2: (USD billion and percent of 2020 GDP)
B3: USD Billion
C4: Above the line measures | G4: Liquidity support | K4: Above the line measures | S4: Liquidity support
C5: Additional spending or foregone revenues | F5: Accelerated spending / deferred revenue | H5: Below the line measures: equity injections, loans, asset purchase or debt assumptions. | I5: Contingent liabilities | K5: Additional spending or foregone revenues | Q5: Accelerated spending / deferred revenue | U5: Below the line measures: equity injections, loans, asset purchase or debt assumptions. | W5: Contingent liabilities
C6: Subtotal | D6: Health sector | E6: Non-health sector | G6: Subtotal | I6: Guarantees | J6: Quasi-fiscal operations | K6: Subtotal | M6: Health sector | O6: Non-health sector | S6: Subtotal | W6: Guarantees | Y6: Quasi-fiscal operations
B7: G20: Advanced economies | K7: ab_per | L7: ab_ppp | M7: health_per | N7: health_ppp | O7: nohealth_per | P7: nhealth_ppp | Q7: acc_per | R7: acc_ppp | S7: of_per | T7: of_ppp | U7: be_per | V7: be_ppp | W7: gu_per | X7: gu_ppp | Y7: qf_per | Z7: qf_ppp | AA7: GDP 2019 in US Dollar constant PPP 2019 | AB7: in bn | AC7: GDP 2019 in US Dollar constant Prices 2015 | AD7: in bn
B8: Australia | C8: 249.7258 | D8: 13.808449 | E8: 235.91735 | F8: 0 | G8: 24.164785 | H8: 10.356337 | I8: 13.808449 | J8: 0 | K8: =M8+O8 -> 16.706599 | L8: =N8+P8 -> 20.360587 | M8: =($D8/AD8)*100 -> 0.9237821 | N8: =($D8/AB8)*100 -> 1.1258273 | O8: =($E8/$AD8)*100 -> 15.782817 | P8: =($E8/$AB8)*100 -> 19.234759 | Q8: =($F8/$AD8)*100 -> 0 | R8: =($F8/$AB8)*100 -> 0 | S8: =U8+W8 -> 1.6166187 | T8: =V8+X8 -> 1.9701978 | U8: =($H8/$AD8)*100 -> 0.69283658 | V8: =($H8/$AB8)*100 -> 0.84437048 | W8: =($I8/$AD8)*100 -> 0.9237821 | X8: =($I8/$AB8)*100 -> 1.1258273 | Y8: =($J8/$AD8)*100 -> 0 | Z8: =($J8/$AB8)*100 -> 0 | AA8: 1.2265157e+12 | AB8: 1226.5157 | AC8: 1.4947734e+12 | AD8: 1494.7734
B9: Canada | C9: 261.78973 | D9: 45.632389 | E9: 216.15734 | F9: 68.027304 | G9: 64.944135 | H9: 3.8772618 | I9: 61.066873 | J9: 0 | K9: =M9+O9 -> 15.43021 | L9: =N9+P9 -> 15.189529 | M9: =($D9/AD9)*100 -> 2.6896294 | N9: =($D9/AB9)*100 -> 2.6476764 | O9: =($E9/$AD9)*100 -> 12.740581 | P9: =($E9/$AB9)*100 -> 12.541853 | Q9: =($F9/$AD9)*100 -> 4.0096133 | R9: =($F9/$AB9)*100 -> 3.9470712 | S9: =U9+W9 -> 3.8278875 | T9: =V9+X9 -> 3.7681799 | U9: =($H9/$AD9)*100 -> 0.2285306 | V9: =($H9/$AB9)*100 -> 0.22496597 | W9: =($I9/$AD9)*100 -> 3.5993569 | X9: =($I9/$AB9)*100 -> 3.543214 | Y9: =($J9/$AD9)*100 -> 0 | Z9: =($J9/$AB9)*100 -> 0 | AA9: 1.7234882e+12 | AB9: 1723.4882 | AC9: 1.6966051e+12 | AD9: 1696.6051
B10: France | C10: 252.88464 | D10: 38.63357 | E10: 214.25107 | F10: 79.204517 | G10: 399.21356 | H10: 18.006207 | I10: 381.20735 | J10: 0 | K10: =M10+O10 -> 9.6638425 | L10: =N10+P10 -> 8.6988919 | M10: =($D10/AD10)*100 -> 1.4763599 | N10: =($D10/AB10)*100 -> 1.3289429 | O10: =($E10/$AD10)*100 -> 8.1874826 | P10: =($E10/$AB10)*100 -> 7.369949 | Q10: =($F10/$AD10)*100 -> 3.0267555 | R10: =($F10/$AB10)*100 -> 2.724529 | S10: =U10+W10 -> 15.255719 | T10: =V10+X10 -> 13.73241 | U10: =($H10/$AD10)*100 -> 0.68809694 | V10: =($H10/$AB10)*100 -> 0.61938933 | W10: =($I10/$AD10)*100 -> 14.567622 | X10: =($I10/$AB10)*100 -> 13.113021 | Y10: =($J10/$AD10)*100 -> 0 | Z10: =($J10/$AB10)*100 -> 0 | AA10: 2.9070902e+12 | AB10: 2907.0902 | AC10: 2.6168125e+12 | AD10: 2616.8125
B11: Germany | C11: 588.90144 | D11: 69.618193 | E11: 519.28325 | F11: 0 | G11: 1057.9683 | H11: 114.12819 | I11: 943.8401 | J11: 0 | K11: =M11+O11 -> 16.370572 | L11: =N11+P11 -> 14.150214 | M11: =($D11/AD11)*100 -> 1.9352808 | N11: =($D11/AB11)*100 -> 1.6727966 | O11: =($E11/$AD11)*100 -> 14.435292 | P11: =($E11/$AB11)*100 -> 12.477417 | Q11: =($F11/$AD11)*100 -> 0 | R11: =($F11/$AB11)*100 -> 0 | S11: =U11+W11 -> 29.409924 | T11: =V11+X11 -> 25.421024 | U11: =($H11/$AD11)*100 -> 3.1725916 | V11: =($H11/$AB11)*100 -> 2.7422895 | W11: =($I11/$AD11)*100 -> 26.237332 | X11: =($I11/$AB11)*100 -> 22.678734 | Y11: =($J11/$AD11)*100 -> 0 | Z11: =($J11/$AB11)*100 -> 0 | AA11: 4.1617847e+12 | AB11: 4161.7847 | AC11: 3.5973173e+12 | AD11: 3597.3173
B12: Italy | C12: 205.43073 | D12: 22.825637 | E12: 182.6051 | F12: 7.988973 | G12: 664.51136 | H12: 3.709166 | I12: 660.8022 | J12: 0 | K12: =M12+O12 -> 10.709794 | L12: =N12+P12 -> 8.7878798 | M12: =($D12/AD12)*100 -> 1.1899771 | N12: =($D12/AB12)*100 -> 0.97643109 | O12: =($E12/$AD12)*100 -> 9.5198171 | P12: =($E12/$AB12)*100 -> 7.8114487 | Q12: =($F12/$AD12)*100 -> 0.416492 | R12: =($F12/$AB12)*100 -> 0.34175088 | S12: =U12+W12 -> 34.64321 | T12: =V12+X12 -> 28.42635 | U12: =($H12/$AD12)*100 -> 0.19337129 | V12: =($H12/$AB12)*100 -> 0.15867005 | W12: =($I12/$AD12)*100 -> 34.449838 | X12: =($I12/$AB12)*100 -> 28.26768 | Y12: =($J12/$AD12)*100 -> 0 | Z12: =($J12/$AB12)*100 -> 0 | AA12: 2.3376598e+12 | AB12: 2337.6598 | AC12: 1.9181576e+12 | AD12: 1918.1576
B13: Japan | C13: 843.83379 | D13: 104.89388 | E13: 738.93991 | F13: 27.160022 | G13: 1429.1791 | H13: 0 | I13: 147.03874 | J13: 1282.1403 | K13: =M13+O13 -> 18.487561 | L13: =N13+P13 -> 15.847084 | M13: =($D13/AD13)*100 -> 2.2981208 | N13: =($D13/AB13)*100 -> 1.9698927 | O13: =($E13/$AD13)*100 -> 16.189441 | P13: =($E13/$AB13)*100 -> 13.877191 | Q13: =($F13/$AD13)*100 -> 0.59504915 | R13: =($F13/$AB13)*100 -> 0.51006152 | S13: =U13+W13 -> 3.221473 | T13: =V13+X13 -> 2.7613675 | U13: =($H13/$AD13)*100 -> 0 | V13: =($H13/$AB13)*100 -> 0 | W13: =($I13/$AD13)*100 -> 3.221473 | X13: =($I13/$AB13)*100 -> 2.7613675 | Y13: =($J13/$AD13)*100 -> 28.090424 | Z13: =($J13/$AB13)*100 -> 24.078421 | AA13: 5.3248522e+12 | AB13: 5324.8522 | AC13: 4.5643326e+12 | AD13: 4564.3326
B14: Korea | C14: 104.83005 | D14: 11.9491 | E14: 92.880946 | F14: 27.965978 | G14: 166.01622 | H14: 0 | I14: 60.084481 | J14: 105.93174 | K14: =M14+O14 -> 6.3993065 | L14: =N14+P14 -> 4.8610305 | M14: =($D14/AD14)*100 -> 0.72942783 | N14: =($D14/AB14)*100 -> 0.55408674 | O14: =($E14/$AD14)*100 -> 5.6698787 | P14: =($E14/$AB14)*100 -> 4.3069437 | Q14: =($F14/$AD14)*100 -> 1.7071715 | R14: =($F14/$AB14)*100 -> 1.2967988 | S14: =U14+W14 -> 3.6678321 | T14: =V14+X14 -> 2.7861525 | U14: =($H14/$AD14)*100 -> 0 | V14: =($H14/$AB14)*100 -> 0 | W14: =($I14/$AD14)*100 -> 3.6678321 | X14: =($I14/$AB14)*100 -> 2.7861525 | Y14: =($J14/$AD14)*100 -> 6.4665588 | Z14: =($J14/$AB14)*100 -> 4.9121165 | AA14: 2.1565396e+12 | AB14: 2156.5396 | AC14: 1.638147e+12 | AD14: 1638.147
B15: Spain | C15: 107.45169 | D15: 21.924025 | E15: 85.527663 | F15: 0.051357684 | G15: 184.01915 | H15: 0.72927911 | I15: 171.87705 | J15: 11.412819 | K15: =M15+O15 -> 8.116186 | L15: =N15+P15 -> 5.981076 | M15: =($D15/AD15)*100 -> 1.655995 | N15: =($D15/AB15)*100 -> 1.2203555 | O15: =($E15/$AD15)*100 -> 6.460191 | P15: =($E15/$AB15)*100 -> 4.7607205 | Q15: =($F15/$AD15)*100 -> 0.0038792179 | R15: =($F15/$AB15)*100 -> 0.0028587193 | S15: =U15+W15 -> 13.037534 | T15: =V15+X15 -> 9.6077744 | U15: =($H15/$AD15)*100 -> 0.055084895 | V15: =($H15/$AB15)*100 -> 0.040593814 | W15: =($I15/$AD15)*100 -> 12.982449 | X15: =($I15/$AB15)*100 -> 9.5671805 | Y15: =($J15/$AD15)*100 -> 0.86204843 | Z15: =($J15/$AB15)*100 -> 0.63527095 | AA15: 1.7965277e+12 | AB15: 1796.5277 | AC15: 1.3239185e+12 | AD15: 1323.9185
B16: United Kingdom | C16: 522.16797 | D16: 130.86273 | E16: 391.30523 | F16: 16.0371 | G16: 452.92619 | H16: 1.321457 | I16: 451.60473 | J16: 0 | K16: =M16+O16 -> 16.537972 | L16: =N16+P16 -> 17.748812 | M16: =($D16/AD16)*100 -> 4.1446514 | N16: =($D16/AB16)*100 -> 4.4481051 | O16: =($E16/$AD16)*100 -> 12.393321 | P16: =($E16/$AB16)*100 -> 13.300707 | Q16: =($F16/$AD16)*100 -> 0.50792297 | R16: =($F16/$AB16)*100 -> 0.54511092 | S16: =U16+W16 -> 14.344964 | T16: =V16+X16 -> 15.395241 | U16: =($H16/$AD16)*100 -> 0.041852853 | V16: =($H16/$AB16)*100 -> 0.04491714 | W16: =($I16/$AD16)*100 -> 14.303111 | X16: =($I16/$AB16)*100 -> 15.350324 | Y16: =($J16/$AD16)*100 -> 0 | Z16: =($J16/$AB16)*100 -> 0 | AA16: 2.9419883e+12 | AB16: 2941.9883 | AC16: 3.1573882e+12 | AD16: 3157.3882
B17: United States | C17: 5328.3 | D17: 687.3 | E17: 4641 | F17: 17.98 | G17: 510 | H17: 56 | I17: 454 | J17: 0 | K17: =M17+O17 -> 26.736448 | L17: =N17+P17 -> 26.675893 | M17: =($D17/AD17)*100 -> 3.4487473 | N17: =($D17/AB17)*100 -> 3.4409364 | O17: =($E17/$AD17)*100 -> 23.2877 | P17: =($E17/$AB17)*100 -> 23.234957 | Q17: =($F17/$AD17)*100 -> 0.090220394 | R17: =($F17/$AB17)*100 -> 0.090016058 | S17: =U17+W17 -> 2.5590879 | T17: =V17+X17 -> 2.553292 | U17: =($H17/$AD17)*100 -> 0.28099789 | V17: =($H17/$AB17)*100 -> 0.28036147 | W17: =($I17/$AD17)*100 -> 2.27809 | X17: =($I17/$AB17)*100 -> 2.2729305 | Y17: =($J17/$AD17)*100 -> 0 | Z17: =($J17/$AB17)*100 -> 0 | AA17: 1.9974214e+13 | AB17: 19974.214 | AC17: 19928975197000 | AD17: 19928.975
B18: Mexico | C18: 7.0279602 | D18: 4.8032152 | E18: 2.224745 | F18: 4.281936 | G18: 13.41363 | H18: 0.89362143 | I18: 0.2792567 | J18: 12.240752 | K18: =M18+O18 -> 0.54942367 | L18: =N18+P18 -> 0.29508569 | M18: =($D18/AD18)*100 -> 0.37550015 | N18: =($D18/AB18)*100 -> 0.20167446 | O18: =($E18/$AD18)*100 -> 0.17392352 | P18: =($E18/$AB18)*100 -> 0.093411232 | Q18: =($F18/$AD18)*100 -> 0.3347482 | R18: =($F18/$AB18)*100 -> 0.17978731 | S18: =U18+W18 -> 0.091691898 | T18: =V18+X18 -> 0.049246089 | U18: =($H18/$AD18)*100 -> 0.069860493 | V18: =($H18/$AB18)*100 -> 0.03752083 | W18: =($I18/$AD18)*100 -> 0.021831404 | X18: =($I18/$AB18)*100 -> 0.011725259 | Y18: =($J18/$AD18)*100 -> 0.95694322 | Z18: =($J18/$AB18)*100 -> 0.5139572 | AA18: 2.3816676e+12 | AB18: 2381.6676 | AC18: 1.2791513e+12 | AD18: 1279.1513
B19: Turkey | C19: 25.234121 | D19: 2.7673372 | E19: 22.466784 | F19: 10.013767 | G19: 69.354606 | H19: 2.9955712 | I19: 45.932092 | J19: 20.426943 | K19: =M19+O19 -> 2.5308692 | L19: =N19+P19 -> 1.0812538 | M19: =($D19/AD19)*100 -> 0.27755151 | N19: =($D19/AB19)*100 -> 0.11857729 | O19: =($E19/$AD19)*100 -> 2.2533177 | P19: =($E19/$AB19)*100 -> 0.96267648 | Q19: =($F19/$AD19)*100 -> 1.0043359 | R19: =($F19/$AB19)*100 -> 0.42907866 | S19: =U19+W19 -> 4.9072252 | T19: =V19+X19 -> 2.0964955 | U19: =($H19/$AD19)*100 -> 0.30044236 | V19: =($H19/$AB19)*100 -> 0.12835686 | W19: =($I19/$AD19)*100 -> 4.6067828 | X19: =($I19/$AB19)*100 -> 1.9681386 | Y19: =($J19/$AD19)*100 -> 2.0487307 | Z19: =($J19/$AB19)*100 -> 0.87527157 | AA19: 2.3337834e+12 | AB19: 2333.7834 | AC19: 9.9705355e+11 | AD19: 997.05355
... B45: Poland | C45: 38.516359 | D45: 3.7695771 | E45: 34.746782 | F45: 0 | G45: 28.720588 | H45: 9.7444851 | I45: 18.976103 | J45: 0 | K45: =M45+O45 -> 6.7394837 | L45: =N45+P45 -> 3.1689678 | M45: =($D45/AD45)*100 -> 0.65958995 | N45: =($D45/AB45)*100 -> 0.31014532 | O45: =($E45/$AD45)*100 -> 6.0798937 | P45: =($E45/$AB45)*100 -> 2.8588225 | Q45: =($F45/$AD45)*100 -> 0 | R45: =($F45/$AB45)*100 -> 0 | S45: =U45+W45 -> 5.0254472 | T45: =V45+X45 -> 2.3630119 | U45: =($H45/$AD45)*100 -> 1.7050625 | V45: =($H45/$AB45)*100 -> 0.8017362 | W45: =($I45/$AD45)*100 -> 3.3203848 | X45: =($I45/$AB45)*100 -> 1.5612757 | Y45: =($J45/$AD45)*100 -> 0 | Z45: =($J45/$AB45)*100 -> 0 | AA45: 1.2154229e+12 | AB45: 1215.4229 | AC45: 5.7150312e+11 | AD45: 571.50312

Sheet data
A1: Country | B1: Year | C1: ab_us | D1: health_us | E1: nhealth_us | F1: acc_us | G1: of_us | H1: be_us | I1: gu_us | J1: qf_us | K1: ab_per | L1: ab_ppp | M1: health_per | N1: health_ppp | O1: nhealth_per | P1: nhealth_ppp | Q1: acc_per | R1: acc_ppp | S1: of_per | T1: of_ppp | U1: be_per | V1: be_ppp | W1: gu_per | X1: gu_ppp | Y1: qf_per | Z1: qf_ppp
A2: AUS | B2: 2020 | C2: 218.44778 | D2: 11.460914 | E2: 206.98687 | F2: 0 | G2: 24.164577 | H2: 10.356247 | I2: 13.80833 | J2: 0 | K2: 16.177852 | L2: =N2+P2 -> 17.810435 | M2: 0.8487748 | N2: ='2020'!N8 -> 0.93442861 | O2: 15.329077 | P2: ='2020'!P8 -> 16.876006 | Q2: 0 | R2: ='2020'!S8 -> 0 | S2: =U2+W2 -> 1.7895854 | T2: =V2+X2 -> 1.9701808 | U2: 0.76696518 | V2: ='2020'!W8 -> 0.84436321 | W2: 1.0226202 | X2: ='2020'!Y8 -> 1.1258176 | Y2: 0 | Z2: ='2020'!AA8 -> 0
A3: CAN | B3: 2020 | C3: 240.10444 | D3: 39.211354 | E3: 200.89308 | F3: 63.244119 | G3: 65.922694 | H3: 3.869052 | I3: 62.053642 | J3: 0 | K3: 14.646142 | L3: =N3+P3 -> 13.931308 | M3: 2.3918552 | N3: ='2020'!N9 -> 2.275116 | O3: 12.254287 | P3: ='2020'!P9 -> 11.656192 | Q3: 3.8578309 | R3: ='2020'!S9 -> 3.6695419 | S3: =U3+W3 -> 4.0212214 | T3: =V3+X3 -> 3.8249577 | U3: 0.23600848 | V3: ='2020'!W9 -> 0.22448962 | W3: 3.7852129 | X3: ='2020'!Y9 -> 3.6004681 | Y3: 0 | Z3: ='2020'!AA9 -> 0
A4: FRA | B4: 2020 | C4: 198.05783 | D4: 20.261089 | E4: 177.79675 | F4: 62.604488 | G4: 404.65264 | H4: 23.903532 | I4: 380.74911 | J4: 0 | K4: 7.7103009 | L4: =N4+P4 -> 6.8129235 | M4: 0.78875492 | N4: ='2020'!N10 -> 0.69695424 | O4: 6.921546 | P4: ='2020'!P10 -> 6.1159692 | Q4: 2.4371641 | R4: ='2020'!S10 -> 2.1535103 | S4: =U4+W4 -> 15.752942 | T4: =V4+X4 -> 13.919507 | U4: 0.93055356 | V4: ='2020'!W10 -> 0.82224938 | W4: 14.822389 | X4: ='2020'!Y10 -> 13.097258 | Y4: 0 | Z4: ='2020'!AA10 -> 0
A5: DEU | B5: 2020 | C5: 417.74267 | D5: 45.530537 | E5: 372.21214 | F5: 0 | G5: 1054.3734 | H5: 113.82634 | I5: 940.54706 | J5: 0 | K5: 11.033705 | L5: =N5+P5 -> 10.037585 | M5: 1.2025837 | N5: ='2020'!N11 -> 1.0940147 | O5: 9.8311217 | P5: ='2020'!P11 -> 8.9435702 | Q5: 0 | R5: ='2020'!S11 -> 0 | S5: =U5+W5 -> 27.848832 | T5: =V5+X5 -> 25.334645 | U5: 3.0064592 | V5: ='2020'!W11 -> 2.7350367 | W5: 24.842373 | X5: ='2020'!Y11 -> 22.599609 | Y5: 0 | Z5: ='2020'!AA11 -> 0
A6: ITA | B6: 2020 | C6: 127.4855 | D6: 10.813502 | E6: 116.672 | F6: 7.9678439 | G6: 662.75387 | H6: 3.6993561 | I6: 659.05452 | J6: 0 | K6: 6.8248555 | L6: =N6+P6 -> 5.4535524 | M6: 0.57889399 | N6: ='2020'!N12 -> 0.4625781 | O6: 6.2459615 | P6: ='2020'!P12 -> 4.9909743 | Q6: 0.42655347 | R6: ='2020'!S12 -> 0.34084702 | S6: =U6+W6 -> 35.480108 | T6: =V6+X6 -> 28.351168 | U6: 0.19804268 | V6: ='2020'!W12 -> 0.1582504 | W6: 35.282066 | X6: ='2020'!Y12 -> 28.192918 | Y6: 0 | Z6: ='2020'!AA12 -> 0
A7: JPN | B7: 2020 | C7: 782.33295 | D7: 89.837276 | E7: 692.49567 | F7: 243.30929 | G7: 1428.0384 | H7: 0 | I7: 146.92138 | J7: 1281.117 | K7: 15.580393 | L7: =N7+P7 -> 14.692106 | M7: 1.789136 | N7: ='2020'!N13 -> 1.6871318 | O7: 13.791257 | P7: ='2020'!P13 -> 13.004974 | Q7: 4.8455768 | R7: ='2020'!S13 -> 4.5693153 | S7: =U7+W7 -> 2.9259829 | T7: =V7+X7 -> 2.7591635 | U7: 0 | V7: ='2020'!W13 -> 0 | W7: 2.9259829 | X7: ='2020'!Y13 -> 2.7591635 | Y7: 25.513825 | Z7: ='2020'!AA13 -> 24.059203
A8: KOR | B8: 2020 | C8: 56.080292 | D8: 4.3138686 | E8: 51.766423 | F8: 27.913268 | G8: 165.70331 | H8: 0 | I8: 59.971232 | J8: 105.73207 | K8: 3.4422077 | L8: =N8+P8 -> 2.6004759 | M8: 0.26478521 | N8: ='2020'!N14 -> 0.20003661 | O8: 3.1774225 | P8: ='2020'!P14 -> 2.4004393 | Q8: 1.713316 | R8: ='2020'!S14 -> 1.2943545 | S8: =U8+W8 -> 3.6810335 | T8: =V8+X8 -> 2.7809011 | U8: 0 | V8: ='2020'!W14 -> 0 | W8: 3.6810335 | X8: ='2020'!Y14 -> 2.7809011 | Y8: 6.4898335 | Z8: ='2020'!AA14 -> 4.902858
A9: ESP | B9: 2020 | C9: 52.473943 | D9: 5.008359 | E9: 47.465584 | F9: 0.61466224 | G9: 183.53245 | H9: 0.72735032 | I9: 171.42247 | J9: 11.382634 | K9: 4.1298486 | L9: =N9+P9 -> 2.9208536 | M9: 0.3941721 | N9: ='2020'!N15 -> 0.27877995 | O9: 3.7356765 | P9: ='2020'!P15 -> 2.6420736 | Q9: 0.048375667 | R9: ='2020'!S15 -> 0.034213903 | S9: =U9+W9 -> 13.54868 | T9: =V9+X9 -> 9.5823638 | U9: 0.057244539 | V9: ='2020'!W15 -> 0.040486452 | W9: 13.491436 | X9: ='2020'!Y15 -> 9.5418774 | Y9: 0.89584568 | Z9: ='2020'!AA15 -> 0.6335908
A10: GBR | B10: 2020 | C10: 440.54616 | D10: 144.71429 | E10: 295.83187 | F10: 8.964602 | G10: 436.70419 | H10: 1.2806574 | I10: 435.42353 | J10: 0 | K10: 16.258004 | L10: =N10+P10 -> 14.974436 | M10: 5.3405653 | N10: ='2020'!N16 -> 4.9189281 | O10: 10.917439 | P10: ='2020'!P16 -> 10.055508 | Q10: 0.33083148 | R10: ='2020'!S16 -> 0.30471236 | S10: =U10+W10 -> 16.116219 | T10: =V10+X10 -> 14.843845 | U10: 0.04726164 | V10: ='2020'!W16 -> 0.043530337 | W10: 16.068957 | X10: ='2020'!Y16 -> 14.800315 | Y10: 0 | Z10: ='2020'!AA16 -> 0
A11: USA | B11: 2020 | C11: 3503.3 | D11: 483.8 | E11: 3019.5 | F11: 18 | G11: 510 | H11: 56 | I11: 454 | J11: 0 | K11: 16.719306 | L11: =N11+P11 -> 17.539113 | M11: 2.3089088 | N11: ='2020'!N17 -> 2.4221229 | O11: 14.410397 | P11: ='2020'!P17 -> 15.11699 | Q11: 0.085904007 | R11: ='2020'!S17 -> 0.090116187 | S11: =U11+W11 -> 2.4339469 | T11: =V11+X11 -> 2.553292 | U11: 0.26725691 | V11: ='2020'!W17 -> 0.28036147 | W11: 2.16669 | X11: ='2020'!Y17 -> 2.2729305 | Y11: 0 | Z11: ='2020'!AA17 -> 0
A12: MEX | B12: 2020 | C12: 7.2279883 | D12: 2.3467495 | E12: 4.8812389 | F12: 4.318019 | G12: 13.588243 | H12: 1.8445451 | I12: 1.1504705 | J12: 10.593227 | K12: 0.68126555 | L12: =N12+P12 -> 0.30348435 | M12: 0.22119012 | N12: ='2020'!N18 -> 0.09853388 | O12: 0.46007544 | P12: ='2020'!P18 -> 0.20495047 | Q12: 0.40698981 | R12: ='2020'!S18 -> 0.18130234 | S12: =U12+W12 -> 0.28229167 | T12: =V12+X12 -> 0.12575288 | U12: 0.17385543 | V12: ='2020'!W18 -> 0.07744763 | W12: 0.10843624 | X12: ='2020'!Y18 -> 0.048305249 | Y12: 0.99845218 | Z12: ='2020'!AA18 -> 0.44478193
A13: TUR | B13: 2020 | C13: 7.6102085 | D13: 2.0161373 | E13: 5.5940711 | F13: 9.8677143 | G13: 63.976864 | H13: 2.9816115 | I13: 43.446339 | J13: 17.548914 | K13: 1.0708244 | L13: =N13+P13 -> 0.32608889 | M13: 0.28368856 | N13: ='2020'!N19 -> 0.086389221 | O13: 0.78713585 | P13: ='2020'!P19 -> 0.23969967 | Q13: 1.3884757 | R13: ='2020'!S19 -> 0.42282049 | S13: =U13+W13 -> 6.532828 | T13: =V13+X13 -> 1.9893856 | U13: 0.41953941 | V13: ='2020'!W19 -> 0.12775871 | W13: 6.1132886 | X13: ='2020'!Y19 -> 1.8616269 | Y13: 2.4692891 | Z13: ='2020'!AA19 -> 0.75195125
... A36: COL | B36: 2020 | C36: 11.060054 | D36: 2.9135225 | E36: 8.1465315 | F36: 0.10756165 | G36: 15.411434 | H36: 8.5363618 | I36: 6.875072 | J36: 0 | K36: 4.1001316 | L36: =N36+P36 -> 1.6018173 | M36: 1.0800875 | N36: ='2020'!N42 -> 0.42196275 | O36: 3.0200441 | P36: ='2020'!P42 -> 1.1798546 | Q36: 0.039874754 | R36: ='2020'!S42 -> 0.015578054 | S36: =U36+W36 -> 5.7132548 | T36: =V36+X36 -> 2.2320236 | U36: 3.1645602 | V36: ='2020'!W42 -> 1.2363133 | W36: 2.5486946 | X36: ='2020'!Y42 -> 0.99571027 | Y36: 0 | Z36: ='2020'!AA42 -> 0
A37: CRI | B37: 2020 | C37: 0.84666153 | D37: 0.19538343 | E37: 0.6512781 | F37: 0.40447798 | H37: 0 | I37: 0 | J37: 0 | K37: 1.4290119 | L37: =N37+P37 -> 0.92801618 | M37: 0.32977198 | N37: ='2020'!N43 -> 0.21415758 | O37: 1.0992399 | P37: ='2020'!P43 -> 0.7138586 | Q37: 0.68268585 | R37: ='2020'!S43 -> 0.44334376 | S37: =U37+W37 -> 0 | T37: =V37+X37 -> 0 | U37: 0 | V37: ='2020'!W43 -> 0 | W37: 0 | X37: ='2020'!Y43 -> 0 | Y37: 0 | Z37: ='2020'!AA43 -> 0
A38: HUN | B38: 2020 | C38: 5.997549 | D38: 1.769415 | E38: 4.228134 | F38: 0 | G38: 6.6270226 | H38: 0 | I38: 6.6270226 | J38: 0 | K38: 4 | L38: =N38+P38 -> 1.9353915 | M38: 1.1800921 | N38: ='2020'!N44 -> 0.57098503 | O38: 2.8199079 | P38: ='2020'!P44 -> 1.3644064 | Q38: 0 | R38: ='2020'!S44 -> 0 | S38: =U38+W38 -> 4.4198205 | T38: =V38+X38 -> 2.1385207 | U38: 0 | V38: ='2020'!W44 -> 0 | W38: 4.4198205 | X38: ='2020'!Y44 -> 2.1385207 | Y38: 0 | Z38: ='2020'!AA44 -> 0
A39: POL | B39: 2020 | C39: 44.709731 | D39: 2.1654286 | E39: 42.544303 | F39: 0 | G39: 31.589782 | H39: 12.737815 | I39: 18.851967 | J39: 0 | K39: 7.6769895 | L39: =N39+P39 -> 3.678533 | M39: 0.37182 | N39: ='2020'!N45 -> 0.17816257 | O39: 7.3051695 | P39: ='2020'!P45 -> 3.5003704 | Q39: 0 | R39: ='2020'!S45 -> 0 | S39: =U39+W39 -> 5.4241977 | T39: =V39+X39 -> 2.5990775 | U39: 2.1871765 | V39: ='2020'!W45 -> 1.0480151 | W39: 3.2370212 | X39: ='2020'!Y45 -> 1.5510624 | Y39: 0 | Z39: ='2020'!AA45 -> 0
A40: AUS | B40: 2021 | C40: =D40+E40 -> 31.278018 | D40: ='2021'!D8-'2020'!D8 -> 2.347535 | E40: ='2021'!E8-'2020'!E8 -> 28.930483 | F40: ='2021'!F8-'2020'!F8 -> 0 | G40: =H40+I40 -> 0.00020812525 | H40: ='2021'!H8-'2020'!H8 -> 8.9196534e-05 | I40: ='2021'!I8-'2020'!I8 -> 0.00011892871 | J40: ='2021'!J8-'2020'!J8 -> 0 | K40: =M40+O40 -> 2.0924923 | L40: =N40+P40 -> 2.5501522 | M40: ='2021'!M8-'2020'!M8 -> 0.15704956 | N40: ='2021'!N8-'2020'!N8 -> 0.19139869 | O40: ='2021'!O8-'2020'!O8 -> 1.9354428 | P40: ='2021'!P8-'2020'!P8 -> 2.3587536 | Q40: ='2021'!Q8-'2020'!Q8 -> 0 | R40: ='2021'!R8-'2020'!S8 -> 0 | S40: =U40+W40+Y40 -> 1.3923532e-05 | T40: =V40+X40+Z40 -> 1.696882e-05 | U40: ='2021'!U8-'2020'!V8 -> 5.967228e-06 | V40: ='2021'!V8-'2020'!W8 -> 7.2723515e-06 | W40: ='2021'!W8-'2020'!X8 -> 7.9563039e-06 | X40: ='2021'!X8-'2020'!Y8 -> 9.6964687e-06 | Y40: ='2021'!Y8-'2020'!Z8 -> 0 | Z40: ='2021'!Z8-'2020'!AA8 -> 0
A41: CAN | B41: 2021 | C41: =D41+E41 -> 21.685295 | D41: ='2021'!D9-'2020'!D9 -> 6.4210348 | E41: ='2021'!E9-'2020'!E9 -> 15.26426 | F41: ='2021'!F9-'2020'!F9 -> 4.7831846 | G41: =H41+I41 -> -0.97855874 | H41: ='2021'!H9-'2020'!H9 -> 0.0082097879 | I41: ='2021'!I9-'2020'!I9 -> -0.98676853 | J41: ='2021'!J9-'2020'!J9 -> 0 | K41: =M41+O41 -> 1.2781581 | L41: =N41+P41 -> 1.2582213 | M41: ='2021'!M9-'2020'!M9 -> 0.37846372 | N41: ='2021'!N9-'2020'!N9 -> 0.37256043 | O41: ='2021'!O9-'2020'!O9 -> 0.89969434 | P41: ='2021'!P9-'2020'!P9 -> 0.88566086 | Q41: ='2021'!Q9-'2020'!Q9 -> 0.28192681 | R41: ='2021'!R9-'2020'!S9 -> 0.2775293 | S41: =U41+W41+Y41 -> -0.057677461 | T41: =V41+X41+Z41 -> -0.056777805 | U41: ='2021'!U9-'2020'!V9 -> 0.00048389504 | V41: ='2021'!V9-'2020'!W9 -> 0.00047634722 | W41: ='2021'!W9-'2020'!X9 -> -0.058161356 | X41: ='2021'!X9-'2020'!Y9 -> -0.057254152 | Y41: ='2021'!Y9-'2020'!Z9 -> 0 | Z41: ='2021'!Z9-'2020'!AA9 -> 0
A42: FRA | B42: 2021 | C42: =D42+E42 -> 54.826804 | D42: ='2021'!D10-'2020'!D10 -> 18.372481 | E42: ='2021'!E10-'2020'!E10 -> 36.454322 | F42: ='2021'!F10-'2020'!F10 -> 16.600029 | G42: =H42+I42 -> -5.439085 | H42: ='2021'!H10-'2020'!H10 -> -5.8973249 | I42: ='2021'!I10-'2020'!I10 -> 0.45823993 | J42: ='2021'!J10-'2020'!J10 -> 0 | K42: =M42+O42 -> 2.0951751 | L42: =N42+P42 -> 1.8859684 | M42: ='2021'!M10-'2020'!M10 -> 0.70209392 | N42: ='2021'!N10-'2020'!N10 -> 0.63198868 | O42: ='2021'!O10-'2020'!O10 -> 1.3930812 | P42: ='2021'!P10-'2020'!P10 -> 1.2539797 | Q42: ='2021'!Q10-'2020'!Q10 -> 0.63436067 | R42: ='2021'!R10-'2020'!S10 -> 0.57101871 | S42: =U42+W42+Y42 -> -0.20785154 | T42: =V42+X42+Z42 -> -0.18709722 | U42: ='2021'!U10-'2020'!V10 -> -0.22536292 | V42: ='2021'!V10-'2020'!W10 -> -0.20286006 | W42: ='2021'!W10-'2020'!X10 -> 0.017511378 | X42: ='2021'!X10-'2020'!Y10 -> 0.015762838 | Y42: ='2021'!Y10-'2020'!Z10 -> 0 | Z42: ='2021'!Z10-'2020'!AA10 -> 0
A43: DEU | B43: 2021 | C43: =D43+E43 -> 171.15877 | D43: ='2021'!D11-'2020'!D11 -> 24.087657 | E43: ='2021'!E11-'2020'!E11 -> 147.07111 | F43: ='2021'!F11-'2020'!F11 -> 0 | G43: =H43+I43 -> 3.5948836 | H43: ='2021'!H11-'2020'!H11 -> 0.30184458 | I43: ='2021'!I11-'2020'!I11 -> 3.293039 | J43: ='2021'!J11-'2020'!J11 -> 0 | K43: =M43+O43 -> 4.7579557 | L43: =N43+P43 -> 4.112629 | M43: ='2021'!M11-'2020'!M11 -> 0.66960056 | N43: ='2021'!N11-'2020'!N11 -> 0.57878191 | O43: ='2021'!O11-'2020'!O11 -> 4.0883552 | P43: ='2021'!P11-'2020'!P11 -> 3.5338471 | Q43: ='2021'!Q11-'2020'!Q11 -> 0 | R43: ='2021'!R11-'2020'!S11 -> 0 | S43: =U43+W43+Y43 -> 0.099932346 | T43: =V43+X43+Z43 -> 0.086378413 | U43: ='2021'!U11-'2020'!V11 -> 0.0083908242 | V43: ='2021'!V11-'2020'!W11 -> 0.0072527676 | W43: ='2021'!W11-'2020'!X11 -> 0.091541522 | X43: ='2021'!X11-'2020'!Y11 -> 0.079125646 | Y43: ='2021'!Y11-'2020'!Z11 -> 0 | Z43: ='2021'!Z11-'2020'!AA11 -> 0
A44: ITA | B44: 2021 | C44: =D44+E44 -> 77.945232 | D44: ='2021'!D12-'2020'!D12 -> 12.012135 | E44: ='2021'!E12-'2020'!E12 -> 65.933098 | F44: ='2021'!F12-'2020'!F12 -> 0.02112912 | G44: =H44+I44 -> 1.75749 | H44: ='2021'!H12-'2020'!H12 -> 0.0098099487 | I44: ='2021'!I12-'2020'!I12 -> 1.7476801 | J44: ='2021'!J12-'2020'!J12 -> 0 | K44: =M44+O44 -> 4.0635468 | L44: =N44+P44 -> 3.3343274 | M44: ='2021'!M12-'2020'!M12 -> 0.62623294 | N44: ='2021'!N12-'2020'!N12 -> 0.51385299 | O44: ='2021'!O12-'2020'!O12 -> 3.4373139 | P44: ='2021'!P12-'2020'!P12 -> 2.8204744 | Q44: ='2021'!Q12-'2020'!Q12 -> 0.001101532 | R44: ='2021'!R12-'2020'!S12 -> 0.00090385779 | S44: =U44+W44+Y44 -> 0.09162386 | T44: =V44+X44+Z44 -> 0.0751816 | U44: ='2021'!U12-'2020'!V12 -> 0.00051142558 | V44: ='2021'!V12-'2020'!W12 -> 0.00041964826 | W44: ='2021'!W12-'2020'!X12 -> 0.091112434 | X44: ='2021'!X12-'2020'!Y12 -> 0.074761951 | Y44: ='2021'!Y12-'2020'!Z12 -> 0 | Z44: ='2021'!Z12-'2020'!AA12 -> 0
A45: JPN | B45: 2021 | C45: =D45+E45 -> 61.500838 | D45: ='2021'!D13-'2020'!D13 -> 15.056602 | E45: ='2021'!E13-'2020'!E13 -> 46.444236 | F45: ='2021'!F13-'2020'!F13 -> -216.14927 | G45: =H45+I45 -> 0.11736056 | H45: ='2021'!H13-'2020'!H13 -> 0 | I45: ='2021'!I13-'2020'!I13 -> 0.11736056 | J45: ='2021'!J13-'2020'!J13 -> 1.0233542 | K45: =M45+O45 -> 1.3474224 | L45: =N45+P45 -> 1.1549774 | M45: ='2021'!M13-'2020'!M13 -> 0.32987521 | N45: ='2021'!N13-'2020'!N13 -> 0.28276093 | O45: ='2021'!O13-'2020'!O13 -> 1.0175472 | P45: ='2021'!P13-'2020'!P13 -> 0.87221643 | Q45: ='2021'!Q13-'2020'!Q13 -> -4.7356161 | R45: ='2021'!R13-'2020'!S13 -> -4.0592538 | S45: =U45+W45+Y45 -> 0.02499193 | T45: =V45+X45+Z45 -> 0.021422468 | U45: ='2021'!U13-'2020'!V13 -> 0 | V45: ='2021'!V13-'2020'!W13 -> 0 | W45: ='2021'!W13-'2020'!X13 -> 0.0025712536 | X45: ='2021'!X13-'2020'!Y13 -> 0.0022040154 | Y45: ='2021'!Y13-'2020'!Z13 -> 0.022420676 | Z45: ='2021'!Z13-'2020'!AA13 -> 0.019218453
A46: KOR | B46: 2021 | C46: =D46+E46 -> 48.749754 | D46: ='2021'!D14-'2020'!D14 -> 7.6352312 | E46: ='2021'!E14-'2020'!E14 -> 41.114522 | F46: ='2021'!F14-'2020'!F14 -> 0.052710707 | G46: =H46+I46 -> 0.11324815 | H46: ='2021'!H14-'2020'!H14 -> 0 | I46: ='2021'!I14-'2020'!I14 -> 0.11324815 | J46: ='2021'!J14-'2020'!J14 -> 0.19966177 | K46: =M46+O46 -> 2.9759084 | L46: =N46+P46 -> 2.2605546 | M46: ='2021'!M14-'2020'!M14 -> 0.46608951 | N46: ='2021'!N14-'2020'!N14 -> 0.35405013 | O46: ='2021'!O14-'2020'!O14 -> 2.5098189 | P46: ='2021'!P14-'2020'!P14 -> 1.9065044 | Q46: ='2021'!Q14-'2020'!Q14 -> 0.0032177032 | R46: ='2021'!R14-'2020'!S14 -> 0.0024442263 | S46: =U46+W46+Y46 -> 0.019101456 | T46: =V46+X46+Z46 -> 0.014509816 | U46: ='2021'!U14-'2020'!V14 -> 0 | V46: ='2021'!V14-'2020'!W14 -> 0 | W46: ='2021'!W14-'2020'!X14 -> 0.0069131865 | X46: ='2021'!X14-'2020'!Y14 -> 0.0052513831 | Y46: ='2021'!Y14-'2020'!Z14 -> 0.01218827 | Z46: ='2021'!Z14-'2020'!AA14 -> 0.0092584329
A47: ESP | B47: 2021 | C47: =D47+E47 -> 54.977744 | D47: ='2021'!D15-'2020'!D15 -> 16.915665 | E47: ='2021'!E15-'2020'!E15 -> 38.062078 | F47: ='2021'!F15-'2020'!F15 -> -0.56330456 | G47: =H47+I47 -> 0.45650672 | H47: ='2021'!H15-'2020'!H15 -> 0.0019287868 | I47: ='2021'!I15-'2020'!I15 -> 0.45457793 | J47: ='2021'!J15-'2020'!J15 -> 0.030184458 | K47: =M47+O47 -> 4.1526532 | L47: =N47+P47 -> 3.0602224 | M47: ='2021'!M15-'2020'!M15 -> 1.2776969 | N47: ='2021'!N15-'2020'!N15 -> 0.94157555 | O47: ='2021'!O15-'2020'!O15 -> 2.8749563 | P47: ='2021'!P15-'2020'!P15 -> 2.1186469 | Q47: ='2021'!Q15-'2020'!Q15 -> -0.042548281 | R47: ='2021'!R15-'2020'!S15 -> -0.031355184 | S47: =U47+W47+Y47 -> 0.036761415 | T47: =V47+X47+Z47 -> 0.027090658 | U47: ='2021'!U15-'2020'!V15 -> 0.00014568773 | V47: ='2021'!V15-'2020'!W15 -> 0.00010736193 | W47: ='2021'!W15-'2020'!X15 -> 0.034335794 | X47: ='2021'!X15-'2020'!Y15 -> 0.025303141 | Y47: ='2021'!Y15-'2020'!Z15 -> 0.0022799332 | Z47: ='2021'!Z15-'2020'!AA15 -> 0.0016801554
A48: GBR | B48: 2021 | C48: =D48+E48 -> 81.621811 | D48: ='2021'!D16-'2020'!D16 -> -13.851556 | E48: ='2021'!E16-'2020'!E16 -> 95.473367 | F48: ='2021'!F16-'2020'!F16 -> 7.0724977 | G48: =H48+I48 -> 16.222002 | H48: ='2021'!H16-'2020'!H16 -> 0.040799588 | I48: ='2021'!I16-'2020'!I16 -> 16.181202 | J48: ='2021'!J16-'2020'!J16 -> 0 | K48: =M48+O48 -> 2.5851054 | L48: =N48+P48 -> 2.7743758 | M48: ='2021'!M16-'2020'!M16 -> -0.43870298 | N48: ='2021'!N16-'2020'!N16 -> -0.47082294 | O48: ='2021'!O16-'2020'!O16 -> 3.0238084 | P48: ='2021'!P16-'2020'!P16 -> 3.2451987 | Q48: ='2021'!Q16-'2020'!Q16 -> 0.22399836 | R48: ='2021'!R16-'2020'!S16 -> 0.24039856 | S48: =U48+W48+Y48 -> 0.51377914 | T48: =V48+X48+Z48 -> 0.55139585 | U48: ='2021'!U16-'2020'!V16 -> 0.0012921942 | V48: ='2021'!V16-'2020'!W16 -> 0.0013868032 | W48: ='2021'!W16-'2020'!X16 -> 0.51248694 | X48: ='2021'!X16-'2020'!Y16 -> 0.55000905 | Y48: ='2021'!Y16-'2020'!Z16 -> 0 | Z48: ='2021'!Z16-'2020'!AA16 -> 0
A49: USA | B49: 2021 | C49: =D49+E49 -> 1825 | D49: ='2021'!D17-'2020'!D17 -> 203.5 | E49: ='2021'!E17-'2020'!E17 -> 1621.5 | F49: ='2021'!F17-'2020'!F17 -> -0.02 | G49: =H49+I49 -> 0 | H49: ='2021'!H17-'2020'!H17 -> 0 | I49: ='2021'!I17-'2020'!I17 -> 0 | J49: ='2021'!J17-'2020'!J17 -> 0 | K49: =M49+O49 -> 9.1575206 | L49: =N49+P49 -> 9.1367801 | M49: ='2021'!M17-'2020'!M17 -> 1.0211263 | N49: ='2021'!N17-'2020'!N17 -> 1.0188136 | O49: ='2021'!O17-'2020'!O17 -> 8.1363943 | P49: ='2021'!P17-'2020'!P17 -> 8.1179665 | Q49: ='2021'!Q17-'2020'!Q17 -> -0.00010035639 | R49: ='2021'!R17-'2020'!S17 -> -0.0001001291 | S49: =U49+W49+Y49 -> 0 | T49: =V49+X49+Z49 -> 0 | U49: ='2021'!U17-'2020'!V17 -> 0 | V49: ='2021'!V17-'2020'!W17 -> 0 | W49: ='2021'!W17-'2020'!X17 -> 0 | X49: ='2021'!X17-'2020'!Y17 -> 0 | Y49: ='2021'!Y17-'2020'!Z17 -> 0 | Z49: ='2021'!Z17-'2020'!AA17 -> 0
A50: MEX | B50: 2021 | C50: =D50+E50 -> -0.20002812 | D50: ='2021'!D18-'2020'!D18 -> 2.4564657 | E50: ='2021'!E18-'2020'!E18 -> -2.6564938 | F50: ='2021'!F18-'2020'!F18 -> -0.036082982 | G50: =H50+I50 -> -1.8221374 | H50: ='2021'!H18-'2020'!H18 -> -0.95092364 | I50: ='2021'!I18-'2020'!I18 -> -0.87121376 | J50: ='2021'!J18-'2020'!J18 -> 1.6475248 | K50: =M50+O50 -> -0.015637565 | L50: =N50+P50 -> -0.0083986584 | M50: ='2021'!M18-'2020'!M18 -> 0.19203871 | N50: ='2021'!N18-'2020'!N18 -> 0.10314058 | O50: ='2021'!O18-'2020'!O18 -> -0.20767628 | P50: ='2021'!P18-'2020'!P18 -> -0.11153924 | Q50: ='2021'!Q18-'2020'!Q18 -> -0.0028208533 | R50: ='2021'!R18-'2020'!S18 -> -0.0015150302 | S50: =U50+W50+Y50 -> -0.013650658 | T50: =V50+X50+Z50 -> -0.0073315257 | U50: ='2021'!U18-'2020'!V18 -> -0.074340199 | V50: ='2021'!V18-'2020'!W18 -> -0.0399268 | W50: ='2021'!W18-'2020'!X18 -> -0.068108732 | X50: ='2021'!X18-'2020'!Y18 -> -0.03657999 | Y50: ='2021'!Y18-'2020'!Z18 -> 0.12879827 | Z50: ='2021'!Z18-'2020'!AA18 -> 0.069175264
A51: TUR | B51: 2021 | C51: =D51+E51 -> 17.623913 | D51: ='2021'!D19-'2020'!D19 -> 0.75119989 | E51: ='2021'!E19-'2020'!E19 -> 16.872713 | F51: ='2021'!F19-'2020'!F19 -> 0.14605226 | G51: =H51+I51 -> 2.4997121 | H51: ='2021'!H19-'2020'!H19 -> 0.013959679 | I51: ='2021'!I19-'2020'!I19 -> 2.4857524 | J51: ='2021'!J19-'2020'!J19 -> 2.8780291 | K51: =M51+O51 -> 1.7675994 | L51: =N51+P51 -> 0.75516488 | M51: ='2021'!M19-'2020'!M19 -> 0.07534198 | N51: ='2021'!N19-'2020'!N19 -> 0.032188072 | O51: ='2021'!O19-'2020'!O19 -> 1.6922574 | P51: ='2021'!P19-'2020'!P19 -> 0.72297681 | Q51: ='2021'!Q19-'2020'!Q19 -> 0.014648387 | R51: ='2021'!R19-'2020'!S19 -> 0.0062581756 | S51: =U51+W51+Y51 -> 0.53936333 | T51: =V51+X51+Z51 -> 0.23043018 | U51: ='2021'!U19-'2020'!V19 -> 0.0014000932 | V51: ='2021'!V19-'2020'!W19 -> 0.00059815658 | W51: ='2021'!W19-'2020'!X19 -> 0.24930982 | X51: ='2021'!X19-'2020'!Y19 -> 0.1065117 | Y51: ='2021'!Y19-'2020'!Z19 -> 0.28865342 | Z51: ='2021'!Z19-'2020'!AA19 -> 0.12332032
... A77: POL | B77: 2021 | C77: =D77+E77 -> -6.193372 | D77: ='2021'!D45-'2020'!D45 -> 1.6041485 | E77: ='2021'!E45-'2020'!E45 -> -7.7975205 | F77: ='2021'!F45-'2020'!F45 -> 0 | G77: =H77+I77 -> -2.8691942 | H77: ='2021'!H45-'2020'!H45 -> -2.9933302 | I77: ='2021'!I45-'2020'!I45 -> 0.12413598 | J77: ='2021'!J45-'2020'!J45 -> 0 | K77: =M77+O77 -> -1.0836987 | L77: =N77+P77 -> -0.5095652 | M77: ='2021'!M45-'2020'!M45 -> 0.28068938 | N77: ='2021'!N45-'2020'!N45 -> 0.13198275 | O77: ='2021'!O45-'2020'!O45 -> -1.3643881 | P77: ='2021'!P45-'2020'!P45 -> -0.64154795 | Q77: ='2021'!Q45-'2020'!Q45 -> 0 | R77: ='2021'!R45-'2020'!S45 -> 0 | S77: =U77+W77+Y77 -> -0.50204349 | T77: =V77+X77+Z77 -> -0.23606551 | U77: ='2021'!U45-'2020'!V45 -> -0.52376445 | V77: ='2021'!V45-'2020'!W45 -> -0.24627891 | W77: ='2021'!W45-'2020'!X45 -> 0.021720963 | X77: ='2021'!X45-'2020'!Y45 -> 0.010213398 | Y77: ='2021'!Y45-'2020'!Z45 -> 0 | Z77: ='2021'!Z45-'2020'!AA45 -> 0

Sheet Security
A1: Table 1. Summary of Country Fiscal Measures in Response to the COVID-19 Pandemic since January 2020
A2: (USD billion and percent of 2020 GDP)
A3: USD Billion
B4: Above the line measures | F4: Liquidity support | J4: Above the line measures | N4: Liquidity support
B5: Additional spending or foregone revenues | E5: Accelerated spending / deferred revenue | G5: Below the line measures: equity injections, loans, asset purchase or debt assumptions. | H5: Contingent liabilities | J5: Additional spending or foregone revenues | M5: Accelerated spending / deferred revenue | O5: Below the line measures: equity injections, loans, asset purchase or debt assumptions. | P5: Contingent liabilities
B6: Subtotal | C6: Health sector | D6: Non-health sector | F6: Subtotal | H6: Guarantees | I6: Quasi-fiscal operations | J6: Subtotal | K6: Health sector | L6: Non-health sector | N6: Subtotal | P6: Guarantees | Q6: Quasi-fiscal operations
A7: Australia | B7: =C7+D7 -> 31.278018 | C7: ='2021'!D8-'2020'!D8 -> 2.347535 | D7: ='2021'!E8-'2020'!E8 -> 28.930483 | E7: ='2021'!F8-'2020'!F8 -> 0 | F7: =G7+H7 -> 0.00020812525 | G7: ='2021'!H8-'2020'!H8 -> 8.9196534e-05 | H7: ='2021'!I8-'2020'!I8 -> 0.00011892871 | I7: ='2021'!J8-'2020'!J8 -> 0 | J7: =K7+L7 -> 2.0924923 | K7: ='2021'!M8-'2020'!M8 -> 0.15704956 | L7: ='2021'!O8-'2020'!O8 -> 1.9354428 | M7: ='2021'!Q8-'2020'!Q8 -> 0 | N7: =O7+P7+Q7 -> 1.3923532e-05 | O7: ='2021'!U8-'2020'!V8 -> 5.967228e-06 | P7: ='2021'!W8-'2020'!X8 -> 7.9563039e-06 | Q7: ='2021'!Y8-'2020'!Z8 -> 0
A8: Canada | B8: =C8+D8 -> 21.685295 | C8: ='2021'!D9-'2020'!D9 -> 6.4210348 | D8: ='2021'!E9-'2020'!E9 -> 15.26426 | E8: ='2021'!F9-'2020'!F9 -> 4.7831846 | F8: =G8+H8 -> -0.97855874 | G8: ='2021'!H9-'2020'!H9 -> 0.0082097879 | H8: ='2021'!I9-'2020'!I9 -> -0.98676853 | I8: ='2021'!J9-'2020'!J9 -> 0 | J8: =K8+L8 -> 1.2781581 | K8: ='2021'!M9-'2020'!M9 -> 0.37846372 | L8: ='2021'!O9-'2020'!O9 -> 0.89969434 | M8: ='2021'!Q9-'2020'!Q9 -> 0.28192681 | N8: =O8+P8+Q8 -> -0.057677461 | O8: ='2021'!U9-'2020'!V9 -> 0.00048389504 | P8: ='2021'!W9-'2020'!X9 -> -0.058161356 | Q8: ='2021'!Y9-'2020'!Z9 -> 0
A9: France | B9: =C9+D9 -> 54.826804 | C9: ='2021'!D10-'2020'!D10 -> 18.372481 | D9: ='2021'!E10-'2020'!E10 -> 36.454322 | E9: ='2021'!F10-'2020'!F10 -> 16.600029 | F9: =G9+H9 -> -5.439085 | G9: ='2021'!H10-'2020'!H10 -> -5.8973249 | H9: ='2021'!I10-'2020'!I10 -> 0.45823993 | I9: ='2021'!J10-'2020'!J10 -> 0 | J9: =K9+L9 -> 2.0951751 | K9: ='2021'!M10-'2020'!M10 -> 0.70209392 | L9: ='2021'!O10-'2020'!O10 -> 1.3930812 | M9: ='2021'!Q10-'2020'!Q10 -> 0.63436067 | N9: =O9+P9+Q9 -> -0.20785154 | O9: ='2021'!U10-'2020'!V10 -> -0.22536292 | P9: ='2021'!W10-'2020'!X10 -> 0.017511378 | Q9: ='2021'!Y10-'2020'!Z10 -> 0
A10: Germany | B10: =C10+D10 -> 171.15877 | C10: ='2021'!D11-'2020'!D11 -> 24.087657 | D10: ='2021'!E11-'2020'!E11 -> 147.07111 | E10: ='2021'!F11-'2020'!F11 -> 0 | F10: =G10+H10 -> 3.5948836 | G10: ='2021'!H11-'2020'!H11 -> 0.30184458 | H10: ='2021'!I11-'2020'!I11 -> 3.293039 | I10: ='2021'!J11-'2020'!J11 -> 0 | J10: =K10+L10 -> 4.7579557 | K10: ='2021'!M11-'2020'!M11 -> 0.66960056 | L10: ='2021'!O11-'2020'!O11 -> 4.0883552 | M10: ='2021'!Q11-'2020'!Q11 -> 0 | N10: =O10+P10+Q10 -> 0.099932346 | O10: ='2021'!U11-'2020'!V11 -> 0.0083908242 | P10: ='2021'!W11-'2020'!X11 -> 0.091541522 | Q10: ='2021'!Y11-'2020'!Z11 -> 0
A11: Italy | B11: =C11+D11 -> 77.945232 | C11: ='2021'!D12-'2020'!D12 -> 12.012135 | D11: ='2021'!E12-'2020'!E12 -> 65.933098 | E11: ='2021'!F12-'2020'!F12 -> 0.02112912 | F11: =G11+H11 -> 1.75749 | G11: ='2021'!H12-'2020'!H12 -> 0.0098099487 | H11: ='2021'!I12-'2020'!I12 -> 1.7476801 | I11: ='2021'!J12-'2020'!J12 -> 0 | J11: =K11+L11 -> 4.0635468 | K11: ='2021'!M12-'2020'!M12 -> 0.62623294 | L11: ='2021'!O12-'2020'!O12 -> 3.4373139 | M11: ='2021'!Q12-'2020'!Q12 -> 0.001101532 | N11: =O11+P11+Q11 -> 0.09162386 | O11: ='2021'!U12-'2020'!V12 -> 0.00051142558 | P11: ='2021'!W12-'2020'!X12 -> 0.091112434 | Q11: ='2021'!Y12-'2020'!Z12 -> 0
A12: Japan | B12: =C12+D12 -> 61.500838 | C12: ='2021'!D13-'2020'!D13 -> 15.056602 | D12: ='2021'!E13-'2020'!E13 -> 46.444236 | E12: ='2021'!F13-'2020'!F13 -> -216.14927 | F12: =G12+H12 -> 0.11736056 | G12: ='2021'!H13-'2020'!H13 -> 0 | H12: ='2021'!I13-'2020'!I13 -> 0.11736056 | I12: ='2021'!J13-'2020'!J13 -> 1.0233542 | J12: =K12+L12 -> 1.3474224 | K12: ='2021'!M13-'2020'!M13 -> 0.32987521 | L12: ='2021'!O13-'2020'!O13 -> 1.0175472 | M12: ='2021'!Q13-'2020'!Q13 -> -4.7356161 | N12: =O12+P12+Q12 -> 0.02499193 | O12: ='2021'!U13-'2020'!V13 -> 0 | P12: ='2021'!W13-'2020'!X13 -> 0.0025712536 | Q12: ='2021'!Y13-'2020'!Z13 -> 0.022420676
A13: Korea | B13: =C13+D13 -> 48.749754 | C13: ='2021'!D14-'2020'!D14 -> 7.6352312 | D13: ='2021'!E14-'2020'!E14 -> 41.114522 | E13: ='2021'!F14-'2020'!F14 -> 0.052710707 | F13: =G13+H13 -> 0.11324815 | G13: ='2021'!H14-'2020'!H14 -> 0 | H13: ='2021'!I14-'2020'!I14 -> 0.11324815 | I13: ='2021'!J14-'2020'!J14 -> 0.19966177 | J13: =K13+L13 -> 2.9759084 | K13: ='2021'!M14-'2020'!M14 -> 0.46608951 | L13: ='2021'!O14-'2020'!O14 -> 2.5098189 | M13: ='2021'!Q14-'2020'!Q14 -> 0.0032177032 | N13: =O13+P13+Q13 -> 0.019101456 | O13: ='2021'!U14-'2020'!V14 -> 0 | P13: ='2021'!W14-'2020'!X14 -> 0.0069131865 | Q13: ='2021'!Y14-'2020'!Z14 -> 0.01218827
A14: Spain | B14: =C14+D14 -> 54.977744 | C14: ='2021'!D15-'2020'!D15 -> 16.915665 | D14: ='2021'!E15-'2020'!E15 -> 38.062078 | E14: ='2021'!F15-'2020'!F15 -> -0.56330456 | F14: =G14+H14 -> 0.45650672 | G14: ='2021'!H15-'2020'!H15 -> 0.0019287868 | H14: ='2021'!I15-'2020'!I15 -> 0.45457793 | I14: ='2021'!J15-'2020'!J15 -> 0.030184458 | J14: =K14+L14 -> 4.1526532 | K14: ='2021'!M15-'2020'!M15 -> 1.2776969 | L14: ='2021'!O15-'2020'!O15 -> 2.8749563 | M14: ='2021'!Q15-'2020'!Q15 -> -0.042548281 | N14: =O14+P14+Q14 -> 0.036761415 | O14: ='2021'!U15-'2020'!V15 -> 0.00014568773 | P14: ='2021'!W15-'2020'!X15 -> 0.034335794 | Q14: ='2021'!Y15-'2020'!Z15 -> 0.0022799332
A15: United Kingdom | B15: =C15+D15 -> 81.621811 | C15: ='2021'!D16-'2020'!D16 -> -13.851556 | D15: ='2021'!E16-'2020'!E16 -> 95.473367 | E15: ='2021'!F16-'2020'!F16 -> 7.0724977 | F15: =G15+H15 -> 16.222002 | G15: ='2021'!H16-'2020'!H16 -> 0.040799588 | H15: ='2021'!I16-'2020'!I16 -> 16.181202 | I15: ='2021'!J16-'2020'!J16 -> 0 | J15: =K15+L15 -> 2.5851054 | K15: ='2021'!M16-'2020'!M16 -> -0.43870298 | L15: ='2021'!O16-'2020'!O16 -> 3.0238084 | M15: ='2021'!Q16-'2020'!Q16 -> 0.22399836 | N15: =O15+P15+Q15 -> 0.51377914 | O15: ='2021'!U16-'2020'!V16 -> 0.0012921942 | P15: ='2021'!W16-'2020'!X16 -> 0.51248694 | Q15: ='2021'!Y16-'2020'!Z16 -> 0
A16: United States | B16: =C16+D16 -> 1825 | C16: ='2021'!D17-'2020'!D17 -> 203.5 | D16: ='2021'!E17-'2020'!E17 -> 1621.5 | E16: ='2021'!F17-'2020'!F17 -> -0.02 | F16: =G16+H16 -> 0 | G16: ='2021'!H17-'2020'!H17 -> 0 | H16: ='2021'!I17-'2020'!I17 -> 0 | I16: ='2021'!J17-'2020'!J17 -> 0 | J16: =K16+L16 -> 9.1575206 | K16: ='2021'!M17-'2020'!M17 -> 1.0211263 | L16: ='2021'!O17-'2020'!O17 -> 8.1363943 | M16: ='2021'!Q17-'2020'!Q17 -> -0.00010035639 | N16: =O16+P16+Q16 -> 0 | O16: ='2021'!U17-'2020'!V17 -> 0 | P16: ='2021'!W17-'2020'!X17 -> 0 | Q16: ='2021'!Y17-'2020'!Z17 -> 0
A17: Mexico | B17: =C17+D17 -> -0.20002812 | C17: ='2021'!D18-'2020'!D18 -> 2.4564657 | D17: ='2021'!E18-'2020'!E18 -> -2.6564938 | E17: ='2021'!F18-'2020'!F18 -> -0.036082982 | F17: =G17+H17 -> -1.8221374 | G17: ='2021'!H18-'2020'!H18 -> -0.95092364 | H17: ='2021'!I18-'2020'!I18 -> -0.87121376 | I17: ='2021'!J18-'2020'!J18 -> 1.6475248 | J17: =K17+L17 -> -0.015637565 | K17: ='2021'!M18-'2020'!M18 -> 0.19203871 | L17: ='2021'!O18-'2020'!O18 -> -0.20767628 | M17: ='2021'!Q18-'2020'!Q18 -> -0.0028208533 | N17: =O17+P17+Q17 -> -0.013650658 | O17: ='2021'!U18-'2020'!V18 -> -0.074340199 | P17: ='2021'!W18-'2020'!X18 -> -0.068108732 | Q17: ='2021'!Y18-'2020'!Z18 -> 0.12879827
A18: Turkey | B18: =C18+D18 -> 17.623913 | C18: ='2021'!D19-'2020'!D19 -> 0.75119989 | D18: ='2021'!E19-'2020'!E19 -> 16.872713 | E18: ='2021'!F19-'2020'!F19 -> 0.14605226 | F18: =G18+H18 -> 2.4997121 | G18: ='2021'!H19-'2020'!H19 -> 0.013959679 | H18: ='2021'!I19-'2020'!I19 -> 2.4857524 | I18: ='2021'!J19-'2020'!J19 -> 2.8780291 | J18: =K18+L18 -> 1.7675994 | K18: ='2021'!M19-'2020'!M19 -> 0.07534198 | L18: ='2021'!O19-'2020'!O19 -> 1.6922574 | M18: ='2021'!Q19-'2020'!Q19 -> 0.014648387 | N18: =O18+P18+Q18 -> 0.53936333 | O18: ='2021'!U19-'2020'!V19 -> 0.0014000932 | P18: ='2021'!W19-'2020'!X19 -> 0.24930982 | Q18: ='2021'!Y19-'2020'!Z19 -> 0.28865342
... A44: Poland | B44: =C44+D44 -> -6.193372 | C44: ='2021'!D45-'2020'!D45 -> 1.6041485 | D44: ='2021'!E45-'2020'!E45 -> -7.7975205 | E44: ='2021'!F45-'2020'!F45 -> 0 | F44: =G44+H44 -> -2.8691942 | G44: ='2021'!H45-'2020'!H45 -> -2.9933302 | H44: ='2021'!I45-'2020'!I45 -> 0.12413598 | I44: ='2021'!J45-'2020'!J45 -> 0 | J44: =K44+L44 -> -1.0836987 | K44: ='2021'!M45-'2020'!M45 -> 0.28068938 | L44: ='2021'!O45-'2020'!O45 -> -1.3643881 | M44: ='2021'!Q45-'2020'!Q45 -> 0 | N44: =O44+P44+Q44 -> -0.50204349 | O44: ='2021'!U45-'2020'!V45 -> -0.52376445 | P44: ='2021'!W45-'2020'!X45 -> 0.021720963 | Q44: ='2021'!Y45-'2020'!Z45 -> 0

Sheet Database
C2: Fiscal Monitor: Database of Country Fiscal Measures in Response to the COVID-19 Pandemic
C3: This database summarizes key fiscal measures governments have announced or taken in selected economies in response to the COVID-19 pandemic as of December 31, 2020 for selected economies. The database categorizes different types of fiscal support (for example, above-the-line and below-the line measures, and contingent liabilities) that have different implications for public finances in the near term and beyond. Please refer to Box 1.1 of the April 2020 Fiscal Monitor for details. The database is not meant for classifying the measures for fiscal reporting, nor for comparison across economies as responses vary depending on country-specific circumstances, including the impact of the pandemic and other shocks. It focuses on government discretionary measures that supplement existing automatic stabilizers. These existing stabilizers differ across countries in their breadth and scope. Estimates included here are preliminary as governments are taking additional measures or finalizing the details of individual measures. The information does not represent views of the IMF on the measures listed. Please see IMF Policy Tracker (https://www.imf.org/COVID19policytracker) for information on a broader range of economies and their monetary and financial policies.
H4: A. Above-the line measures | Q4: B. Below the line measures | T4: C. Contingent liabilities | Y4: Other measures
A5: G20 + Spain | B5: Country Group | C5: Country /1 | D5: Government Level | F5: Unit | G5: Total on-budget (A-D) | H5: Total size | I5: Additional spending and forgone revenue in the health sector | J5: Total size | K5: Additional spending and forgone revenue in areas other than health | L5: Total size | M5: D. Accelerated spending and deferred revenue in areas other than health | O5: Unit | P5: Total off-budget (B+C) | Q5: Total size | R5: Equity injections, asset purchases, loans, debt assumptions, including through extra-budgetary funds | T5: Unit | U5: Total size | V5: Guarantees (on loans, deposits etc.) | W5: Total size | X5: Quasi-fiscal operations (noncommercial activity of public corporations on behalf of government) | Y5: Automatic stabilizers, contingency lines
