Workbook
Name FCV_added: OFFSET('Policy select backend'!$O$52,,,2+'Policy select backend'!$B$52)
Name FCV_Scores: OFFSET('Performance across backend'!$H$39,,,2+'Performance across backend'!$P$3)
Name Income_added: OFFSET('Policy select backend'!$O$37,,,4+'Policy select backend'!$B$52)
Name Income_scores: OFFSET('Performance across backend'!$H$24,,,4+'Performance across backend'!$P$3)
Name Lending_added: OFFSET('Policy select backend'!$O$31,,,3+'Policy select backend'!$B$52)
Name Lending_scores: OFFSET('Performance across backend'!$H$18,,,3+'Performance across backend'!$P$3)
Name Regions_added: OFFSET('Policy select backend'!$O$43,,,7+'Policy select backend'!$B$52)
Name Regions_scores: OFFSET('Performance across backend'!$H$30,,,7+'Performance across backend'!$P$3)

Sheet Data
A1: Country | B1: PolicyCategory | C1: PolicyCode | D1: Fullpolicy | E1: Targetability | F1: Speed | G1: Abuse_Resistance | H1: Affordability | I1: Predictability_Cost_Control | J1: Reversibility | K1: Scalability | L1: Administrative_Complexity | M1: Resilience_Health_Measures | N1: Country_Code | O1: Reg | P1: Lendingcategory | Q1: Incomelevel | R1: FCV | S1: GDP change | T1: Fiscal Balance | U1: Debt | V1: Targetability (converted) | W1: Speed (converted) | X1: Abuse_Resistance (converted) | Y1: Affordability (converted) | Z1: Predictability_Cost_Control (converted) | AA1: Reversibility (converted) | AB1: Scalability (converted) | AC1: Administrative_Complexity (converted) | AD1: Resilience_Health_Measures (converted) | AE1: All Regions | AF1: All Income Levels | AG1: IDA | AH1: IBRD | AI1: Neither | AJ1: All | AK1: All Countries | AL1: Other Policy | AM1: Selected Country Ranker | AN1: Region location | AO1: Lending location | AP1: Income location | AQ1: FCV location | AR1: Country location | AS1: Country2 | AT1: Subcategory (clean) | AU1: First of country row (requires sorting alphabetically by country) | AV1: May 1st sample
A2: Afghanistan | B2: 5 | C2: general | D2: Financing requested to the World Bank, Asian Development Bank, Islamic Development Bank, and the IMF. | E2: 1 | F2: -2 | G2: -2 | H2: 2 | I2: -1 | J2: 1 | K2: 1 | L2: 1 | M2: 1 | N2: AFG | O2: South Asia | P2: IDA | Q2: Low Income | R2: 0 | S2: -1.89 | T2: -2.16 | U2: 8.21 | V2: =IF(E2>0,1,IF(E2<0,0,-1)) -> 1 | W2: =IF(F2>0,1,IF(F2<0,0,-1)) -> 0 | X2: =IF(G2>0,1,IF(G2<0,0,-1)) -> 0 | Y2: =IF(H2>0,1,IF(H2<0,0,-1)) -> 1 | Z2: =IF(I2>0,1,IF(I2<0,0,-1)) -> 0 | AA2: =IF(J2>0,1,IF(J2<0,0,-1)) -> 1 | AB2: =IF(K2>0,1,IF(K2<0,0,-1)) -> 1 | AC2: =IF(L2>0,1,IF(L2<0,0,-1)) -> 1 | AD2: =IF(M2>0,1,IF(M2<0,0,-1)) -> 1 | AE2: All Regions | AF2: All Income Levels | AG2: 1 | AH2: 0 | AI2: 0 | AJ2: 1 | AK2: All Countries | AL2: =IF(OR(B2="other",B2="international",B2="Transfers",B2="expenditure"),1,0) -> 0 | AM2: =IF(AND(INDIRECT(AN2)='Sample Select backend'!$C$2,INDIRECT(AO2)=1,INDIRECT(AP2)='Sample Select backend'!$F$2,INDIRECT(AQ2)=1,INDIRECT(AR2)='Sample Select backend'!$M$2),1,0) -> 0 | AN2: =_xlfn.CONCAT('Sample Select backend'!$C$4,ROW(AN2)) -> AE2 | AO2: =_xlfn.CONCAT('Sample Select backend'!$J$2,ROW(AO2)) -> AJ2 | AP2: =_xlfn.CONCAT('Sample Select backend'!$F$4,ROW(AP2)) -> AF2 | AQ2: =_xlfn.CONCAT('Sample Select backend'!$I$10,ROW(AQ2)) -> R2 | AR2: =_xlfn.CONCAT('Sample Select backend'!$M$4,ROW(AR2)) -> AK2 | AS2: =A2 -> Afghanistan | AT2: =IF(ISNUMBER(C2),C2,IF(OR(C2="general",C2="23;general"),"General",IF(OR(C2="exemption",C2="other (exemption)"),"Tax exemption/waiver/suspension","Other"))) -> General | AU2: =IF(A2<>A1,1,0) -> 1 | AV2: 1
A3: Afghanistan | B3: 5 | C3: general | D3: An additional USD 10 million of reserve funds have been earmarked for further health costs of the COVID-19 response. | E3: 1 | F3: -2 | G3: -2 | H3: -1 | I3: -1 | J3: 1 | K3: 1 | L3: 1 | M3: 1 | N3: AFG | O3: South Asia | P3: IDA | Q3: Low Income | R3: 0 | S3: -1.89 | T3: -2.16 | U3: 8.21 | V3: =IF(E3>0,1,IF(E3<0,0,-1)) -> 1 | W3: =IF(F3>0,1,IF(F3<0,0,-1)) -> 0 | X3: =IF(G3>0,1,IF(G3<0,0,-1)) -> 0 | Y3: =IF(H3>0,1,IF(H3<0,0,-1)) -> 0 | Z3: =IF(I3>0,1,IF(I3<0,0,-1)) -> 0 | AA3: =IF(J3>0,1,IF(J3<0,0,-1)) -> 1 | AB3: =IF(K3>0,1,IF(K3<0,0,-1)) -> 1 | AC3: =IF(L3>0,1,IF(L3<0,0,-1)) -> 1 | AD3: =IF(M3>0,1,IF(M3<0,0,-1)) -> 1 | AE3: All Regions | AF3: All Income Levels | AG3: 1 | AH3: 0 | AI3: 0 | AJ3: 1 | AK3: All Countries | AL3: =IF(OR(B3="other",B3="international",B3="Transfers",B3="expenditure"),1,0) -> 0 | AM3: =IF(AND(INDIRECT(AN3)='Sample Select backend'!$C$2,INDIRECT(AO3)=1,INDIRECT(AP3)='Sample Select backend'!$F$2,INDIRECT(AQ3)=1,INDIRECT(AR3)='Sample Select backend'!$M$2),1,0) -> 0 | AN3: =_xlfn.CONCAT('Sample Select backend'!$C$4,ROW(AN3)) -> AE3 | AO3: =_xlfn.CONCAT('Sample Select backend'!$J$2,ROW(AO3)) -> AJ3 | AP3: =_xlfn.CONCAT('Sample Select backend'!$F$4,ROW(AP3)) -> AF3 | AQ3: =_xlfn.CONCAT('Sample Select backend'!$I$10,ROW(AQ3)) -> R3 | AR3: =_xlfn.CONCAT('Sample Select backend'!$M$4,ROW(AR3)) -> AK3 | AS3: =A3 -> Afghanistan | AT3: =IF(ISNUMBER(C3),C3,IF(OR(C3="general",C3="23;general"),"General",IF(OR(C3="exemption",C3="other (exemption)"),"Tax exemption/waiver/suspension","Other"))) -> General | AU3: =IF(A3<>A2,1,0) -> 0 | AV3: 1
A4: Afghanistan | B4: 2 | C4: 13 | D4: Deadline extension for filing tax returns by two months, until May 20 for individual taxpayers. | E4: -2 | F4: 1 | G4: 2 | H4: 1 | I4: 1 | J4: 1 | K4: 1 | L4: 1 | M4: 1 | N4: AFG | O4: South Asia | P4: IDA | Q4: Low Income | R4: 0 | S4: -1.89 | T4: -2.16 | U4: 8.21 | V4: =IF(E4>0,1,IF(E4<0,0,-1)) -> 0 | W4: =IF(F4>0,1,IF(F4<0,0,-1)) -> 1 | X4: =IF(G4>0,1,IF(G4<0,0,-1)) -> 1 | Y4: =IF(H4>0,1,IF(H4<0,0,-1)) -> 1 | Z4: =IF(I4>0,1,IF(I4<0,0,-1)) -> 1 | AA4: =IF(J4>0,1,IF(J4<0,0,-1)) -> 1 | AB4: =IF(K4>0,1,IF(K4<0,0,-1)) -> 1 | AC4: =IF(L4>0,1,IF(L4<0,0,-1)) -> 1 | AD4: =IF(M4>0,1,IF(M4<0,0,-1)) -> 1 | AE4: All Regions | AF4: All Income Levels | AG4: 1 | AH4: 0 | AI4: 0 | AJ4: 1 | AK4: All Countries | AL4: =IF(OR(B4="other",B4="international",B4="Transfers",B4="expenditure"),1,0) -> 0 | AM4: =IF(AND(INDIRECT(AN4)='Sample Select backend'!$C$2,INDIRECT(AO4)=1,INDIRECT(AP4)='Sample Select backend'!$F$2,INDIRECT(AQ4)=1,INDIRECT(AR4)='Sample Select backend'!$M$2),1,0) -> 0 | AN4: =_xlfn.CONCAT('Sample Select backend'!$C$4,ROW(AN4)) -> AE4 | AO4: =_xlfn.CONCAT('Sample Select backend'!$J$2,ROW(AO4)) -> AJ4 | AP4: =_xlfn.CONCAT('Sample Select backend'!$F$4,ROW(AP4)) -> AF4 | AQ4: =_xlfn.CONCAT('Sample Select backend'!$I$10,ROW(AQ4)) -> R4 | AR4: =_xlfn.CONCAT('Sample Select backend'!$M$4,ROW(AR4)) -> AK4 | AS4: =A4 -> Afghanistan | AT4: =IF(ISNUMBER(C4),C4,IF(OR(C4="general",C4="23;general"),"General",IF(OR(C4="exemption",C4="other (exemption)"),"Tax exemption/waiver/suspension","Other"))) -> 13 | AU4: =IF(A4<>A3,1,0) -> 0 | AV4: 1
A5: Afghanistan | B5: 1 | C5: 6 | D5: Tourism, active processing and call centers – as well as small businesses with turnover of Lk14m or less – can defer payments of profit tax to next year. | E5: 2 | F5: 2 | G5: 2 | H5: 1 | I5: 1 | J5: 1 | K5: 1 | L5: 1 | M5: 1 | N5: AFG | O5: South Asia | P5: IDA | Q5: Low Income | R5: 0 | S5: -1.89 | T5: -2.16 | U5: 8.21 | V5: =IF(E5>0,1,IF(E5<0,0,-1)) -> 1 | W5: =IF(F5>0,1,IF(F5<0,0,-1)) -> 1 | X5: =IF(G5>0,1,IF(G5<0,0,-1)) -> 1 | Y5: =IF(H5>0,1,IF(H5<0,0,-1)) -> 1 | Z5: =IF(I5>0,1,IF(I5<0,0,-1)) -> 1 | AA5: =IF(J5>0,1,IF(J5<0,0,-1)) -> 1 | AB5: =IF(K5>0,1,IF(K5<0,0,-1)) -> 1 | AC5: =IF(L5>0,1,IF(L5<0,0,-1)) -> 1 | AD5: =IF(M5>0,1,IF(M5<0,0,-1)) -> 1 | AE5: All Regions | AF5: All Income Levels | AG5: 1 | AH5: 0 | AI5: 0 | AJ5: 1 | AK5: All Countries | AL5: =IF(OR(B5="other",B5="international",B5="Transfers",B5="expenditure"),1,0) -> 0 | AM5: =IF(AND(INDIRECT(AN5)='Sample Select backend'!$C$2,INDIRECT(AO5)=1,INDIRECT(AP5)='Sample Select backend'!$F$2,INDIRECT(AQ5)=1,INDIRECT(AR5)='Sample Select backend'!$M$2),1,0) -> 0 | AN5: =_xlfn.CONCAT('Sample Select backend'!$C$4,ROW(AN5)) -> AE5 | AO5: =_xlfn.CONCAT('Sample Select backend'!$J$2,ROW(AO5)) -> AJ5 | AP5: =_xlfn.CONCAT('Sample Select backend'!$F$4,ROW(AP5)) -> AF5 | AQ5: =_xlfn.CONCAT('Sample Select backend'!$I$10,ROW(AQ5)) -> R5 | AR5: =_xlfn.CONCAT('Sample Select backend'!$M$4,ROW(AR5)) -> AK5 | AS5: =A5 -> Afghanistan | AT5: =IF(ISNUMBER(C5),C5,IF(OR(C5="general",C5="23;general"),"General",IF(OR(C5="exemption",C5="other (exemption)"),"Tax exemption/waiver/suspension","Other"))) -> 6 | AU5: =IF(A5<>A4,1,0) -> 0 | AV5: 1
A6: Afghanistan | B6: 7 | C6: 30 | D6: A sovereign guarantee of Lek 15 billion to provide loans for working capital for the tourism sector as well as active processing exporting companies. The government will bear the interest costs. | E6: 2 | F6: 1 | G6: 1 | H6: 1 | I6: 1 | J6: 2 | K6: 1 | L6: -2 | M6: 1 | N6: AFG | O6: South Asia | P6: IDA | Q6: Low Income | R6: 0 | S6: -1.89 | T6: -2.16 | U6: 8.21 | V6: =IF(E6>0,1,IF(E6<0,0,-1)) -> 1 | W6: =IF(F6>0,1,IF(F6<0,0,-1)) -> 1 | X6: =IF(G6>0,1,IF(G6<0,0,-1)) -> 1 | Y6: =IF(H6>0,1,IF(H6<0,0,-1)) -> 1 | Z6: =IF(I6>0,1,IF(I6<0,0,-1)) -> 1 | AA6: =IF(J6>0,1,IF(J6<0,0,-1)) -> 1 | AB6: =IF(K6>0,1,IF(K6<0,0,-1)) -> 1 | AC6: =IF(L6>0,1,IF(L6<0,0,-1)) -> 0 | AD6: =IF(M6>0,1,IF(M6<0,0,-1)) -> 1 | AE6: All Regions | AF6: All Income Levels | AG6: 1 | AH6: 0 | AI6: 0 | AJ6: 1 | AK6: All Countries | AL6: =IF(OR(B6="other",B6="international",B6="Transfers",B6="expenditure"),1,0) -> 0 | AM6: =IF(AND(INDIRECT(AN6)='Sample Select backend'!$C$2,INDIRECT(AO6)=1,INDIRECT(AP6)='Sample Select backend'!$F$2,INDIRECT(AQ6)=1,INDIRECT(AR6)='Sample Select backend'!$M$2),1,0) -> 0 | AN6: =_xlfn.CONCAT('Sample Select backend'!$C$4,ROW(AN6)) -> AE6 | AO6: =_xlfn.CONCAT('Sample Select backend'!$J$2,ROW(AO6)) -> AJ6 | AP6: =_xlfn.CONCAT('Sample Select backend'!$F$4,ROW(AP6)) -> AF6 | AQ6: =_xlfn.CONCAT('Sample Select backend'!$I$10,ROW(AQ6)) -> R6 | AR6: =_xlfn.CONCAT('Sample Select backend'!$M$4,ROW(AR6)) -> AK6 | AS6: =A6 -> Afghanistan | AT6: =IF(ISNUMBER(C6),C6,IF(OR(C6="general",C6="23;general"),"General",IF(OR(C6="exemption",C6="other (exemption)"),"Tax exemption/waiver/suspension","Other"))) -> 30 | AU6: =IF(A6<>A5,1,0) -> 0 | AV6: 1
A7: Afghanistan | B7: 6 | C7: 25 | D7: One-off transfer of Lk40,000 to employees of small businesses affected by the pandemic, employees of large businesses laid off due to the pandemic, and employees in the tourism sector. | E7: 1 | F7: 1 | G7: 1 | H7: -1 | I7: 2 | J7: 1 | K7: 1 | L7: -2 | M7: 1 | N7: AFG | O7: South Asia | P7: IDA | Q7: Low Income | R7: 0 | S7: -1.89 | T7: -2.16 | U7: 8.21 | V7: =IF(E7>0,1,IF(E7<0,0,-1)) -> 1 | W7: =IF(F7>0,1,IF(F7<0,0,-1)) -> 1 | X7: =IF(G7>0,1,IF(G7<0,0,-1)) -> 1 | Y7: =IF(H7>0,1,IF(H7<0,0,-1)) -> 0 | Z7: =IF(I7>0,1,IF(I7<0,0,-1)) -> 1 | AA7: =IF(J7>0,1,IF(J7<0,0,-1)) -> 1 | AB7: =IF(K7>0,1,IF(K7<0,0,-1)) -> 1 | AC7: =IF(L7>0,1,IF(L7<0,0,-1)) -> 0 | AD7: =IF(M7>0,1,IF(M7<0,0,-1)) -> 1 | AE7: All Regions | AF7: All Income Levels | AG7: 1 | AH7: 0 | AI7: 0 | AJ7: 1 | AK7: All Countries | AL7: =IF(OR(B7="other",B7="international",B7="Transfers",B7="expenditure"),1,0) -> 0 | AM7: =IF(AND(INDIRECT(AN7)='Sample Select backend'!$C$2,INDIRECT(AO7)=1,INDIRECT(AP7)='Sample Select backend'!$F$2,INDIRECT(AQ7)=1,INDIRECT(AR7)='Sample Select backend'!$M$2),1,0) -> 0 | AN7: =_xlfn.CONCAT('Sample Select backend'!$C$4,ROW(AN7)) -> AE7 | AO7: =_xlfn.CONCAT('Sample Select backend'!$J$2,ROW(AO7)) -> AJ7 | AP7: =_xlfn.CONCAT('Sample Select backend'!$F$4,ROW(AP7)) -> AF7 | AQ7: =_xlfn.CONCAT('Sample Select backend'!$I$10,ROW(AQ7)) -> R7 | AR7: =_xlfn.CONCAT('Sample Select backend'!$M$4,ROW(AR7)) -> AK7 | AS7: =A7 -> Afghanistan | AT7: =IF(ISNUMBER(C7),C7,IF(OR(C7="general",C7="23;general"),"General",IF(OR(C7="exemption",C7="other (exemption)"),"Tax exemption/waiver/suspension","Other"))) -> 25 | AU7: =IF(A7<>A6,1,0) -> 0 | AV7: 1
A8: Afghanistan | B8: 1 | C8: 5 | D8: Deadline extension for filing tax returns by two months, until May 20 for business taxpayers. | E8: -2 | F8: 1 | G8: 2 | H8: 1 | I8: 1 | J8: 1 | K8: 1 | L8: 1 | M8: 1 | N8: AFG | O8: South Asia | P8: IDA | Q8: Low Income | R8: 0 | S8: -1.89 | T8: -2.16 | U8: 8.21 | V8: =IF(E8>0,1,IF(E8<0,0,-1)) -> 0 | W8: =IF(F8>0,1,IF(F8<0,0,-1)) -> 1 | X8: =IF(G8>0,1,IF(G8<0,0,-1)) -> 1 | Y8: =IF(H8>0,1,IF(H8<0,0,-1)) -> 1 | Z8: =IF(I8>0,1,IF(I8<0,0,-1)) -> 1 | AA8: =IF(J8>0,1,IF(J8<0,0,-1)) -> 1 | AB8: =IF(K8>0,1,IF(K8<0,0,-1)) -> 1 | AC8: =IF(L8>0,1,IF(L8<0,0,-1)) -> 1 | AD8: =IF(M8>0,1,IF(M8<0,0,-1)) -> 1 | AE8: All Regions | AF8: All Income Levels | AG8: 1 | AH8: 0 | AI8: 0 | AJ8: 1 | AK8: All Countries | AL8: =IF(OR(B8="other",B8="international",B8="Transfers",B8="expenditure"),1,0) -> 0 | AM8: =IF(AND(INDIRECT(AN8)='Sample Select backend'!$C$2,INDIRECT(AO8)=1,INDIRECT(AP8)='Sample Select backend'!$F$2,INDIRECT(AQ8)=1,INDIRECT(AR8)='Sample Select backend'!$M$2),1,0) -> 0 | AN8: =_xlfn.CONCAT('Sample Select backend'!$C$4,ROW(AN8)) -> AE8 | AO8: =_xlfn.CONCAT('Sample Select backend'!$J$2,ROW(AO8)) -> AJ8 | AP8: =_xlfn.CONCAT('Sample Select backend'!$F$4,ROW(AP8)) -> AF8 | AQ8: =_xlfn.CONCAT('Sample Select backend'!$I$10,ROW(AQ8)) -> R8 | AR8: =_xlfn.CONCAT('Sample Select backend'!$M$4,ROW(AR8)) -> AK8 | AS8: =A8 -> Afghanistan | AT8: =IF(ISNUMBER(C8),C8,IF(OR(C8="general",C8="23;general"),"General",IF(OR(C8="exemption",C8="other (exemption)"),"Tax exemption/waiver/suspension","Other"))) -> 5 | AU8: =IF(A8<>A7,1,0) -> 0 | AV8: 1
A9: Afghanistan | B9: 5 | C9: general | D9: The Government has allocated USD 15 million for immediate health emergency response. | E9: 1 | F9: -2 | G9: -2 | H9: -1 | I9: -1 | J9: 1 | K9: 1 | L9: 1 | M9: 1 | N9: AFG | O9: South Asia | P9: IDA | Q9: Low Income | R9: 0 | S9: -1.89 | T9: -2.16 | U9: 8.21 | V9: =IF(E9>0,1,IF(E9<0,0,-1)) -> 1 | W9: =IF(F9>0,1,IF(F9<0,0,-1)) -> 0 | X9: =IF(G9>0,1,IF(G9<0,0,-1)) -> 0 | Y9: =IF(H9>0,1,IF(H9<0,0,-1)) -> 0 | Z9: =IF(I9>0,1,IF(I9<0,0,-1)) -> 0 | AA9: =IF(J9>0,1,IF(J9<0,0,-1)) -> 1 | AB9: =IF(K9>0,1,IF(K9<0,0,-1)) -> 1 | AC9: =IF(L9>0,1,IF(L9<0,0,-1)) -> 1 | AD9: =IF(M9>0,1,IF(M9<0,0,-1)) -> 1 | AE9: All Regions | AF9: All Income Levels | AG9: 1 | AH9: 0 | AI9: 0 | AJ9: 1 | AK9: All Countries | AL9: =IF(OR(B9="other",B9="international",B9="Transfers",B9="expenditure"),1,0) -> 0 | AM9: =IF(AND(INDIRECT(AN9)='Sample Select backend'!$C$2,INDIRECT(AO9)=1,INDIRECT(AP9)='Sample Select backend'!$F$2,INDIRECT(AQ9)=1,INDIRECT(AR9)='Sample Select backend'!$M$2),1,0) -> 0 | AN9: =_xlfn.CONCAT('Sample Select backend'!$C$4,ROW(AN9)) -> AE9 | AO9: =_xlfn.CONCAT('Sample Select backend'!$J$2,ROW(AO9)) -> AJ9 | AP9: =_xlfn.CONCAT('Sample Select backend'!$F$4,ROW(AP9)) -> AF9 | AQ9: =_xlfn.CONCAT('Sample Select backend'!$I$10,ROW(AQ9)) -> R9 | AR9: =_xlfn.CONCAT('Sample Select backend'!$M$4,ROW(AR9)) -> AK9 | AS9: =A9 -> Afghanistan | AT9: =IF(ISNUMBER(C9),C9,IF(OR(C9="general",C9="23;general"),"General",IF(OR(C9="exemption",C9="other (exemption)"),"Tax exemption/waiver/suspension","Other"))) -> General | AU9: =IF(A9<>A8,1,0) -> 0 | AV9: 1
A10: Afghanistan | B10: 6 | C10: 28 | D10: Free bread to about 2.5 million needy and poor people in Kabul. | E10: 1 | F10: 1 | G10: 2 | H10: -1 | I10: 1 | J10: 1 | K10: 1 | L10: 1 | N10: AFG | O10: South Asia | P10: IDA | Q10: Low Income | R10: 0 | S10: -1.89 | T10: -2.16 | U10: 8.21 | V10: =IF(E10>0,1,IF(E10<0,0,-1)) -> 1 | W10: =IF(F10>0,1,IF(F10<0,0,-1)) -> 1 | X10: =IF(G10>0,1,IF(G10<0,0,-1)) -> 1 | Y10: =IF(H10>0,1,IF(H10<0,0,-1)) -> 0 | Z10: =IF(I10>0,1,IF(I10<0,0,-1)) -> 1 | AA10: =IF(J10>0,1,IF(J10<0,0,-1)) -> 1 | AB10: =IF(K10>0,1,IF(K10<0,0,-1)) -> 1 | AC10: =IF(L10>0,1,IF(L10<0,0,-1)) -> 1 | AD10: =IF(M10>0,1,IF(M10<0,0,-1)) -> -1 | AE10: All Regions | AF10: All Income Levels | AG10: 1 | AH10: 0 | AI10: 0 | AJ10: 1 | AK10: All Countries | AL10: =IF(OR(B10="other",B10="international",B10="Transfers",B10="expenditure"),1,0) -> 0 | AM10: =IF(AND(INDIRECT(AN10)='Sample Select backend'!$C$2,INDIRECT(AO10)=1,INDIRECT(AP10)='Sample Select backend'!$F$2,INDIRECT(AQ10)=1,INDIRECT(AR10)='Sample Select backend'!$M$2),1,0) -> 0 | AN10: =_xlfn.CONCAT('Sample Select backend'!$C$4,ROW(AN10)) -> AE10 | AO10: =_xlfn.CONCAT('Sample Select backend'!$J$2,ROW(AO10)) -> AJ10 | AP10: =_xlfn.CONCAT('Sample Select backend'!$F$4,ROW(AP10)) -> AF10 | AQ10: =_xlfn.CONCAT('Sample Select backend'!$I$10,ROW(AQ10)) -> R10 | AR10: =_xlfn.CONCAT('Sample Select backend'!$M$4,ROW(AR10)) -> AK10 | AS10: =A10 -> Afghanistan | AT10: =IF(ISNUMBER(C10),C10,IF(OR(C10="general",C10="23;general"),"General",IF(OR(C10="exemption",C10="other (exemption)"),"Tax exemption/waiver/suspension","Other"))) -> 28 | AU10: =IF(A10<>A9,1,0) -> 0 | AV10: 1
A11: Afghanistan | B11: 6 | C11: 28 | D11: In May, government waived electricity bills of less than AFN 1,000 (USD 13) for family residences in Kabul for two months and paid utility bills of the past two months for 50 percent of households in Kabul. This decision benefited more than 1.5 million Kabul residents. | O11: South Asia | P11: IDA | Q11: Low Income | R11: 0 | S11: -1.89 | T11: -2.16 | U11: 8.21 | V11: -1 | W11: -1 | X11: -1 | Y11: -1 | Z11: -1 | AA11: -1 | AB11: -1 | AC11: -1 | AD11: -1 | AE11: All Regions | AF11: All Income Levels | AG11: 1 | AH11: 0 | AI11: 0 | AJ11: 1 | AK11: All Countries | AL11: =IF(OR(B11="other",B11="international",B11="Transfers",B11="expenditure"),1,0) -> 0 | AM11: =IF(AND(INDIRECT(AN11)='Sample Select backend'!$C$2,INDIRECT(AO11)=1,INDIRECT(AP11)='Sample Select backend'!$F$2,INDIRECT(AQ11)=1,INDIRECT(AR11)='Sample Select backend'!$M$2),1,0) -> 0 | AN11: =_xlfn.CONCAT('Sample Select backend'!$C$4,ROW(AN11)) -> AE11 | AO11: =_xlfn.CONCAT('Sample Select backend'!$J$2,ROW(AO11)) -> AJ11 | AP11: =_xlfn.CONCAT('Sample Select backend'!$F$4,ROW(AP11)) -> AF11 | AQ11: =_xlfn.CONCAT('Sample Select backend'!$I$10,ROW(AQ11)) -> R11 | AR11: =_xlfn.CONCAT('Sample Select backend'!$M$4,ROW(AR11)) -> AK11 | AS11: =A11 -> Afghanistan | AT11: =IF(ISNUMBER(C11),C11,IF(OR(C11="general",C11="23;general"),"General",IF(OR(C11="exemption",C11="other (exemption)"),"Tax exemption/waiver/suspension","Other"))) -> 28 | AU11: =IF(A11<>A10,1,0) -> 0 | AV11: 0
A12: Afghanistan | B12: 2 | C12: 5 | D12: To ease tax compliance, the government extended filing deadlines for the first and second quarter of the fiscal year by 45 days. | O12: South Asia | P12: IDA | Q12: Low Income | R12: 0 | S12: -1.89 | T12: -2.16 | U12: 8.21 | V12: -1 | W12: -1 | X12: -1 | Y12: -1 | Z12: -1 | AA12: -1 | AB12: -1 | AC12: -1 | AD12: -1 | AE12: All Regions | AF12: All Income Levels | AG12: 1 | AH12: 0 | AI12: 0 | AJ12: 1 | AK12: All Countries | AL12: =IF(OR(B12="other",B12="international",B12="Transfers",B12="expenditure"),1,0) -> 0 | AM12: =IF(AND(INDIRECT(AN12)='Sample Select backend'!$C$2,INDIRECT(AO12)=1,INDIRECT(AP12)='Sample Select backend'!$F$2,INDIRECT(AQ12)=1,INDIRECT(AR12)='Sample Select backend'!$M$2),1,0) -> 0 | AN12: =_xlfn.CONCAT('Sample Select backend'!$C$4,ROW(AN12)) -> AE12 | AO12: =_xlfn.CONCAT('Sample Select backend'!$J$2,ROW(AO12)) -> AJ12 | AP12: =_xlfn.CONCAT('Sample Select backend'!$F$4,ROW(AP12)) -> AF12 | AQ12: =_xlfn.CONCAT('Sample Select backend'!$I$10,ROW(AQ12)) -> R12 | AR12: =_xlfn.CONCAT('Sample Select backend'!$M$4,ROW(AR12)) -> AK12 | AS12: =A12 -> Afghanistan | AT12: =IF(ISNUMBER(C12),C12,IF(OR(C12="general",C12="23;general"),"General",IF(OR(C12="exemption",C12="other (exemption)"),"Tax exemption/waiver/suspension","Other"))) -> 5 | AU12: =IF(A12<>A11,1,0) -> 0 | AV12: 0
A13: Afghanistan | B13: 5 | C13: general | D13: Planned health expenditure package amounting to AFN 6.2 billion, including for building hospitals. | O13: South Asia | P13: IDA | Q13: Low Income | R13: 0 | S13: -1.89 | T13: -2.16 | U13: 8.21 | V13: -1 | W13: -1 | X13: -1 | Y13: -1 | Z13: -1 | AA13: -1 | AB13: -1 | AC13: -1 | AD13: -1 | AE13: All Regions | AF13: All Income Levels | AG13: 1 | AH13: 0 | AI13: 0 | AJ13: 1 | AK13: All Countries | AL13: =IF(OR(B13="other",B13="international",B13="Transfers",B13="expenditure"),1,0) -> 0 | AM13: =IF(AND(INDIRECT(AN13)='Sample Select backend'!$C$2,INDIRECT(AO13)=1,INDIRECT(AP13)='Sample Select backend'!$F$2,INDIRECT(AQ13)=1,INDIRECT(AR13)='Sample Select backend'!$M$2),1,0) -> 0 | AN13: =_xlfn.CONCAT('Sample Select backend'!$C$4,ROW(AN13)) -> AE13 | AO13: =_xlfn.CONCAT('Sample Select backend'!$J$2,ROW(AO13)) -> AJ13 | AP13: =_xlfn.CONCAT('Sample Select backend'!$F$4,ROW(AP13)) -> AF13 | AQ13: =_xlfn.CONCAT('Sample Select backend'!$I$10,ROW(AQ13)) -> R13 | AR13: =_xlfn.CONCAT('Sample Select backend'!$M$4,ROW(AR13)) -> AK13 | AS13: =A13 -> Afghanistan | AT13: =IF(ISNUMBER(C13),C13,IF(OR(C13="general",C13="23;general"),"General",IF(OR(C13="exemption",C13="other (exemption)"),"Tax exemption/waiver/suspension","Other"))) -> General | AU13: =IF(A13<>A12,1,0) -> 0 | AV13: 0
A14: Afghanistan | B14: 6 | D14: Planned expenditure of AF 1.7 billion on wheat purchase program | O14: South Asia | P14: IDA | Q14: Low Income | R14: 0 | S14: -1.89 | T14: -2.16 | U14: 8.21 | V14: -1 | W14: -1 | X14: -1 | Y14: -1 | Z14: -1 | AA14: -1 | AB14: -1 | AC14: -1 | AD14: -1 | AE14: All Regions | AF14: All Income Levels | AG14: 1 | AH14: 0 | AI14: 0 | AJ14: 1 | AK14: All Countries | AL14: =IF(OR(B14="other",B14="international",B14="Transfers",B14="expenditure"),1,0) -> 0 | AM14: =IF(AND(INDIRECT(AN14)='Sample Select backend'!$C$2,INDIRECT(AO14)=1,INDIRECT(AP14)='Sample Select backend'!$F$2,INDIRECT(AQ14)=1,INDIRECT(AR14)='Sample Select backend'!$M$2),1,0) -> 0 | AN14: =_xlfn.CONCAT('Sample Select backend'!$C$4,ROW(AN14)) -> AE14 | AO14: =_xlfn.CONCAT('Sample Select backend'!$J$2,ROW(AO14)) -> AJ14 | AP14: =_xlfn.CONCAT('Sample Select backend'!$F$4,ROW(AP14)) -> AF14 | AQ14: =_xlfn.CONCAT('Sample Select backend'!$I$10,ROW(AQ14)) -> R14 | AR14: =_xlfn.CONCAT('Sample Select backend'!$M$4,ROW(AR14)) -> AK14 | AS14: =A14 -> Afghanistan | AT14: =IF(ISNUMBER(C14),C14,IF(OR(C14="general",C14="23;general"),"General",IF(OR(C14="exemption",C14="other (exemption)"),"Tax exemption/waiver/suspension","Other"))) -> Other | AU14: =IF(A14<>A13,1,0) -> 0 | AV14: 0
A15: Afghanistan | B15: 6 | D15: Planned transfers of AFN 2.3 billion to provinces to finance COVID-19 response | O15: South Asia | P15: IDA | Q15: Low Income | R15: 0 | S15: -1.89 | T15: -2.16 | U15: 8.21 | V15: -1 | W15: -1 | X15: -1 | Y15: -1 | Z15: -1 | AA15: -1 | AB15: -1 | AC15: -1 | AD15: -1 | AE15: All Regions | AF15: All Income Levels | AG15: 1 | AH15: 0 | AI15: 0 | AJ15: 1 | AK15: All Countries | AL15: =IF(OR(B15="other",B15="international",B15="Transfers",B15="expenditure"),1,0) -> 0 | AM15: =IF(AND(INDIRECT(AN15)='Sample Select backend'!$C$2,INDIRECT(AO15)=1,INDIRECT(AP15)='Sample Select backend'!$F$2,INDIRECT(AQ15)=1,INDIRECT(AR15)='Sample Select backend'!$M$2),1,0) -> 0 | AN15: =_xlfn.CONCAT('Sample Select backend'!$C$4,ROW(AN15)) -> AE15 | AO15: =_xlfn.CONCAT('Sample Select backend'!$J$2,ROW(AO15)) -> AJ15 | AP15: =_xlfn.CONCAT('Sample Select backend'!$F$4,ROW(AP15)) -> AF15 | AQ15: =_xlfn.CONCAT('Sample Select backend'!$I$10,ROW(AQ15)) -> R15 | AR15: =_xlfn.CONCAT('Sample Select backend'!$M$4,ROW(AR15)) -> AK15 | AS15: =A15 -> Afghanistan | AT15: =IF(ISNUMBER(C15),C15,IF(OR(C15="general",C15="23;general"),"General",IF(OR(C15="exemption",C15="other (exemption)"),"Tax exemption/waiver/suspension","Other"))) -> Other | AU15: =IF(A15<>A14,1,0) -> 0 | AV15: 0
A16: Afghanistan | B16: 6 | D16: Planned agriculture support package of AFN 5.9 billion | O16: South Asia | P16: IDA | Q16: Low Income | R16: 0 | S16: -1.89 | T16: -2.16 | U16: 8.21 | V16: -1 | W16: -1 | X16: -1 | Y16: -1 | Z16: -1 | AA16: -1 | AB16: -1 | AC16: -1 | AD16: -1 | AE16: All Regions | AF16: All Income Levels | AG16: 1 | AH16: 0 | AI16: 0 | AJ16: 1 | AK16: All Countries | AL16: =IF(OR(B16="other",B16="international",B16="Transfers",B16="expenditure"),1,0) -> 0 | AM16: =IF(AND(INDIRECT(AN16)='Sample Select backend'!$C$2,INDIRECT(AO16)=1,INDIRECT(AP16)='Sample Select backend'!$F$2,INDIRECT(AQ16)=1,INDIRECT(AR16)='Sample Select backend'!$M$2),1,0) -> 0 | AN16: =_xlfn.CONCAT('Sample Select backend'!$C$4,ROW(AN16)) -> AE16 | AO16: =_xlfn.CONCAT('Sample Select backend'!$J$2,ROW(AO16)) -> AJ16 | AP16: =_xlfn.CONCAT('Sample Select backend'!$F$4,ROW(AP16)) -> AF16 | AQ16: =_xlfn.CONCAT('Sample Select backend'!$I$10,ROW(AQ16)) -> R16 | AR16: =_xlfn.CONCAT('Sample Select backend'!$M$4,ROW(AR16)) -> AK16 | AS16: =A16 -> Afghanistan | AT16: =IF(ISNUMBER(C16),C16,IF(OR(C16="general",C16="23;general"),"General",IF(OR(C16="exemption",C16="other (exemption)"),"Tax exemption/waiver/suspension","Other"))) -> Other | AU16: =IF(A16<>A15,1,0) -> 0 | AV16: 0
A17: Afghanistan | B17: 6 | D17: Planned expenditure of AF 1 billion to support short-term jobs | O17: South Asia | P17: IDA | Q17: Low Income | R17: 0 | S17: -1.89 | T17: -2.16 | U17: 8.21 | V17: -1 | W17: -1 | X17: -1 | Y17: -1 | Z17: -1 | AA17: -1 | AB17: -1 | AC17: -1 | AD17: -1 | AE17: All Regions | AF17: All Income Levels | AG17: 1 | AH17: 0 | AI17: 0 | AJ17: 1 | AK17: All Countries | AL17: =IF(OR(B17="other",B17="international",B17="Transfers",B17="expenditure"),1,0) -> 0 | AM17: =IF(AND(INDIRECT(AN17)='Sample Select backend'!$C$2,INDIRECT(AO17)=1,INDIRECT(AP17)='Sample Select backend'!$F$2,INDIRECT(AQ17)=1,INDIRECT(AR17)='Sample Select backend'!$M$2),1,0) -> 0 | AN17: =_xlfn.CONCAT('Sample Select backend'!$C$4,ROW(AN17)) -> AE17 | AO17: =_xlfn.CONCAT('Sample Select backend'!$J$2,ROW(AO17)) -> AJ17 | AP17: =_xlfn.CONCAT('Sample Select backend'!$F$4,ROW(AP17)) -> AF17 | AQ17: =_xlfn.CONCAT('Sample Select backend'!$I$10,ROW(AQ17)) -> R17 | AR17: =_xlfn.CONCAT('Sample Select backend'!$M$4,ROW(AR17)) -> AK17 | AS17: =A17 -> Afghanistan | AT17: =IF(ISNUMBER(C17),C17,IF(OR(C17="general",C17="23;general"),"General",IF(OR(C17="exemption",C17="other (exemption)"),"Tax exemption/waiver/suspension","Other"))) -> Other | AU17: =IF(A17<>A16,1,0) -> 0 | AV17: 0
A18: Albania | B18: 6 | C18: 25/27 | D18: Self-employed families will receive a special benefit equivalent to a state-set monthly salary. | E18: -1 | F18: 1 | G18: -2 | H18: -1 | I18: -2 | J18: -2 | K18: 1 | L18: -2 | M18: 1 | N18: ALB | O18: Europe & Central Asia | P18: IBRD | Q18: Upper Middle Income | R18: 0 | S18: -4.74 | T18: -4.77 | U18: 80.04 | V18: =IF(E18>0,1,IF(E18<0,0,-1)) -> 0 | W18: =IF(F18>0,1,IF(F18<0,0,-1)) -> 1 | X18: =IF(G18>0,1,IF(G18<0,0,-1)) -> 0 | Y18: =IF(H18>0,1,IF(H18<0,0,-1)) -> 0 | Z18: =IF(I18>0,1,IF(I18<0,0,-1)) -> 0 | AA18: =IF(J18>0,1,IF(J18<0,0,-1)) -> 0 | AB18: =IF(K18>0,1,IF(K18<0,0,-1)) -> 1 | AC18: =IF(L18>0,1,IF(L18<0,0,-1)) -> 0 | AD18: =IF(M18>0,1,IF(M18<0,0,-1)) -> 1 | AE18: All Regions | AF18: All Income Levels | AG18: 0 | AH18: 1 | AI18: 0 | AJ18: 1 | AK18: All Countries | AL18: =IF(OR(B18="other",B18="international",B18="Transfers",B18="expenditure"),1,0) -> 0 | AM18: =IF(AND(INDIRECT(AN18)='Sample Select backend'!$C$2,INDIRECT(AO18)=1,INDIRECT(AP18)='Sample Select backend'!$F$2,INDIRECT(AQ18)=1,INDIRECT(AR18)='Sample Select backend'!$M$2),1,0) -> 0 | AN18: =_xlfn.CONCAT('Sample Select backend'!$C$4,ROW(AN18)) -> AE18 | AO18: =_xlfn.CONCAT('Sample Select backend'!$J$2,ROW(AO18)) -> AJ18 | AP18: =_xlfn.CONCAT('Sample Select backend'!$F$4,ROW(AP18)) -> AF18 | AQ18: =_xlfn.CONCAT('Sample Select backend'!$I$10,ROW(AQ18)) -> R18 | AR18: =_xlfn.CONCAT('Sample Select backend'!$M$4,ROW(AR18)) -> AK18 | AS18: =A18 -> Albania | AT18: =IF(ISNUMBER(C18),C18,IF(OR(C18="general",C18="23;general"),"General",IF(OR(C18="exemption",C18="other (exemption)"),"Tax exemption/waiver/suspension","Other"))) -> Other | AU18: =IF(A18<>A17,1,0) -> 1 | AV18: 1
A19: Albania | B19: 1 | C19: other (exemption) | D19: for taxpayers with an annual turnover up to ALL 14 million it is removed | E19: 2 | F19: 2 | G19: -2 | H19: -1 | I19: -2 | J19: 2 | K19: 1 | L19: 2 | M19: 1 | N19: ALB | O19: Europe & Central Asia | P19: IBRD | Q19: Upper Middle Income | R19: 0 | S19: -4.74 | T19: -4.77 | U19: 80.04 | V19: =IF(E19>0,1,IF(E19<0,0,-1)) -> 1 | W19: =IF(F19>0,1,IF(F19<0,0,-1)) -> 1 | X19: =IF(G19>0,1,IF(G19<0,0,-1)) -> 0 | Y19: =IF(H19>0,1,IF(H19<0,0,-1)) -> 0 | Z19: =IF(I19>0,1,IF(I19<0,0,-1)) -> 0 | AA19: =IF(J19>0,1,IF(J19<0,0,-1)) -> 1 | AB19: =IF(K19>0,1,IF(K19<0,0,-1)) -> 1 | AC19: =IF(L19>0,1,IF(L19<0,0,-1)) -> 1 | AD19: =IF(M19>0,1,IF(M19<0,0,-1)) -> 1 | AE19: All Regions | AF19: All Income Levels | AG19: 0 | AH19: 1 | AI19: 0 | AJ19: 1 | AK19: All Countries | AL19: =IF(OR(B19="other",B19="international",B19="Transfers",B19="expenditure"),1,0) -> 0 | AM19: =IF(AND(INDIRECT(AN19)='Sample Select backend'!$C$2,INDIRECT(AO19)=1,INDIRECT(AP19)='Sample Select backend'!$F$2,INDIRECT(AQ19)=1,INDIRECT(AR19)='Sample Select backend'!$M$2),1,0) -> 0 | AN19: =_xlfn.CONCAT('Sample Select backend'!$C$4,ROW(AN19)) -> AE19 | AO19: =_xlfn.CONCAT('Sample Select backend'!$J$2,ROW(AO19)) -> AJ19 | AP19: =_xlfn.CONCAT('Sample Select backend'!$F$4,ROW(AP19)) -> AF19 | AQ19: =_xlfn.CONCAT('Sample Select backend'!$I$10,ROW(AQ19)) -> R19 | AR19: =_xlfn.CONCAT('Sample Select backend'!$M$4,ROW(AR19)) -> AK19 | AS19: =A19 -> Albania | AT19: =IF(ISNUMBER(C19),C19,IF(OR(C19="general",C19="23;general"),"General",IF(OR(C19="exemption",C19="other (exemption)"),"Tax exemption/waiver/suspension","Other"))) -> Tax exemption/waiver/suspension | AU19: =IF(A19<>A18,1,0) -> 0 | AV19: 1
A20: Albania | B20: 5 | C20: general | D20: Additional funding for health sector in the amount of Lk 3.5 billion. | E20: 1 | F20: -2 | G20: -2 | H20: -1 | I20: -1 | J20: 1 | K20: 1 | L20: 1 | M20: 1 | N20: ALB | O20: Europe & Central Asia | P20: IBRD | Q20: Upper Middle Income | R20: 0 | S20: -4.74 | T20: -4.77 | U20: 80.04 | V20: =IF(E20>0,1,IF(E20<0,0,-1)) -> 1 | W20: =IF(F20>0,1,IF(F20<0,0,-1)) -> 0 | X20: =IF(G20>0,1,IF(G20<0,0,-1)) -> 0 | Y20: =IF(H20>0,1,IF(H20<0,0,-1)) -> 0 | Z20: =IF(I20>0,1,IF(I20<0,0,-1)) -> 0 | AA20: =IF(J20>0,1,IF(J20<0,0,-1)) -> 1 | AB20: =IF(K20>0,1,IF(K20<0,0,-1)) -> 1 | AC20: =IF(L20>0,1,IF(L20<0,0,-1)) -> 1 | AD20: =IF(M20>0,1,IF(M20<0,0,-1)) -> 1 | AE20: All Regions | AF20: All Income Levels | AG20: 0 | AH20: 1 | AI20: 0 | AJ20: 1 | AK20: All Countries | AL20: =IF(OR(B20="other",B20="international",B20="Transfers",B20="expenditure"),1,0) -> 0 | AM20: =IF(AND(INDIRECT(AN20)='Sample Select backend'!$C$2,INDIRECT(AO20)=1,INDIRECT(AP20)='Sample Select backend'!$F$2,INDIRECT(AQ20)=1,INDIRECT(AR20)='Sample Select backend'!$M$2),1,0) -> 0 | AN20: =_xlfn.CONCAT('Sample Select backend'!$C$4,ROW(AN20)) -> AE20 | AO20: =_xlfn.CONCAT('Sample Select backend'!$J$2,ROW(AO20)) -> AJ20 | AP20: =_xlfn.CONCAT('Sample Select backend'!$F$4,ROW(AP20)) -> AF20 | AQ20: =_xlfn.CONCAT('Sample Select backend'!$I$10,ROW(AQ20)) -> R20 | AR20: =_xlfn.CONCAT('Sample Select backend'!$M$4,ROW(AR20)) -> AK20 | AS20: =A20 -> Albania | AT20: =IF(ISNUMBER(C20),C20,IF(OR(C20="general",C20="23;general"),"General",IF(OR(C20="exemption",C20="other (exemption)"),"Tax exemption/waiver/suspension","Other"))) -> General | AU20: =IF(A20<>A19,1,0) -> 0 | AV20: 1
A21: Albania | B21: 6 | C21: 27 | D21: Increase in pensions. | E21: 1 | F21: 1 | G21: 1 | H21: -1 | I21: 1 | J21: -2 | K21: 1 | L21: 1 | M21: 1 | N21: ALB | O21: Europe & Central Asia | P21: IBRD | Q21: Upper Middle Income | R21: 0 | S21: -4.74 | T21: -4.77 | U21: 80.04 | V21: =IF(E21>0,1,IF(E21<0,0,-1)) -> 1 | W21: =IF(F21>0,1,IF(F21<0,0,-1)) -> 1 | X21: =IF(G21>0,1,IF(G21<0,0,-1)) -> 1 | Y21: =IF(H21>0,1,IF(H21<0,0,-1)) -> 0 | Z21: =IF(I21>0,1,IF(I21<0,0,-1)) -> 1 | AA21: =IF(J21>0,1,IF(J21<0,0,-1)) -> 0 | AB21: =IF(K21>0,1,IF(K21<0,0,-1)) -> 1 | AC21: =IF(L21>0,1,IF(L21<0,0,-1)) -> 1 | AD21: =IF(M21>0,1,IF(M21<0,0,-1)) -> 1 | AE21: All Regions | AF21: All Income Levels | AG21: 0 | AH21: 1 | AI21: 0 | AJ21: 1 | AK21: All Countries | AL21: =IF(OR(B21="other",B21="international",B21="Transfers",B21="expenditure"),1,0) -> 0 | AM21: =IF(AND(INDIRECT(AN21)='Sample Select backend'!$C$2,INDIRECT(AO21)=1,INDIRECT(AP21)='Sample Select backend'!$F$2,INDIRECT(AQ21)=1,INDIRECT(AR21)='Sample Select backend'!$M$2),1,0) -> 0 | AN21: =_xlfn.CONCAT('Sample Select backend'!$C$4,ROW(AN21)) -> AE21 | AO21: =_xlfn.CONCAT('Sample Select backend'!$J$2,ROW(AO21)) -> AJ21 | AP21: =_xlfn.CONCAT('Sample Select backend'!$F$4,ROW(AP21)) -> AF21 | AQ21: =_xlfn.CONCAT('Sample Select backend'!$I$10,ROW(AQ21)) -> R21 | AR21: =_xlfn.CONCAT('Sample Select backend'!$M$4,ROW(AR21)) -> AK21 | AS21: =A21 -> Albania | AT21: =IF(ISNUMBER(C21),C21,IF(OR(C21="general",C21="23;general"),"General",IF(OR(C21="exemption",C21="other (exemption)"),"Tax exemption/waiver/suspension","Other"))) -> 27 | AU21: =IF(A21<>A20,1,0) -> 0 | AV21: 1
A22: Albania | B22: 1 | C22: 5 | D22: Extension of deadline to submit CIT financial statements to July 31, 2020 | E22: -2 | F22: 2 | G22: 2 | H22: 1 | I22: 2 | J22: 1 | K22: 1 | L22: 1 | M22: 1 | N22: ALB | O22: Europe & Central Asia | P22: IBRD | Q22: Upper Middle Income | R22: 0 | S22: -4.74 | T22: -4.77 | U22: 80.04 | V22: =IF(E22>0,1,IF(E22<0,0,-1)) -> 0 | W22: =IF(F22>0,1,IF(F22<0,0,-1)) -> 1 | X22: =IF(G22>0,1,IF(G22<0,0,-1)) -> 1 | Y22: =IF(H22>0,1,IF(H22<0,0,-1)) -> 1 | Z22: =IF(I22>0,1,IF(I22<0,0,-1)) -> 1 | AA22: =IF(J22>0,1,IF(J22<0,0,-1)) -> 1 | AB22: =IF(K22>0,1,IF(K22<0,0,-1)) -> 1 | AC22: =IF(L22>0,1,IF(L22<0,0,-1)) -> 1 | AD22: =IF(M22>0,1,IF(M22<0,0,-1)) -> 1 | AE22: All Regions | AF22: All Income Levels | AG22: 0 | AH22: 1 | AI22: 0 | AJ22: 1 | AK22: All Countries | AL22: =IF(OR(B22="other",B22="international",B22="Transfers",B22="expenditure"),1,0) -> 0 | AM22: =IF(AND(INDIRECT(AN22)='Sample Select backend'!$C$2,INDIRECT(AO22)=1,INDIRECT(AP22)='Sample Select backend'!$F$2,INDIRECT(AQ22)=1,INDIRECT(AR22)='Sample Select backend'!$M$2),1,0) -> 0 | AN22: =_xlfn.CONCAT('Sample Select backend'!$C$4,ROW(AN22)) -> AE22 | AO22: =_xlfn.CONCAT('Sample Select backend'!$J$2,ROW(AO22)) -> AJ22 | AP22: =_xlfn.CONCAT('Sample Select backend'!$F$4,ROW(AP22)) -> AF22 | AQ22: =_xlfn.CONCAT('Sample Select backend'!$I$10,ROW(AQ22)) -> R22 | AR22: =_xlfn.CONCAT('Sample Select backend'!$M$4,ROW(AR22)) -> AK22 | AS22: =A22 -> Albania | AT22: =IF(ISNUMBER(C22),C22,IF(OR(C22="general",C22="23;general"),"General",IF(OR(C22="exemption",C22="other (exemption)"),"Tax exemption/waiver/suspension","Other"))) -> 5 | AU22: =IF(A22<>A21,1,0) -> 0 | AV22: 1
A23: Albania | B23: 6 | C23: 26 | D23: Unemployment benefits will be doubled. | E23: 1 | F23: 1 | G23: 2 | H23: -1 | I23: -2 | J23: -2 | K23: 1 | L23: 1 | M23: 1 | N23: ALB | O23: Europe & Central Asia | P23: IBRD | Q23: Upper Middle Income | R23: 0 | S23: -4.74 | T23: -4.77 | U23: 80.04 | V23: =IF(E23>0,1,IF(E23<0,0,-1)) -> 1 | W23: =IF(F23>0,1,IF(F23<0,0,-1)) -> 1 | X23: =IF(G23>0,1,IF(G23<0,0,-1)) -> 1 | Y23: =IF(H23>0,1,IF(H23<0,0,-1)) -> 0 | Z23: =IF(I23>0,1,IF(I23<0,0,-1)) -> 0 | AA23: =IF(J23>0,1,IF(J23<0,0,-1)) -> 0 | AB23: =IF(K23>0,1,IF(K23<0,0,-1)) -> 1 | AC23: =IF(L23>0,1,IF(L23<0,0,-1)) -> 1 | AD23: =IF(M23>0,1,IF(M23<0,0,-1)) -> 1 | AE23: All Regions | AF23: All Income Levels | AG23: 0 | AH23: 1 | AI23: 0 | AJ23: 1 | AK23: All Countries | AL23: =IF(OR(B23="other",B23="international",B23="Transfers",B23="expenditure"),1,0) -> 0 | AM23: =IF(AND(INDIRECT(AN23)='Sample Select backend'!$C$2,INDIRECT(AO23)=1,INDIRECT(AP23)='Sample Select backend'!$F$2,INDIRECT(AQ23)=1,INDIRECT(AR23)='Sample Select backend'!$M$2),1,0) -> 0 | AN23: =_xlfn.CONCAT('Sample Select backend'!$C$4,ROW(AN23)) -> AE23 | AO23: =_xlfn.CONCAT('Sample Select backend'!$J$2,ROW(AO23)) -> AJ23 | AP23: =_xlfn.CONCAT('Sample Select backend'!$F$4,ROW(AP23)) -> AF23 | AQ23: =_xlfn.CONCAT('Sample Select backend'!$I$10,ROW(AQ23)) -> R23 | AR23: =_xlfn.CONCAT('Sample Select backend'!$M$4,ROW(AR23)) -> AK23 | AS23: =A23 -> Albania | AT23: =IF(ISNUMBER(C23),C23,IF(OR(C23="general",C23="23;general"),"General",IF(OR(C23="exemption",C23="other (exemption)"),"Tax exemption/waiver/suspension","Other"))) -> 26 | AU23: =IF(A23<>A22,1,0) -> 0 | AV23: 1
A24: Albania | B24: 1 | C24: 6 | D24: for taxpayers engaged in tourism, inward processing regime and call-centers it is postponed to April-December 2021 | E24: 2 | F24: 2 | G24: 2 | H24: 1 | I24: 2 | J24: 2 | K24: 1 | L24: 1 | M24: 1 | N24: ALB | O24: Europe & Central Asia | P24: IBRD | Q24: Upper Middle Income | R24: 0 | S24: -4.74 | T24: -4.77 | U24: 80.04 | V24: =IF(E24>0,1,IF(E24<0,0,-1)) -> 1 | W24: =IF(F24>0,1,IF(F24<0,0,-1)) -> 1 | X24: =IF(G24>0,1,IF(G24<0,0,-1)) -> 1 | Y24: =IF(H24>0,1,IF(H24<0,0,-1)) -> 1 | Z24: =IF(I24>0,1,IF(I24<0,0,-1)) -> 1 | AA24: =IF(J24>0,1,IF(J24<0,0,-1)) -> 1 | AB24: =IF(K24>0,1,IF(K24<0,0,-1)) -> 1 | AC24: =IF(L24>0,1,IF(L24<0,0,-1)) -> 1 | AD24: =IF(M24>0,1,IF(M24<0,0,-1)) -> 1 | AE24: All Regions | AF24: All Income Levels | AG24: 0 | AH24: 1 | AI24: 0 | AJ24: 1 | AK24: All Countries | AL24: =IF(OR(B24="other",B24="international",B24="Transfers",B24="expenditure"),1,0) -> 0 | AM24: =IF(AND(INDIRECT(AN24)='Sample Select backend'!$C$2,INDIRECT(AO24)=1,INDIRECT(AP24)='Sample Select backend'!$F$2,INDIRECT(AQ24)=1,INDIRECT(AR24)='Sample Select backend'!$M$2),1,0) -> 0 | AN24: =_xlfn.CONCAT('Sample Select backend'!$C$4,ROW(AN24)) -> AE24 | AO24: =_xlfn.CONCAT('Sample Select backend'!$J$2,ROW(AO24)) -> AJ24 | AP24: =_xlfn.CONCAT('Sample Select backend'!$F$4,ROW(AP24)) -> AF24 | AQ24: =_xlfn.CONCAT('Sample Select backend'!$I$10,ROW(AQ24)) -> R24 | AR24: =_xlfn.CONCAT('Sample Select backend'!$M$4,ROW(AR24)) -> AK24 | AS24: =A24 -> Albania | AT24: =IF(ISNUMBER(C24),C24,IF(OR(C24="general",C24="23;general"),"General",IF(OR(C24="exemption",C24="other (exemption)"),"Tax exemption/waiver/suspension","Other"))) -> 6 | AU24: =IF(A24<>A23,1,0) -> 0 | AV24: 1
A25: Albania | B25: 1 | C25: 6 | D25: for taxpayers with a turnover of more than that, it is postponed to April-September 2021 | E25: -2 | F25: 2 | G25: 2 | H25: 1 | I25: 2 | J25: 2 | K25: 1 | L25: 1 | M25: 1 | N25: ALB | O25: Europe & Central Asia | P25: IBRD | Q25: Upper Middle Income | R25: 0 | S25: -4.74 | T25: -4.77 | U25: 80.04 | V25: =IF(E25>0,1,IF(E25<0,0,-1)) -> 0 | W25: =IF(F25>0,1,IF(F25<0,0,-1)) -> 1 | X25: =IF(G25>0,1,IF(G25<0,0,-1)) -> 1 | Y25: =IF(H25>0,1,IF(H25<0,0,-1)) -> 1 | Z25: =IF(I25>0,1,IF(I25<0,0,-1)) -> 1 | AA25: =IF(J25>0,1,IF(J25<0,0,-1)) -> 1 | AB25: =IF(K25>0,1,IF(K25<0,0,-1)) -> 1 | AC25: =IF(L25>0,1,IF(L25<0,0,-1)) -> 1 | AD25: =IF(M25>0,1,IF(M25<0,0,-1)) -> 1 | AE25: All Regions | AF25: All Income Levels | AG25: 0 | AH25: 1 | AI25: 0 | AJ25: 1 | AK25: All Countries | AL25: =IF(OR(B25="other",B25="international",B25="Transfers",B25="expenditure"),1,0) -> 0 | AM25: =IF(AND(INDIRECT(AN25)='Sample Select backend'!$C$2,INDIRECT(AO25)=1,INDIRECT(AP25)='Sample Select backend'!$F$2,INDIRECT(AQ25)=1,INDIRECT(AR25)='Sample Select backend'!$M$2),1,0) -> 0 | AN25: =_xlfn.CONCAT('Sample Select backend'!$C$4,ROW(AN25)) -> AE25 | AO25: =_xlfn.CONCAT('Sample Select backend'!$J$2,ROW(AO25)) -> AJ25 | AP25: =_xlfn.CONCAT('Sample Select backend'!$F$4,ROW(AP25)) -> AF25 | AQ25: =_xlfn.CONCAT('Sample Select backend'!$I$10,ROW(AQ25)) -> R25 | AR25: =_xlfn.CONCAT('Sample Select backend'!$M$4,ROW(AR25)) -> AK25 | AS25: =A25 -> Albania | AT25: =IF(ISNUMBER(C25),C25,IF(OR(C25="general",C25="23;general"),"General",IF(OR(C25="exemption",C25="other (exemption)"),"Tax exemption/waiver/suspension","Other"))) -> 6 | AU25: =IF(A25<>A24,1,0) -> 0 | AV25: 1
A26: Albania | B26: 6 | C26: 28 | D26: Postponement for the property/premises/house rent payments for two months (April and May) for individuals/business (up to 14 million ALL turnover)/students. | E26: 2 | F26: 1 | G26: 2 | H26: 1 | I26: 2 | J26: 1 | K26: 1 | L26: 1 | M26: 1 | N26: ALB | O26: Europe & Central Asia | P26: IBRD | Q26: Upper Middle Income | R26: 0 | S26: -4.74 | T26: -4.77 | U26: 80.04 | V26: =IF(E26>0,1,IF(E26<0,0,-1)) -> 1 | W26: =IF(F26>0,1,IF(F26<0,0,-1)) -> 1 | X26: =IF(G26>0,1,IF(G26<0,0,-1)) -> 1 | Y26: =IF(H26>0,1,IF(H26<0,0,-1)) -> 1 | Z26: =IF(I26>0,1,IF(I26<0,0,-1)) -> 1 | AA26: =IF(J26>0,1,IF(J26<0,0,-1)) -> 1 | AB26: =IF(K26>0,1,IF(K26<0,0,-1)) -> 1 | AC26: =IF(L26>0,1,IF(L26<0,0,-1)) -> 1 | AD26: =IF(M26>0,1,IF(M26<0,0,-1)) -> 1 | AE26: All Regions | AF26: All Income Levels | AG26: 0 | AH26: 1 | AI26: 0 | AJ26: 1 | AK26: All Countries | AL26: =IF(OR(B26="other",B26="international",B26="Transfers",B26="expenditure"),1,0) -> 0 | AM26: =IF(AND(INDIRECT(AN26)='Sample Select backend'!$C$2,INDIRECT(AO26)=1,INDIRECT(AP26)='Sample Select backend'!$F$2,INDIRECT(AQ26)=1,INDIRECT(AR26)='Sample Select backend'!$M$2),1,0) -> 0 | AN26: =_xlfn.CONCAT('Sample Select backend'!$C$4,ROW(AN26)) -> AE26 | AO26: =_xlfn.CONCAT('Sample Select backend'!$J$2,ROW(AO26)) -> AJ26 | AP26: =_xlfn.CONCAT('Sample Select backend'!$F$4,ROW(AP26)) -> AF26 | AQ26: =_xlfn.CONCAT('Sample Select backend'!$I$10,ROW(AQ26)) -> R26 | AR26: =_xlfn.CONCAT('Sample Select backend'!$M$4,ROW(AR26)) -> AK26 | AS26: =A26 -> Albania | AT26: =IF(ISNUMBER(C26),C26,IF(OR(C26="general",C26="23;general"),"General",IF(OR(C26="exemption",C26="other (exemption)"),"Tax exemption/waiver/suspension","Other"))) -> 28 | AU26: =IF(A26<>A25,1,0) -> 0 | AV26: 1
A27: Albania | B27: 1 | C27: 6 | D27: Deferral of profit tax installment payments for small companies (announced). | E27: 2 | F27: 2 | G27: 2 | H27: 1 | I27: 2 | J27: 1 | K27: 1 | L27: 1 | M27: 1 | N27: ALB | O27: Europe & Central Asia | P27: IBRD | Q27: Upper Middle Income | R27: 0 | S27: -4.74 | T27: -4.77 | U27: 80.04 | V27: =IF(E27>0,1,IF(E27<0,0,-1)) -> 1 | W27: =IF(F27>0,1,IF(F27<0,0,-1)) -> 1 | X27: =IF(G27>0,1,IF(G27<0,0,-1)) -> 1 | Y27: =IF(H27>0,1,IF(H27<0,0,-1)) -> 1 | Z27: =IF(I27>0,1,IF(I27<0,0,-1)) -> 1 | AA27: =IF(J27>0,1,IF(J27<0,0,-1)) -> 1 | AB27: =IF(K27>0,1,IF(K27<0,0,-1)) -> 1 | AC27: =IF(L27>0,1,IF(L27<0,0,-1)) -> 1 | AD27: =IF(M27>0,1,IF(M27<0,0,-1)) -> 1 | AE27: All Regions | AF27: All Income Levels | AG27: 0 | AH27: 1 | AI27: 0 | AJ27: 1 | AK27: All Countries | AL27: =IF(OR(B27="other",B27="international",B27="Transfers",B27="expenditure"),1,0) -> 0 | AM27: =IF(AND(INDIRECT(AN27)='Sample Select backend'!$C$2,INDIRECT(AO27)=1,INDIRECT(AP27)='Sample Select backend'!$F$2,INDIRECT(AQ27)=1,INDIRECT(AR27)='Sample Select backend'!$M$2),1,0) -> 0 | AN27: =_xlfn.CONCAT('Sample Select backend'!$C$4,ROW(AN27)) -> AE27 | AO27: =_xlfn.CONCAT('Sample Select backend'!$J$2,ROW(AO27)) -> AJ27 | AP27: =_xlfn.CONCAT('Sample Select backend'!$F$4,ROW(AP27)) -> AF27 | AQ27: =_xlfn.CONCAT('Sample Select backend'!$I$10,ROW(AQ27)) -> R27 | AR27: =_xlfn.CONCAT('Sample Select backend'!$M$4,ROW(AR27)) -> AK27 | AS27: =A27 -> Albania | AT27: =IF(ISNUMBER(C27),C27,IF(OR(C27="general",C27="23;general"),"General",IF(OR(C27="exemption",C27="other (exemption)"),"Tax exemption/waiver/suspension","Other"))) -> 6 | AU27: =IF(A27<>A26,1,0) -> 0 | AV27: 1
A28: Albania | B28: 2 | C28: 13 | D28: Extension of deadline for submission of the individual tax return for individuals with an annual income exceeding ALL 2 million in 2019 to 31 July 2020 | E28: -1 | F28: 2 | G28: 2 | H28: 1 | I28: 2 | J28: 1 | K28: 1 | L28: 1 | M28: 1 | N28: ALB | O28: Europe & Central Asia | P28: IBRD | Q28: Upper Middle Income | R28: 0 | S28: -4.74 | T28: -4.77 | U28: 80.04 | V28: =IF(E28>0,1,IF(E28<0,0,-1)) -> 0 | W28: =IF(F28>0,1,IF(F28<0,0,-1)) -> 1 | X28: =IF(G28>0,1,IF(G28<0,0,-1)) -> 1 | Y28: =IF(H28>0,1,IF(H28<0,0,-1)) -> 1 | Z28: =IF(I28>0,1,IF(I28<0,0,-1)) -> 1 | AA28: =IF(J28>0,1,IF(J28<0,0,-1)) -> 1 | AB28: =IF(K28>0,1,IF(K28<0,0,-1)) -> 1 | AC28: =IF(L28>0,1,IF(L28<0,0,-1)) -> 1 | AD28: =IF(M28>0,1,IF(M28<0,0,-1)) -> 1 | AE28: All Regions | AF28: All Income Levels | AG28: 0 | AH28: 1 | AI28: 0 | AJ28: 1 | AK28: All Countries | AL28: =IF(OR(B28="other",B28="international",B28="Transfers",B28="expenditure"),1,0) -> 0 | AM28: =IF(AND(INDIRECT(AN28)='Sample Select backend'!$C$2,INDIRECT(AO28)=1,INDIRECT(AP28)='Sample Select backend'!$F$2,INDIRECT(AQ28)=1,INDIRECT(AR28)='Sample Select backend'!$M$2),1,0) -> 0 | AN28: =_xlfn.CONCAT('Sample Select backend'!$C$4,ROW(AN28)) -> AE28 | AO28: =_xlfn.CONCAT('Sample Select backend'!$J$2,ROW(AO28)) -> AJ28 | AP28: =_xlfn.CONCAT('Sample Select backend'!$F$4,ROW(AP28)) -> AF28 | AQ28: =_xlfn.CONCAT('Sample Select backend'!$I$10,ROW(AQ28)) -> R28 | AR28: =_xlfn.CONCAT('Sample Select backend'!$M$4,ROW(AR28)) -> AK28 | AS28: =A28 -> Albania | AT28: =IF(ISNUMBER(C28),C28,IF(OR(C28="general",C28="23;general"),"General",IF(OR(C28="exemption",C28="other (exemption)"),"Tax exemption/waiver/suspension","Other"))) -> 13 | AU28: =IF(A28<>A27,1,0) -> 0 | AV28: 1
A29: Albania | B29: 6 | C29: 29 | D29: Payment of the minimum wage to employees of firms with a turnover up to 14,000 which have interrupted their activities because of the COVID-19 outbreak. | E29: 1 | F29: 1 | G29: 1 | H29: -1 | I29: -2 | J29: 1 | K29: 1 | L29: -2 | M29: 1 | N29: ALB | O29: Europe & Central Asia | P29: IBRD | Q29: Upper Middle Income | R29: 0 | S29: -4.74 | T29: -4.77 | U29: 80.04 | V29: =IF(E29>0,1,IF(E29<0,0,-1)) -> 1 | W29: =IF(F29>0,1,IF(F29<0,0,-1)) -> 1 | X29: =IF(G29>0,1,IF(G29<0,0,-1)) -> 1 | Y29: =IF(H29>0,1,IF(H29<0,0,-1)) -> 0 | Z29: =IF(I29>0,1,IF(I29<0,0,-1)) -> 0 | AA29: =IF(J29>0,1,IF(J29<0,0,-1)) -> 1 | AB29: =IF(K29>0,1,IF(K29<0,0,-1)) -> 1 | AC29: =IF(L29>0,1,IF(L29<0,0,-1)) -> 0 | AD29: =IF(M29>0,1,IF(M29<0,0,-1)) -> 1 | AE29: All Regions | AF29: All Income Levels | AG29: 0 | AH29: 1 | AI29: 0 | AJ29: 1 | AK29: All Countries | AL29: =IF(OR(B29="other",B29="international",B29="Transfers",B29="expenditure"),1,0) -> 0 | AM29: =IF(AND(INDIRECT(AN29)='Sample Select backend'!$C$2,INDIRECT(AO29)=1,INDIRECT(AP29)='Sample Select backend'!$F$2,INDIRECT(AQ29)=1,INDIRECT(AR29)='Sample Select backend'!$M$2),1,0) -> 0 | AN29: =_xlfn.CONCAT('Sample Select backend'!$C$4,ROW(AN29)) -> AE29 | AO29: =_xlfn.CONCAT('Sample Select backend'!$J$2,ROW(AO29)) -> AJ29 | AP29: =_xlfn.CONCAT('Sample Select backend'!$F$4,ROW(AP29)) -> AF29 | AQ29: =_xlfn.CONCAT('Sample Select backend'!$I$10,ROW(AQ29)) -> R29 | AR29: =_xlfn.CONCAT('Sample Select backend'!$M$4,ROW(AR29)) -> AK29 | AS29: =A29 -> Albania | AT29: =IF(ISNUMBER(C29),C29,IF(OR(C29="general",C29="23;general"),"General",IF(OR(C29="exemption",C29="other (exemption)"),"Tax exemption/waiver/suspension","Other"))) -> 29 | AU29: =IF(A29<>A28,1,0) -> 0 | AV29: 1
A30: Albania | B30: 7 | C30: 30 | D30: Lk11bn (0.6% of GDP) sovereign guarantee fund for companies to access overdrafts in the banking system to pay wages for their employees for up to 3 months with an interest rate capped at 2.85% for a maturity of up to 2 years. | E30: -1 | F30: 1 | G30: 1 | H30: 1 | I30: 1 | J30: 1 | K30: 1 | L30: -1 | M30: 1 | N30: ALB | O30: Europe & Central Asia | P30: IBRD | Q30: Upper Middle Income | R30: 0 | S30: -4.74 | T30: -4.77 | U30: 80.04 | V30: =IF(E30>0,1,IF(E30<0,0,-1)) -> 0 | W30: =IF(F30>0,1,IF(F30<0,0,-1)) -> 1 | X30: =IF(G30>0,1,IF(G30<0,0,-1)) -> 1 | Y30: =IF(H30>0,1,IF(H30<0,0,-1)) -> 1 | Z30: =IF(I30>0,1,IF(I30<0,0,-1)) -> 1 | AA30: =IF(J30>0,1,IF(J30<0,0,-1)) -> 1 | AB30: =IF(K30>0,1,IF(K30<0,0,-1)) -> 1 | AC30: =IF(L30>0,1,IF(L30<0,0,-1)) -> 0 | AD30: =IF(M30>0,1,IF(M30<0,0,-1)) -> 1 | AE30: All Regions | AF30: All Income Levels | AG30: 0 | AH30: 1 | AI30: 0 | AJ30: 1 | AK30: All Countries | AL30: =IF(OR(B30="other",B30="international",B30="Transfers",B30="expenditure"),1,0) -> 0 | AM30: =IF(AND(INDIRECT(AN30)='Sample Select backend'!$C$2,INDIRECT(AO30)=1,INDIRECT(AP30)='Sample Select backend'!$F$2,INDIRECT(AQ30)=1,INDIRECT(AR30)='Sample Select backend'!$M$2),1,0) -> 0 | AN30: =_xlfn.CONCAT('Sample Select backend'!$C$4,ROW(AN30)) -> AE30 | AO30: =_xlfn.CONCAT('Sample Select backend'!$J$2,ROW(AO30)) -> AJ30 | AP30: =_xlfn.CONCAT('Sample Select backend'!$F$4,ROW(AP30)) -> AF30 | AQ30: =_xlfn.CONCAT('Sample Select backend'!$I$10,ROW(AQ30)) -> R30 | AR30: =_xlfn.CONCAT('Sample Select backend'!$M$4,ROW(AR30)) -> AK30 | AS30: =A30 -> Albania | AT30: =IF(ISNUMBER(C30),C30,IF(OR(C30="general",C30="23;general"),"General",IF(OR(C30="exemption",C30="other (exemption)"),"Tax exemption/waiver/suspension","Other"))) -> 30 | AU30: =IF(A30<>A29,1,0) -> 0 | AV30: 1
A31: Albania | B31: 6 | C31: 27 | D31: Benefits under the Ndihma Economike (flagship cash transfer program) will be doubled. | E31: 1 | F31: 1 | G31: 1 | H31: -1 | I31: 2 | J31: -2 | K31: 1 | L31: 1 | M31: 1 | N31: ALB | O31: Europe & Central Asia | P31: IBRD | Q31: Upper Middle Income | R31: 0 | S31: -4.74 | T31: -4.77 | U31: 80.04 | V31: =IF(E31>0,1,IF(E31<0,0,-1)) -> 1 | W31: =IF(F31>0,1,IF(F31<0,0,-1)) -> 1 | X31: =IF(G31>0,1,IF(G31<0,0,-1)) -> 1 | Y31: =IF(H31>0,1,IF(H31<0,0,-1)) -> 0 | Z31: =IF(I31>0,1,IF(I31<0,0,-1)) -> 1 | AA31: =IF(J31>0,1,IF(J31<0,0,-1)) -> 0 | AB31: =IF(K31>0,1,IF(K31<0,0,-1)) -> 1 | AC31: =IF(L31>0,1,IF(L31<0,0,-1)) -> 1 | AD31: =IF(M31>0,1,IF(M31<0,0,-1)) -> 1 | AE31: All Regions | AF31: All Income Levels | AG31: 0 | AH31: 1 | AI31: 0 | AJ31: 1 | AK31: All Countries | AL31: =IF(OR(B31="other",B31="international",B31="Transfers",B31="expenditure"),1,0) -> 0 | AM31: =IF(AND(INDIRECT(AN31)='Sample Select backend'!$C$2,INDIRECT(AO31)=1,INDIRECT(AP31)='Sample Select backend'!$F$2,INDIRECT(AQ31)=1,INDIRECT(AR31)='Sample Select backend'!$M$2),1,0) -> 0 | AN31: =_xlfn.CONCAT('Sample Select backend'!$C$4,ROW(AN31)) -> AE31 | AO31: =_xlfn.CONCAT('Sample Select backend'!$J$2,ROW(AO31)) -> AJ31 | AP31: =_xlfn.CONCAT('Sample Select backend'!$F$4,ROW(AP31)) -> AF31 | AQ31: =_xlfn.CONCAT('Sample Select backend'!$I$10,ROW(AQ31)) -> R31 | AR31: =_xlfn.CONCAT('Sample Select backend'!$M$4,ROW(AR31)) -> AK31 | AS31: =A31 -> Albania | AT31: =IF(ISNUMBER(C31),C31,IF(OR(C31="general",C31="23;general"),"General",IF(OR(C31="exemption",C31="other (exemption)"),"Tax exemption/waiver/suspension","Other"))) -> 27 | AU31: =IF(A31<>A30,1,0) -> 0 | AV31: 1
A32: Albania | B32: 6 | C32: 25 | D32: One-off transfer of Lek 40,000 to employees of small businesses affected by the pandemic and not covered by the earlier support package, employees of large businesses laid off due to the pandemic, and employees in the tourism sector. | O32: Europe & Central Asia | P32: IBRD | Q32: Upper Middle Income | R32: 0 | S32: -4.74 | T32: -4.77 | U32: 80.04 | V32: -1 | W32: -1 | X32: -1 | Y32: -1 | Z32: -1 | AA32: -1 | AB32: -1 | AC32: -1 | AD32: -1 | AE32: All Regions | AF32: All Income Levels | AG32: 0 | AH32: 1 | AI32: 0 | AJ32: 1 | AK32: All Countries | AL32: =IF(OR(B32="other",B32="international",B32="Transfers",B32="expenditure"),1,0) -> 0 | AM32: =IF(AND(INDIRECT(AN32)='Sample Select backend'!$C$2,INDIRECT(AO32)=1,INDIRECT(AP32)='Sample Select backend'!$F$2,INDIRECT(AQ32)=1,INDIRECT(AR32)='Sample Select backend'!$M$2),1,0) -> 0 | AN32: =_xlfn.CONCAT('Sample Select backend'!$C$4,ROW(AN32)) -> AE32 | AO32: =_xlfn.CONCAT('Sample Select backend'!$J$2,ROW(AO32)) -> AJ32 | AP32: =_xlfn.CONCAT('Sample Select backend'!$F$4,ROW(AP32)) -> AF32 | AQ32: =_xlfn.CONCAT('Sample Select backend'!$I$10,ROW(AQ32)) -> R32 | AR32: =_xlfn.CONCAT('Sample Select backend'!$M$4,ROW(AR32)) -> AK32 | AS32: =A32 -> Albania | AT32: =IF(ISNUMBER(C32),C32,IF(OR(C32="general",C32="23;general"),"General",IF(OR(C32="exemption",C32="other (exemption)"),"Tax exemption/waiver/suspension","Other"))) -> 25 | AU32: =IF(A32<>A31,1,0) -> 0 | AV32: 0
A33: Albania | B33: 7 | C33: 30 | D33: A sovereign guarantee of Lek 15 billion (0.9 percent of GDP) to provide loans for working capital for all private companies that were tax-compliant and solvent before the pandemic. The government will guarantee 60 percent of the loans, and interest is capped at 5 percent. As of August 13th, 95% of the overall budgeted direct support measures had been paid out while the take up for the first guarantee scheme was 60 percent and for the second scheme 22 percent. | O33: Europe & Central Asia | P33: IBRD | Q33: Upper Middle Income | R33: 0 | S33: -4.74 | T33: -4.77 | U33: 80.04 | V33: -1 | W33: -1 | X33: -1 | Y33: -1 | Z33: -1 | AA33: -1 | AB33: -1 | AC33: -1 | AD33: -1 | AE33: All Regions | AF33: All Income Levels | AG33: 0 | AH33: 1 | AI33: 0 | AJ33: 1 | AK33: All Countries | AL33: =IF(OR(B33="other",B33="international",B33="Transfers",B33="expenditure"),1,0) -> 0 | AM33: =IF(AND(INDIRECT(AN33)='Sample Select backend'!$C$2,INDIRECT(AO33)=1,INDIRECT(AP33)='Sample Select backend'!$F$2,INDIRECT(AQ33)=1,INDIRECT(AR33)='Sample Select backend'!$M$2),1,0) -> 0 | AN33: =_xlfn.CONCAT('Sample Select backend'!$C$4,ROW(AN33)) -> AE33 | AO33: =_xlfn.CONCAT('Sample Select backend'!$J$2,ROW(AO33)) -> AJ33 | AP33: =_xlfn.CONCAT('Sample Select backend'!$F$4,ROW(AP33)) -> AF33 | AQ33: =_xlfn.CONCAT('Sample Select backend'!$I$10,ROW(AQ33)) -> R33 | AR33: =_xlfn.CONCAT('Sample Select backend'!$M$4,ROW(AR33)) -> AK33 | AS33: =A33 -> Albania | AT33: =IF(ISNUMBER(C33),C33,IF(OR(C33="general",C33="23;general"),"General",IF(OR(C33="exemption",C33="other (exemption)"),"Tax exemption/waiver/suspension","Other"))) -> 30 | AU33: =IF(A33<>A32,1,0) -> 0 | AV33: 0
A34: Albania | B34: 8 | C34: other | D34: Starting in April, cabinet ministers and lawmakers will receive half of their salaries for the next three months with the savings going to the Anti-Covid 19 social support fund. | O34: Europe & Central Asia | P34: IBRD | Q34: Upper Middle Income | R34: 0 | S34: -4.74 | T34: -4.77 | U34: 80.04 | V34: -1 | W34: -1 | X34: -1 | Y34: -1 | Z34: -1 | AA34: -1 | AB34: -1 | AC34: -1 | AD34: -1 | AE34: All Regions | AF34: All Income Levels | AG34: 0 | AH34: 1 | AI34: 0 | AJ34: 1 | AK34: All Countries | AL34: =IF(OR(B34="other",B34="international",B34="Transfers",B34="expenditure"),1,0) -> 0 | AM34: =IF(AND(INDIRECT(AN34)='Sample Select backend'!$C$2,INDIRECT(AO34)=1,INDIRECT(AP34)='Sample Select backend'!$F$2,INDIRECT(AQ34)=1,INDIRECT(AR34)='Sample Select backend'!$M$2),1,0) -> 0 | AN34: =_xlfn.CONCAT('Sample Select backend'!$C$4,ROW(AN34)) -> AE34 | AO34: =_xlfn.CONCAT('Sample Select backend'!$J$2,ROW(AO34)) -> AJ34 | AP34: =_xlfn.CONCAT('Sample Select backend'!$F$4,ROW(AP34)) -> AF34 | AQ34: =_xlfn.CONCAT('Sample Select backend'!$I$10,ROW(AQ34)) -> R34 | AR34: =_xlfn.CONCAT('Sample Select backend'!$M$4,ROW(AR34)) -> AK34 | AS34: =A34 -> Albania | AT34: =IF(ISNUMBER(C34),C34,IF(OR(C34="general",C34="23;general"),"General",IF(OR(C34="exemption",C34="other (exemption)"),"Tax exemption/waiver/suspension","Other"))) -> Other | AU34: =IF(A34<>A33,1,0) -> 0 | AV34: 0
A35: Albania | B35: Other | C35: 33 | D35: Lek 2bn of defense spending reallocated toward humanitarian relief for the most vulnerable | O35: Europe & Central Asia | P35: IBRD | Q35: Upper Middle Income | R35: 0 | S35: -4.74 | T35: -4.77 | U35: 80.04 | V35: -1 | W35: -1 | X35: -1 | Y35: -1 | Z35: -1 | AA35: -1 | AB35: -1 | AC35: -1 | AD35: -1 | AE35: All Regions | AF35: All Income Levels | AG35: 0 | AH35: 1 | AI35: 0 | AJ35: 1 | AK35: All Countries | AL35: =IF(OR(B35="other",B35="international",B35="Transfers",B35="expenditure"),1,0) -> 1 | AM35: =IF(AND(INDIRECT(AN35)='Sample Select backend'!$C$2,INDIRECT(AO35)=1,INDIRECT(AP35)='Sample Select backend'!$F$2,INDIRECT(AQ35)=1,INDIRECT(AR35)='Sample Select backend'!$M$2),1,0) -> 0 | AN35: =_xlfn.CONCAT('Sample Select backend'!$C$4,ROW(AN35)) -> AE35 | AO35: =_xlfn.CONCAT('Sample Select backend'!$J$2,ROW(AO35)) -> AJ35 | AP35: =_xlfn.CONCAT('Sample Select backend'!$F$4,ROW(AP35)) -> AF35 | AQ35: =_xlfn.CONCAT('Sample Select backend'!$I$10,ROW(AQ35)) -> R35 | AR35: =_xlfn.CONCAT('Sample Select backend'!$M$4,ROW(AR35)) -> AK35 | AS35: =A35 -> Albania | AT35: =IF(ISNUMBER(C35),C35,IF(OR(C35="general",C35="23;general"),"General",IF(OR(C35="exemption",C35="other (exemption)"),"Tax exemption/waiver/suspension","Other"))) -> 33 | AU35: =IF(A35<>A34,1,0) -> 0 | AV35: 0
A36: Albania | B36: 1 | C36: 6 | D36: Deferral of CIT payments and for companies with a turnover up to Lek 14,000. | O36: Europe & Central Asia | P36: IBRD | Q36: Upper Middle Income | R36: 0 | S36: -4.74 | T36: -4.77 | U36: 80.04 | V36: -1 | W36: -1 | X36: -1 | Y36: -1 | Z36: -1 | AA36: -1 | AB36: -1 | AC36: -1 | AD36: -1 | AE36: All Regions | AF36: All Income Levels | AG36: 0 | AH36: 1 | AI36: 0 | AJ36: 1 | AK36: All Countries | AL36: =IF(OR(B36="other",B36="international",B36="Transfers",B36="expenditure"),1,0) -> 0 | AM36: =IF(AND(INDIRECT(AN36)='Sample Select backend'!$C$2,INDIRECT(AO36)=1,INDIRECT(AP36)='Sample Select backend'!$F$2,INDIRECT(AQ36)=1,INDIRECT(AR36)='Sample Select backend'!$M$2),1,0) -> 0 | AN36: =_xlfn.CONCAT('Sample Select backend'!$C$4,ROW(AN36)) -> AE36 | AO36: =_xlfn.CONCAT('Sample Select backend'!$J$2,ROW(AO36)) -> AJ36 | AP36: =_xlfn.CONCAT('Sample Select backend'!$F$4,ROW(AP36)) -> AF36 | AQ36: =_xlfn.CONCAT('Sample Select backend'!$I$10,ROW(AQ36)) -> R36 | AR36: =_xlfn.CONCAT('Sample Select backend'!$M$4,ROW(AR36)) -> AK36 | AS36: =A36 -> Albania | AT36: =IF(ISNUMBER(C36),C36,IF(OR(C36="general",C36="23;general"),"General",IF(OR(C36="exemption",C36="other (exemption)"),"Tax exemption/waiver/suspension","Other"))) -> 6 | AU36: =IF(A36<>A35,1,0) -> 0 | AV36: 0
A37: Algeria | B37: 6 | C37: 25/28 | D37: A benefit of 10,000 Algerian Dinars (79 USD ) is to be extended to poor families impacted by COVID-19 to cover Ramadhan expenses. | E37: 2 | F37: 1 | G37: 2 | H37: -1 | I37: 1 | J37: 1 | K37: -1 | L37: -2 | M37: 1 | N37: DZA | O37: Middle East & North Africa | P37: IBRD | Q37: Lower Middle Income | R37: 0 | S37: -5.48 | T37: -15.74 | U37: 51.4 | V37: =IF(E37>0,1,IF(E37<0,0,-1)) -> 1 | W37: =IF(F37>0,1,IF(F37<0,0,-1)) -> 1 | X37: =IF(G37>0,1,IF(G37<0,0,-1)) -> 1 | Y37: =IF(H37>0,1,IF(H37<0,0,-1)) -> 0 | Z37: =IF(I37>0,1,IF(I37<0,0,-1)) -> 1 | AA37: =IF(J37>0,1,IF(J37<0,0,-1)) -> 1 | AB37: =IF(K37>0,1,IF(K37<0,0,-1)) -> 0 | AC37: =IF(L37>0,1,IF(L37<0,0,-1)) -> 0 | AD37: =IF(M37>0,1,IF(M37<0,0,-1)) -> 1 | AE37: All Regions | AF37: All Income Levels | AG37: 0 | AH37: 1 | AI37: 0 | AJ37: 1 | AK37: All Countries | AL37: =IF(OR(B37="other",B37="international",B37="Transfers",B37="expenditure"),1,0) -> 0 | AM37: =IF(AND(INDIRECT(AN37)='Sample Select backend'!$C$2,INDIRECT(AO37)=1,INDIRECT(AP37)='Sample Select backend'!$F$2,INDIRECT(AQ37)=1,INDIRECT(AR37)='Sample Select backend'!$M$2),1,0) -> 0 | AN37: =_xlfn.CONCAT('Sample Select backend'!$C$4,ROW(AN37)) -> AE37 | AO37: =_xlfn.CONCAT('Sample Select backend'!$J$2,ROW(AO37)) -> AJ37 | AP37: =_xlfn.CONCAT('Sample Select backend'!$F$4,ROW(AP37)) -> AF37 | AQ37: =_xlfn.CONCAT('Sample Select backend'!$I$10,ROW(AQ37)) -> R37 | AR37: =_xlfn.CONCAT('Sample Select backend'!$M$4,ROW(AR37)) -> AK37 | AS37: =A37 -> Algeria | AT37: =IF(ISNUMBER(C37),C37,IF(OR(C37="general",C37="23;general"),"General",IF(OR(C37="exemption",C37="other (exemption)"),"Tax exemption/waiver/suspension","Other"))) -> Other | AU37: =IF(A37<>A36,1,0) -> 1 | AV37: 1
