Workbook
Name FCV_added: OFFSET('Policy select backend'!$O$52,,,2+'Policy select backend'!$B$52)
Name FCV_Scores: OFFSET('Performance across backend'!$H$39,,,2+'Performance across backend'!$P$3)
Name Income_added: OFFSET('Policy select backend'!$O$37,,,4+'Policy select backend'!$B$52)
Name Income_scores: OFFSET('Performance across backend'!$H$24,,,4+'Performance across backend'!$P$3)
Name Lending_added: OFFSET('Policy select backend'!$O$31,,,3+'Policy select backend'!$B$52)
Name Lending_scores: OFFSET('Performance across backend'!$H$18,,,3+'Performance across backend'!$P$3)
Name Regions_added: OFFSET('Policy select backend'!$O$43,,,7+'Policy select backend'!$B$52)
Name Regions_scores: OFFSET('Performance across backend'!$H$30,,,7+'Performance across backend'!$P$3)

Sheet Data
A1: Treatment | B1: Country | C1: First Case | D1: First Lockdown start | E1: First Lockdown end | F1: Duration | G1: First Fiscal | H1: Jahr implementiert | I1: Treatment | J1: PolicyCategory | K1: PolicyCode | L1: Fullpolicy | M1: Targetability | N1: Speed | O1: Abuse_Resistance | P1: Affordability | Q1: Predictability_Cost_Control | R1: Reversibility | S1: Scalability | T1: Administrative_Complexity | U1: Resilience_Health_Measures | V1: Country_Code | W1: Reg | X1: Lendingcategory | Y1: Incomelevel | Z1: FCV | AA1: Targetability (converted) | AB1: Speed (converted) | AC1: Abuse_Resistance (converted) | AD1: Affordability (converted) | AE1: Predictability_Cost_Control (converted) | AF1: Reversibility (converted) | AG1: Scalability (converted) | AH1: Administrative_Complexity (converted) | AI1: Resilience_Health_Measures (converted) | AJ1: Subcategory (clean) | AK1: First of country row (requires sorting alphabetically by country) | AL1: May 1st sample
A2: 1 | B2: Australia | C2: 43855 | D2: 43919 | E2: 43951 | F2: =DATEDIF(D2,E2,"D") -> 32 | G2: 43919 | H2: 2020 | I2: 1 | J2: 6 | K2: 27 | L2: One-off payment of A$750 to social security, veteran and other income support recipients and eligible concession card holders. | M2: 1 | N2: 1 | O2: 1 | P2: -1 | Q2: 1 | R2: 1 | S2: 1 | T2: 1 | U2: 1 | V2: AUS | W2: East Asia & Pacific | X2: None | Y2: High Income | Z2: 1 | AA2: =IF(M2>0,1,IF(M2<0,0,-1)) -> 1 | AB2: =IF(N2>0,1,IF(N2<0,0,-1)) -> 1 | AC2: =IF(O2>0,1,IF(O2<0,0,-1)) -> 1 | AD2: =IF(P2>0,1,IF(P2<0,0,-1)) -> 0 | AE2: =IF(Q2>0,1,IF(Q2<0,0,-1)) -> 1 | AF2: =IF(R2>0,1,IF(R2<0,0,-1)) -> 1 | AG2: =IF(S2>0,1,IF(S2<0,0,-1)) -> 1 | AH2: =IF(T2>0,1,IF(T2<0,0,-1)) -> 1 | AI2: =IF(U2>0,1,IF(U2<0,0,-1)) -> 1 | AJ2: =IF(ISNUMBER(K2),K2,IF(OR(K2="general",K2="23;general"),"General",IF(OR(K2="exemption",K2="other (exemption)"),"Tax exemption/waiver/suspension","Other"))) -> 27 | AK2: =IF(B2<>#REF!,1,0) -> #REF! | AL2: 1
A3: 1 | B3: Australia | C3: 43855 | D3: 43919 | E3: 43951 | F3: =DATEDIF(D3,E3,"D") -> 32 | G3: 43919 | H3: 2020 | I3: 1 | J3: 1 | K3: 9 | L3: Accelerating refunds: ATO will allow businesses on a quarterly reporting cycle to opt into monthly GST reporting in order to get quicker access to GST refunds they may be entitled to. | M3: -2 | N3: 1 | O3: 2 | P3: 1 | Q3: 2 | R3: -2 | S3: -2 | T3: 2 | U3: 1 | V3: AUS | W3: East Asia & Pacific | X3: None | Y3: High Income | Z3: 1 | AA3: =IF(M3>0,1,IF(M3<0,0,-1)) -> 0 | AB3: =IF(N3>0,1,IF(N3<0,0,-1)) -> 1 | AC3: =IF(O3>0,1,IF(O3<0,0,-1)) -> 1 | AD3: =IF(P3>0,1,IF(P3<0,0,-1)) -> 1 | AE3: =IF(Q3>0,1,IF(Q3<0,0,-1)) -> 1 | AF3: =IF(R3>0,1,IF(R3<0,0,-1)) -> 0 | AG3: =IF(S3>0,1,IF(S3<0,0,-1)) -> 0 | AH3: =IF(T3>0,1,IF(T3<0,0,-1)) -> 1 | AI3: =IF(U3>0,1,IF(U3<0,0,-1)) -> 1 | AJ3: =IF(ISNUMBER(K3),K3,IF(OR(K3="general",K3="23;general"),"General",IF(OR(K3="exemption",K3="other (exemption)"),"Tax exemption/waiver/suspension","Other"))) -> 9 | AK3: =IF(B3<>B2,1,0) -> 0 | AL3: 1
A4: 1 | B4: Australia | C4: 43855 | D4: 43919 | E4: 43951 | F4: =DATEDIF(D4,E4,"D") -> 32 | G4: 43919 | H4: 2020 | I4: 1 | J4: 6 | K4: 27 | L4: Changes to pension deeming rate (cut of lower deeming rate, top rate). Individuals affected by the COVID-19 can access up to A$10,000 of their superannuation in 2019-2020 and a further USD 10,000 in 2020-21. | M4: 1 | N4: 1 | R4: -2 | S4: 1 | T4: 2 | U4: 1 | V4: AUS | W4: East Asia & Pacific | X4: None | Y4: High Income | Z4: 1 | AA4: =IF(M4>0,1,IF(M4<0,0,-1)) -> 1 | AB4: =IF(N4>0,1,IF(N4<0,0,-1)) -> 1 | AC4: =IF(O4>0,1,IF(O4<0,0,-1)) -> -1 | AD4: =IF(P4>0,1,IF(P4<0,0,-1)) -> -1 | AE4: =IF(Q4>0,1,IF(Q4<0,0,-1)) -> -1 | AF4: =IF(R4>0,1,IF(R4<0,0,-1)) -> 0 | AG4: =IF(S4>0,1,IF(S4<0,0,-1)) -> 1 | AH4: =IF(T4>0,1,IF(T4<0,0,-1)) -> 1 | AI4: =IF(U4>0,1,IF(U4<0,0,-1)) -> 1 | AJ4: =IF(ISNUMBER(K4),K4,IF(OR(K4="general",K4="23;general"),"General",IF(OR(K4="exemption",K4="other (exemption)"),"Tax exemption/waiver/suspension","Other"))) -> 27 | AK4: =IF(B4<>B3,1,0) -> 0 | AL4: 1
A5: 1 | B5: Australia | C5: 43855 | D5: 43919 | E5: 43951 | F5: =DATEDIF(D5,E5,"D") -> 32 | G5: 43919 | H5: 2020 | I5: 1 | J5: 6 | K5: 25 | L5: One-off emergency relief payment of USD 250 for individuals and up to USD 1,000 for families who are required to self- quarantine. This will be available to informal casual workers and those on low incomes. | M5: 1 | N5: 1 | O5: -2 | P5: -1 | Q5: 2 | R5: 1 | S5: 1 | T5: -2 | U5: 1 | V5: AUS | W5: East Asia & Pacific | X5: None | Y5: High Income | Z5: 1 | AA5: =IF(M5>0,1,IF(M5<0,0,-1)) -> 1 | AB5: =IF(N5>0,1,IF(N5<0,0,-1)) -> 1 | AC5: =IF(O5>0,1,IF(O5<0,0,-1)) -> 0 | AD5: =IF(P5>0,1,IF(P5<0,0,-1)) -> 0 | AE5: =IF(Q5>0,1,IF(Q5<0,0,-1)) -> 1 | AF5: =IF(R5>0,1,IF(R5<0,0,-1)) -> 1 | AG5: =IF(S5>0,1,IF(S5<0,0,-1)) -> 1 | AH5: =IF(T5>0,1,IF(T5<0,0,-1)) -> 0 | AI5: =IF(U5>0,1,IF(U5<0,0,-1)) -> 1 | AJ5: =IF(ISNUMBER(K5),K5,IF(OR(K5="general",K5="23;general"),"General",IF(OR(K5="exemption",K5="other (exemption)"),"Tax exemption/waiver/suspension","Other"))) -> 25 | AK5: =IF(B5<>B4,1,0) -> 0 | AL5: 1
A6: 1 | B6: Australia | C6: 43855 | D6: 43919 | E6: 43951 | F6: =DATEDIF(D6,E6,"D") -> 32 | G6: 43919 | H6: 2020 | I6: 1 | J6: 7 | K6: 30 | L6: COVID-19 SME Guarantee Scheme which will support small and medium enterprises (SMEs) to get access to working capital to help them get them through the impact of the COVID-19. Under the Scheme, the Government will guarantee 50 per cent of new loans issued by eligible lenders to SMEs. | M6: 2 | N6: 1 | O6: 1 | P6: 1 | Q6: 2 | R6: 2 | S6: 1 | T6: -1 | U6: 1 | V6: AUS | W6: East Asia & Pacific | X6: None | Y6: High Income | Z6: 1 | AA6: =IF(M6>0,1,IF(M6<0,0,-1)) -> 1 | AB6: =IF(N6>0,1,IF(N6<0,0,-1)) -> 1 | AC6: =IF(O6>0,1,IF(O6<0,0,-1)) -> 1 | AD6: =IF(P6>0,1,IF(P6<0,0,-1)) -> 1 | AE6: =IF(Q6>0,1,IF(Q6<0,0,-1)) -> 1 | AF6: =IF(R6>0,1,IF(R6<0,0,-1)) -> 1 | AG6: =IF(S6>0,1,IF(S6<0,0,-1)) -> 1 | AH6: =IF(T6>0,1,IF(T6<0,0,-1)) -> 0 | AI6: =IF(U6>0,1,IF(U6<0,0,-1)) -> 1 | AJ6: =IF(ISNUMBER(K6),K6,IF(OR(K6="general",K6="23;general"),"General",IF(OR(K6="exemption",K6="other (exemption)"),"Tax exemption/waiver/suspension","Other"))) -> 30 | AK6: =IF(B6<>B5,1,0) -> 0 | AL6: 1
A7: 1 | B7: Australia | C7: 43855 | D7: 43919 | E7: 43951 | F7: =DATEDIF(D7,E7,"D") -> 32 | G7: 43919 | H7: 2020 | I7: 1 | J7: 5 | K7: 23 | L7: Commitment to spend A$2.4 billion to strengthen the health system and protect vulnerable people from the outbreak of COVID-19. | M7: 1 | N7: -1 | O7: -2 | P7: -1 | Q7: -2 | R7: 1 | S7: 1 | T7: 1 | U7: 1 | V7: AUS | W7: East Asia & Pacific | X7: None | Y7: High Income | Z7: 1 | AA7: =IF(M7>0,1,IF(M7<0,0,-1)) -> 1 | AB7: =IF(N7>0,1,IF(N7<0,0,-1)) -> 0 | AC7: =IF(O7>0,1,IF(O7<0,0,-1)) -> 0 | AD7: =IF(P7>0,1,IF(P7<0,0,-1)) -> 0 | AE7: =IF(Q7>0,1,IF(Q7<0,0,-1)) -> 0 | AF7: =IF(R7>0,1,IF(R7<0,0,-1)) -> 1 | AG7: =IF(S7>0,1,IF(S7<0,0,-1)) -> 1 | AH7: =IF(T7>0,1,IF(T7<0,0,-1)) -> 1 | AI7: =IF(U7>0,1,IF(U7<0,0,-1)) -> 1 | AJ7: =IF(ISNUMBER(K7),K7,IF(OR(K7="general",K7="23;general"),"General",IF(OR(K7="exemption",K7="other (exemption)"),"Tax exemption/waiver/suspension","Other"))) -> 23 | AK7: =IF(B7<>B6,1,0) -> 0 | AL7: 1
A8: 1 | B8: Australia | C8: 43855 | D8: 43919 | E8: 43951 | F8: =DATEDIF(D8,E8,"D") -> 32 | G8: 43919 | H8: 2020 | I8: 1 | J8: 2 | K8: 17 | L8: From 1 March 2020 to 30 June 2020, taxpayers are allowed to claim AUD 0.80 for each hour working from home for all their running expenses | M8: -2 | O8: -2 | P8: -1 | Q8: 2 | R8: 2 | S8: 1 | T8: -2 | U8: 1 | V8: AUS | W8: East Asia & Pacific | X8: None | Y8: High Income | Z8: 1 | AA8: =IF(M8>0,1,IF(M8<0,0,-1)) -> 0 | AB8: =IF(N8>0,1,IF(N8<0,0,-1)) -> -1 | AC8: =IF(O8>0,1,IF(O8<0,0,-1)) -> 0 | AD8: =IF(P8>0,1,IF(P8<0,0,-1)) -> 0 | AE8: =IF(Q8>0,1,IF(Q8<0,0,-1)) -> 1 | AF8: =IF(R8>0,1,IF(R8<0,0,-1)) -> 1 | AG8: =IF(S8>0,1,IF(S8<0,0,-1)) -> 1 | AH8: =IF(T8>0,1,IF(T8<0,0,-1)) -> 0 | AI8: =IF(U8>0,1,IF(U8<0,0,-1)) -> 1 | AJ8: =IF(ISNUMBER(K8),K8,IF(OR(K8="general",K8="23;general"),"General",IF(OR(K8="exemption",K8="other (exemption)"),"Tax exemption/waiver/suspension","Other"))) -> 17 | AK8: =IF(B8<>B7,1,0) -> 0 | AL8: 1
A9: 1 | B9: Australia | C9: 43855 | D9: 43919 | E9: 43951 | F9: =DATEDIF(D9,E9,"D") -> 32 | G9: 43919 | H9: 2020 | I9: 1 | J9: 6 | K9: 25 | L9: A further A$750 payment to social security and veteran income support recipients and eligible concession card holders, except for those who are receiving an income support payment that is eligible to receive the COVID-19 supplement. | M9: 1 | N9: 1 | O9: 2 | P9: -1 | Q9: 2 | R9: 1 | S9: 1 | T9: 2 | U9: 1 | V9: AUS | W9: East Asia & Pacific | X9: None | Y9: High Income | Z9: 1 | AA9: =IF(M9>0,1,IF(M9<0,0,-1)) -> 1 | AB9: =IF(N9>0,1,IF(N9<0,0,-1)) -> 1 | AC9: =IF(O9>0,1,IF(O9<0,0,-1)) -> 1 | AD9: =IF(P9>0,1,IF(P9<0,0,-1)) -> 0 | AE9: =IF(Q9>0,1,IF(Q9<0,0,-1)) -> 1 | AF9: =IF(R9>0,1,IF(R9<0,0,-1)) -> 1 | AG9: =IF(S9>0,1,IF(S9<0,0,-1)) -> 1 | AH9: =IF(T9>0,1,IF(T9<0,0,-1)) -> 1 | AI9: =IF(U9>0,1,IF(U9<0,0,-1)) -> 1 | AJ9: =IF(ISNUMBER(K9),K9,IF(OR(K9="general",K9="23;general"),"General",IF(OR(K9="exemption",K9="other (exemption)"),"Tax exemption/waiver/suspension","Other"))) -> 25 | AK9: =IF(B9<>B8,1,0) -> 0 | AL9: 1
A10: 1 | B10: Australia | C10: 43855 | D10: 43919 | E10: 43951 | F10: =DATEDIF(D10,E10,"D") -> 32 | G10: 43919 | H10: 2020 | I10: 1 | J10: 6 | K10: 29 | L10: Eligible employers can apply for a wage subsidy of 50% of the apprentice’s or trainee’s wage for up to 9 months from 1 January 2020 to 30 September. Where a small business is not able to retain an apprentice, the subsidy will be available to a new employer that employs that apprentice. | M10: 2 | N10: 1 | O10: -2 | P10: -1 | Q10: -2 | R10: 1 | S10: 1 | T10: -1 | U10: 1 | V10: AUS | W10: East Asia & Pacific | X10: None | Y10: High Income | Z10: 1 | AA10: =IF(M10>0,1,IF(M10<0,0,-1)) -> 1 | AB10: =IF(N10>0,1,IF(N10<0,0,-1)) -> 1 | AC10: =IF(O10>0,1,IF(O10<0,0,-1)) -> 0 | AD10: =IF(P10>0,1,IF(P10<0,0,-1)) -> 0 | AE10: =IF(Q10>0,1,IF(Q10<0,0,-1)) -> 0 | AF10: =IF(R10>0,1,IF(R10<0,0,-1)) -> 1 | AG10: =IF(S10>0,1,IF(S10<0,0,-1)) -> 1 | AH10: =IF(T10>0,1,IF(T10<0,0,-1)) -> 0 | AI10: =IF(U10>0,1,IF(U10<0,0,-1)) -> 1 | AJ10: =IF(ISNUMBER(K10),K10,IF(OR(K10="general",K10="23;general"),"General",IF(OR(K10="exemption",K10="other (exemption)"),"Tax exemption/waiver/suspension","Other"))) -> 29 | AK10: =IF(B10<>B9,1,0) -> 0 | AL10: 1
A11: 1 | B11: Australia | C11: 43855 | D11: 43919 | E11: 43951 | F11: =DATEDIF(D11,E11,"D") -> 32 | G11: 43919 | H11: 2020 | I11: 1 | J11: 9 | K11: 34 | L11: State and Territory governments also announced fiscal stimulus packages, together amounting to A$11.5 billion (0.6% of GDP), including payroll tax relief for businesses and relief for households, such as discount utility bills, cash payments to vulnerable households, and support for health spending. | V11: AUS | W11: East Asia & Pacific | X11: None | Y11: High Income | Z11: 1 | AA11: =IF(M11>0,1,IF(M11<0,0,-1)) -> -1 | AB11: =IF(N11>0,1,IF(N11<0,0,-1)) -> -1 | AC11: =IF(O11>0,1,IF(O11<0,0,-1)) -> -1 | AD11: =IF(P11>0,1,IF(P11<0,0,-1)) -> -1 | AE11: =IF(Q11>0,1,IF(Q11<0,0,-1)) -> -1 | AF11: =IF(R11>0,1,IF(R11<0,0,-1)) -> -1 | AG11: =IF(S11>0,1,IF(S11<0,0,-1)) -> -1 | AH11: =IF(T11>0,1,IF(T11<0,0,-1)) -> -1 | AI11: =IF(U11>0,1,IF(U11<0,0,-1)) -> -1 | AJ11: =IF(ISNUMBER(K11),K11,IF(OR(K11="general",K11="23;general"),"General",IF(OR(K11="exemption",K11="other (exemption)"),"Tax exemption/waiver/suspension","Other"))) -> 34 | AK11: =IF(B11<>B10,1,0) -> 0 | AL11: 0
A12: 1 | B12: Australia | C12: 43855 | D12: 43919 | E12: 43951 | F12: =DATEDIF(D12,E12,"D") -> 32 | G12: 43919 | H12: 2020 | I12: 1 | J12: 6 | K12: 28 | L12: Temporary expansion of eligibility to income support payments and the establishment of a new, time-limited COVID-19 supplement to be paid at a rate of A$550 per fortnight. This will be paid to both existing and new recipients of the JobSeeker Payment, Youth Allowance jobseeker, Parenting Payment, Farm Household Allowance and Special Benefit. | M12: 1 | N12: 1 | O12: 2 | P12: -1 | Q12: -2 | R12: 1 | S12: 1 | T12: -1 | U12: 1 | V12: AUS | W12: East Asia & Pacific | X12: None | Y12: High Income | Z12: 1 | AA12: =IF(M12>0,1,IF(M12<0,0,-1)) -> 1 | AB12: =IF(N12>0,1,IF(N12<0,0,-1)) -> 1 | AC12: =IF(O12>0,1,IF(O12<0,0,-1)) -> 1 | AD12: =IF(P12>0,1,IF(P12<0,0,-1)) -> 0 | AE12: =IF(Q12>0,1,IF(Q12<0,0,-1)) -> 0 | AF12: =IF(R12>0,1,IF(R12<0,0,-1)) -> 1 | AG12: =IF(S12>0,1,IF(S12<0,0,-1)) -> 1 | AH12: =IF(T12>0,1,IF(T12<0,0,-1)) -> 0 | AI12: =IF(U12>0,1,IF(U12<0,0,-1)) -> 1 | AJ12: =IF(ISNUMBER(K12),K12,IF(OR(K12="general",K12="23;general"),"General",IF(OR(K12="exemption",K12="other (exemption)"),"Tax exemption/waiver/suspension","Other"))) -> 28 | AK12: =IF(B12<>B11,1,0) -> 0 | AL12: 1
A13: 1 | B13: Australia | C13: 43855 | D13: 43919 | E13: 43951 | F13: =DATEDIF(D13,E13,"D") -> 32 | G13: 43919 | H13: 2020 | I13: 1 | J13: 6 | K13: 28 | L13: A$1 billion to support those regions and communities that have been disproportionately affected by the economic impacts of the COVID-19, including those heavily reliant on industries such as tourism, agriculture and education. | M13: 2 | N13: 1 | O13: -2 | P13: -1 | Q13: 1 | R13: 2 | S13: 1 | T13: 2 | U13: 1 | V13: AUS | W13: East Asia & Pacific | X13: None | Y13: High Income | Z13: 1 | AA13: =IF(M13>0,1,IF(M13<0,0,-1)) -> 1 | AB13: =IF(N13>0,1,IF(N13<0,0,-1)) -> 1 | AC13: =IF(O13>0,1,IF(O13<0,0,-1)) -> 0 | AD13: =IF(P13>0,1,IF(P13<0,0,-1)) -> 0 | AE13: =IF(Q13>0,1,IF(Q13<0,0,-1)) -> 1 | AF13: =IF(R13>0,1,IF(R13<0,0,-1)) -> 1 | AG13: =IF(S13>0,1,IF(S13<0,0,-1)) -> 1 | AH13: =IF(T13>0,1,IF(T13<0,0,-1)) -> 1 | AI13: =IF(U13>0,1,IF(U13<0,0,-1)) -> 1 | AJ13: =IF(ISNUMBER(K13),K13,IF(OR(K13="general",K13="23;general"),"General",IF(OR(K13="exemption",K13="other (exemption)"),"Tax exemption/waiver/suspension","Other"))) -> 28 | AK13: =IF(B13<>B12,1,0) -> 0 | AL13: 1
A14: 1 | B14: Australia | C14: 43855 | D14: 43919 | E14: 43951 | F14: =DATEDIF(D14,E14,"D") -> 32 | G14: 43919 | H14: 2020 | I14: 1 | J14: 1 | K14: 1 | L14: Accelerated depreciation: Businesses with a turnover of less than A$500 million will be able to deduct 50 per cent of the cost of an eligible asset on installation, with existing depreciation rules applying to the balance of the asset’s cost. | N14: 1 | O14: 2 | P14: -1 | Q14: 2 | R14: -2 | S14: 2 | T14: 2 | U14: 1 | V14: AUS | W14: East Asia & Pacific | X14: None | Y14: High Income | Z14: 1 | AA14: =IF(M14>0,1,IF(M14<0,0,-1)) -> -1 | AB14: =IF(N14>0,1,IF(N14<0,0,-1)) -> 1 | AC14: =IF(O14>0,1,IF(O14<0,0,-1)) -> 1 | AD14: =IF(P14>0,1,IF(P14<0,0,-1)) -> 0 | AE14: =IF(Q14>0,1,IF(Q14<0,0,-1)) -> 1 | AF14: =IF(R14>0,1,IF(R14<0,0,-1)) -> 0 | AG14: =IF(S14>0,1,IF(S14<0,0,-1)) -> 1 | AH14: =IF(T14>0,1,IF(T14<0,0,-1)) -> 1 | AI14: =IF(U14>0,1,IF(U14<0,0,-1)) -> 1 | AJ14: =IF(ISNUMBER(K14),K14,IF(OR(K14="general",K14="23;general"),"General",IF(OR(K14="exemption",K14="other (exemption)"),"Tax exemption/waiver/suspension","Other"))) -> 1 | AK14: =IF(B14<>B13,1,0) -> 0 | AL14: 1
A15: 1 | B15: Australia | C15: 43855 | D15: 43919 | E15: 43951 | F15: =DATEDIF(D15,E15,"D") -> 32 | G15: 43919 | H15: 2020 | I15: 1 | J15: 5 | K15: general | L15: Commonwealth government to spend almost an extra AS5 billion (0.3% of GDP) to strengthen the health system and protect the vulnerable people, including those in aged care, from the outbreak of COVID-19. | M15: 1 | N15: -1 | O15: -2 | P15: -1 | Q15: -2 | R15: 1 | S15: 1 | T15: 1 | U15: 1 | V15: AUS | W15: East Asia & Pacific | X15: None | Y15: High Income | Z15: 1 | AA15: =IF(M15>0,1,IF(M15<0,0,-1)) -> 1 | AB15: =IF(N15>0,1,IF(N15<0,0,-1)) -> 0 | AC15: =IF(O15>0,1,IF(O15<0,0,-1)) -> 0 | AD15: =IF(P15>0,1,IF(P15<0,0,-1)) -> 0 | AE15: =IF(Q15>0,1,IF(Q15<0,0,-1)) -> 0 | AF15: =IF(R15>0,1,IF(R15<0,0,-1)) -> 1 | AG15: =IF(S15>0,1,IF(S15<0,0,-1)) -> 1 | AH15: =IF(T15>0,1,IF(T15<0,0,-1)) -> 1 | AI15: =IF(U15>0,1,IF(U15<0,0,-1)) -> 1 | AJ15: =IF(ISNUMBER(K15),K15,IF(OR(K15="general",K15="23;general"),"General",IF(OR(K15="exemption",K15="other (exemption)"),"Tax exemption/waiver/suspension","Other"))) -> General | AK15: =IF(B15<>B14,1,0) -> 0 | AL15: 1
A16: 1 | B16: Australia | C16: 43855 | D16: 43919 | E16: 43951 | F16: =DATEDIF(D16,E16,"D") -> 32 | G16: 43919 | H16: 2020 | I16: 1 | J16: 9 | K16: 34 | L16: Under the enhanced scheme from the first package, employers will receive a payment equal to 100% of their salary and wages withheld (up from 50%), with the maximum payment being increased from USD 25,000 to USD 50,000. In addition, the minimum payment is being increased from A$2,000 to A$10,000. The payment will be available from April 28. | N16: 1 | P16: -1 | Q16: 2 | R16: 1 | S16: 1 | T16: 2 | U16: 1 | V16: AUS | W16: East Asia & Pacific | X16: None | Y16: High Income | Z16: 1 | AA16: =IF(M16>0,1,IF(M16<0,0,-1)) -> -1 | AB16: =IF(N16>0,1,IF(N16<0,0,-1)) -> 1 | AC16: =IF(O16>0,1,IF(O16<0,0,-1)) -> -1 | AD16: =IF(P16>0,1,IF(P16<0,0,-1)) -> 0 | AE16: =IF(Q16>0,1,IF(Q16<0,0,-1)) -> 1 | AF16: =IF(R16>0,1,IF(R16<0,0,-1)) -> 1 | AG16: =IF(S16>0,1,IF(S16<0,0,-1)) -> 1 | AH16: =IF(T16>0,1,IF(T16<0,0,-1)) -> 1 | AI16: =IF(U16>0,1,IF(U16<0,0,-1)) -> 1 | AJ16: =IF(ISNUMBER(K16),K16,IF(OR(K16="general",K16="23;general"),"General",IF(OR(K16="exemption",K16="other (exemption)"),"Tax exemption/waiver/suspension","Other"))) -> 34 | AK16: =IF(B16<>B15,1,0) -> 0 | AL16: 1
A17: 1 | B17: Australia | C17: 43855 | D17: 43919 | E17: 43951 | F17: =DATEDIF(D17,E17,"D") -> 32 | G17: 43919 | H17: 2020 | I17: 1 | J17: 9 | K17: 34 | L17: SME protection (retroactive to January 1-June 30): SMEs with aggregated annual turnover under A$50 million that withhold tax to the ATO on their employees’ salary and wages will receive a payment equal to 50% of the amount withheld up to a maximum payment of A$25,000. SMEs that pay salary and wages will receive a minimum payment of A$2,000, even if they are not required to withhold tax. | M17: 1 | N17: 1 | O17: 1 | P17: -1 | Q17: 2 | R17: 1 | S17: 1 | T17: -2 | U17: 1 | V17: AUS | W17: East Asia & Pacific | X17: None | Y17: High Income | Z17: 1 | AA17: =IF(M17>0,1,IF(M17<0,0,-1)) -> 1 | AB17: =IF(N17>0,1,IF(N17<0,0,-1)) -> 1 | AC17: =IF(O17>0,1,IF(O17<0,0,-1)) -> 1 | AD17: =IF(P17>0,1,IF(P17<0,0,-1)) -> 0 | AE17: =IF(Q17>0,1,IF(Q17<0,0,-1)) -> 1 | AF17: =IF(R17>0,1,IF(R17<0,0,-1)) -> 1 | AG17: =IF(S17>0,1,IF(S17<0,0,-1)) -> 1 | AH17: =IF(T17>0,1,IF(T17<0,0,-1)) -> 0 | AI17: =IF(U17>0,1,IF(U17<0,0,-1)) -> 1 | AJ17: =IF(ISNUMBER(K17),K17,IF(OR(K17="general",K17="23;general"),"General",IF(OR(K17="exemption",K17="other (exemption)"),"Tax exemption/waiver/suspension","Other"))) -> 34 | AK17: =IF(B17<>B16,1,0) -> 0 | AL17: 1
A18: 1 | B18: Australia | C18: 43855 | D18: 43919 | E18: 43951 | F18: =DATEDIF(D18,E18,"D") -> 32 | G18: 43919 | H18: 2020 | I18: 1 | J18: 2 | K18: 15 | L18: Tax relief measures to individuals experiencing financial hardship, and their tax agents for serious and exceptional circumstances, On 6 October, the Government announced the 2020-21 Federal Budget, which brings forward Stage Two of previously legislated tax cuts by two years, increasing certain tax bracket thresholds to widen the coverage of the relief. The Low and Middle Income Tax Offset will also be retained for an additional year. The Government estimates that more than 7 million Australians will receive a tax relief of approximately A$17.8bn. | M18: 2 | N18: 2 | O18: -2 | P18: -1 | Q18: -2 | R18: -2 | S18: 2 | T18: 2 | U18: 1 | V18: AUS | W18: East Asia & Pacific | X18: None | Y18: High Income | Z18: 1 | AA18: =IF(M18>0,1,IF(M18<0,0,-1)) -> 1 | AB18: =IF(N18>0,1,IF(N18<0,0,-1)) -> 1 | AC18: =IF(O18>0,1,IF(O18<0,0,-1)) -> 0 | AD18: =IF(P18>0,1,IF(P18<0,0,-1)) -> 0 | AE18: =IF(Q18>0,1,IF(Q18<0,0,-1)) -> 0 | AF18: =IF(R18>0,1,IF(R18<0,0,-1)) -> 0 | AG18: =IF(S18>0,1,IF(S18<0,0,-1)) -> 1 | AH18: =IF(T18>0,1,IF(T18<0,0,-1)) -> 1 | AI18: =IF(U18>0,1,IF(U18<0,0,-1)) -> 1 | AJ18: =IF(ISNUMBER(K18),K18,IF(OR(K18="general",K18="23;general"),"General",IF(OR(K18="exemption",K18="other (exemption)"),"Tax exemption/waiver/suspension","Other"))) -> 15 | AK18: =IF(B18<>B17,1,0) -> 0 | AL18: 1
A19: 1 | B19: Australia | C19: 43855 | D19: 43919 | E19: 43951 | F19: =DATEDIF(D19,E19,"D") -> 32 | G19: 43919 | H19: 2020 | I19: 1 | J19: 6 | K19: 28 | L19: The Commonwealth government has committed to provide free childcare to around one million families and announced targeted support to the education system. | M19: 2 | N19: 2 | O19: 1 | P19: -1 | Q19: 2 | R19: -2 | S19: 1 | T19: -2 | U19: -2 | V19: AUS | W19: East Asia & Pacific | X19: None | Y19: High Income | Z19: 1 | AA19: =IF(M19>0,1,IF(M19<0,0,-1)) -> 1 | AB19: =IF(N19>0,1,IF(N19<0,0,-1)) -> 1 | AC19: =IF(O19>0,1,IF(O19<0,0,-1)) -> 1 | AD19: =IF(P19>0,1,IF(P19<0,0,-1)) -> 0 | AE19: =IF(Q19>0,1,IF(Q19<0,0,-1)) -> 1 | AF19: =IF(R19>0,1,IF(R19<0,0,-1)) -> 0 | AG19: =IF(S19>0,1,IF(S19<0,0,-1)) -> 1 | AH19: =IF(T19>0,1,IF(T19<0,0,-1)) -> 0 | AI19: =IF(U19>0,1,IF(U19<0,0,-1)) -> 0 | AJ19: =IF(ISNUMBER(K19),K19,IF(OR(K19="general",K19="23;general"),"General",IF(OR(K19="exemption",K19="other (exemption)"),"Tax exemption/waiver/suspension","Other"))) -> 28 | AK19: =IF(B19<>B18,1,0) -> 0 | AL19: 1
A20: 1 | B20: Australia | C20: 43855 | D20: 43919 | E20: 43951 | F20: =DATEDIF(D20,E20,"D") -> 32 | G20: 43919 | H20: 2020 | I20: 1 | J20: 5 | K20: general | L20: Commonwealth office to share public health costs incurred by States and Territories, estimated at A$544.6 million. | M20: 1 | N20: -1 | O20: -2 | P20: -1 | Q20: -2 | R20: 1 | S20: 1 | T20: 1 | U20: 1 | V20: AUS | W20: East Asia & Pacific | X20: None | Y20: High Income | Z20: 1 | AA20: =IF(M20>0,1,IF(M20<0,0,-1)) -> 1 | AB20: =IF(N20>0,1,IF(N20<0,0,-1)) -> 0 | AC20: =IF(O20>0,1,IF(O20<0,0,-1)) -> 0 | AD20: =IF(P20>0,1,IF(P20<0,0,-1)) -> 0 | AE20: =IF(Q20>0,1,IF(Q20<0,0,-1)) -> 0 | AF20: =IF(R20>0,1,IF(R20<0,0,-1)) -> 1 | AG20: =IF(S20>0,1,IF(S20<0,0,-1)) -> 1 | AH20: =IF(T20>0,1,IF(T20<0,0,-1)) -> 1 | AI20: =IF(U20>0,1,IF(U20<0,0,-1)) -> 1 | AJ20: =IF(ISNUMBER(K20),K20,IF(OR(K20="general",K20="23;general"),"General",IF(OR(K20="exemption",K20="other (exemption)"),"Tax exemption/waiver/suspension","Other"))) -> General | AK20: =IF(B20<>B19,1,0) -> 0 | AL20: 1
A21: 1 | B21: Australia | C21: 43855 | D21: 43919 | E21: 43951 | F21: =DATEDIF(D21,E21,"D") -> 32 | G21: 43919 | H21: 2020 | I21: 1 | J21: 1 | K21: 6 | L21: Deferral: Taxpayers affected by the pandemic are eligible to apply for a deferral of payment of tax liability for up to 6 months without incurring interest or penalties. This deferral may apply to income tax, goods and services tax (GST), fringe benefits tax and excise taxes. Businesses requiring further deferral may be able to access low-interest repayment options. Businesses that vary their PAYG instalment to zero can also claim a refund for any instalments made for the September 2019 and December 2019 quarters. According to the 2020-21 Federal Budget, small, medium and larger businesses with a turnover of up to A$5 billion will be able to write off the full value of eligible assets until June 2022. Losses incurred to June 2022 will also be able to be offset against prior profits made in or after the 2018-19 financial year. The total temporary full expensing will mount to A$31.6bn (1.6% of GDP) over the course of 2020-21/2023-24. | M21: 2 | N21: 2 | O21: 2 | P21: 1 | Q21: 2 | R21: 2 | S21: 1 | T21: 1 | U21: 1 | V21: AUS | W21: East Asia & Pacific | X21: None | Y21: High Income | Z21: 1 | AA21: =IF(M21>0,1,IF(M21<0,0,-1)) -> 1 | AB21: =IF(N21>0,1,IF(N21<0,0,-1)) -> 1 | AC21: =IF(O21>0,1,IF(O21<0,0,-1)) -> 1 | AD21: =IF(P21>0,1,IF(P21<0,0,-1)) -> 1 | AE21: =IF(Q21>0,1,IF(Q21<0,0,-1)) -> 1 | AF21: =IF(R21>0,1,IF(R21<0,0,-1)) -> 1 | AG21: =IF(S21>0,1,IF(S21<0,0,-1)) -> 1 | AH21: =IF(T21>0,1,IF(T21<0,0,-1)) -> 1 | AI21: =IF(U21>0,1,IF(U21<0,0,-1)) -> 1 | AJ21: =IF(ISNUMBER(K21),K21,IF(OR(K21="general",K21="23;general"),"General",IF(OR(K21="exemption",K21="other (exemption)"),"Tax exemption/waiver/suspension","Other"))) -> 6 | AK21: =IF(B21<>B20,1,0) -> 0 | AL21: 1
A22: 1 | B22: Australia | C22: 43855 | D22: 43919 | E22: 43951 | F22: =DATEDIF(D22,E22,"D") -> 32 | G22: 43919 | H22: 2020 | I22: 1 | J22: 9 | K22: 34 | L22: The Government is providing up to A$100,000 to eligible small and medium sized businesses, and not-for-profits (including charities) that employ people, with a minimum payment of A$20,000. These payments will help businesses’ and not-for-profits’ cash flow so they can keep operating, pay their rent, electricity and other bills and retain staff. | M22: 1 | N22: 1 | O22: 1 | P22: -1 | Q22: 2 | R22: 2 | S22: 1 | T22: -2 | U22: 1 | V22: AUS | W22: East Asia & Pacific | X22: None | Y22: High Income | Z22: 1 | AA22: =IF(M22>0,1,IF(M22<0,0,-1)) -> 1 | AB22: =IF(N22>0,1,IF(N22<0,0,-1)) -> 1 | AC22: =IF(O22>0,1,IF(O22<0,0,-1)) -> 1 | AD22: =IF(P22>0,1,IF(P22<0,0,-1)) -> 0 | AE22: =IF(Q22>0,1,IF(Q22<0,0,-1)) -> 1 | AF22: =IF(R22>0,1,IF(R22<0,0,-1)) -> 1 | AG22: =IF(S22>0,1,IF(S22<0,0,-1)) -> 1 | AH22: =IF(T22>0,1,IF(T22<0,0,-1)) -> 0 | AI22: =IF(U22>0,1,IF(U22<0,0,-1)) -> 1 | AJ22: =IF(ISNUMBER(K22),K22,IF(OR(K22="general",K22="23;general"),"General",IF(OR(K22="exemption",K22="other (exemption)"),"Tax exemption/waiver/suspension","Other"))) -> 34 | AK22: =IF(B22<>B21,1,0) -> 0 | AL22: 1
A23: 1 | B23: Australia | C23: 43855 | D23: 43919 | E23: 43951 | F23: =DATEDIF(D23,E23,"D") -> 32 | G23: 43919 | H23: 2020 | I23: 1 | J23: 1 | K23: 3 | L23: Increase the instant asset write-off : instant asset write-off threshold is increased from A$30,000 to A$150,000 with access expanded access to include businesses with aggregated annual turnover of less than A$500 million (up from A$50 million) | M23: -2 | N23: -2 | O23: -2 | P23: -1 | Q23: 2 | R23: -2 | S23: 1 | T23: -2 | U23: 1 | V23: AUS | W23: East Asia & Pacific | X23: None | Y23: High Income | Z23: 1 | AA23: =IF(M23>0,1,IF(M23<0,0,-1)) -> 0 | AB23: =IF(N23>0,1,IF(N23<0,0,-1)) -> 0 | AC23: =IF(O23>0,1,IF(O23<0,0,-1)) -> 0 | AD23: =IF(P23>0,1,IF(P23<0,0,-1)) -> 0 | AE23: =IF(Q23>0,1,IF(Q23<0,0,-1)) -> 1 | AF23: =IF(R23>0,1,IF(R23<0,0,-1)) -> 0 | AG23: =IF(S23>0,1,IF(S23<0,0,-1)) -> 1 | AH23: =IF(T23>0,1,IF(T23<0,0,-1)) -> 0 | AI23: =IF(U23>0,1,IF(U23<0,0,-1)) -> 1 | AJ23: =IF(ISNUMBER(K23),K23,IF(OR(K23="general",K23="23;general"),"General",IF(OR(K23="exemption",K23="other (exemption)"),"Tax exemption/waiver/suspension","Other"))) -> 3 | AK23: =IF(B23<>B22,1,0) -> 0 | AL23: 1
A24: 1 | B24: Australia | C24: 43855 | D24: 43919 | E24: 43951 | F24: =DATEDIF(D24,E24,"D") -> 32 | G24: 43919 | H24: 2020 | I24: 1 | J24: 4 | K24: other | L24: The Commonwealth government will help finance a series of fast-track infrastructure projects across States and Territories (A$3.9 billion) and the arts and screen industries to support job creation under the JobMaker program, 06.10 additional A$73 bn. | V24: AUS | W24: East Asia & Pacific | X24: None | Y24: High Income | Z24: 1 | AA24: -1 | AB24: -1 | AC24: -1 | AD24: -1 | AE24: -1 | AF24: -1 | AG24: -1 | AH24: -1 | AI24: -1 | AJ24: =IF(ISNUMBER(K24),K24,IF(OR(K24="general",K24="23;general"),"General",IF(OR(K24="exemption",K24="other (exemption)"),"Tax exemption/waiver/suspension","Other"))) -> Other | AK24: =IF(B24<>B23,1,0) -> 0 | AL24: 0
A25: 1 | B25: Australia | C25: 43855 | D25: 43919 | E25: 43951 | F25: =DATEDIF(D25,E25,"D") -> 32 | G25: 43919 | H25: 2020 | I25: 1 | J25: 6 | K25: 28 | L25: The Commonwealth government will help finance a home care package to support senior citizens (A$0.3 billion) | V25: AUS | W25: East Asia & Pacific | X25: None | Y25: High Income | Z25: 1 | AA25: -1 | AB25: -1 | AC25: -1 | AD25: -1 | AE25: -1 | AF25: -1 | AG25: -1 | AH25: -1 | AI25: -1 | AJ25: =IF(ISNUMBER(K25),K25,IF(OR(K25="general",K25="23;general"),"General",IF(OR(K25="exemption",K25="other (exemption)"),"Tax exemption/waiver/suspension","Other"))) -> 28 | AK25: =IF(B25<>B24,1,0) -> 0 | AL25: 0
A26: 1 | B26: Australia | C26: 43855 | D26: 43919 | E26: 43951 | F26: =DATEDIF(D26,E26,"D") -> 32 | G26: 43919 | H26: 2020 | I26: 1 | J26: 6 | K26: 26 | L26: The Commonwealth government instituted a new JobTrainer skills package (A$2 billion). | V26: AUS | W26: East Asia & Pacific | X26: None | Y26: High Income | Z26: 1 | AA26: -1 | AB26: -1 | AC26: -1 | AD26: -1 | AE26: -1 | AF26: -1 | AG26: -1 | AH26: -1 | AI26: -1 | AJ26: =IF(ISNUMBER(K26),K26,IF(OR(K26="general",K26="23;general"),"General",IF(OR(K26="exemption",K26="other (exemption)"),"Tax exemption/waiver/suspension","Other"))) -> 26 | AK26: =IF(B26<>B25,1,0) -> 0 | AL26: 0
A27: 1 | B27: Australia | C27: 43855 | D27: 43919 | E27: 43951 | F27: =DATEDIF(D27,E27,"D") -> 32 | G27: 43919 | H27: 2020 | I27: 1 | J27: 6 | K27: 27 | L27: The Government will allow individuals in financial stress as a result of the Coronavirus to access up to $10,000 of their superannuation in 2019-20 and a further $10,000 in 2020-21. Eligible individuals will be able to apply online for access of up to $10,000 of their superannuation before 1 July 2020. Minimum superannuation drawdown requirements have also been reduced and social security deeming rates (the rate of income beneficiaries are assumed to be earning from financial investments) have also been reduced. | V27: AUS | W27: East Asia & Pacific | X27: None | Y27: High Income | Z27: 1 | AA27: -1 | AB27: -1 | AC27: -1 | AD27: -1 | AE27: -1 | AF27: -1 | AG27: -1 | AH27: -1 | AI27: -1 | AJ27: =IF(ISNUMBER(K27),K27,IF(OR(K27="general",K27="23;general"),"General",IF(OR(K27="exemption",K27="other (exemption)"),"Tax exemption/waiver/suspension","Other"))) -> 27 | AK27: =IF(B27<>B26,1,0) -> 0 | AL27: 0
A28: 1 | B28: Australia | C28: 43855 | D28: 43919 | E28: 43951 | F28: =DATEDIF(D28,E28,"D") -> 32 | G28: 43919 | H28: 2020 | I28: 1 | J28: 6 | K28: 27 | L28: The Government is temporarily reducing superannuation minimum drawdown requirements for account based pensions and similar products by 50 per cent for 2019-20 and 2020-21. This measure will benefit retirees by providing them with more flexibility as to how they manage their superannuation assets. | V28: AUS | W28: East Asia & Pacific | X28: None | Y28: High Income | Z28: 1 | AA28: -1 | AB28: -1 | AC28: -1 | AD28: -1 | AE28: -1 | AF28: -1 | AG28: -1 | AH28: -1 | AI28: -1 | AJ28: =IF(ISNUMBER(K28),K28,IF(OR(K28="general",K28="23;general"),"General",IF(OR(K28="exemption",K28="other (exemption)"),"Tax exemption/waiver/suspension","Other"))) -> 27 | AK28: =IF(B28<>B27,1,0) -> 0 | AL28: 0
A29: 1 | B29: Australia | C29: 43855 | D29: 43919 | E29: 43951 | F29: =DATEDIF(D29,E29,"D") -> 32 | G29: 43919 | H29: 2020 | I29: 1 | J29: 3 | K29: 19 | L29: VAT tax rate reduction from 20% to 0% for respiratory masks for deliveries and intra-Community purchases. | V29: AUS | W29: East Asia & Pacific | X29: None | Y29: High Income | Z29: 1 | AA29: -1 | AB29: -1 | AC29: -1 | AD29: -1 | AE29: -1 | AF29: -1 | AG29: -1 | AH29: -1 | AI29: -1 | AJ29: =IF(ISNUMBER(K29),K29,IF(OR(K29="general",K29="23;general"),"General",IF(OR(K29="exemption",K29="other (exemption)"),"Tax exemption/waiver/suspension","Other"))) -> 19 | AK29: =IF(B29<>B28,1,0) -> 0 | AL29: 0
A30: 1 | B30: Australia | C30: 43855 | D30: 43919 | E30: 43951 | F30: =DATEDIF(D30,E30,"D") -> 32 | G30: 43919 | H30: 2020 | I30: 1 | J30: 6 | K30: 27 | L30: There has been a temporary expansion of eligibility for income support payments (the JobSeeker Programme) and the establishment of a new, time-limited Coronavirus supplement to be paid at a rate of A$550 per fortnight until the end of September 2020. This will be paid to both existing and new recipients of various government benefits. On 21 July, the government announced that the supplementary payment will be extended to the end of December 2020, but that the size of the payment will be reduced to A$250 per fortnight. New arrangements for the supplement are expected to cost A$3.8 billion. | V30: AUS | W30: East Asia & Pacific | X30: None | Y30: High Income | Z30: 1 | AA30: -1 | AB30: -1 | AC30: -1 | AD30: -1 | AE30: -1 | AF30: -1 | AG30: -1 | AH30: -1 | AI30: -1 | AJ30: =IF(ISNUMBER(K30),K30,IF(OR(K30="general",K30="23;general"),"General",IF(OR(K30="exemption",K30="other (exemption)"),"Tax exemption/waiver/suspension","Other"))) -> 27 | AK30: =IF(B30<>B29,1,0) -> 0 | AL30: 0
A31: 1 | B31: Australia | C31: 43855 | D31: 43919 | E31: 43951 | F31: =DATEDIF(D31,E31,"D") -> 32 | G31: 43919 | H31: 2020 | I31: 1 | J31: 6 | K31: 25 | L31: On August 3, in response to a rise in COVID-19 cases and tighter confinement measures announced in Victoria, the Federal Government announced $1,500 "disaster payment" for workers who are required to self-isolate because of coronavirus but do not have leave entitlements. | V31: AUS | W31: East Asia & Pacific | X31: None | Y31: High Income | Z31: 1 | AA31: -1 | AB31: -1 | AC31: -1 | AD31: -1 | AE31: -1 | AF31: -1 | AG31: -1 | AH31: -1 | AI31: -1 | AJ31: =IF(ISNUMBER(K31),K31,IF(OR(K31="general",K31="23;general"),"General",IF(OR(K31="exemption",K31="other (exemption)"),"Tax exemption/waiver/suspension","Other"))) -> 25 | AK31: =IF(B31<>B30,1,0) -> 0 | AL31: 0
A32: 1 | B32: Australia | C32: 43855 | D32: 43919 | E32: 43951 | F32: =DATEDIF(D32,E32,"D") -> 32 | G32: 43919 | H32: 2020 | I32: 1 | J32: 6 | K32: 29 | L32: Across a large range of work types (103 of the 121 modern awards), employees will receive two weeks of unpaid pandemic leave. The covered employees will also be allowed to take double the duration of annual leave at half pay. | V32: AUS | W32: East Asia & Pacific | X32: None | Y32: High Income | Z32: 1 | AA32: -1 | AB32: -1 | AC32: -1 | AD32: -1 | AE32: -1 | AF32: -1 | AG32: -1 | AH32: -1 | AI32: -1 | AJ32: =IF(ISNUMBER(K32),K32,IF(OR(K32="general",K32="23;general"),"General",IF(OR(K32="exemption",K32="other (exemption)"),"Tax exemption/waiver/suspension","Other"))) -> 29 | AK32: =IF(B32<>B31,1,0) -> 0 | AL32: 0
A33: 1 | B33: Australia | C33: 43855 | D33: 43919 | E33: 43951 | F33: =DATEDIF(D33,E33,"D") -> 32 | G33: 43919 | H33: 2021 | I33: 1 | J33: 6 | K33: 29 | L33: On 2 April, a subsidy to childcare providers was announced, conditional on them staying open and not charging families for care. The Commonwealth Government will pay 50 per cent of the sector's fee revenue up to the existing hourly rate cap. The funding will apply from 6 April based on the number of children who were in care during the fortnight leading into 2 March, whether or not they are attending services. The existing arrangements will end in mid-July and be replaced by a three month A$708 million support package to the childcare sector. Families will return to paying for childcare, with the reintroduction of the Child Care Subsidy, but the criteria for families impacted by the economic downturn will be loosened. | V33: AUS | AA33: 1 | AB33: -1 | AC33: -1 | AD33: -1 | AE33: 1 | AF33: 1 | AG33: 1 | AH33: 1 | AI33: 1 | AJ33: =IF(ISNUMBER(K33),K33,IF(OR(K33="general",K33="23;general"),"General",IF(OR(K33="exemption",K33="other (exemption)"),"Tax exemption/waiver/suspension","Other"))) -> 29
A34: 1 | B34: Australia | C34: 43855 | D34: 43919 | E34: 43951 | F34: =DATEDIF(D34,E34,"D") -> 32 | G34: 43919 | H34: 2021 | I34: 1 | J34: 6 | K34: 25 | L34: Aged pensioners will receive an additional A$250 payment from December 2020 and a further A$250 payment from March 2021 according to the 2020-21 Federal Budget announced on 6 October. | V34: AUS | AA34: 1 | AB34: -1 | AC34: 1 | AD34: -1 | AE34: 1 | AF34: 1 | AG34: 1 | AH34: 1 | AI34: 1 | AJ34: =IF(ISNUMBER(K34),K34,IF(OR(K34="general",K34="23;general"),"General",IF(OR(K34="exemption",K34="other (exemption)"),"Tax exemption/waiver/suspension","Other"))) -> 25
A35: 1 | B35: Australia | C35: 43855 | D35: 43919 | E35: 43951 | F35: =DATEDIF(D35,E35,"D") -> 32 | G35: 43919 | H35: 2021 | I35: 1 | J35: 4 | K35: other | L35: The government has also announced the HomeBuilder programme to support residential construction activity in the second half of 2020. The programme will provide all eligible owner-occupiers with a grant of A$25,000 to build a new home or substantially renovate an existing home. Construction must be contracted to commence within three months of the contract date. Applicants are subject to eligibility criteria, including caps on household income and the price of a new home or renovation. The program is expected to provide around 27,000 grants at a total cost of around A$680 million. | V35: AUS | AA35: 1 | AB35: -1 | AC35: -1 | AD35: -1 | AE35: 1 | AF35: 1 | AG35: 1 | AH35: 1 | AI35: 1 | AJ35: =IF(ISNUMBER(K35),K35,IF(OR(K35="general",K35="23;general"),"General",IF(OR(K35="exemption",K35="other (exemption)"),"Tax exemption/waiver/suspension","Other"))) -> Other
A36: 1 | B36: Australia | C36: 43855 | D36: 43919 | E36: 43951 | F36: =DATEDIF(D36,E36,"D") -> 32 | G36: 43919 | H36: 2021 | I36: 1 | J36: 4 | K36: other | L36: According to the 2020-21 Federal Budget, an additional A$1 billion of low cost finance will be spent to support the construction of affordable housing. | V36: AUS | AA36: 1 | AB36: -1 | AC36: 1 | AD36: 1 | AE36: 1 | AF36: 1 | AG36: 1 | AH36: 1 | AI36: 1 | AJ36: =IF(ISNUMBER(K36),K36,IF(OR(K36="general",K36="23;general"),"General",IF(OR(K36="exemption",K36="other (exemption)"),"Tax exemption/waiver/suspension","Other"))) -> Other
A37: 1 | B37: Australia | C37: 43855 | D37: 43919 | E37: 43951 | F37: =DATEDIF(D37,E37,"D") -> 32 | G37: 43919 | H37: 2021 | I37: 1 | J37: 2 | K37: 15 | L37: Additional tax reduction for low and middle income households 11. Mai 2021 | V37: AUS | AA37: 1 | AB37: -1 | AC37: -1 | AD37: -1 | AE37: 1 | AF37: 1 | AG37: 1 | AH37: 1 | AI37: 1 | AJ37: =IF(ISNUMBER(K37),K37,IF(OR(K37="general",K37="23;general"),"General",IF(OR(K37="exemption",K37="other (exemption)"),"Tax exemption/waiver/suspension","Other"))) -> 15
A38: 1 | B38: Australia | C38: 43855 | D38: 43919 | E38: 43951 | F38: =DATEDIF(D38,E38,"D") -> 32 | G38: 43919 | H38: 2021 | I38: 1 | J38: 4 | K38: other | L38: Additional Investestments into Infrastructure 11.Mai 2021 | V38: AUS | AA38: -1 | AB38: -1 | AC38: -1 | AD38: -1 | AE38: -1 | AF38: -1 | AG38: 1 | AH38: -1 | AI38: 1 | AJ38: =IF(ISNUMBER(K38),K38,IF(OR(K38="general",K38="23;general"),"General",IF(OR(K38="exemption",K38="other (exemption)"),"Tax exemption/waiver/suspension","Other"))) -> Other
A39: 1 | B39: Australia | C39: 43855 | D39: 43919 | E39: 43951 | F39: =DATEDIF(D39,E39,"D") -> 32 | G39: 43919 | H39: 2021 | I39: 1 | J39: 5 | K39: 22 | L39: A$7 bn. for vaccines | V39: AUS | AA39: -1 | AB39: -1 | AC39: -1 | AD39: -1 | AE39: -1 | AF39: -1 | AG39: 1 | AH39: -1 | AI39: 1 | AJ39: =IF(ISNUMBER(K39),K39,IF(OR(K39="general",K39="23;general"),"General",IF(OR(K39="exemption",K39="other (exemption)"),"Tax exemption/waiver/suspension","Other"))) -> 22
A40: 1 | B40: Australia | C40: 43855 | D40: 43919 | E40: 43951 | F40: =DATEDIF(D40,E40,"D") -> 32 | G40: 43919 | H40: 2021 | I40: 1 | J40: 7 | K40: 30 | L40: Coronavirus SME Guarantee → SME Recovery Loan Scheme (2021/22) – Fortsetzung/Neuauflage mit hoeherer Garantie (bis 80% in 2021; 50% in 2022). | AJ40: =IF(ISNUMBER(K40),K40,IF(OR(K40="general",K40="23;general"),"General",IF(OR(K40="exemption",K40="other (exemption)"),"Tax exemption/waiver/suspension","Other"))) -> 30
...

Sheet Mapping
A1: PolicyCode | B1: PolicyName | C1: PolicyCategory | D1: IMF_Classification | E1: Notes
A2: 1 | B2: Accelerated asset depreciation (CIT) | C2: 1 Revenue Measures to protect businesses | D2: On-Budget | E2: Parameteraenderung der Steuerbasis; Mindereinnahmen. Auch temporaer On-Budget (Timing-Effekt).
A3: 2 | B3: Extend loss carry-forward (CIT) | C3: 1 Revenue Measures to protect businesses | D3: On-Budget | E3: Reduziert kuenftige Steuerbasis; Mindereinnahmen.
A4: 3 | B4: Broaden tax deductibility | C4: 1 Revenue Measures to protect businesses | D4: On-Budget | E4: Parameteraenderung; Mindereinnahmen.
A5: 4 | B5: Tax credits | C5: 1 Revenue Measures to protect businesses | D5: On-Budget | E5: Anrechenbare/auszahlbare Credits; Mindereinnahmen/Ausgaben.
A6: 5 | B6: Deferral of tax filing | C6: 1 Revenue Measures to protect businesses | D6: Off-Budget | E6: Timing/Verwaltung; keine Accrual-Wirkung.
A7: 6 | B7: Deferral of tax payments | C7: 1 Revenue Measures to protect businesses | D7: Off-Budget | E7: Stundung; Liquiditaetsmassnahme.
A8: 7 | B8: Tax rate reduction | C8: 1 Revenue Measures to protect businesses | D8: On-Budget | E8: Mindereinnahmen durch niedrigere Saetze.
A9: 8 | B9: Tax amnesty / incentives | C9: 1 Revenue Measures to protect businesses | D9: On-Budget | E9: Erlass/Reduktion von Steuerschulden = Mindereinnahmen.
A10: 9 | B10: Accelerating refunds | C10: 1 Revenue Measures to protect businesses | D10: Off-Budget | E10: Vorgezogene Rueckerstattungen; Timing-Effekt.
A11: 10 | B11: Lower advance payment | C11: 1 Revenue Measures to protect businesses | D11: Off-Budget | E11: Niedrigere Akontos; Timing/Liquiditaet.
A12: 11 | B12: Suspend debt collection | C12: 1 Revenue Measures to protect businesses | D12: Off-Budget | E12: Vollstreckung ausgesetzt; Timing/Verwaltung.
A13: 12 | B13: Suspend audit activities | C13: 1 Revenue Measures to protect businesses | D13: Off-Budget | E13: Verwaltungsakt; keine unmittelbare Accrual-Wirkung.
A14: exemption | B14: Tax exemption/waiver/suspension | C14: 1 Revenue Measures to protect businesses | D14: Split (see notes) | E14: Echte Befreiung/Erlass = On-Budget; blosse Suspension/Stundung = Off-Budget.
A15: other | B15: Other | C15: 1 Revenue Measures to protect businesses | D15: Context-dependent | E15: Parameteraenderung → On-Budget; reine Timing/Admin → Off-Budget.
A16: 13 | B16: Deferral of tax filing | C16: 2 Revenue Measures to protect individuals | D16: Off-Budget | E16: Wie Code 5; Timing/Verwaltung.
A17: 14 | B17: Deferral of tax payments | C17: 2 Revenue Measures to protect individuals | D17: Off-Budget | E17: Wie Code 6; Stundung.
A18: 15 | B18: Tax rate reduction | C18: 2 Revenue Measures to protect individuals | D18: On-Budget | E18: Mindereinnahmen.
A19: 16 | B19: Tax amnesty / incentives | C19: 2 Revenue Measures to protect individuals | D19: On-Budget | E19: Erlass/Reduktion; Mindereinnahmen.
A20: 17 | B20: Broaden tax deductibility | C20: 2 Revenue Measures to protect individuals | D20: On-Budget | E20: Parameteraenderung; Mindereinnahmen.
A21: 18 | B21: Tax credits | C21: 2 Revenue Measures to protect individuals | D21: On-Budget | E21: Anrechenbare/auszahlbare Credits; Mindereinnahmen/Ausgaben.
A22: exemption | B22: Tax exemption/waiver/suspension | C22: 2 Revenue Measures to protect individuals | D22: Split (see notes) | E22: Befreiung/Erlass = On-Budget; Suspension/Stundung = Off-Budget.
A23: other | B23: Other | C23: 2 Revenue Measures to protect individuals | D23: Context-dependent | E23: Parameteraenderung → On-Budget; reine Timing/Admin → Off-Budget.
A24: 19 | B24: Lower tax rates for medical items | C24: 3 Revenue Measures to promote availability of medical items | D24: On-Budget | E24: Gezielte Mindereinnahmen.
A25: exemption | B25: Tax exemption/waiver/suspension | C25: 3 Revenue Measures to promote availability of medical items | D25: Split (see notes) | E25: Befreiung/Erlass = On-Budget; Suspension/Stundung = Off-Budget.
A26: other | B26: Other | C26: 3 Revenue Measures to promote availability of medical items | D26: Context-dependent | E26: Parameteraenderung → On-Budget; reine Timing/Admin → Off-Budget.
A27: 20 | B27: Lower tax rates | C27: 4 Revenue Measures to boost consumption / demand | D27: On-Budget | E27: Mindereinnahmen (z. B. Mehrwertsteuer).
A28: exemption | B28: Tax exemption/waiver/suspension | C28: 4 Revenue Measures to boost consumption / demand | D28: Split (see notes) | E28: Befreiung/Erlass = On-Budget; Suspension/Stundung = Off-Budget.
A29: other | B29: Other | C29: 4 Revenue Measures to boost consumption / demand | D29: Context-dependent | E29: Parameteraenderung → On-Budget; reine Timing/Admin → Off-Budget.
A30: 21 | B30: Supply of low cost medical items | C30: 5 Health Expenditures measures | D30: On-Budget | E30: Zusaetzliche Sachausgaben.
A31: 22 | B31: Supply of high cost medical items | C31: 5 Health Expenditures measures | D31: On-Budget | E31: Investitionen/hohe Ausgaben.
A32: 23 | B32: Targeted infrastructure investments | C32: 5 Health Expenditures measures | D32: On-Budget | E32: Oeffentliche Investitionen (CapEx).
A33: 24 | B33: Expansion of human resources | C33: 5 Health Expenditures measures | D33: On-Budget | E33: Personal-/Betriebsausgaben.
A34: general | B34: General | C34: 5 Health Expenditures measures | D34: On-Budget | E34: Allgemeine Gesundheitsausgaben.
A35: 25 | B35: Direct cash transfers for individuals | C35: 6 Expenditure Measures for cash transfers to individuals | D35: On-Budget | E35: Transfers erhoehen Ausgaben.
A36: 26 | B36: Expansion of unemployment benefits | C36: 6 Expenditure Measures for cash transfers to individuals | D36: On-Budget | E36: Hoehere Sozialausgaben.
A37: 27 | B37: Temporary expansion of existing benefits | C37: 6 Expenditure Measures for cash transfers to individuals | D37: On-Budget | E37: Hoehere Transfers.
A38: 28 | B38: Supplementary ad hoc programs | C38: 6 Expenditure Measures for cash transfers to individuals | D38: On-Budget | E38: Zusaetzliche Programme/Transfers.
A39: 29 | B39: Wage compensation/ enhanced paid leave | C39: 6 Expenditure Measures for cash transfers to individuals | D39: On-Budget | E39: Subventionen/Transfers.
A40: other | B40: Other | C40: 6 Expenditure Measures for cash transfers to individuals | D40: On-Budget | E40: Andere monetare Transfers/Subventionen.
...

Sheet Makro Analysis Count per 2 
A1: PolicyCategory | B1: PolicyCode | C1: Gruppe 0 | D1: Gruppe 1 | E1: Gruppe 0 Share | F1: Gruppe 1 Share | G1: Gruppe 0 pro Land | H1: Gruppe 1 pro Land | I1: Gruppe 0 pro Mio GDP $ ppp | J1: Gruppe 1 pro Mio GDP $ ppp | K1: Gruppe 0 pro Mio GDP $ | L1: Gruppe 1 pro Mio GDP $ | M1: Gruppe 0 pro 100'000 Einwohnende | N1: Gruppe 1 pro 100'000 Einwohnende | O1: Gruppe 0 pro Capita ppp | P1: Gruppe 1 per Capita ppp
A2: 1 | B2: 1 | C2: 3 | D2: 5 | E2: =C2/(C2+D2) -> 0.375 | F2: =1-E2 -> 0.625 | G2: =C2/23 -> 0.13043478 | H2: =D2/15 -> 0.33333333 | I2: =(C2/B$80)*1000 -> 0.15947235 | J2: =(D2/B$81)*1000 -> 0.12590638 | K2: =(C2/D$80)*1000 -> 0.19814443 | L2: =(D2/D$81)*1000 -> 0.13736294 | M2: =(C2/C$84)*100000 -> 0.013436818 | N2: =(D2/D$84)*100000 -> 0.0088376331 | O2: =C2/E$80 -> 0.35604936 | P2: =D2/E$81 -> 0.71233091
A3: 1 | B3: 10 | C3: 12 | D3: 11 | E3: =C3/(C3+D3) -> 0.52173913 | F3: =1-E3 -> 0.47826087 | G3: =C3/23 -> 0.52173913 | H3: =D3/15 -> 0.73333333 | I3: =(C3/B$80)*1000 -> 0.63788939 | J3: =(D3/B$81)*1000 -> 0.27699405 | K3: =(C3/D$80)*1000 -> 0.79257771 | L3: =(D3/D$81)*1000 -> 0.30219848 | M3: =(C3/C$84)*100000 -> 0.053747271 | N3: =(D3/D$84)*100000 -> 0.019442793 | O3: =C3/E$80 -> 1.4241975 | P3: =D3/E$81 -> 1.567128
A4: 1 | B4: 11 | C4: 8 | D4: 15 | E4: =C4/(C4+D4) -> 0.34782609 | F4: =1-E4 -> 0.65217391 | G4: =C4/23 -> 0.34782609 | H4: =D4/15 -> 1 | I4: =(C4/B$80)*1000 -> 0.42525959 | J4: =(D4/B$81)*1000 -> 0.37771915 | K4: =(C4/D$80)*1000 -> 0.52838514 | L4: =(D4/D$81)*1000 -> 0.41208883 | M4: =(C4/C$84)*100000 -> 0.035831514 | N4: =(D4/D$84)*100000 -> 0.026512899 | O4: =C4/E$80 -> 0.94946497 | P4: =D4/E$81 -> 2.1369927
A5: 1 | B5: 12 | C5: 7 | D5: 7 | E5: =C5/(C5+D5) -> 0.5 | F5: =1-E5 -> 0.5 | G5: =C5/23 -> 0.30434783 | H5: =D5/15 -> 0.46666667 | I5: =(C5/B$80)*1000 -> 0.37210214 | J5: =(D5/B$81)*1000 -> 0.17626894 | K5: =(C5/D$80)*1000 -> 0.46233699 | L5: =(D5/D$81)*1000 -> 0.19230812 | M5: =(C5/C$84)*100000 -> 0.031352575 | N5: =(D5/D$84)*100000 -> 0.012372686 | O5: =C5/E$80 -> 0.83078185 | P5: =D5/E$81 -> 0.99726327
A6: 1 | B6: 2 | C6: 6 | D6: 7 | E6: =C6/(C6+D6) -> 0.46153846 | F6: =1-E6 -> 0.53846154 | G6: =C6/23 -> 0.26086957 | H6: =D6/15 -> 0.46666667 | I6: =(C6/B$80)*1000 -> 0.31894469 | J6: =(D6/B$81)*1000 -> 0.17626894 | K6: =(C6/D$80)*1000 -> 0.39628885 | L6: =(D6/D$81)*1000 -> 0.19230812 | M6: =(C6/C$84)*100000 -> 0.026873635 | N6: =(D6/D$84)*100000 -> 0.012372686 | O6: =C6/E$80 -> 0.71209873 | P6: =D6/E$81 -> 0.99726327
A7: 1 | B7: 3 | C7: 16 | D7: 8 | E7: =C7/(C7+D7) -> 0.66666667 | F7: =1-E7 -> 0.33333333 | G7: =C7/23 -> 0.69565217 | H7: =D7/15 -> 0.53333333 | I7: =(C7/B$80)*1000 -> 0.85051918 | J7: =(D7/B$81)*1000 -> 0.20145022 | K7: =(C7/D$80)*1000 -> 1.0567703 | L7: =(D7/D$81)*1000 -> 0.21978071 | M7: =(C7/C$84)*100000 -> 0.071663028 | N7: =(D7/D$84)*100000 -> 0.014140213 | O7: =C7/E$80 -> 1.8989299 | P7: =D7/E$81 -> 1.1397295 | R7: ad-hoc programme
A8: 1 | B8: 4 | C8: 8 | D8: 20 | E8: =C8/(C8+D8) -> 0.28571429 | F8: =1-E8 -> 0.71428571 | G8: =C8/23 -> 0.34782609 | H8: =D8/15 -> 1.3333333 | I8: =(C8/B$80)*1000 -> 0.42525959 | J8: =(D8/B$81)*1000 -> 0.50362554 | K8: =(C8/D$80)*1000 -> 0.52838514 | L8: =(D8/D$81)*1000 -> 0.54945178 | M8: =(C8/C$84)*100000 -> 0.035831514 | N8: =(D8/D$84)*100000 -> 0.035350533 | O8: =C8/E$80 -> 0.94946497 | P8: =D8/E$81 -> 2.8493236
A9: 1 | B9: 5 | C9: 13 | D9: 10 | E9: =C9/(C9+D9) -> 0.56521739 | F9: =1-E9 -> 0.43478261 | G9: =C9/23 -> 0.56521739 | H9: =D9/15 -> 0.66666667 | I9: =(C9/B$80)*1000 -> 0.69104684 | J9: =(D9/B$81)*1000 -> 0.25181277 | K9: =(C9/D$80)*1000 -> 0.85862585 | L9: =(D9/D$81)*1000 -> 0.27472589 | M9: =(C9/C$84)*100000 -> 0.05822621 | N9: =(D9/D$84)*100000 -> 0.017675266 | O9: =C9/E$80 -> 1.5428806 | P9: =D9/E$81 -> 1.4246618
A10: 1 | B10: 6 | C10: 77 | D10: 66 | E10: =C10/(C10+D10) -> 0.53846154 | F10: =1-E10 -> 0.46153846 | G10: =C10/23 -> 3.3478261 | H10: =D10/15 -> 4.4 | I10: =(C10/B$80)*1000 -> 4.0931236 | J10: =(D10/B$81)*1000 -> 1.6619643 | K10: =(C10/D$80)*1000 -> 5.0857069 | L10: =(D10/D$81)*1000 -> 1.8131909 | M10: =(C10/C$84)*100000 -> 0.34487832 | N10: =(D10/D$84)*100000 -> 0.11665676 | O10: =C10/E$80 -> 9.1386003 | P10: =D10/E$81 -> 9.402768
A11: 1 | B11: 7 | C11: 24 | D11: 20 | E11: =C11/(C11+D11) -> 0.54545455 | F11: =1-E11 -> 0.45454545 | G11: =C11/23 -> 1.0434783 | H11: =D11/15 -> 1.3333333 | I11: =(C11/B$80)*1000 -> 1.2757788 | J11: =(D11/B$81)*1000 -> 0.50362554 | K11: =(C11/D$80)*1000 -> 1.5851554 | L11: =(D11/D$81)*1000 -> 0.54945178 | M11: =(C11/C$84)*100000 -> 0.10749454 | N11: =(D11/D$84)*100000 -> 0.035350533 | O11: =C11/E$80 -> 2.8483949 | P11: =D11/E$81 -> 2.8493236
A12: 1 | B12: 8 | C12: 15 | D12: 3 | E12: =C12/(C12+D12) -> 0.83333333 | F12: =1-E12 -> 0.16666667 | G12: =C12/23 -> 0.65217391 | H12: =D12/15 -> 0.2 | I12: =(C12/B$80)*1000 -> 0.79736173 | J12: =(D12/B$81)*1000 -> 0.075543831 | K12: =(C12/D$80)*1000 -> 0.99072213 | L12: =(D12/D$81)*1000 -> 0.082417766 | M12: =(C12/C$84)*100000 -> 0.067184089 | N12: =(D12/D$84)*100000 -> 0.0053025799 | O12: =C12/E$80 -> 1.7802468 | P12: =D12/E$81 -> 0.42739854
A13: 1 | B13: 9 | C13: 13 | D13: 10 | E13: =C13/(C13+D13) -> 0.56521739 | F13: =1-E13 -> 0.43478261 | G13: =C13/23 -> 0.56521739 | H13: =D13/15 -> 0.66666667 | I13: =(C13/B$80)*1000 -> 0.69104684 | J13: =(D13/B$81)*1000 -> 0.25181277 | K13: =(C13/D$80)*1000 -> 0.85862585 | L13: =(D13/D$81)*1000 -> 0.27472589 | M13: =(C13/C$84)*100000 -> 0.05822621 | N13: =(D13/D$84)*100000 -> 0.017675266 | O13: =C13/E$80 -> 1.5428806 | P13: =D13/E$81 -> 1.4246618
A14: 1 | B14: exemption | C14: 38 | D14: 26 | E14: =C14/(C14+D14) -> 0.59375 | F14: =1-E14 -> 0.40625 | G14: =C14/23 -> 1.6521739 | H14: =D14/15 -> 1.7333333 | I14: =(C14/B$80)*1000 -> 2.0199831 | J14: =(D14/B$81)*1000 -> 0.6547132 | K14: =(C14/D$80)*1000 -> 2.5098294 | L14: =(D14/D$81)*1000 -> 0.71428731 | M14: =(C14/C$84)*100000 -> 0.17019969 | N14: =(D14/D$84)*100000 -> 0.045955692 | O14: =C14/E$80 -> 4.5099586 | P14: =D14/E$81 -> 3.7041207
A15: 1 | B15: other | C15: 1 | D15: 7 | E15: =C15/(C15+D15) -> 0.125 | F15: =1-E15 -> 0.875 | G15: =C15/23 -> 0.043478261 | H15: =D15/15 -> 0.46666667 | I15: =(C15/B$80)*1000 -> 0.053157449 | J15: =(D15/B$81)*1000 -> 0.17626894 | K15: =(C15/D$80)*1000 -> 0.066048142 | L15: =(D15/D$81)*1000 -> 0.19230812 | M15: =(C15/C$84)*100000 -> 0.0044789392 | N15: =(D15/D$84)*100000 -> 0.012372686 | O15: =C15/E$80 -> 0.11868312 | P15: =D15/E$81 -> 0.99726327
A16: 2 | B16: 13 | C16: 4 | D16: 3 | E16: =C16/(C16+D16) -> 0.57142857 | F16: =1-E16 -> 0.42857143 | G16: =C16/23 -> 0.17391304 | H16: =D16/15 -> 0.2 | I16: =(C16/B$80)*1000 -> 0.2126298 | J16: =(D16/B$81)*1000 -> 0.075543831 | K16: =(C16/D$80)*1000 -> 0.26419257 | L16: =(D16/D$81)*1000 -> 0.082417766 | M16: =(C16/C$84)*100000 -> 0.017915757 | N16: =(D16/D$84)*100000 -> 0.0053025799 | O16: =C16/E$80 -> 0.47473248 | P16: =D16/E$81 -> 0.42739854
A17: 2 | B17: 14 | C17: 13 | D17: 18 | E17: =C17/(C17+D17) -> 0.41935484 | F17: =1-E17 -> 0.58064516 | G17: =C17/23 -> 0.56521739 | H17: =D17/15 -> 1.2 | I17: =(C17/B$80)*1000 -> 0.69104684 | J17: =(D17/B$81)*1000 -> 0.45326298 | K17: =(C17/D$80)*1000 -> 0.85862585 | L17: =(D17/D$81)*1000 -> 0.4945066 | M17: =(C17/C$84)*100000 -> 0.05822621 | N17: =(D17/D$84)*100000 -> 0.031815479 | O17: =C17/E$80 -> 1.5428806 | P17: =D17/E$81 -> 2.5643913
A18: 2 | B18: 15 | C18: 7 | D18: 2 | E18: =C18/(C18+D18) -> 0.77777778 | F18: =1-E18 -> 0.22222222 | G18: =C18/23 -> 0.30434783 | H18: =D18/15 -> 0.13333333 | I18: =(C18/B$80)*1000 -> 0.37210214 | J18: =(D18/B$81)*1000 -> 0.050362554 | K18: =(C18/D$80)*1000 -> 0.46233699 | L18: =(D18/D$81)*1000 -> 0.054945178 | M18: =(C18/C$84)*100000 -> 0.031352575 | N18: =(D18/D$84)*100000 -> 0.0035350533 | O18: =C18/E$80 -> 0.83078185 | P18: =D18/E$81 -> 0.28493236
A19: 2 | B19: 16 | C19: 2 | D19: 2 | E19: =C19/(C19+D19) -> 0.5 | F19: =1-E19 -> 0.5 | G19: =C19/23 -> 0.086956522 | H19: =D19/15 -> 0.13333333 | I19: =(C19/B$80)*1000 -> 0.1063149 | J19: =(D19/B$81)*1000 -> 0.050362554 | K19: =(C19/D$80)*1000 -> 0.13209628 | L19: =(D19/D$81)*1000 -> 0.054945178 | M19: =(C19/C$84)*100000 -> 0.0089578785 | N19: =(D19/D$84)*100000 -> 0.0035350533 | O19: =C19/E$80 -> 0.23736624 | P19: =D19/E$81 -> 0.28493236
... A45: other | B45: other | C45: 1 | D45: 1 | E45: =C45/(C45+D45) -> 0.5 | F45: =1-E45 -> 0.5 | G45: =C45/23 -> 0.043478261 | H45: =D45/15 -> 0.066666667 | I45: =(C45/B$80)*1000 -> 0.053157449 | J45: =(D45/B$81)*1000 -> 0.025181277 | K45: =(C45/D$80)*1000 -> 0.066048142 | L45: =(D45/D$81)*1000 -> 0.027472589 | M45: =(C45/C$84)*100000 -> 0.0044789392 | N45: =(D45/D$84)*100000 -> 0.0017675266 | O45: =C45/E$80 -> 0.11868312 | P45: =D45/E$81 -> 0.14246618
C76: =C77/23 -> 37.173913 | D76: =D77/15 -> 49.133333
C77: =SUM(C2:C44) -> 855 | D77: =SUM(D2:D44) -> 737
B78: in 10'000 CHF
A79: Group | B79: pre Covid real GDP ppp (2019) | C79: pre Covid real GDP usd (2019) | E79: ppp per Capita | F79: real per Capita
A80: 0 | B80: 18812.039 | D80: 15140.471 | E80: =(B80/C84)*10000 -> 8.425798 | F80: =B80/D84 -> 0.0003325078
A81: 1 | B81: 39712.045 | D81: 36399.919 | E81: =(B81/D84)*10000 -> 7.0192097 | F81: =D81/D84 -> 0.00064337826
A83: AUS | B83: 25334826 | C83: Gruppe 0 | D83: Gruppe 1
A84: AUT | B84: 8877637 | C84: 22326715 | D84: 56576234
A85: BEL | B85: 11489000
A86: CAN | B86: 37618495
A87: CHE | B87: 8575280
A88: CHL | B88: 19107216
A89: COL | B89: 48322807
A90: CRI | B90: 5055238
A91: CZE | B91: 10550313
A92: DEU | B92: 83093000
A93: DNK | B93: 5816940
A94: ESP | B94: 47105358
A95: EST | B95: 1324820
A96: FIN | B96: 5521600
...

Sheet Makro Analysis Count per
A1: PolicyCode | B1: Beschreibung (Beispiel) | C1: Gruppe 0 | D1: Gruppe 1 | E1: Gruppe 0 Share | F1: Gruppe 1 Share | G1: Gruppe 0 pro Land | H1: Gruppe 1 pro Land | I1: Gruppe 0 pro Mio GDP $ ppp | J1: Gruppe 1 pro Mio GDP $ ppp | K1: Gruppe 0 pro Mio GDP $ | L1: Gruppe 1 pro Mio GDP $ | M1: Gruppe 0 pro 100'000 Einwohnende | N1: Gruppe 1 pro 100'000 Einwohnende | O1: Gruppe 0 pro Capita ppp | P1: Gruppe 1 per Capita ppp
A2: other | B2: Sonstige Maßnahmen (nicht klass.) | C2: 112 | D2: 83 | E2: =C2/(C2+D2) -> 0.57435897 | F2: =1-E2 -> 0.42564103 | G2: =C2/23 -> 4.8695652 | H2: =D2/15 -> 5.5333333 | I2: =(C2/B$45)*1000 -> 5.9536343 | J2: =(D2/B$46)*1000 -> 2.090046 | K2: =(C2/D$45)*1000 -> 7.3973919 | L2: =(D2/D$46)*1000 -> 2.2802249 | M2: =(C2/C$49)*100000 -> 0.5016412 | N2: =(D2/D$49)*100000 -> 0.14670471 | O2: =C2/E$45 -> 13.29251 | P2: =D2/E$46 -> 11.824693
A3: 30 | B3: KMU-Kreditgarantie-Programme | C3: 92 | D3: 54 | E3: =C3/(C3+D3) -> 0.63013699 | F3: =1-E3 -> 0.36986301 | G3: =C3/23 -> 4 | H3: =D3/15 -> 3.6 | I3: =(C3/B$45)*1000 -> 4.8904853 | J3: =(D3/B$46)*1000 -> 1.359789 | K3: =(C3/D$45)*1000 -> 6.0764291 | L3: =(D3/D$46)*1000 -> 1.4835198 | M3: =(C3/C$49)*100000 -> 0.41206241 | N3: =(D3/D$49)*100000 -> 0.095446438 | O3: =C3/E$45 -> 10.918847 | P3: =D3/E$46 -> 7.6931738
A4: 6 | B4: Steuerstundungen/-aufschub | C4: 68 | D4: 55 | E4: =C4/(C4+D4) -> 0.55284553 | F4: =1-E4 -> 0.44715447 | G4: =C4/23 -> 2.9565217 | H4: =D4/15 -> 3.6666667 | I4: =(C4/B$45)*1000 -> 3.6147065 | J4: =(D4/B$46)*1000 -> 1.3849702 | K4: =(C4/D$45)*1000 -> 4.4912737 | L4: =(D4/D$46)*1000 -> 1.5109924 | M4: =(C4/C$49)*100000 -> 0.30456787 | N4: =(D4/D$49)*100000 -> 0.097213964 | O4: =C4/E$45 -> 8.0704522 | P4: =D4/E$46 -> 7.83564
A5: exemption | B5: Steuer-/Abgabenbefreiungen | C5: 59 | D5: 46 | E5: =C5/(C5+D5) -> 0.56190476 | F5: =1-E5 -> 0.43809524 | G5: =C5/23 -> 2.5652174 | H5: =D5/15 -> 3.0666667 | I5: =(C5/B$45)*1000 -> 3.1362895 | J5: =(D5/B$46)*1000 -> 1.1583387 | K5: =(C5/D$45)*1000 -> 3.8968404 | L5: =(D5/D$46)*1000 -> 1.2637391 | M5: =(C5/C$49)*100000 -> 0.26425742 | N5: =(D5/D$49)*100000 -> 0.081306225 | O5: =C5/E$45 -> 7.0023041 | P5: =D5/E$46 -> 6.5534444
A6: 29 | B6: Lohnsubventionen (Kurzarbeit etc.) | C6: 63 | D6: 38 | E6: =C6/(C6+D6) -> 0.62376238 | F6: =1-E6 -> 0.37623762 | G6: =C6/23 -> 2.7391304 | H6: =D6/15 -> 2.5333333 | I6: =(C6/B$45)*1000 -> 3.3489193 | J6: =(D6/B$46)*1000 -> 0.95688852 | K6: =(C6/D$45)*1000 -> 4.161033 | L6: =(D6/D$46)*1000 -> 1.0439584 | M6: =(C6/C$49)*100000 -> 0.28217317 | N6: =(D6/D$49)*100000 -> 0.067166012 | O6: =C6/E$45 -> 7.4770366 | P6: =D6/E$46 -> 5.4137149
A7: 28 | B7: Ausweitung Sozialhilfe/Unterstützung | C7: 33 | D7: 33 | E7: =C7/(C7+D7) -> 0.5 | F7: =1-E7 -> 0.5 | G7: =C7/23 -> 1.4347826 | H7: =D7/15 -> 2.2 | I7: =(C7/B$45)*1000 -> 1.7541958 | J7: =(D7/B$46)*1000 -> 0.83098214 | K7: =(C7/D$45)*1000 -> 2.1795887 | L7: =(D7/D$46)*1000 -> 0.90659543 | M7: =(C7/C$49)*100000 -> 0.147805 | N7: =(D7/D$49)*100000 -> 0.058328379 | O7: =C7/E$45 -> 3.916543 | P7: =D7/E$46 -> 4.701384
A8: 34 | B8: Aufgestockte Lohnsubvention (100%) | C8: 48 | D8: 17 | E8: =C8/(C8+D8) -> 0.73846154 | F8: =1-E8 -> 0.26153846 | G8: =C8/23 -> 2.0869565 | H8: =D8/15 -> 1.1333333 | I8: =(C8/B$45)*1000 -> 2.5515575 | J8: =(D8/B$46)*1000 -> 0.42808171 | K8: =(C8/D$45)*1000 -> 3.1703108 | L8: =(D8/D$46)*1000 -> 0.46703401 | M8: =(C8/C$49)*100000 -> 0.21498908 | N8: =(D8/D$49)*100000 -> 0.030047953 | O8: =C8/E$45 -> 5.6967898 | P8: =D8/E$46 -> 2.4219251
